/*******************************************************************************
 * Copyright 2016 Zollern Wolf
 * - Zollern Galaxy
 * Galacticraft Add-On Mod
 * You CAN:
 * - Learn from it
 * - Use it to get ideas and concepts
 * You CAN'T:
 * - Redistribute it
 * - Claim it as your own
 * Steve Kung's "More Planets" mod was a big help.
 *******************************************************************************/

package galaxymod.worldgen.eden.village;

import galaxymod.blocks.BlockList;
import galaxymod.worldgen.NGWorldGenStructureCore;
import galaxymod.worldgen.eden.treasure.TreasureGenEden;
import java.util.Random;
import net.minecraft.init.Blocks;
import net.minecraft.world.World;

public class VillageHouseThree extends NGWorldGenStructureCore {
	
	public VillageHouseThree() {
	}
	
	@Override
	public boolean generate(World world, Random rand, int i, int j, int k) {
		// NovaHelper.echo("Attempting to spawn village house three..");
		if (!LocationIsValidSpawn(world, i, j, k)) {
			// NovaHelper.echo("Failed");
			return false;
		}
		
		NGEdenVillageHelper.spawnAlien(world, i - 2, j + 1, k + 0, 3);
		world.setBlock(i + 0, j + 0, k + 0, BlockList.edenCobbleRock);
		world.setBlock(i + 0, j + 0, k + 1, BlockList.edenCobbleRock);
		world.setBlock(i + 0, j + 0, k + 2, BlockList.edenCobbleRock);
		world.setBlock(i + 0, j + 0, k + 3, BlockList.edenCobbleRock);
		world.setBlock(i + 0, j + 0, k + 4, BlockList.edenCobbleRock);
		world.setBlock(i + 0, j + 0, k + 5, BlockList.edenCobbleRock);
		world.setBlock(i + 0, j + 0, k + 6, BlockList.edenCobbleRock);
		world.setBlock(i + 0, j + 0, k + 7, BlockList.edenCobbleRock);
		world.setBlock(i + 0, j + 0, k + 8, BlockList.edenCobbleRock);
		world.setBlock(i + 0, j + 0, k + 9, BlockList.edenCobbleRock);
		world.setBlock(i + 0, j + 1, k + 0, BlockList.edenWoodLog);
		world.setBlock(i + 0, j + 1, k + 1, BlockList.edenWoodPlanks);
		world.setBlock(i + 0, j + 1, k + 2, BlockList.edenWoodPlanks);
		world.setBlock(i + 0, j + 1, k + 3, BlockList.edenWoodPlanks);
		world.setBlock(i + 0, j + 1, k + 4, BlockList.edenWoodPlanks);
		world.setBlock(i + 0, j + 1, k + 5, BlockList.edenWoodPlanks);
		world.setBlock(i + 0, j + 1, k + 6, BlockList.edenCobbleRock);
		world.setBlock(i + 0, j + 1, k + 7, BlockList.edenCobbleRock);
		world.setBlock(i + 0, j + 1, k + 8, BlockList.edenCobbleRock);
		world.setBlock(i + 0, j + 1, k + 9, BlockList.edenCobbleRock);
		world.setBlock(i + 0, j + 2, k + 0, BlockList.edenWoodLog);
		world.setBlock(i + 0, j + 2, k + 1, BlockList.edenWoodPlanks);
		world.setBlock(i + 0, j + 2, k + 2, BlockList.edenGlass);
		world.setBlock(i + 0, j + 2, k + 3, BlockList.edenWoodPlanks);
		world.setBlock(i + 0, j + 2, k + 4, BlockList.edenGlass);
		world.setBlock(i + 0, j + 2, k + 5, BlockList.edenWoodPlanks);
		world.setBlock(i + 0, j + 2, k + 6, BlockList.edenCobbleRock);
		world.setBlock(i + 0, j + 2, k + 7, BlockList.edenCobbleRock);
		world.setBlock(i + 0, j + 2, k + 8, BlockList.edenCobbleRock);
		world.setBlock(i + 0, j + 2, k + 9, BlockList.edenCobbleRock);
		world.setBlock(i + 0, j + 3, k + 0, BlockList.edenWoodLog);
		world.setBlock(i + 0, j + 3, k + 1, BlockList.edenWoodPlanks);
		world.setBlock(i + 0, j + 3, k + 2, BlockList.edenWoodPlanks);
		world.setBlock(i + 0, j + 3, k + 3, BlockList.edenWoodPlanks);
		world.setBlock(i + 0, j + 3, k + 4, BlockList.edenWoodPlanks);
		world.setBlock(i + 0, j + 3, k + 5, BlockList.edenWoodPlanks);
		world.setBlock(i + 0, j + 3, k + 6, BlockList.edenCobbleRock);
		world.setBlock(i + 0, j + 3, k + 7, BlockList.edenCobbleRock);
		world.setBlock(i + 0, j + 3, k + 8, BlockList.edenCobbleRock);
		world.setBlock(i + 0, j + 3, k + 9, BlockList.edenCobbleRock);
		world.setBlock(i + 0, j + 4, k + 0, BlockList.edenWoodLog);
		world.setBlock(i + 0, j + 4, k + 1, BlockList.edenCobbleRock);
		world.setBlock(i + 0, j + 4, k + 2, BlockList.edenCobbleRock);
		world.setBlock(i + 0, j + 4, k + 3, BlockList.edenCobbleRock);
		world.setBlock(i + 0, j + 4, k + 4, BlockList.edenCobbleRock);
		world.setBlock(i + 0, j + 4, k + 5, BlockList.edenCobbleRock);
		world.setBlock(i + 0, j + 4, k + 6, BlockList.edenCobbleRock);
		world.setBlock(i + 0, j + 4, k + 7, BlockList.edenCobbleRock);
		world.setBlock(i + 0, j + 4, k + 8, BlockList.edenCobbleRock);
		world.setBlock(i + 0, j + 4, k + 9, BlockList.edenCobbleRock);
		world.setBlock(i + 0, j + 5, k + 0, Blocks.stone_slab);
		world.setBlock(i + 0, j + 5, k + 1, Blocks.stone_slab);
		world.setBlock(i + 0, j + 5, k + 2, Blocks.stone_slab);
		world.setBlock(i + 0, j + 5, k + 3, Blocks.stone_slab);
		world.setBlock(i + 0, j + 5, k + 4, Blocks.stone_slab);
		world.setBlock(i + 0, j + 5, k + 5, Blocks.stone_slab);
		world.setBlock(i + 0, j + 5, k + 6, Blocks.stone_slab);
		world.setBlock(i + 0, j + 5, k + 7, Blocks.stone_slab);
		world.setBlock(i + 0, j + 5, k + 8, Blocks.stone_slab);
		world.setBlock(i + 0, j + 5, k + 9, Blocks.stone_slab);
		world.setBlock(i + 1, j + 0, k + 0, BlockList.edenCobbleRock);
		world.setBlock(i + 1, j + 0, k + 1, BlockList.edenCobbleRock);
		world.setBlock(i + 1, j + 0, k + 2, BlockList.edenCobbleRock);
		world.setBlock(i + 1, j + 0, k + 3, BlockList.edenCobbleRock);
		world.setBlock(i + 1, j + 0, k + 4, BlockList.edenCobbleRock);
		world.setBlock(i + 1, j + 0, k + 5, BlockList.edenCobbleRock);
		world.setBlock(i + 1, j + 0, k + 6, BlockList.edenCobbleRock);
		world.setBlock(i + 1, j + 0, k + 7, BlockList.edenCobbleRock);
		world.setBlock(i + 1, j + 0, k + 8, BlockList.edenCobbleRock);
		world.setBlock(i + 1, j + 0, k + 9, BlockList.edenCobbleRock);
		world.setBlock(i + 1, j + 1, k + 0, BlockList.edenWoodPlanks);
		world.setBlock(i + 1, j + 1, k + 1, BlockList.edenWoodPlanks);
		world.setBlock(i + 1, j + 1, k + 6, BlockList.edenCobbleRock);
		world.setBlock(i + 1, j + 1, k + 9, BlockList.edenCobbleRock);
		world.setBlock(i + 1, j + 2, k + 0, BlockList.edenWoodPlanks);
		world.setBlock(i + 1, j + 2, k + 6, BlockList.edenCobbleRock);
		world.setBlock(i + 1, j + 2, k + 9, Blocks.iron_bars);
		world.setBlock(i + 1, j + 3, k + 0, BlockList.edenWoodPlanks);
		world.setBlock(i + 1, j + 3, k + 6, BlockList.edenCobbleRock);
		world.setBlock(i + 1, j + 3, k + 7, BlockList.edenCobbleRock);
		world.setBlock(i + 1, j + 3, k + 8, BlockList.edenCobbleRock);
		world.setBlock(i + 1, j + 3, k + 9, BlockList.edenCobbleRock);
		world.setBlock(i + 1, j + 4, k + 0, BlockList.edenCobbleRock);
		world.setBlock(i + 1, j + 4, k + 1, BlockList.edenCobbleRock);
		world.setBlock(i + 1, j + 4, k + 2, BlockList.edenCobbleRock);
		world.setBlock(i + 1, j + 4, k + 3, BlockList.edenCobbleRock);
		world.setBlock(i + 1, j + 4, k + 4, BlockList.edenCobbleRock);
		world.setBlock(i + 1, j + 4, k + 5, BlockList.edenCobbleRock);
		world.setBlock(i + 1, j + 4, k + 6, BlockList.edenCobbleRock);
		world.setBlock(i + 1, j + 4, k + 7, BlockList.edenCobbleRock);
		world.setBlock(i + 1, j + 4, k + 8, BlockList.edenCobbleRock);
		world.setBlock(i + 1, j + 4, k + 9, BlockList.edenCobbleRock);
		world.setBlock(i + 1, j + 5, k + 0, Blocks.stone_slab);
		world.setBlock(i + 1, j + 5, k + 9, Blocks.stone_slab);
		world.setBlock(i + 2, j + 0, k + 0, BlockList.edenCobbleRock);
		world.setBlock(i + 2, j + 0, k + 1, BlockList.edenCobbleRock);
		world.setBlock(i + 2, j + 0, k + 2, BlockList.edenCobbleRock);
		world.setBlock(i + 2, j + 0, k + 3, BlockList.edenCobbleRock);
		world.setBlock(i + 2, j + 0, k + 4, BlockList.edenCobbleRock);
		world.setBlock(i + 2, j + 0, k + 5, BlockList.edenCobbleRock);
		world.setBlock(i + 2, j + 0, k + 6, BlockList.edenCobbleRock);
		world.setBlock(i + 2, j + 0, k + 7, BlockList.edenCobbleRock);
		world.setBlock(i + 2, j + 0, k + 8, BlockList.edenCobbleRock);
		world.setBlock(i + 2, j + 0, k + 9, BlockList.edenCobbleRock);
		world.setBlock(i + 2, j + 1, k + 0, BlockList.edenWoodPlanks);
		world.setBlock(i + 2, j + 1, k + 2, Blocks.fence);
		world.setBlock(i + 2, j + 1, k + 6, BlockList.edenCobbleRock);
		world.setBlock(i + 2, j + 1, k + 7, BlockList.edenCobbleRock);
		world.setBlock(i + 2, j + 1, k + 8, BlockList.edenCobbleRock);
		world.setBlock(i + 2, j + 1, k + 9, BlockList.edenCobbleRock);
		world.setBlock(i + 2, j + 2, k + 0, BlockList.edenGlass);
		world.setBlock(i + 2, j + 2, k + 6, BlockList.edenCobbleRock);
		world.setBlock(i + 2, j + 2, k + 9, Blocks.iron_bars);
		world.setBlock(i + 2, j + 3, k + 0, BlockList.edenWoodPlanks);
		world.setBlock(i + 2, j + 3, k + 6, BlockList.edenCobbleRock);
		world.setBlock(i + 2, j + 3, k + 7, BlockList.edenCobbleRock);
		world.setBlock(i + 2, j + 3, k + 8, BlockList.edenCobbleRock);
		world.setBlock(i + 2, j + 3, k + 9, BlockList.edenCobbleRock);
		world.setBlock(i + 2, j + 4, k + 0, BlockList.edenCobbleRock);
		world.setBlock(i + 2, j + 4, k + 1, BlockList.edenCobbleRock);
		world.setBlock(i + 2, j + 4, k + 2, BlockList.edenCobbleRock);
		world.setBlock(i + 2, j + 4, k + 3, BlockList.edenCobbleRock);
		world.setBlock(i + 2, j + 4, k + 4, BlockList.edenCobbleRock);
		world.setBlock(i + 2, j + 4, k + 5, BlockList.edenCobbleRock);
		world.setBlock(i + 2, j + 4, k + 6, BlockList.edenCobbleRock);
		world.setBlock(i + 2, j + 4, k + 7, BlockList.edenCobbleRock);
		world.setBlock(i + 2, j + 4, k + 8, BlockList.edenCobbleRock);
		world.setBlock(i + 2, j + 4, k + 9, BlockList.edenCobbleRock);
		world.setBlock(i + 2, j + 5, k + 0, Blocks.stone_slab);
		world.setBlock(i + 2, j + 5, k + 9, Blocks.stone_slab);
		world.setBlock(i + 3, j + 0, k + 0, BlockList.edenCobbleRock);
		world.setBlock(i + 3, j + 0, k + 1, BlockList.edenCobbleRock);
		world.setBlock(i + 3, j + 0, k + 2, BlockList.edenCobbleRock);
		world.setBlock(i + 3, j + 0, k + 3, BlockList.edenCobbleRock);
		world.setBlock(i + 3, j + 0, k + 4, BlockList.edenCobbleRock);
		world.setBlock(i + 3, j + 0, k + 5, BlockList.edenCobbleRock);
		world.setBlock(i + 3, j + 0, k + 6, BlockList.edenCobbleRock);
		world.setBlock(i + 3, j + 0, k + 7, BlockList.edenCobbleRock);
		world.setBlock(i + 3, j + 0, k + 8, BlockList.edenCobbleRock);
		world.setBlock(i + 3, j + 0, k + 9, BlockList.edenCobbleRock);
		world.setBlock(i + 3, j + 1, k + 0, BlockList.edenWoodPlanks);
		world.setBlock(i + 3, j + 1, k + 4, BlockList.edenWoodPlanks);
		world.setBlock(i + 3, j + 1, k + 5, BlockList.edenWoodPlanks);
		world.setBlock(i + 3, j + 1, k + 6, BlockList.edenCobbleRock);
		world.setBlock(i + 3, j + 2, k + 0, BlockList.edenWoodPlanks);
		world.setBlock(i + 3, j + 2, k + 4, BlockList.edenWoodPlanks);
		world.setBlock(i + 3, j + 2, k + 5, BlockList.edenWoodPlanks);
		world.setBlock(i + 3, j + 2, k + 6, Blocks.furnace);
		world.setBlock(i + 3, j + 3, k + 0, BlockList.edenWoodPlanks);
		world.setBlock(i + 3, j + 3, k + 4, BlockList.edenWoodPlanks);
		world.setBlock(i + 3, j + 3, k + 5, BlockList.edenWoodPlanks);
		world.setBlock(i + 3, j + 3, k + 6, Blocks.furnace);
		world.setBlock(i + 3, j + 4, k + 0, BlockList.edenCobbleRock);
		world.setBlock(i + 3, j + 4, k + 1, BlockList.edenCobbleRock);
		world.setBlock(i + 3, j + 4, k + 2, BlockList.edenCobbleRock);
		world.setBlock(i + 3, j + 4, k + 3, BlockList.edenCobbleRock);
		world.setBlock(i + 3, j + 4, k + 4, BlockList.edenCobbleRock);
		world.setBlock(i + 3, j + 4, k + 5, BlockList.edenCobbleRock);
		world.setBlock(i + 3, j + 4, k + 6, BlockList.edenCobbleRock);
		world.setBlock(i + 3, j + 4, k + 7, BlockList.edenCobbleRock);
		world.setBlock(i + 3, j + 4, k + 8, BlockList.edenCobbleRock);
		world.setBlock(i + 3, j + 4, k + 9, BlockList.edenCobbleRock);
		world.setBlock(i + 3, j + 5, k + 0, Blocks.stone_slab);
		world.setBlock(i + 3, j + 5, k + 9, Blocks.stone_slab);
		world.setBlock(i + 4, j + 0, k + 0, BlockList.edenCobbleRock);
		world.setBlock(i + 4, j + 0, k + 1, BlockList.edenCobbleRock);
		world.setBlock(i + 4, j + 0, k + 2, BlockList.edenCobbleRock);
		world.setBlock(i + 4, j + 0, k + 3, BlockList.edenCobbleRock);
		world.setBlock(i + 4, j + 0, k + 4, BlockList.edenCobbleRock);
		world.setBlock(i + 4, j + 0, k + 5, BlockList.edenCobbleRock);
		world.setBlock(i + 4, j + 0, k + 6, BlockList.edenCobbleRock);
		world.setBlock(i + 4, j + 0, k + 7, BlockList.edenCobbleRock);
		world.setBlock(i + 4, j + 0, k + 8, BlockList.edenCobbleRock);
		world.setBlock(i + 4, j + 0, k + 9, BlockList.edenCobbleRock);
		world.setBlock(i + 4, j + 1, k + 0, BlockList.edenWoodPlanks);
		world.setBlock(i + 4, j + 1, k + 3, BlockList.edenWoodPlanks);
		world.setBlock(i + 4, j + 2, k + 0, BlockList.edenGlass);
		world.setBlock(i + 4, j + 2, k + 3, BlockList.edenWoodPlanks);
		world.setBlock(i + 4, j + 3, k + 0, BlockList.edenWoodPlanks);
		world.setBlock(i + 4, j + 3, k + 3, BlockList.edenWoodPlanks);
		world.setBlock(i + 4, j + 4, k + 0, BlockList.edenCobbleRock);
		world.setBlock(i + 4, j + 4, k + 1, BlockList.edenCobbleRock);
		world.setBlock(i + 4, j + 4, k + 2, BlockList.edenCobbleRock);
		world.setBlock(i + 4, j + 4, k + 3, BlockList.edenCobbleRock);
		world.setBlock(i + 4, j + 4, k + 4, BlockList.edenCobbleRock);
		world.setBlock(i + 4, j + 4, k + 5, BlockList.edenCobbleRock);
		world.setBlock(i + 4, j + 4, k + 6, BlockList.edenCobbleRock);
		world.setBlock(i + 4, j + 4, k + 7, BlockList.edenCobbleRock);
		world.setBlock(i + 4, j + 4, k + 8, BlockList.edenCobbleRock);
		world.setBlock(i + 4, j + 4, k + 9, BlockList.edenCobbleRock);
		world.setBlock(i + 4, j + 5, k + 0, Blocks.stone_slab);
		world.setBlock(i + 4, j + 5, k + 9, Blocks.stone_slab);
		world.setBlock(i + 5, j + 0, k + 0, BlockList.edenCobbleRock);
		world.setBlock(i + 5, j + 0, k + 1, BlockList.edenCobbleRock);
		world.setBlock(i + 5, j + 0, k + 2, BlockList.edenCobbleRock);
		world.setBlock(i + 5, j + 0, k + 3, BlockList.edenCobbleRock);
		world.setBlock(i + 5, j + 0, k + 4, BlockList.edenCobbleRock);
		world.setBlock(i + 5, j + 0, k + 5, BlockList.edenCobbleRock);
		world.setBlock(i + 5, j + 0, k + 6, BlockList.edenCobbleRock);
		world.setBlock(i + 5, j + 0, k + 7, BlockList.edenCobbleRock);
		world.setBlock(i + 5, j + 0, k + 8, BlockList.edenCobbleRock);
		world.setBlock(i + 5, j + 0, k + 9, BlockList.edenCobbleRock);
		world.setBlock(i + 5, j + 1, k + 0, BlockList.edenWoodPlanks);
		world.setBlock(i + 5, j + 1, k + 8, Blocks.stone_slab);
		world.setBlock(i + 5, j + 2, k + 0, BlockList.edenWoodPlanks);
		world.setBlock(i + 5, j + 3, k + 0, BlockList.edenWoodPlanks);
		world.setBlock(i + 5, j + 3, k + 3, BlockList.edenWoodPlanks);
		world.setBlock(i + 5, j + 4, k + 0, BlockList.edenCobbleRock);
		world.setBlock(i + 5, j + 4, k + 1, BlockList.edenCobbleRock);
		world.setBlock(i + 5, j + 4, k + 2, BlockList.edenCobbleRock);
		world.setBlock(i + 5, j + 4, k + 3, BlockList.edenCobbleRock);
		world.setBlock(i + 5, j + 4, k + 4, BlockList.edenCobbleRock);
		world.setBlock(i + 5, j + 4, k + 5, BlockList.edenCobbleRock);
		world.setBlock(i + 5, j + 4, k + 6, BlockList.edenCobbleRock);
		world.setBlock(i + 5, j + 4, k + 7, BlockList.edenCobbleRock);
		world.setBlock(i + 5, j + 4, k + 8, BlockList.edenCobbleRock);
		world.setBlock(i + 5, j + 4, k + 9, BlockList.edenCobbleRock);
		world.setBlock(i + 5, j + 5, k + 0, Blocks.stone_slab);
		world.setBlock(i + 5, j + 5, k + 9, Blocks.stone_slab);
		world.setBlock(i + 6, j + 0, k + 0, BlockList.edenCobbleRock);
		world.setBlock(i + 6, j + 0, k + 1, BlockList.edenCobbleRock);
		world.setBlock(i + 6, j + 0, k + 2, BlockList.edenCobbleRock);
		world.setBlock(i + 6, j + 0, k + 3, BlockList.edenCobbleRock);
		world.setBlock(i + 6, j + 0, k + 4, BlockList.edenCobbleRock);
		world.setBlock(i + 6, j + 0, k + 5, BlockList.edenCobbleRock);
		world.setBlock(i + 6, j + 0, k + 6, BlockList.edenCobbleRock);
		world.setBlock(i + 6, j + 0, k + 7, BlockList.edenCobbleRock);
		world.setBlock(i + 6, j + 0, k + 8, BlockList.edenCobbleRock);
		world.setBlock(i + 6, j + 0, k + 9, BlockList.edenCobbleRock);
		world.setBlock(i + 6, j + 1, k + 0, BlockList.edenWoodLog);
		world.setBlock(i + 6, j + 1, k + 1, BlockList.edenWoodPlanks);
		world.setBlock(i + 6, j + 1, k + 2, BlockList.edenWoodPlanks);
		world.setBlock(i + 6, j + 1, k + 3, BlockList.edenWoodLog);
		world.setBlock(i + 6, j + 1, k + 5, Blocks.fence);
		world.setBlock(i + 6, j + 1, k + 9, Blocks.fence);
		TreasureGenEden.addChest(i + 1, j + 1, k + 5, rand, world);
		world.setBlock(i + 6, j + 2, k + 0, BlockList.edenWoodLog);
		world.setBlock(i + 6, j + 2, k + 1, BlockList.edenWoodPlanks);
		world.setBlock(i + 6, j + 2, k + 2, BlockList.edenWoodPlanks);
		world.setBlock(i + 6, j + 2, k + 3, BlockList.edenWoodLog);
		world.setBlock(i + 6, j + 2, k + 5, Blocks.fence);
		world.setBlock(i + 6, j + 2, k + 9, Blocks.fence);
		world.setBlock(i + 6, j + 3, k + 0, BlockList.edenWoodLog);
		world.setBlock(i + 6, j + 3, k + 1, BlockList.edenWoodPlanks);
		world.setBlock(i + 6, j + 3, k + 2, BlockList.edenWoodPlanks);
		world.setBlock(i + 6, j + 3, k + 3, BlockList.edenWoodLog);
		world.setBlock(i + 6, j + 3, k + 5, Blocks.fence);
		world.setBlock(i + 6, j + 3, k + 9, Blocks.fence);
		world.setBlock(i + 6, j + 4, k + 0, BlockList.edenWoodLog);
		world.setBlock(i + 6, j + 4, k + 1, BlockList.edenCobbleRock);
		world.setBlock(i + 6, j + 4, k + 2, BlockList.edenCobbleRock);
		world.setBlock(i + 6, j + 4, k + 3, BlockList.edenWoodLog);
		world.setBlock(i + 6, j + 4, k + 4, BlockList.edenCobbleRock);
		world.setBlock(i + 6, j + 4, k + 5, BlockList.edenCobbleRock);
		world.setBlock(i + 6, j + 4, k + 6, BlockList.edenCobbleRock);
		world.setBlock(i + 6, j + 4, k + 7, BlockList.edenCobbleRock);
		world.setBlock(i + 6, j + 4, k + 8, BlockList.edenCobbleRock);
		world.setBlock(i + 6, j + 4, k + 9, BlockList.edenCobbleRock);
		world.setBlock(i + 6, j + 5, k + 0, Blocks.stone_slab);
		world.setBlock(i + 6, j + 5, k + 1, Blocks.stone_slab);
		world.setBlock(i + 6, j + 5, k + 2, Blocks.stone_slab);
		world.setBlock(i + 6, j + 5, k + 3, Blocks.stone_slab);
		world.setBlock(i + 6, j + 5, k + 4, Blocks.stone_slab);
		world.setBlock(i + 6, j + 5, k + 5, Blocks.stone_slab);
		world.setBlock(i + 6, j + 5, k + 6, Blocks.stone_slab);
		world.setBlock(i + 6, j + 5, k + 7, Blocks.stone_slab);
		world.setBlock(i + 6, j + 5, k + 8, Blocks.stone_slab);
		world.setBlock(i + 6, j + 5, k + 9, Blocks.stone_slab);
		world.setBlock(i + 1, j + 1, k + 7, Blocks.lava);
		world.setBlock(i + 1, j + 1, k + 8, Blocks.lava);
		world.setBlock(i + 2, j + 2, k + 2, Blocks.wooden_pressure_plate);
		// NovaHelper.echo("Success! At: " + i + " " + j + " " + k);
		return true;
	}
}