/**
 * Zollern Galaxy by @author Zollern Wolf
 * Copyright 2016 - 2025
 * You may use this code to learn from,
 * but do not claim it as your own, and
 * do not redistribute it.
 */
package zollerngalaxy.worldgen.eden;

import java.util.Random;
import net.minecraft.init.Blocks;
import net.minecraft.util.math.BlockPos;
import net.minecraft.world.World;
import zollerngalaxy.blocks.ZGBlocks;
import zollerngalaxy.core.ZGLootTables;
import zollerngalaxy.worldgen.ZGWorldGenMaster;

public class WorldGenDropship extends ZGWorldGenMaster {
	
	@Override
	public boolean generate(World worldIn, Random rand, BlockPos position) {
		if (!this.isValidSpawn(worldIn, position)) {
			return false;
		}
		
		this.setBlock(worldIn, position.add(5, 9, 9), ZGBlocks.blockViri);
		this.setBlock(worldIn, position.add(5, 9, 10), ZGBlocks.blockViri);
		this.setBlock(worldIn, position.add(5, 9, 11), ZGBlocks.blockViri);
		this.setBlock(worldIn, position.add(5, 9, 12), ZGBlocks.blockViri);
		this.setBlock(worldIn, position.add(5, 9, 18), ZGBlocks.blockViri);
		this.setBlock(worldIn, position.add(5, 9, 19), ZGBlocks.blockViri);
		this.setBlock(worldIn, position.add(5, 9, 20), ZGBlocks.blockViri);
		this.setBlock(worldIn, position.add(5, 9, 21), ZGBlocks.blockViri);
		this.setBlock(worldIn, position.add(5, 10, 9), ZGBlocks.blockViri);
		this.setBlock(worldIn, position.add(5, 10, 10), ZGBlocks.blockViri);
		this.setBlock(worldIn, position.add(5, 10, 11), ZGBlocks.blockViri);
		this.setBlock(worldIn, position.add(5, 10, 12), ZGBlocks.blockViri);
		this.setBlock(worldIn, position.add(5, 10, 18), ZGBlocks.blockViri);
		this.setBlock(worldIn, position.add(5, 10, 19), ZGBlocks.blockViri);
		this.setBlock(worldIn, position.add(5, 10, 20), ZGBlocks.blockViri);
		this.setBlock(worldIn, position.add(5, 10, 21), ZGBlocks.blockViri);
		this.setBlock(worldIn, position.add(5, 11, 10), ZGBlocks.edenBoneStone);
		this.setBlock(worldIn, position.add(5, 11, 11), ZGBlocks.edenBoneStone);
		this.setBlock(worldIn, position.add(5, 11, 19), ZGBlocks.edenBoneStone);
		this.setBlock(worldIn, position.add(5, 11, 20), ZGBlocks.edenBoneStone);
		this.setBlock(worldIn, position.add(6, 9, 10), ZGBlocks.blockRedObsidian);
		this.setBlock(worldIn, position.add(6, 9, 11), ZGBlocks.blockRedObsidian);
		this.setBlock(worldIn, position.add(6, 9, 19), ZGBlocks.blockRedObsidian);
		this.setBlock(worldIn, position.add(6, 9, 20), ZGBlocks.blockRedObsidian);
		this.setBlock(worldIn, position.add(6, 10, 10), ZGBlocks.blockRedObsidian);
		this.setBlock(worldIn, position.add(6, 10, 11), ZGBlocks.blockRedObsidian);
		this.setBlock(worldIn, position.add(6, 10, 19), ZGBlocks.blockRedObsidian);
		this.setBlock(worldIn, position.add(6, 10, 20), ZGBlocks.blockRedObsidian);
		this.setBlock(worldIn, position.add(6, 11, 10), ZGBlocks.blockViri);
		this.setBlock(worldIn, position.add(6, 11, 11), ZGBlocks.blockViri);
		this.setBlock(worldIn, position.add(6, 11, 19), ZGBlocks.blockViri);
		this.setBlock(worldIn, position.add(6, 11, 20), ZGBlocks.blockViri);
		this.setBlock(worldIn, position.add(7, 9, 9), ZGBlocks.blockRedObsidian);
		this.setBlock(worldIn, position.add(7, 9, 10), ZGBlocks.purgBlackRock);
		this.setBlock(worldIn, position.add(7, 9, 11), ZGBlocks.purgBlackRock);
		this.setBlock(worldIn, position.add(7, 9, 12), ZGBlocks.blockRedObsidian);
		this.setBlock(worldIn, position.add(7, 9, 18), ZGBlocks.blockRedObsidian);
		this.setBlock(worldIn, position.add(7, 9, 19), ZGBlocks.purgBlackRock);
		this.setBlock(worldIn, position.add(7, 9, 20), ZGBlocks.purgBlackRock);
		this.setBlock(worldIn, position.add(7, 9, 21), ZGBlocks.blockRedObsidian);
		this.setBlock(worldIn, position.add(7, 10, 9), ZGBlocks.blockRedObsidian);
		this.setBlock(worldIn, position.add(7, 10, 10), ZGBlocks.purgBlackRock);
		this.setBlock(worldIn, position.add(7, 10, 11), ZGBlocks.purgBlackRock);
		this.setBlock(worldIn, position.add(7, 10, 12), ZGBlocks.blockRedObsidian);
		this.setBlock(worldIn, position.add(7, 10, 18), ZGBlocks.blockRedObsidian);
		this.setBlock(worldIn, position.add(7, 10, 19), ZGBlocks.purgBlackRock);
		this.setBlock(worldIn, position.add(7, 10, 20), ZGBlocks.purgBlackRock);
		this.setBlock(worldIn, position.add(7, 10, 21), ZGBlocks.blockRedObsidian);
		this.setBlock(worldIn, position.add(7, 11, 10), ZGBlocks.edenBoneStone);
		this.setBlock(worldIn, position.add(7, 11, 11), ZGBlocks.edenBoneStone);
		this.setBlock(worldIn, position.add(7, 11, 19), ZGBlocks.edenBoneStone);
		this.setBlock(worldIn, position.add(7, 11, 20), ZGBlocks.edenBoneStone);
		this.setBlock(worldIn, position.add(8, 7, 15), ZGBlocks.blockRedObsidian);
		this.setBlock(worldIn, position.add(8, 8, 15), ZGBlocks.purgBlackRock);
		this.setBlock(worldIn, position.add(8, 11, 10), ZGBlocks.blockViri);
		this.setBlock(worldIn, position.add(8, 11, 11), ZGBlocks.blockViri);
		this.setBlock(worldIn, position.add(8, 11, 19), ZGBlocks.blockViri);
		this.setBlock(worldIn, position.add(8, 11, 20), ZGBlocks.blockViri);
		this.setBlock(worldIn, position.add(9, 11, 10), ZGBlocks.edenBoneStone);
		this.setBlock(worldIn, position.add(9, 11, 11), ZGBlocks.edenBoneStone);
		this.setBlock(worldIn, position.add(9, 11, 19), ZGBlocks.edenBoneStone);
		this.setBlock(worldIn, position.add(9, 11, 20), ZGBlocks.edenBoneStone);
		this.setBlock(worldIn, position.add(10, 6, 15), ZGBlocks.edenBoneStone);
		this.setBlock(worldIn, position.add(10, 11, 10), ZGBlocks.blockViri);
		this.setBlock(worldIn, position.add(10, 11, 11), ZGBlocks.blockViri);
		this.setBlock(worldIn, position.add(10, 11, 19), ZGBlocks.blockViri);
		this.setBlock(worldIn, position.add(10, 11, 20), ZGBlocks.blockViri);
		this.setBlock(worldIn, position.add(11, 6, 15), ZGBlocks.edenBoneStone);
		this.setBlock(worldIn, position.add(11, 9, 9), ZGBlocks.blockViri);
		this.setBlock(worldIn, position.add(11, 9, 10), ZGBlocks.blockViri);
		this.setBlock(worldIn, position.add(11, 9, 11), ZGBlocks.blockViri);
		this.setBlock(worldIn, position.add(11, 9, 12), ZGBlocks.blockViri);
		this.setBlock(worldIn, position.add(11, 9, 18), ZGBlocks.blockViri);
		this.setBlock(worldIn, position.add(11, 9, 19), ZGBlocks.blockViri);
		this.setBlock(worldIn, position.add(11, 9, 20), ZGBlocks.blockViri);
		this.setBlock(worldIn, position.add(11, 9, 21), ZGBlocks.blockViri);
		this.setBlock(worldIn, position.add(11, 11, 10), ZGBlocks.blockViri);
		this.setBlock(worldIn, position.add(11, 11, 11), ZGBlocks.blockViri);
		this.setBlock(worldIn, position.add(11, 11, 19), ZGBlocks.blockViri);
		this.setBlock(worldIn, position.add(11, 11, 20), ZGBlocks.blockViri);
		this.setBlock(worldIn, position.add(12, 7, 15), ZGBlocks.edenBoneStone);
		this.setBlock(worldIn, position.add(12, 9, 9), ZGBlocks.blockViri);
		this.setBlock(worldIn, position.add(12, 9, 10), ZGBlocks.blockViri);
		this.setBlock(worldIn, position.add(12, 9, 11), ZGBlocks.blockViri);
		this.setBlock(worldIn, position.add(12, 9, 12), ZGBlocks.blockViri);
		this.setBlock(worldIn, position.add(12, 9, 18), ZGBlocks.blockViri);
		this.setBlock(worldIn, position.add(12, 9, 19), ZGBlocks.blockViri);
		this.setBlock(worldIn, position.add(12, 9, 20), ZGBlocks.blockViri);
		this.setBlock(worldIn, position.add(12, 9, 21), ZGBlocks.blockViri);
		this.setBlock(worldIn, position.add(12, 10, 9), ZGBlocks.blockViri);
		this.setBlock(worldIn, position.add(12, 10, 10), ZGBlocks.blockViri);
		this.setBlock(worldIn, position.add(12, 10, 11), ZGBlocks.blockViri);
		this.setBlock(worldIn, position.add(12, 10, 12), ZGBlocks.blockViri);
		this.setBlock(worldIn, position.add(12, 10, 18), ZGBlocks.blockViri);
		this.setBlock(worldIn, position.add(12, 10, 19), ZGBlocks.blockViri);
		this.setBlock(worldIn, position.add(12, 10, 20), ZGBlocks.blockViri);
		this.setBlock(worldIn, position.add(12, 10, 21), ZGBlocks.blockViri);
		this.setBlock(worldIn, position.add(12, 11, 10), ZGBlocks.blockViri);
		this.setBlock(worldIn, position.add(12, 11, 11), ZGBlocks.blockViri);
		this.setBlock(worldIn, position.add(12, 11, 19), ZGBlocks.blockViri);
		this.setBlock(worldIn, position.add(12, 11, 20), ZGBlocks.blockViri);
		this.setBlock(worldIn, position.add(13, 7, 15), ZGBlocks.edenBoneStone);
		this.setBlock(worldIn, position.add(14, 7, 15), ZGBlocks.edenBoneStone);
		this.setBlock(worldIn, position.add(15, 7, 15), ZGBlocks.edenBoneStone);
		this.setBlock(worldIn, position.add(16, 7, 15), ZGBlocks.edenBoneStone);
		this.setBlock(worldIn, position.add(16, 9, 16), ZGBlocks.blockViri);
		this.setBlock(worldIn, position.add(17, 7, 15), ZGBlocks.edenBoneStone);
		this.setBlock(worldIn, position.add(17, 9, 16), ZGBlocks.blockViri);
		this.setBlock(worldIn, position.add(18, 6, 12), Blocks.GLASS);
		this.setBlock(worldIn, position.add(18, 6, 13), ZGBlocks.edenBoneStone);
		this.setBlock(worldIn, position.add(18, 6, 17), ZGBlocks.edenBoneStone);
		this.setBlock(worldIn, position.add(18, 6, 18), Blocks.GLASS);
		this.setBlock(worldIn, position.add(18, 7, 13), ZGBlocks.edenBoneStone);
		this.setBlock(worldIn, position.add(18, 7, 17), ZGBlocks.edenBoneStone);
		this.setBlock(worldIn, position.add(18, 8, 14), ZGBlocks.edenBoneStone);
		this.setBlock(worldIn, position.add(18, 8, 15), ZGBlocks.edenBoneStone);
		this.setBlock(worldIn, position.add(18, 8, 16), ZGBlocks.edenBoneStone);
		this.setBlock(worldIn, position.add(18, 9, 16), ZGBlocks.blockViri);
		this.setBlock(worldIn, position.add(19, 0, 14), Blocks.GLASS);
		this.setBlock(worldIn, position.add(19, 0, 15), Blocks.GLASS);
		this.setBlock(worldIn, position.add(19, 0, 16), Blocks.GLASS);
		this.setBlock(worldIn, position.add(19, 3, 9), Blocks.GLASS);
		this.setBlock(worldIn, position.add(19, 3, 10), Blocks.GLASS);
		this.setBlock(worldIn, position.add(19, 3, 11), Blocks.GLASS);
		this.setBlock(worldIn, position.add(19, 3, 19), Blocks.GLASS);
		this.setBlock(worldIn, position.add(19, 3, 20), Blocks.GLASS);
		this.setBlock(worldIn, position.add(19, 3, 21), Blocks.GLASS);
		this.setBlock(worldIn, position.add(19, 5, 12), ZGBlocks.edenBoneStone);
		this.setBlock(worldIn, position.add(19, 5, 13), ZGBlocks.edenBoneStone);
		this.setBlock(worldIn, position.add(19, 5, 17), ZGBlocks.edenBoneStone);
		this.setBlock(worldIn, position.add(19, 5, 18), ZGBlocks.edenBoneStone);
		this.setBlock(worldIn, position.add(19, 6, 5), ZGBlocks.blockViri);
		this.setBlock(worldIn, position.add(19, 6, 6), ZGBlocks.blockViri);
		this.setBlock(worldIn, position.add(19, 6, 12), ZGBlocks.edenBoneStone);
		this.setBlock(worldIn, position.add(19, 6, 13), ZGBlocks.edenBoneStone);
		this.setBlock(worldIn, position.add(19, 6, 17), ZGBlocks.edenBoneStone);
		this.setBlock(worldIn, position.add(19, 6, 18), ZGBlocks.edenBoneStone);
		this.setBlock(worldIn, position.add(19, 6, 24), ZGBlocks.blockViri);
		this.setBlock(worldIn, position.add(19, 6, 25), ZGBlocks.blockViri);
		this.setBlock(worldIn, position.add(19, 7, 12), Blocks.GLASS);
		this.setBlock(worldIn, position.add(19, 7, 13), ZGBlocks.edenBoneStone);
		this.setBlock(worldIn, position.add(19, 7, 17), ZGBlocks.edenBoneStone);
		this.setBlock(worldIn, position.add(19, 7, 18), Blocks.GLASS);
		this.setBlock(worldIn, position.add(19, 8, 14), ZGBlocks.edenBoneStone);
		this.setBlock(worldIn, position.add(19, 8, 15), ZGBlocks.edenBoneStone);
		this.setBlock(worldIn, position.add(19, 8, 16), ZGBlocks.edenBoneStone);
		this.setBlock(worldIn, position.add(19, 9, 16), ZGBlocks.blockViri);
		this.setBlock(worldIn, position.add(19, 10, 5), Blocks.GLASS);
		this.setBlock(worldIn, position.add(19, 10, 6), Blocks.GLASS);
		this.setBlock(worldIn, position.add(19, 10, 24), Blocks.GLASS);
		this.setBlock(worldIn, position.add(19, 10, 25), Blocks.GLASS);
		this.setBlock(worldIn, position.add(20, 1, 14), Blocks.GLASS);
		this.setBlock(worldIn, position.add(20, 1, 15), Blocks.GLASS);
		this.setBlock(worldIn, position.add(20, 1, 16), Blocks.GLASS);
		this.setBlock(worldIn, position.add(20, 2, 10), ZGBlocks.blockViri);
		this.setBlock(worldIn, position.add(20, 2, 20), ZGBlocks.blockViri);
		this.setBlock(worldIn, position.add(20, 4, 12), ZGBlocks.edenBoneStone);
		this.setBlock(worldIn, position.add(20, 4, 13), ZGBlocks.edenBoneStone);
		this.setBlock(worldIn, position.add(20, 4, 17), ZGBlocks.edenBoneStone);
		this.setBlock(worldIn, position.add(20, 4, 18), ZGBlocks.edenBoneStone);
		this.setBlock(worldIn, position.add(20, 5, 7), ZGBlocks.edenBoneStone);
		this.setBlock(worldIn, position.add(20, 5, 12), ZGBlocks.edenBoneStone);
		this.setBlock(worldIn, position.add(20, 5, 13), ZGBlocks.edenBoneStone);
		this.setBlock(worldIn, position.add(20, 5, 17), ZGBlocks.edenBoneStone);
		this.setBlock(worldIn, position.add(20, 5, 18), ZGBlocks.edenBoneStone);
		this.setBlock(worldIn, position.add(20, 5, 23), ZGBlocks.edenBoneStone);
		this.setBlock(worldIn, position.add(20, 6, 5), ZGBlocks.blockViri);
		this.setBlock(worldIn, position.add(20, 6, 6), ZGBlocks.blockViri);
		this.setBlock(worldIn, position.add(20, 6, 12), ZGBlocks.edenBoneStone);
		this.setBlock(worldIn, position.add(20, 6, 13), ZGBlocks.edenBoneStone);
		this.setBlock(worldIn, position.add(20, 6, 17), ZGBlocks.edenBoneStone);
		this.setBlock(worldIn, position.add(20, 6, 18), ZGBlocks.edenBoneStone);
		this.setBlock(worldIn, position.add(20, 6, 23), ZGBlocks.edenBoneStone);
		this.setBlock(worldIn, position.add(20, 6, 24), ZGBlocks.blockViri);
		this.setBlock(worldIn, position.add(20, 6, 25), ZGBlocks.blockViri);
		this.setBlock(worldIn, position.add(20, 7, 4), ZGBlocks.edenBoneStone);
		this.setBlock(worldIn, position.add(20, 7, 7), ZGBlocks.edenBoneStone);
		this.setBlock(worldIn, position.add(20, 7, 12), ZGBlocks.edenBoneStone);
		this.setBlock(worldIn, position.add(20, 7, 13), ZGBlocks.edenBoneStone);
		this.setBlock(worldIn, position.add(20, 7, 17), ZGBlocks.edenBoneStone);
		this.setBlock(worldIn, position.add(20, 7, 18), ZGBlocks.edenBoneStone);
		this.setBlock(worldIn, position.add(20, 8, 14), ZGBlocks.edenBoneStone);
		this.setBlock(worldIn, position.add(20, 8, 15), ZGBlocks.edenBoneStone);
		this.setBlock(worldIn, position.add(20, 8, 16), ZGBlocks.edenBoneStone);
		this.setBlock(worldIn, position.add(20, 8, 23), ZGBlocks.edenBoneStone);
		this.setBlock(worldIn, position.add(20, 9, 7), ZGBlocks.edenBoneStone);
		this.setBlock(worldIn, position.add(20, 9, 16), ZGBlocks.blockViri);
		this.setBlock(worldIn, position.add(20, 9, 23), ZGBlocks.edenBoneStone);
		this.setBlock(worldIn, position.add(21, 2, 9), ZGBlocks.edenBoneStone);
		this.setBlock(worldIn, position.add(21, 2, 10), ZGBlocks.edenBoneStone);
		this.setBlock(worldIn, position.add(21, 2, 11), ZGBlocks.edenBoneStone);
		this.setBlock(worldIn, position.add(21, 2, 14), Blocks.GLASS);
		this.setBlock(worldIn, position.add(21, 2, 15), Blocks.GLASS);
		this.setBlock(worldIn, position.add(21, 2, 16), Blocks.GLASS);
		this.setBlock(worldIn, position.add(21, 2, 19), ZGBlocks.edenBoneStone);
		this.setBlock(worldIn, position.add(21, 2, 20), ZGBlocks.edenBoneStone);
		this.setBlock(worldIn, position.add(21, 2, 21), ZGBlocks.edenBoneStone);
		this.setBlock(worldIn, position.add(21, 3, 9), ZGBlocks.edenBoneStone);
		this.setBlock(worldIn, position.add(21, 3, 10), ZGBlocks.edenBoneStone);
		this.setBlock(worldIn, position.add(21, 3, 11), ZGBlocks.edenBoneStone);
		this.setBlock(worldIn, position.add(21, 3, 13), ZGBlocks.edenBoneStone);
		this.setBlock(worldIn, position.add(21, 3, 17), ZGBlocks.edenBoneStone);
		this.setBlock(worldIn, position.add(21, 3, 19), ZGBlocks.edenBoneStone);
		this.setBlock(worldIn, position.add(21, 3, 20), ZGBlocks.edenBoneStone);
		this.setBlock(worldIn, position.add(21, 3, 21), ZGBlocks.edenBoneStone);
		this.setBlock(worldIn, position.add(21, 4, 12), ZGBlocks.purgBlackRock);
		this.setBlock(worldIn, position.add(21, 4, 13), ZGBlocks.blockRedObsidian);
		this.setBlock(worldIn, position.add(21, 4, 17), ZGBlocks.blockRedObsidian);
		this.setBlock(worldIn, position.add(21, 4, 18), ZGBlocks.purgBlackRock);
		this.setBlock(worldIn, position.add(21, 5, 5), ZGBlocks.blockViri);
		this.setBlock(worldIn, position.add(21, 5, 6), ZGBlocks.blockViri);
		this.setBlock(worldIn, position.add(21, 5, 7), ZGBlocks.edenBoneStone);
		this.setBlock(worldIn, position.add(21, 5, 12), ZGBlocks.edenBoneStone);
		this.setBlock(worldIn, position.add(21, 5, 18), ZGBlocks.edenBoneStone);
		this.setBlock(worldIn, position.add(21, 5, 24), ZGBlocks.blockViri);
		this.setBlock(worldIn, position.add(21, 5, 25), ZGBlocks.blockViri);
		this.setBlock(worldIn, position.add(21, 6, 5), ZGBlocks.blockViri);
		this.setBlock(worldIn, position.add(21, 6, 6), ZGBlocks.blockViri);
		this.setBlock(worldIn, position.add(21, 6, 12), ZGBlocks.edenBoneStone);
		this.setBlock(worldIn, position.add(21, 6, 18), ZGBlocks.edenBoneStone);
		this.setBlock(worldIn, position.add(21, 6, 23), ZGBlocks.edenBoneStone);
		this.setBlock(worldIn, position.add(21, 6, 24), ZGBlocks.blockViri);
		this.setBlock(worldIn, position.add(21, 6, 25), ZGBlocks.blockViri);
		this.setBlock(worldIn, position.add(21, 7, 4), ZGBlocks.edenBoneStone);
		this.setBlock(worldIn, position.add(21, 7, 7), ZGBlocks.edenBoneStone);
		this.setBlock(worldIn, position.add(21, 7, 12), ZGBlocks.edenBoneStone);
		this.setBlock(worldIn, position.add(21, 7, 18), ZGBlocks.edenBoneStone);
		this.setBlock(worldIn, position.add(21, 7, 23), ZGBlocks.edenBoneStone);
		this.setBlock(worldIn, position.add(21, 7, 26), ZGBlocks.edenBoneStone);
		this.setBlock(worldIn, position.add(21, 8, 12), ZGBlocks.edenBoneStone);
		this.setBlock(worldIn, position.add(21, 8, 14), ZGBlocks.edenBoneStone);
		this.setBlock(worldIn, position.add(21, 8, 15), ZGBlocks.edenBoneStone);
		this.setBlock(worldIn, position.add(21, 8, 16), ZGBlocks.edenBoneStone);
		this.setBlock(worldIn, position.add(21, 8, 18), ZGBlocks.edenBoneStone);
		this.setBlock(worldIn, position.add(21, 8, 23), ZGBlocks.edenBoneStone);
		this.setBlock(worldIn, position.add(21, 9, 7), ZGBlocks.edenBoneStone);
		this.setBlock(worldIn, position.add(21, 9, 16), ZGBlocks.blockViri);
		this.setBlock(worldIn, position.add(21, 11, 5), ZGBlocks.blockViri);
		this.setBlock(worldIn, position.add(21, 11, 6), ZGBlocks.blockViri);
		this.setBlock(worldIn, position.add(21, 11, 24), ZGBlocks.blockViri);
		this.setBlock(worldIn, position.add(21, 11, 25), ZGBlocks.blockViri);
		this.setBlock(worldIn, position.add(22, 2, 10), ZGBlocks.blockViri);
		this.setBlock(worldIn, position.add(22, 2, 20), ZGBlocks.blockViri);
		this.setBlock(worldIn, position.add(22, 3, 10), ZGBlocks.edenBoneStone);
		this.setBlock(worldIn, position.add(22, 3, 12), ZGBlocks.edenBoneStone);
		this.setBlock(worldIn, position.add(22, 3, 13), ZGBlocks.blockRedObsidian);
		this.setBlock(worldIn, position.add(22, 3, 17), ZGBlocks.blockRedObsidian);
		this.setBlock(worldIn, position.add(22, 3, 18), ZGBlocks.edenBoneStone);
		this.setBlock(worldIn, position.add(22, 3, 20), ZGBlocks.edenBoneStone);
		this.setBlock(worldIn, position.add(22, 4, 12), ZGBlocks.edenBoneStone);
		this.setBlock(worldIn, position.add(22, 4, 13), ZGBlocks.blockRedObsidian);
		this.setBlock(worldIn, position.add(22, 4, 17), ZGBlocks.blockRedObsidian);
		this.setBlock(worldIn, position.add(22, 4, 18), ZGBlocks.edenBoneStone);
		this.setBlock(worldIn, position.add(22, 5, 5), ZGBlocks.blockRedObsidian);
		this.setBlock(worldIn, position.add(22, 5, 6), ZGBlocks.blockRedObsidian);
		this.setBlock(worldIn, position.add(22, 5, 7), ZGBlocks.edenBoneStone);
		this.setBlock(worldIn, position.add(22, 5, 12), ZGBlocks.edenBoneStone);
		this.setBlock(worldIn, position.add(22, 5, 18), ZGBlocks.edenBoneStone);
		this.setBlock(worldIn, position.add(22, 5, 24), ZGBlocks.blockRedObsidian);
		this.setBlock(worldIn, position.add(22, 5, 25), ZGBlocks.blockRedObsidian);
		this.setBlock(worldIn, position.add(22, 6, 5), ZGBlocks.blockRedObsidian);
		this.setBlock(worldIn, position.add(22, 6, 6), ZGBlocks.blockRedObsidian);
		this.setBlock(worldIn, position.add(22, 6, 12), ZGBlocks.blockRedObsidian);
		this.setBlock(worldIn, position.add(22, 6, 18), ZGBlocks.blockRedObsidian);
		this.setBlock(worldIn, position.add(22, 6, 23), ZGBlocks.edenBoneStone);
		this.setBlock(worldIn, position.add(22, 6, 24), ZGBlocks.blockRedObsidian);
		this.setBlock(worldIn, position.add(22, 6, 25), ZGBlocks.blockRedObsidian);
		this.setBlock(worldIn, position.add(22, 7, 4), ZGBlocks.edenBoneStone);
		this.setBlock(worldIn, position.add(22, 7, 5), ZGBlocks.blockRedObsidian);
		this.setBlock(worldIn, position.add(22, 7, 6), ZGBlocks.blockRedObsidian);
		this.setBlock(worldIn, position.add(22, 7, 7), ZGBlocks.edenBoneStone);
		this.setBlock(worldIn, position.add(22, 7, 12), ZGBlocks.blockRedObsidian);
		this.setBlock(worldIn, position.add(22, 7, 18), ZGBlocks.blockRedObsidian);
		this.setBlock(worldIn, position.add(22, 7, 23), ZGBlocks.edenBoneStone);
		this.setBlock(worldIn, position.add(22, 7, 24), ZGBlocks.blockRedObsidian);
		this.setBlock(worldIn, position.add(22, 7, 25), ZGBlocks.blockRedObsidian);
		this.setBlock(worldIn, position.add(22, 7, 26), ZGBlocks.edenBoneStone);
		this.setBlock(worldIn, position.add(22, 8, 5), ZGBlocks.blockRedObsidian);
		this.setBlock(worldIn, position.add(22, 8, 6), ZGBlocks.blockRedObsidian);
		this.setBlock(worldIn, position.add(22, 8, 12), ZGBlocks.blockRedObsidian);
		this.setBlock(worldIn, position.add(22, 8, 13), ZGBlocks.blockRedObsidian);
		this.setBlock(worldIn, position.add(22, 8, 14), ZGBlocks.blockRedObsidian);
		this.setBlock(worldIn, position.add(22, 8, 15), ZGBlocks.blockRedObsidian);
		this.setBlock(worldIn, position.add(22, 8, 16), ZGBlocks.blockRedObsidian);
		this.setBlock(worldIn, position.add(22, 8, 17), ZGBlocks.blockRedObsidian);
		this.setBlock(worldIn, position.add(22, 8, 18), ZGBlocks.blockRedObsidian);
		this.setBlock(worldIn, position.add(22, 8, 23), ZGBlocks.edenBoneStone);
		this.setBlock(worldIn, position.add(22, 8, 24), ZGBlocks.blockRedObsidian);
		this.setBlock(worldIn, position.add(22, 8, 25), ZGBlocks.blockRedObsidian);
		this.setBlock(worldIn, position.add(22, 9, 5), ZGBlocks.blockRedObsidian);
		this.setBlock(worldIn, position.add(22, 9, 6), ZGBlocks.blockRedObsidian);
		this.setBlock(worldIn, position.add(22, 9, 7), ZGBlocks.edenBoneStone);
		this.setBlock(worldIn, position.add(22, 9, 24), ZGBlocks.blockRedObsidian);
		this.setBlock(worldIn, position.add(22, 9, 25), ZGBlocks.blockRedObsidian);
		this.setBlock(worldIn, position.add(22, 11, 5), ZGBlocks.blockViri);
		this.setBlock(worldIn, position.add(22, 11, 6), ZGBlocks.blockViri);
		this.setBlock(worldIn, position.add(22, 11, 24), ZGBlocks.blockViri);
		this.setBlock(worldIn, position.add(22, 11, 25), ZGBlocks.blockViri);
		this.setBlock(worldIn, position.add(23, 2, 10), ZGBlocks.blockViri);
		this.setBlock(worldIn, position.add(23, 2, 20), ZGBlocks.blockViri);
		this.setBlock(worldIn, position.add(23, 3, 10), ZGBlocks.edenBoneStone);
		this.setBlock(worldIn, position.add(23, 3, 12), ZGBlocks.edenBoneStone);
		this.setBlock(worldIn, position.add(23, 3, 18), ZGBlocks.edenBoneStone);
		this.setBlock(worldIn, position.add(23, 3, 20), ZGBlocks.edenBoneStone);
		this.setBlock(worldIn, position.add(23, 4, 11), ZGBlocks.blockViri);
		this.setBlock(worldIn, position.add(23, 4, 12), ZGBlocks.edenBoneStone);
		this.setBlock(worldIn, position.add(23, 4, 18), ZGBlocks.edenBoneStone);
		this.setBlock(worldIn, position.add(23, 4, 19), ZGBlocks.blockViri);
		this.setBlock(worldIn, position.add(23, 5, 5), ZGBlocks.purgBlackRock);
		this.setBlock(worldIn, position.add(23, 5, 6), ZGBlocks.purgBlackRock);
		this.setBlock(worldIn, position.add(23, 5, 7), ZGBlocks.edenBoneStone);
		this.setBlock(worldIn, position.add(23, 5, 12), ZGBlocks.blockViri);
		this.setBlock(worldIn, position.add(23, 5, 18), ZGBlocks.blockViri);
		this.setBlock(worldIn, position.add(23, 5, 24), ZGBlocks.purgBlackRock);
		this.setBlock(worldIn, position.add(23, 5, 25), ZGBlocks.purgBlackRock);
		this.setBlock(worldIn, position.add(23, 6, 5), ZGBlocks.purgBlackRock);
		this.setBlock(worldIn, position.add(23, 6, 6), ZGBlocks.purgBlackRock);
		this.setBlock(worldIn, position.add(23, 6, 8), ZGBlocks.edenBoneStone);
		this.setBlock(worldIn, position.add(23, 6, 12), ZGBlocks.blockRedObsidian);
		this.setBlock(worldIn, position.add(23, 6, 18), ZGBlocks.blockRedObsidian);
		this.setBlock(worldIn, position.add(23, 6, 22), ZGBlocks.edenBoneStone);
		this.setBlock(worldIn, position.add(23, 6, 23), ZGBlocks.edenBoneStone);
		this.setBlock(worldIn, position.add(23, 6, 24), ZGBlocks.purgBlackRock);
		this.setBlock(worldIn, position.add(23, 6, 25), ZGBlocks.purgBlackRock);
		this.setBlock(worldIn, position.add(23, 7, 4), ZGBlocks.edenBoneStone);
		this.setBlock(worldIn, position.add(23, 7, 5), ZGBlocks.purgBlackRock);
		this.setBlock(worldIn, position.add(23, 7, 6), ZGBlocks.purgBlackRock);
		this.setBlock(worldIn, position.add(23, 7, 7), ZGBlocks.edenBoneStone);
		this.setBlock(worldIn, position.add(23, 7, 8), ZGBlocks.edenBoneStone);
		this.setBlock(worldIn, position.add(23, 7, 9), ZGBlocks.purgBlackRock);
		this.setBlock(worldIn, position.add(23, 7, 10), ZGBlocks.purgBlackRock);
		this.setBlock(worldIn, position.add(23, 7, 11), ZGBlocks.purgBlackRock);
		this.setBlock(worldIn, position.add(23, 7, 12), ZGBlocks.edenBoneStone);
		this.setBlock(worldIn, position.add(23, 7, 13), ZGBlocks.blockRedObsidian);
		this.setBlock(worldIn, position.add(23, 7, 17), ZGBlocks.blockRedObsidian);
		this.setBlock(worldIn, position.add(23, 7, 18), ZGBlocks.edenBoneStone);
		this.setBlock(worldIn, position.add(23, 7, 19), ZGBlocks.purgBlackRock);
		this.setBlock(worldIn, position.add(23, 7, 20), ZGBlocks.purgBlackRock);
		this.setBlock(worldIn, position.add(23, 7, 21), ZGBlocks.purgBlackRock);
		this.setBlock(worldIn, position.add(23, 7, 22), ZGBlocks.edenBoneStone);
		this.setBlock(worldIn, position.add(23, 7, 23), ZGBlocks.edenBoneStone);
		this.setBlock(worldIn, position.add(23, 7, 24), ZGBlocks.purgBlackRock);
		this.setBlock(worldIn, position.add(23, 7, 25), ZGBlocks.purgBlackRock);
		this.setBlock(worldIn, position.add(23, 7, 26), ZGBlocks.edenBoneStone);
		this.setBlock(worldIn, position.add(23, 8, 5), ZGBlocks.purgBlackRock);
		this.setBlock(worldIn, position.add(23, 8, 6), ZGBlocks.purgBlackRock);
		this.setBlock(worldIn, position.add(23, 8, 8), ZGBlocks.edenBoneStone);
		this.setBlock(worldIn, position.add(23, 8, 9), Blocks.GLASS);
		this.setBlock(worldIn, position.add(23, 8, 10), Blocks.GLASS);
		this.setBlock(worldIn, position.add(23, 8, 11), Blocks.GLASS);
		this.setBlock(worldIn, position.add(23, 8, 12), ZGBlocks.blockRedObsidian);
		this.setBlock(worldIn, position.add(23, 8, 13), ZGBlocks.blockRedObsidian);
		this.setBlock(worldIn, position.add(23, 8, 14), ZGBlocks.blockRedObsidian);
		this.setBlock(worldIn, position.add(23, 8, 15), ZGBlocks.blockRedObsidian);
		this.setBlock(worldIn, position.add(23, 8, 16), ZGBlocks.blockRedObsidian);
		this.setBlock(worldIn, position.add(23, 8, 17), ZGBlocks.blockRedObsidian);
		this.setBlock(worldIn, position.add(23, 8, 18), ZGBlocks.blockRedObsidian);
		this.setBlock(worldIn, position.add(23, 8, 19), Blocks.GLASS);
		this.setBlock(worldIn, position.add(23, 8, 20), Blocks.GLASS);
		this.setBlock(worldIn, position.add(23, 8, 21), Blocks.GLASS);
		this.setBlock(worldIn, position.add(23, 8, 22), ZGBlocks.edenBoneStone);
		this.setBlock(worldIn, position.add(23, 8, 23), ZGBlocks.edenBoneStone);
		this.setBlock(worldIn, position.add(23, 8, 24), ZGBlocks.purgBlackRock);
		this.setBlock(worldIn, position.add(23, 8, 25), ZGBlocks.purgBlackRock);
		this.setBlock(worldIn, position.add(23, 9, 5), ZGBlocks.purgBlackRock);
		this.setBlock(worldIn, position.add(23, 9, 6), ZGBlocks.purgBlackRock);
		this.setBlock(worldIn, position.add(23, 9, 7), ZGBlocks.edenBoneStone);
		this.setBlock(worldIn, position.add(23, 9, 24), ZGBlocks.purgBlackRock);
		this.setBlock(worldIn, position.add(23, 9, 25), ZGBlocks.purgBlackRock);
		this.setBlock(worldIn, position.add(23, 11, 5), ZGBlocks.blockViri);
		this.setBlock(worldIn, position.add(23, 11, 6), ZGBlocks.blockViri);
		this.setBlock(worldIn, position.add(23, 11, 24), ZGBlocks.blockViri);
		this.setBlock(worldIn, position.add(23, 11, 25), ZGBlocks.blockViri);
		this.setBlock(worldIn, position.add(24, 1, 13), ZGBlocks.blockViri);
		this.setBlock(worldIn, position.add(24, 1, 17), ZGBlocks.blockViri);
		this.setBlock(worldIn, position.add(24, 2, 10), ZGBlocks.blockViri);
		this.setBlock(worldIn, position.add(24, 2, 13), ZGBlocks.blockViri);
		this.setBlock(worldIn, position.add(24, 2, 17), ZGBlocks.blockViri);
		this.setBlock(worldIn, position.add(24, 2, 20), ZGBlocks.blockViri);
		this.setBlock(worldIn, position.add(24, 3, 10), ZGBlocks.blockViri);
		this.setBlock(worldIn, position.add(24, 3, 12), ZGBlocks.edenBoneStone);
		this.setBlock(worldIn, position.add(24, 3, 18), ZGBlocks.edenBoneStone);
		this.setBlock(worldIn, position.add(24, 3, 20), ZGBlocks.blockViri);
		this.setBlock(worldIn, position.add(24, 4, 11), ZGBlocks.blockViri);
		this.setBlock(worldIn, position.add(24, 4, 12), ZGBlocks.edenBoneStone);
		this.setBlock(worldIn, position.add(24, 4, 19), ZGBlocks.blockViri);
		this.setBlock(worldIn, position.add(24, 5, 5), ZGBlocks.blockRedObsidian);
		this.setBlock(worldIn, position.add(24, 5, 6), ZGBlocks.blockRedObsidian);
		this.setBlock(worldIn, position.add(24, 5, 7), ZGBlocks.edenBoneStone);
		this.setBlock(worldIn, position.add(24, 5, 12), ZGBlocks.blockViri);
		this.setBlock(worldIn, position.add(24, 5, 18), ZGBlocks.blockViri);
		this.setBlock(worldIn, position.add(24, 5, 24), ZGBlocks.blockRedObsidian);
		this.setBlock(worldIn, position.add(24, 5, 25), ZGBlocks.blockRedObsidian);
		this.setBlock(worldIn, position.add(24, 6, 8), ZGBlocks.edenBoneStone);
		this.setBlock(worldIn, position.add(24, 6, 9), ZGBlocks.purgBlackRock);
		this.setBlock(worldIn, position.add(24, 6, 10), ZGBlocks.purgBlackRock);
		this.setBlock(worldIn, position.add(24, 6, 11), ZGBlocks.purgBlackRock);
		this.setBlock(worldIn, position.add(24, 6, 12), ZGBlocks.blockRedObsidian);
		this.setBlock(worldIn, position.add(24, 6, 18), ZGBlocks.blockRedObsidian);
		this.setBlock(worldIn, position.add(24, 6, 19), ZGBlocks.purgBlackRock);
		this.setBlock(worldIn, position.add(24, 6, 20), ZGBlocks.purgBlackRock);
		this.setBlock(worldIn, position.add(24, 6, 21), ZGBlocks.purgBlackRock);
		this.setBlock(worldIn, position.add(24, 6, 22), ZGBlocks.edenBoneStone);
		this.setBlock(worldIn, position.add(24, 6, 23), ZGBlocks.edenBoneStone);
		this.setBlock(worldIn, position.add(24, 7, 4), ZGBlocks.edenBoneStone);
		this.setBlock(worldIn, position.add(24, 7, 5), ZGBlocks.blockRedObsidian);
		this.setBlock(worldIn, position.add(24, 7, 6), ZGBlocks.blockRedObsidian);
		this.setBlock(worldIn, position.add(24, 7, 7), ZGBlocks.edenBoneStone);
		this.setBlock(worldIn, position.add(24, 7, 8), ZGBlocks.edenBoneStone);
		this.setBlock(worldIn, position.add(24, 7, 9), ZGBlocks.edenBoneStone);
		this.setBlock(worldIn, position.add(24, 7, 10), ZGBlocks.edenBoneStone);
		this.setBlock(worldIn, position.add(24, 7, 11), ZGBlocks.edenBoneStone);
		this.setBlock(worldIn, position.add(24, 7, 12), ZGBlocks.edenBoneStone);
		this.setBlock(worldIn, position.add(24, 7, 13), ZGBlocks.blockRedObsidian);
		this.setBlock(worldIn, position.add(24, 7, 17), ZGBlocks.blockRedObsidian);
		this.setBlock(worldIn, position.add(24, 7, 18), ZGBlocks.edenBoneStone);
		this.setBlock(worldIn, position.add(24, 7, 19), ZGBlocks.edenBoneStone);
		this.setBlock(worldIn, position.add(24, 7, 20), ZGBlocks.edenBoneStone);
		this.setBlock(worldIn, position.add(24, 7, 21), ZGBlocks.edenBoneStone);
		this.setBlock(worldIn, position.add(24, 7, 22), ZGBlocks.edenBoneStone);
		this.setBlock(worldIn, position.add(24, 7, 23), ZGBlocks.edenBoneStone);
		this.setBlock(worldIn, position.add(24, 7, 24), ZGBlocks.blockRedObsidian);
		this.setBlock(worldIn, position.add(24, 7, 25), ZGBlocks.blockRedObsidian);
		this.setBlock(worldIn, position.add(24, 7, 26), ZGBlocks.edenBoneStone);
		this.setBlock(worldIn, position.add(24, 8, 8), ZGBlocks.edenBoneStone);
		this.setBlock(worldIn, position.add(24, 8, 9), ZGBlocks.purgBlackRock);
		this.setBlock(worldIn, position.add(24, 8, 10), ZGBlocks.purgBlackRock);
		this.setBlock(worldIn, position.add(24, 8, 11), ZGBlocks.purgBlackRock);
		this.setBlock(worldIn, position.add(24, 8, 12), ZGBlocks.blockRedObsidian);
		this.setBlock(worldIn, position.add(24, 8, 13), ZGBlocks.blockRedObsidian);
		this.setBlock(worldIn, position.add(24, 8, 14), ZGBlocks.blockRedObsidian);
		this.setBlock(worldIn, position.add(24, 8, 15), ZGBlocks.blockRedObsidian);
		this.setBlock(worldIn, position.add(24, 8, 16), ZGBlocks.blockRedObsidian);
		this.setBlock(worldIn, position.add(24, 8, 17), ZGBlocks.blockRedObsidian);
		this.setBlock(worldIn, position.add(24, 8, 18), ZGBlocks.blockRedObsidian);
		this.setBlock(worldIn, position.add(24, 8, 19), ZGBlocks.purgBlackRock);
		this.setBlock(worldIn, position.add(24, 8, 20), ZGBlocks.purgBlackRock);
		this.setBlock(worldIn, position.add(24, 8, 21), ZGBlocks.purgBlackRock);
		this.setBlock(worldIn, position.add(24, 8, 22), ZGBlocks.edenBoneStone);
		this.setBlock(worldIn, position.add(24, 8, 23), ZGBlocks.edenBoneStone);
		this.setBlock(worldIn, position.add(24, 9, 5), ZGBlocks.blockRedObsidian);
		this.setBlock(worldIn, position.add(24, 9, 6), ZGBlocks.blockRedObsidian);
		this.setBlock(worldIn, position.add(24, 9, 24), ZGBlocks.blockRedObsidian);
		this.setBlock(worldIn, position.add(24, 9, 25), ZGBlocks.blockRedObsidian);
		this.setBlock(worldIn, position.add(24, 11, 5), ZGBlocks.blockViri);
		this.setBlock(worldIn, position.add(24, 11, 6), ZGBlocks.blockViri);
		this.setBlock(worldIn, position.add(24, 11, 24), ZGBlocks.blockViri);
		this.setBlock(worldIn, position.add(24, 11, 25), ZGBlocks.blockViri);
		this.setBlock(worldIn, position.add(25, 1, 13), ZGBlocks.blockViri);
		this.setBlock(worldIn, position.add(25, 1, 17), ZGBlocks.blockViri);
		this.setBlock(worldIn, position.add(25, 2, 9), ZGBlocks.edenBoneStone);
		this.setBlock(worldIn, position.add(25, 2, 10), ZGBlocks.blockViri);
		this.setBlock(worldIn, position.add(25, 2, 11), ZGBlocks.edenBoneStone);
		this.setBlock(worldIn, position.add(25, 2, 13), ZGBlocks.blockViri);
		this.setBlock(worldIn, position.add(25, 2, 17), ZGBlocks.blockViri);
		this.setBlock(worldIn, position.add(25, 2, 19), ZGBlocks.edenBoneStone);
		this.setBlock(worldIn, position.add(25, 2, 20), ZGBlocks.blockViri);
		this.setBlock(worldIn, position.add(25, 2, 21), ZGBlocks.edenBoneStone);
		this.setBlock(worldIn, position.add(25, 3, 9), ZGBlocks.edenBoneStone);
		this.setBlock(worldIn, position.add(25, 3, 11), ZGBlocks.edenBoneStone);
		this.setBlock(worldIn, position.add(25, 3, 12), ZGBlocks.edenBoneStone);
		this.setBlock(worldIn, position.add(25, 3, 18), ZGBlocks.edenBoneStone);
		this.setBlock(worldIn, position.add(25, 3, 19), ZGBlocks.edenBoneStone);
		this.setBlock(worldIn, position.add(25, 3, 21), ZGBlocks.edenBoneStone);
		this.setBlock(worldIn, position.add(25, 4, 11), ZGBlocks.blockViri);
		this.setBlock(worldIn, position.add(25, 4, 12), ZGBlocks.edenBoneStone);
		this.setBlock(worldIn, position.add(25, 4, 18), ZGBlocks.edenBoneStone);
		this.setBlock(worldIn, position.add(25, 4, 19), ZGBlocks.blockViri);
		this.setBlock(worldIn, position.add(25, 5, 7), ZGBlocks.edenBoneStone);
		this.setBlock(worldIn, position.add(25, 5, 12), ZGBlocks.blockViri);
		this.setBlock(worldIn, position.add(25, 5, 18), ZGBlocks.blockViri);
		this.setBlock(worldIn, position.add(25, 6, 8), ZGBlocks.edenBoneStone);
		this.setBlock(worldIn, position.add(25, 6, 12), ZGBlocks.blockRedObsidian);
		this.setBlock(worldIn, position.add(25, 6, 18), ZGBlocks.blockRedObsidian);
		this.setBlock(worldIn, position.add(25, 6, 22), ZGBlocks.edenBoneStone);
		this.setBlock(worldIn, position.add(25, 6, 23), ZGBlocks.edenBoneStone);
		this.setBlock(worldIn, position.add(25, 7, 4), ZGBlocks.edenBoneStone);
		this.setBlock(worldIn, position.add(25, 7, 7), ZGBlocks.edenBoneStone);
		this.setBlock(worldIn, position.add(25, 7, 8), ZGBlocks.edenBoneStone);
		this.setBlock(worldIn, position.add(25, 7, 9), ZGBlocks.purgBlackRock);
		this.setBlock(worldIn, position.add(25, 7, 10), ZGBlocks.purgBlackRock);
		this.setBlock(worldIn, position.add(25, 7, 11), ZGBlocks.purgBlackRock);
		this.setBlock(worldIn, position.add(25, 7, 12), ZGBlocks.edenBoneStone);
		this.setBlock(worldIn, position.add(25, 7, 14), ZGBlocks.edenBoneStone);
		this.setBlock(worldIn, position.add(25, 7, 15), ZGBlocks.edenBoneStone);
		this.setBlock(worldIn, position.add(25, 7, 16), ZGBlocks.edenBoneStone);
		this.setBlock(worldIn, position.add(25, 7, 18), ZGBlocks.edenBoneStone);
		this.setBlock(worldIn, position.add(25, 7, 19), ZGBlocks.purgBlackRock);
		this.setBlock(worldIn, position.add(25, 7, 20), ZGBlocks.purgBlackRock);
		this.setBlock(worldIn, position.add(25, 7, 21), ZGBlocks.purgBlackRock);
		this.setBlock(worldIn, position.add(25, 7, 22), ZGBlocks.edenBoneStone);
		this.setBlock(worldIn, position.add(25, 7, 23), ZGBlocks.edenBoneStone);
		this.setBlock(worldIn, position.add(25, 7, 26), ZGBlocks.edenBoneStone);
		this.setBlock(worldIn, position.add(25, 8, 8), ZGBlocks.edenBoneStone);
		this.setBlock(worldIn, position.add(25, 8, 12), ZGBlocks.blockRedObsidian);
		this.setBlock(worldIn, position.add(25, 8, 13), ZGBlocks.edenBoneStone);
		this.setBlock(worldIn, position.add(25, 8, 14), ZGBlocks.edenBoneStone);
		this.setBlock(worldIn, position.add(25, 8, 15), ZGBlocks.edenBoneStone);
		this.setBlock(worldIn, position.add(25, 8, 16), ZGBlocks.edenBoneStone);
		this.setBlock(worldIn, position.add(25, 8, 17), ZGBlocks.edenBoneStone);
		this.setBlock(worldIn, position.add(25, 8, 18), ZGBlocks.blockRedObsidian);
		this.setBlock(worldIn, position.add(25, 8, 22), ZGBlocks.edenBoneStone);
		this.setBlock(worldIn, position.add(25, 8, 23), ZGBlocks.edenBoneStone);
		this.setBlock(worldIn, position.add(25, 11, 5), ZGBlocks.blockViri);
		this.setBlock(worldIn, position.add(25, 11, 6), ZGBlocks.blockViri);
		this.setBlock(worldIn, position.add(25, 11, 24), ZGBlocks.blockViri);
		this.setBlock(worldIn, position.add(25, 11, 25), ZGBlocks.blockViri);
		this.setBlock(worldIn, position.add(26, 2, 9), ZGBlocks.edenBoneStone);
		this.setBlock(worldIn, position.add(26, 2, 10), ZGBlocks.blockViri);
		this.setBlock(worldIn, position.add(26, 2, 11), ZGBlocks.edenBoneStone);
		this.setBlock(worldIn, position.add(26, 2, 19), ZGBlocks.edenBoneStone);
		this.setBlock(worldIn, position.add(26, 2, 20), ZGBlocks.blockViri);
		this.setBlock(worldIn, position.add(26, 2, 21), ZGBlocks.edenBoneStone);
		this.setBlock(worldIn, position.add(26, 3, 9), ZGBlocks.edenBoneStone);
		this.setBlock(worldIn, position.add(26, 3, 10), ZGBlocks.edenBoneStone);
		this.setBlock(worldIn, position.add(26, 3, 11), ZGBlocks.edenBoneStone);
		this.setBlock(worldIn, position.add(26, 3, 12), ZGBlocks.edenBoneStone);
		this.setBlock(worldIn, position.add(26, 3, 15), ZGBlocks.blockRedObsidian);
		this.setBlock(worldIn, position.add(26, 3, 18), ZGBlocks.edenBoneStone);
		this.setBlock(worldIn, position.add(26, 3, 19), ZGBlocks.edenBoneStone);
		this.setBlock(worldIn, position.add(26, 3, 20), ZGBlocks.edenBoneStone);
		this.setBlock(worldIn, position.add(26, 3, 21), ZGBlocks.edenBoneStone);
		this.setBlock(worldIn, position.add(26, 4, 11), ZGBlocks.blockViri);
		this.setBlock(worldIn, position.add(26, 4, 12), ZGBlocks.edenBoneStone);
		this.setBlock(worldIn, position.add(26, 4, 18), ZGBlocks.edenBoneStone);
		this.setBlock(worldIn, position.add(26, 4, 19), ZGBlocks.blockViri);
		this.setBlock(worldIn, position.add(26, 5, 7), ZGBlocks.edenBoneStone);
		this.setBlock(worldIn, position.add(26, 5, 12), ZGBlocks.blockViri);
		this.setBlock(worldIn, position.add(26, 5, 18), ZGBlocks.blockViri);
		this.setBlock(worldIn, position.add(26, 6, 12), ZGBlocks.blockRedObsidian);
		this.setBlock(worldIn, position.add(26, 6, 18), ZGBlocks.blockRedObsidian);
		this.setBlock(worldIn, position.add(26, 6, 23), ZGBlocks.edenBoneStone);
		this.setBlock(worldIn, position.add(26, 7, 4), ZGBlocks.edenBoneStone);
		this.setBlock(worldIn, position.add(26, 7, 7), ZGBlocks.edenBoneStone);
		this.setBlock(worldIn, position.add(26, 7, 12), ZGBlocks.blockRedObsidian);
		this.setBlock(worldIn, position.add(26, 7, 18), ZGBlocks.blockRedObsidian);
		this.setBlock(worldIn, position.add(26, 7, 23), ZGBlocks.edenBoneStone);
		this.setBlock(worldIn, position.add(26, 7, 26), ZGBlocks.edenBoneStone);
		this.setBlock(worldIn, position.add(26, 8, 12), ZGBlocks.blockRedObsidian);
		this.setBlock(worldIn, position.add(26, 8, 18), ZGBlocks.blockRedObsidian);
		this.setBlock(worldIn, position.add(26, 8, 23), ZGBlocks.edenBoneStone);
		this.setBlock(worldIn, position.add(26, 9, 7), ZGBlocks.edenBoneStone);
		this.setBlock(worldIn, position.add(26, 11, 5), ZGBlocks.blockViri);
		this.setBlock(worldIn, position.add(26, 11, 6), ZGBlocks.blockViri);
		this.setBlock(worldIn, position.add(26, 11, 24), ZGBlocks.blockViri);
		this.setBlock(worldIn, position.add(26, 11, 25), ZGBlocks.blockViri);
		this.setBlock(worldIn, position.add(27, 2, 9), ZGBlocks.edenBoneStone);
		this.setBlock(worldIn, position.add(27, 2, 10), ZGBlocks.blockViri);
		this.setBlock(worldIn, position.add(27, 2, 11), ZGBlocks.edenBoneStone);
		this.setBlock(worldIn, position.add(27, 2, 19), ZGBlocks.edenBoneStone);
		this.setBlock(worldIn, position.add(27, 2, 20), ZGBlocks.blockViri);
		this.setBlock(worldIn, position.add(27, 2, 21), ZGBlocks.edenBoneStone);
		this.setBlock(worldIn, position.add(27, 3, 9), ZGBlocks.edenBoneStone);
		this.setBlock(worldIn, position.add(27, 3, 10), ZGBlocks.edenBoneStone);
		this.setBlock(worldIn, position.add(27, 3, 11), ZGBlocks.edenBoneStone);
		this.setBlock(worldIn, position.add(27, 3, 12), ZGBlocks.edenBoneStone);
		this.setBlock(worldIn, position.add(27, 3, 13), ZGBlocks.blockRedObsidian);
		this.setBlock(worldIn, position.add(27, 3, 17), ZGBlocks.blockRedObsidian);
		this.setBlock(worldIn, position.add(27, 3, 18), ZGBlocks.edenBoneStone);
		this.setBlock(worldIn, position.add(27, 3, 19), ZGBlocks.edenBoneStone);
		this.setBlock(worldIn, position.add(27, 3, 20), ZGBlocks.edenBoneStone);
		this.setBlock(worldIn, position.add(27, 3, 21), ZGBlocks.edenBoneStone);
		this.setBlock(worldIn, position.add(27, 4, 12), ZGBlocks.edenBoneStone);
		this.setBlock(worldIn, position.add(27, 4, 13), ZGBlocks.blockRedObsidian);
		this.setBlock(worldIn, position.add(27, 4, 17), ZGBlocks.blockRedObsidian);
		this.setBlock(worldIn, position.add(27, 4, 18), ZGBlocks.edenBoneStone);
		this.setBlock(worldIn, position.add(27, 5, 7), ZGBlocks.edenBoneStone);
		this.setBlock(worldIn, position.add(27, 5, 12), ZGBlocks.edenBoneStone);
		this.setBlock(worldIn, position.add(27, 5, 13), ZGBlocks.blockRedObsidian);
		this.setBlock(worldIn, position.add(27, 5, 17), ZGBlocks.blockRedObsidian);
		this.setBlock(worldIn, position.add(27, 5, 18), ZGBlocks.edenBoneStone);
		this.setBlock(worldIn, position.add(27, 6, 12), ZGBlocks.edenBoneStone);
		this.setBlock(worldIn, position.add(27, 6, 18), ZGBlocks.edenBoneStone);
		this.setBlock(worldIn, position.add(27, 6, 23), ZGBlocks.edenBoneStone);
		this.setBlock(worldIn, position.add(27, 7, 4), ZGBlocks.edenBoneStone);
		this.setBlock(worldIn, position.add(27, 7, 5), ZGBlocks.edenBoneStone);
		this.setBlock(worldIn, position.add(27, 7, 6), ZGBlocks.edenBoneStone);
		this.setBlock(worldIn, position.add(27, 7, 7), ZGBlocks.edenBoneStone);
		this.setBlock(worldIn, position.add(27, 7, 23), ZGBlocks.edenBoneStone);
		this.setBlock(worldIn, position.add(27, 7, 24), ZGBlocks.edenBoneStone);
		this.setBlock(worldIn, position.add(27, 7, 25), ZGBlocks.edenBoneStone);
		this.setBlock(worldIn, position.add(27, 7, 26), ZGBlocks.edenBoneStone);
		this.setBlock(worldIn, position.add(27, 8, 23), ZGBlocks.edenBoneStone);
		this.setBlock(worldIn, position.add(27, 9, 7), ZGBlocks.edenBoneStone);
		this.setBlock(worldIn, position.add(27, 11, 5), ZGBlocks.blockViri);
		this.setBlock(worldIn, position.add(27, 11, 6), ZGBlocks.blockViri);
		this.setBlock(worldIn, position.add(27, 11, 24), ZGBlocks.blockViri);
		this.setBlock(worldIn, position.add(27, 11, 25), ZGBlocks.blockViri);
		this.setBlock(worldIn, position.add(28, 2, 10), ZGBlocks.blockViri);
		this.setBlock(worldIn, position.add(28, 2, 20), ZGBlocks.blockViri);
		this.setBlock(worldIn, position.add(28, 3, 12), ZGBlocks.edenBoneStone);
		this.setBlock(worldIn, position.add(28, 3, 13), ZGBlocks.blockRedObsidian);
		this.setBlock(worldIn, position.add(28, 3, 17), ZGBlocks.blockRedObsidian);
		this.setBlock(worldIn, position.add(28, 3, 18), ZGBlocks.edenBoneStone);
		this.setBlock(worldIn, position.add(28, 4, 13), ZGBlocks.blockRedObsidian);
		this.setBlock(worldIn, position.add(28, 4, 17), ZGBlocks.blockRedObsidian);
		this.setBlock(worldIn, position.add(28, 4, 18), ZGBlocks.edenBoneStone);
		this.setBlock(worldIn, position.add(28, 5, 7), ZGBlocks.edenBoneStone);
		this.setBlock(worldIn, position.add(28, 5, 13), ZGBlocks.purgBlackRock);
		this.setBlock(worldIn, position.add(28, 5, 14), ZGBlocks.blockRedObsidian);
		this.setBlock(worldIn, position.add(28, 5, 16), ZGBlocks.blockRedObsidian);
		this.setBlock(worldIn, position.add(28, 5, 17), ZGBlocks.purgBlackRock);
		this.setBlock(worldIn, position.add(28, 5, 23), ZGBlocks.edenBoneStone);
		this.setBlock(worldIn, position.add(28, 6, 12), ZGBlocks.blockViri);
		this.setBlock(worldIn, position.add(28, 6, 14), ZGBlocks.blockRedObsidian);
		this.setBlock(worldIn, position.add(28, 6, 15), ZGBlocks.blockRedObsidian);
		this.setBlock(worldIn, position.add(28, 6, 16), ZGBlocks.blockRedObsidian);
		this.setBlock(worldIn, position.add(28, 6, 18), ZGBlocks.blockViri);
		this.setBlock(worldIn, position.add(28, 6, 23), ZGBlocks.edenBoneStone);
		this.setBlock(worldIn, position.add(28, 7, 4), ZGBlocks.edenBoneStone);
		this.setBlock(worldIn, position.add(28, 7, 5), ZGBlocks.edenBoneStone);
		this.setBlock(worldIn, position.add(28, 7, 6), ZGBlocks.edenBoneStone);
		this.setBlock(worldIn, position.add(28, 7, 7), ZGBlocks.edenBoneStone);
		this.setBlock(worldIn, position.add(28, 7, 24), ZGBlocks.edenBoneStone);
		this.setBlock(worldIn, position.add(28, 7, 25), ZGBlocks.edenBoneStone);
		this.setBlock(worldIn, position.add(28, 8, 15), ZGBlocks.blockViri);
		this.setBlock(worldIn, position.add(28, 8, 23), ZGBlocks.edenBoneStone);
		this.setBlock(worldIn, position.add(28, 9, 7), ZGBlocks.edenBoneStone);
		this.setBlock(worldIn, position.add(28, 9, 23), ZGBlocks.edenBoneStone);
		this.setBlock(worldIn, position.add(29, 2, 10), ZGBlocks.edenBoneStone);
		this.setBlock(worldIn, position.add(29, 2, 20), ZGBlocks.blockViri);
		this.setBlock(worldIn, position.add(29, 3, 10), ZGBlocks.blockViri);
		this.setBlock(worldIn, position.add(29, 3, 12), ZGBlocks.edenBoneStone);
		this.setBlock(worldIn, position.add(29, 3, 13), ZGBlocks.edenBoneStone);
		this.setBlock(worldIn, position.add(29, 3, 17), ZGBlocks.edenBoneStone);
		this.setBlock(worldIn, position.add(29, 3, 18), ZGBlocks.edenBoneStone);
		this.setBlock(worldIn, position.add(29, 4, 13), ZGBlocks.blockRedObsidian);
		this.setBlock(worldIn, position.add(29, 4, 17), ZGBlocks.blockRedObsidian);
		this.setBlock(worldIn, position.add(29, 5, 13), ZGBlocks.blockRedObsidian);
		this.setBlock(worldIn, position.add(29, 5, 17), ZGBlocks.blockRedObsidian);
		this.setBlock(worldIn, position.add(29, 6, 12), ZGBlocks.blockViri);
		this.setBlock(worldIn, position.add(29, 6, 18), ZGBlocks.blockViri);
		this.setBlock(worldIn, position.add(29, 8, 15), ZGBlocks.blockViri);
		this.setBlock(worldIn, position.add(30, 2, 10), ZGBlocks.blockViri);
		this.setBlock(worldIn, position.add(30, 2, 20), ZGBlocks.blockViri);
		this.setBlock(worldIn, position.add(30, 3, 13), ZGBlocks.edenBoneStone);
		this.setBlock(worldIn, position.add(30, 3, 17), ZGBlocks.edenBoneStone);
		this.setBlock(worldIn, position.add(30, 5, 13), ZGBlocks.blockViri);
		this.setBlock(worldIn, position.add(30, 5, 17), ZGBlocks.blockViri);
		this.setBlock(worldIn, position.add(30, 6, 12), ZGBlocks.blockViri);
		this.setBlock(worldIn, position.add(30, 6, 18), ZGBlocks.blockViri);
		this.setBlock(worldIn, position.add(30, 8, 15), ZGBlocks.blockViri);
		this.setBlock(worldIn, position.add(31, 2, 10), ZGBlocks.blockViri);
		this.setBlock(worldIn, position.add(31, 2, 20), ZGBlocks.blockViri);
		this.setBlock(worldIn, position.add(31, 3, 9), ZGBlocks.blockViri);
		this.setBlock(worldIn, position.add(31, 3, 11), ZGBlocks.blockViri);
		this.setBlock(worldIn, position.add(31, 3, 13), ZGBlocks.edenBoneStone);
		this.setBlock(worldIn, position.add(31, 3, 14), ZGBlocks.edenBoneStone);
		this.setBlock(worldIn, position.add(31, 3, 16), ZGBlocks.edenBoneStone);
		this.setBlock(worldIn, position.add(31, 3, 17), ZGBlocks.edenBoneStone);
		this.setBlock(worldIn, position.add(31, 3, 19), ZGBlocks.blockViri);
		this.setBlock(worldIn, position.add(31, 3, 21), ZGBlocks.blockViri);
		this.setBlock(worldIn, position.add(31, 6, 12), ZGBlocks.blockViri);
		this.setBlock(worldIn, position.add(31, 6, 18), ZGBlocks.blockViri);
		this.setBlock(worldIn, position.add(31, 8, 15), ZGBlocks.blockViri);
		this.setBlock(worldIn, position.add(32, 2, 10), ZGBlocks.blockViri);
		this.setBlock(worldIn, position.add(32, 2, 20), ZGBlocks.blockViri);
		this.setBlock(worldIn, position.add(32, 3, 13), ZGBlocks.edenBoneStone);
		this.setBlock(worldIn, position.add(32, 3, 14), ZGBlocks.edenBoneStone);
		this.setBlock(worldIn, position.add(32, 3, 15), Blocks.GLASS);
		this.setBlock(worldIn, position.add(32, 3, 16), ZGBlocks.edenBoneStone);
		this.setBlock(worldIn, position.add(32, 3, 17), ZGBlocks.edenBoneStone);
		this.setBlock(worldIn, position.add(32, 4, 13), ZGBlocks.edenBoneStone);
		this.setBlock(worldIn, position.add(32, 4, 17), ZGBlocks.edenBoneStone);
		this.setBlock(worldIn, position.add(32, 5, 13), ZGBlocks.blockViri);
		this.setBlock(worldIn, position.add(32, 5, 17), ZGBlocks.blockViri);
		this.setBlock(worldIn, position.add(32, 6, 12), ZGBlocks.blockViri);
		this.setBlock(worldIn, position.add(32, 6, 18), ZGBlocks.blockViri);
		this.setBlock(worldIn, position.add(32, 8, 15), ZGBlocks.blockViri);
		this.setBlock(worldIn, position.add(33, 2, 15), ZGBlocks.blockRedObsidian);
		this.setBlock(worldIn, position.add(33, 3, 14), ZGBlocks.edenBoneStone);
		this.setBlock(worldIn, position.add(33, 3, 15), ZGBlocks.purgBlackRock);
		this.setBlock(worldIn, position.add(33, 3, 16), ZGBlocks.edenBoneStone);
		this.setBlock(worldIn, position.add(33, 6, 12), ZGBlocks.blockViri);
		this.setBlock(worldIn, position.add(33, 6, 18), ZGBlocks.blockViri);
		this.setBlock(worldIn, position.add(33, 8, 15), ZGBlocks.blockViri);
		this.setBlock(worldIn, position.add(34, 3, 14), ZGBlocks.edenBoneStone);
		this.setBlock(worldIn, position.add(34, 3, 15), ZGBlocks.edenBoneStone);
		this.setBlock(worldIn, position.add(34, 4, 13), ZGBlocks.blockRedObsidian);
		this.setBlock(worldIn, position.add(34, 4, 14), ZGBlocks.blockRedObsidian);
		this.setBlock(worldIn, position.add(34, 4, 15), Blocks.GLASS);
		this.setBlock(worldIn, position.add(34, 4, 16), ZGBlocks.blockRedObsidian);
		this.setBlock(worldIn, position.add(34, 4, 17), ZGBlocks.blockRedObsidian);
		this.setBlock(worldIn, position.add(34, 6, 12), ZGBlocks.blockViri);
		this.setBlock(worldIn, position.add(34, 6, 18), ZGBlocks.blockViri);
		this.setBlock(worldIn, position.add(34, 8, 15), ZGBlocks.blockViri);
		this.setBlock(worldIn, position.add(35, 1, 15), ZGBlocks.blockViri);
		this.setBlock(worldIn, position.add(35, 2, 15), ZGBlocks.blockViri);
		this.setBlock(worldIn, position.add(35, 3, 14), ZGBlocks.edenBoneStone);
		this.setBlock(worldIn, position.add(35, 3, 15), ZGBlocks.blockRedObsidian);
		this.setBlock(worldIn, position.add(35, 3, 16), ZGBlocks.edenBoneStone);
		this.setBlock(worldIn, position.add(35, 4, 13), ZGBlocks.blockRedObsidian);
		this.setBlock(worldIn, position.add(35, 4, 14), ZGBlocks.purgBlackRock);
		this.setBlock(worldIn, position.add(35, 4, 15), ZGBlocks.blockRedObsidian);
		this.setBlock(worldIn, position.add(35, 4, 16), ZGBlocks.purgBlackRock);
		this.setBlock(worldIn, position.add(35, 4, 17), ZGBlocks.blockRedObsidian);
		this.setBlock(worldIn, position.add(35, 5, 14), ZGBlocks.blockRedObsidian);
		this.setBlock(worldIn, position.add(35, 5, 16), ZGBlocks.blockRedObsidian);
		this.setBlock(worldIn, position.add(35, 6, 12), ZGBlocks.blockViri);
		this.setBlock(worldIn, position.add(35, 6, 18), ZGBlocks.blockViri);
		this.setBlock(worldIn, position.add(36, 2, 15), ZGBlocks.blockViri);
		this.setBlock(worldIn, position.add(36, 3, 14), ZGBlocks.edenBoneStone);
		this.setBlock(worldIn, position.add(36, 3, 15), ZGBlocks.blockRedObsidian);
		this.setBlock(worldIn, position.add(36, 3, 16), ZGBlocks.edenBoneStone);
		this.setBlock(worldIn, position.add(36, 4, 13), ZGBlocks.blockRedObsidian);
		this.setBlock(worldIn, position.add(36, 4, 15), ZGBlocks.blockRedObsidian);
		this.setBlock(worldIn, position.add(36, 4, 17), ZGBlocks.blockRedObsidian);
		this.setBlock(worldIn, position.add(36, 6, 12), ZGBlocks.blockViri);
		this.setBlock(worldIn, position.add(36, 6, 13), ZGBlocks.blockViri);
		this.setBlock(worldIn, position.add(36, 6, 17), ZGBlocks.blockViri);
		this.setBlock(worldIn, position.add(36, 6, 18), ZGBlocks.blockViri);
		this.setBlock(worldIn, position.add(37, 3, 14), ZGBlocks.edenBoneStone);
		this.setBlock(worldIn, position.add(37, 3, 15), ZGBlocks.blockRedObsidian);
		this.setBlock(worldIn, position.add(37, 3, 16), ZGBlocks.edenBoneStone);
		this.setBlock(worldIn, position.add(37, 4, 13), ZGBlocks.blockRedObsidian);
		this.setBlock(worldIn, position.add(37, 4, 14), ZGBlocks.edenBoneStone);
		this.setBlock(worldIn, position.add(37, 4, 15), ZGBlocks.blockRedObsidian);
		this.setBlock(worldIn, position.add(37, 4, 16), ZGBlocks.edenBoneStone);
		this.setBlock(worldIn, position.add(37, 4, 17), ZGBlocks.blockRedObsidian);
		this.setBlock(worldIn, position.add(37, 6, 12), ZGBlocks.blockViri);
		this.setBlock(worldIn, position.add(37, 6, 13), ZGBlocks.blockViri);
		this.setBlock(worldIn, position.add(37, 6, 17), ZGBlocks.blockViri);
		this.setBlock(worldIn, position.add(37, 6, 18), ZGBlocks.blockViri);
		this.setBlock(worldIn, position.add(38, 3, 14), ZGBlocks.edenBoneStone);
		this.setBlock(worldIn, position.add(38, 3, 15), ZGBlocks.blockRedObsidian);
		this.setBlock(worldIn, position.add(38, 3, 16), ZGBlocks.edenBoneStone);
		this.setBlock(worldIn, position.add(38, 4, 13), ZGBlocks.blockRedObsidian);
		this.setBlock(worldIn, position.add(38, 4, 14), ZGBlocks.blockViri);
		this.setBlock(worldIn, position.add(38, 4, 16), ZGBlocks.blockViri);
		this.setBlock(worldIn, position.add(38, 4, 17), ZGBlocks.blockRedObsidian);
		this.setBlock(worldIn, position.add(38, 5, 14), ZGBlocks.blockRedObsidian);
		this.setBlock(worldIn, position.add(38, 5, 16), ZGBlocks.blockRedObsidian);
		this.setBlock(worldIn, position.add(38, 6, 12), ZGBlocks.blockViri);
		this.setBlock(worldIn, position.add(38, 6, 13), ZGBlocks.blockViri);
		this.setBlock(worldIn, position.add(38, 6, 17), ZGBlocks.blockViri);
		this.setBlock(worldIn, position.add(38, 6, 18), ZGBlocks.blockViri);
		this.setBlock(worldIn, position.add(39, 5, 15), Blocks.GLASS);
		this.setBlock(worldIn, position.add(39, 6, 12), ZGBlocks.blockViri);
		this.setBlock(worldIn, position.add(39, 6, 13), ZGBlocks.blockViri);
		this.setBlock(worldIn, position.add(39, 6, 14), ZGBlocks.blockViri);
		this.setBlock(worldIn, position.add(39, 6, 15), ZGBlocks.blockViri);
		this.setBlock(worldIn, position.add(39, 6, 16), ZGBlocks.blockViri);
		this.setBlock(worldIn, position.add(39, 6, 17), ZGBlocks.blockViri);
		this.setBlock(worldIn, position.add(39, 6, 18), ZGBlocks.blockViri);
		this.setBlock(worldIn, position.add(40, 6, 12), ZGBlocks.blockViri);
		this.setBlock(worldIn, position.add(40, 6, 13), ZGBlocks.blockViri);
		this.setBlock(worldIn, position.add(40, 6, 14), ZGBlocks.blockViri);
		this.setBlock(worldIn, position.add(40, 6, 15), ZGBlocks.blockViri);
		this.setBlock(worldIn, position.add(40, 6, 16), ZGBlocks.blockViri);
		this.setBlock(worldIn, position.add(40, 6, 17), ZGBlocks.blockViri);
		this.setBlock(worldIn, position.add(40, 6, 18), ZGBlocks.blockViri);
		this.setBlock(worldIn, position.add(41, 6, 14), ZGBlocks.blockViri);
		this.setBlock(worldIn, position.add(41, 6, 15), ZGBlocks.blockViri);
		this.setBlock(worldIn, position.add(41, 6, 16), ZGBlocks.blockViri);
		this.setBlock(worldIn, position.add(42, 6, 15), ZGBlocks.blockViri);
		this.setBlock(worldIn, position.add(3, 11, 9), ZGBlocks.blockRedObsidian);
		this.setBlock(worldIn, position.add(3, 11, 10), ZGBlocks.blockRedObsidian);
		this.setBlock(worldIn, position.add(3, 11, 11), ZGBlocks.blockRedObsidian);
		this.setBlock(worldIn, position.add(3, 11, 12), ZGBlocks.blockRedObsidian);
		this.setBlock(worldIn, position.add(3, 11, 18), ZGBlocks.blockRedObsidian);
		this.setBlock(worldIn, position.add(3, 11, 19), ZGBlocks.blockRedObsidian);
		this.setBlock(worldIn, position.add(3, 11, 20), ZGBlocks.blockRedObsidian);
		this.setBlock(worldIn, position.add(3, 11, 21), ZGBlocks.blockRedObsidian);
		this.setBlock(worldIn, position.add(25, 4, 15), ZGBlocks.blockRedObsidian);
		this.setBlock(worldIn, position.add(30, 4, 10), ZGBlocks.blockRedObsidian);
		this.setBlock(worldIn, position.add(30, 4, 20), ZGBlocks.blockRedObsidian);
		this.setBlock(worldIn, position.add(32, 4, 10), ZGBlocks.blockRedObsidian);
		this.setBlock(worldIn, position.add(32, 4, 20), ZGBlocks.blockRedObsidian);
		this.setBlock(worldIn, position.add(33, 4, 10), ZGBlocks.blockRedObsidian);
		this.setBlock(worldIn, position.add(33, 4, 20), ZGBlocks.blockRedObsidian);
		
		//
		BlockPos chestPos1 = position.add(37, 6, 15);
		ZGLootTables.generateChest(worldIn, chestPos1, rand, ZGLootTables.CHEST_DROPSHIP);
		//
		
		return true;
	}
	
}
