/**
 * Zollern Galaxy by @author Zollern Wolf
 * Copyright 2016 - 2025
 * You may use this code to learn from,
 * but do not claim it as your own, and
 * do not redistribute it.
 */
package zollerngalaxy.worldgen.caligro;

import java.util.Random;
import net.minecraft.block.Block;
import net.minecraft.init.Blocks;
import net.minecraft.util.math.BlockPos;
import net.minecraft.world.World;
import zollerngalaxy.blocks.ZGBlocks;
import zollerngalaxy.worldgen.ZGWorldGenMaster;

public class WorldGenShadowShrine extends ZGWorldGenMaster {
	
	@Override
	public boolean generate(World world, Random rand, BlockPos position) {
		if (!this.isValidSpawn(world, position)) {
			return false;
		}
		
		int i = position.getX();
		int j = position.getY();
		int k = position.getZ();
		
		// j -= 12;
		// j -= 2;
		// j += 10;
		
		Block NETHERIZED_OBSIDIAN = ZGBlocks.blockNetherizedObsidian;
		Block OBSIDIAN = Blocks.OBSIDIAN;
		
		setBlock(world, new BlockPos(i + 0, j + 0, k + 0), NETHERIZED_OBSIDIAN);
		setBlock(world, new BlockPos(i + 0, j + 0, k + 1), NETHERIZED_OBSIDIAN);
		setBlock(world, new BlockPos(i + 0, j + 0, k + 2), NETHERIZED_OBSIDIAN);
		setBlock(world, new BlockPos(i + 0, j + 0, k + 3), NETHERIZED_OBSIDIAN);
		setBlock(world, new BlockPos(i + 0, j + 0, k + 4), NETHERIZED_OBSIDIAN);
		setBlock(world, new BlockPos(i + 0, j + 0, k + 5), NETHERIZED_OBSIDIAN);
		setBlock(world, new BlockPos(i + 0, j + 0, k + 6), NETHERIZED_OBSIDIAN);
		setBlock(world, new BlockPos(i + 0, j + 0, k + 7), NETHERIZED_OBSIDIAN);
		setBlock(world, new BlockPos(i + 0, j + 0, k + 8), NETHERIZED_OBSIDIAN);
		setBlock(world, new BlockPos(i + 0, j + 0, k + 9), NETHERIZED_OBSIDIAN);
		setBlock(world, new BlockPos(i + 0, j + 0, k + 10), NETHERIZED_OBSIDIAN);
		setBlock(world, new BlockPos(i + 0, j + 0, k + 11), NETHERIZED_OBSIDIAN);
		setBlock(world, new BlockPos(i + 0, j + 0, k + 12), NETHERIZED_OBSIDIAN);
		setBlock(world, new BlockPos(i + 0, j + 0, k + 13), NETHERIZED_OBSIDIAN);
		setBlock(world, new BlockPos(i + 0, j + 0, k + 14), NETHERIZED_OBSIDIAN);
		setBlock(world, new BlockPos(i + 0, j + 0, k + 15), NETHERIZED_OBSIDIAN);
		setBlock(world, new BlockPos(i + 0, j + 0, k + 16), NETHERIZED_OBSIDIAN);
		setBlock(world, new BlockPos(i + 0, j + 0, k + 17), NETHERIZED_OBSIDIAN);
		setBlock(world, new BlockPos(i + 1, j + 0, k + 0), NETHERIZED_OBSIDIAN);
		setBlock(world, new BlockPos(i + 1, j + 0, k + 1), OBSIDIAN);
		setBlock(world, new BlockPos(i + 1, j + 0, k + 2), OBSIDIAN);
		setBlock(world, new BlockPos(i + 1, j + 0, k + 3), OBSIDIAN);
		setBlock(world, new BlockPos(i + 1, j + 0, k + 4), OBSIDIAN);
		setBlock(world, new BlockPos(i + 1, j + 0, k + 5), OBSIDIAN);
		setBlock(world, new BlockPos(i + 1, j + 0, k + 6), OBSIDIAN);
		setBlock(world, new BlockPos(i + 1, j + 0, k + 7), OBSIDIAN);
		setBlock(world, new BlockPos(i + 1, j + 0, k + 8), OBSIDIAN);
		setBlock(world, new BlockPos(i + 1, j + 0, k + 9), OBSIDIAN);
		setBlock(world, new BlockPos(i + 1, j + 0, k + 10), OBSIDIAN);
		setBlock(world, new BlockPos(i + 1, j + 0, k + 11), OBSIDIAN);
		setBlock(world, new BlockPos(i + 1, j + 0, k + 12), OBSIDIAN);
		setBlock(world, new BlockPos(i + 1, j + 0, k + 13), OBSIDIAN);
		setBlock(world, new BlockPos(i + 1, j + 0, k + 14), OBSIDIAN);
		setBlock(world, new BlockPos(i + 1, j + 0, k + 15), OBSIDIAN);
		setBlock(world, new BlockPos(i + 1, j + 0, k + 16), OBSIDIAN);
		setBlock(world, new BlockPos(i + 1, j + 0, k + 17), NETHERIZED_OBSIDIAN);
		setBlock(world, new BlockPos(i + 1, j + 1, k + 1), NETHERIZED_OBSIDIAN);
		setBlock(world, new BlockPos(i + 1, j + 1, k + 2), NETHERIZED_OBSIDIAN);
		setBlock(world, new BlockPos(i + 1, j + 1, k + 3), NETHERIZED_OBSIDIAN);
		setBlock(world, new BlockPos(i + 1, j + 1, k + 4), NETHERIZED_OBSIDIAN);
		setBlock(world, new BlockPos(i + 1, j + 1, k + 5), NETHERIZED_OBSIDIAN);
		setBlock(world, new BlockPos(i + 1, j + 1, k + 6), NETHERIZED_OBSIDIAN);
		setBlock(world, new BlockPos(i + 1, j + 1, k + 7), NETHERIZED_OBSIDIAN);
		setBlock(world, new BlockPos(i + 1, j + 1, k + 8), NETHERIZED_OBSIDIAN);
		setBlock(world, new BlockPos(i + 1, j + 1, k + 9), NETHERIZED_OBSIDIAN);
		setBlock(world, new BlockPos(i + 1, j + 1, k + 10), NETHERIZED_OBSIDIAN);
		setBlock(world, new BlockPos(i + 1, j + 1, k + 11), NETHERIZED_OBSIDIAN);
		setBlock(world, new BlockPos(i + 1, j + 1, k + 12), NETHERIZED_OBSIDIAN);
		setBlock(world, new BlockPos(i + 1, j + 1, k + 13), NETHERIZED_OBSIDIAN);
		setBlock(world, new BlockPos(i + 1, j + 1, k + 14), NETHERIZED_OBSIDIAN);
		setBlock(world, new BlockPos(i + 1, j + 1, k + 15), NETHERIZED_OBSIDIAN);
		setBlock(world, new BlockPos(i + 1, j + 1, k + 16), NETHERIZED_OBSIDIAN);
		setBlock(world, new BlockPos(i + 2, j + 0, k + 0), NETHERIZED_OBSIDIAN);
		setBlock(world, new BlockPos(i + 2, j + 0, k + 1), OBSIDIAN);
		setBlock(world, new BlockPos(i + 2, j + 0, k + 2), OBSIDIAN);
		setBlock(world, new BlockPos(i + 2, j + 0, k + 3), OBSIDIAN);
		setBlock(world, new BlockPos(i + 2, j + 0, k + 4), OBSIDIAN);
		setBlock(world, new BlockPos(i + 2, j + 0, k + 5), OBSIDIAN);
		setBlock(world, new BlockPos(i + 2, j + 0, k + 6), OBSIDIAN);
		setBlock(world, new BlockPos(i + 2, j + 0, k + 7), OBSIDIAN);
		setBlock(world, new BlockPos(i + 2, j + 0, k + 8), OBSIDIAN);
		setBlock(world, new BlockPos(i + 2, j + 0, k + 9), OBSIDIAN);
		setBlock(world, new BlockPos(i + 2, j + 0, k + 10), OBSIDIAN);
		setBlock(world, new BlockPos(i + 2, j + 0, k + 11), OBSIDIAN);
		setBlock(world, new BlockPos(i + 2, j + 0, k + 12), OBSIDIAN);
		setBlock(world, new BlockPos(i + 2, j + 0, k + 13), OBSIDIAN);
		setBlock(world, new BlockPos(i + 2, j + 0, k + 14), OBSIDIAN);
		setBlock(world, new BlockPos(i + 2, j + 0, k + 15), OBSIDIAN);
		setBlock(world, new BlockPos(i + 2, j + 0, k + 16), OBSIDIAN);
		setBlock(world, new BlockPos(i + 2, j + 0, k + 17), NETHERIZED_OBSIDIAN);
		setBlock(world, new BlockPos(i + 2, j + 1, k + 1), NETHERIZED_OBSIDIAN);
		setBlock(world, new BlockPos(i + 2, j + 1, k + 16), NETHERIZED_OBSIDIAN);
		setBlock(world, new BlockPos(i + 2, j + 2, k + 2), NETHERIZED_OBSIDIAN);
		setBlock(world, new BlockPos(i + 2, j + 2, k + 3), NETHERIZED_OBSIDIAN);
		setBlock(world, new BlockPos(i + 2, j + 2, k + 4), NETHERIZED_OBSIDIAN);
		setBlock(world, new BlockPos(i + 2, j + 2, k + 5), NETHERIZED_OBSIDIAN);
		setBlock(world, new BlockPos(i + 2, j + 2, k + 6), NETHERIZED_OBSIDIAN);
		setBlock(world, new BlockPos(i + 2, j + 2, k + 7), NETHERIZED_OBSIDIAN);
		setBlock(world, new BlockPos(i + 2, j + 2, k + 8), NETHERIZED_OBSIDIAN);
		setBlock(world, new BlockPos(i + 2, j + 2, k + 9), NETHERIZED_OBSIDIAN);
		setBlock(world, new BlockPos(i + 2, j + 2, k + 10), NETHERIZED_OBSIDIAN);
		setBlock(world, new BlockPos(i + 2, j + 2, k + 11), NETHERIZED_OBSIDIAN);
		setBlock(world, new BlockPos(i + 2, j + 2, k + 12), NETHERIZED_OBSIDIAN);
		setBlock(world, new BlockPos(i + 2, j + 2, k + 13), NETHERIZED_OBSIDIAN);
		setBlock(world, new BlockPos(i + 2, j + 2, k + 14), NETHERIZED_OBSIDIAN);
		setBlock(world, new BlockPos(i + 2, j + 2, k + 15), NETHERIZED_OBSIDIAN);
		setBlock(world, new BlockPos(i + 3, j + 0, k + 0), NETHERIZED_OBSIDIAN);
		setBlock(world, new BlockPos(i + 3, j + 0, k + 1), OBSIDIAN);
		setBlock(world, new BlockPos(i + 3, j + 0, k + 2), OBSIDIAN);
		setBlock(world, new BlockPos(i + 3, j + 0, k + 3), OBSIDIAN);
		setBlock(world, new BlockPos(i + 3, j + 0, k + 4), OBSIDIAN);
		setBlock(world, new BlockPos(i + 3, j + 0, k + 5), OBSIDIAN);
		setBlock(world, new BlockPos(i + 3, j + 0, k + 6), OBSIDIAN);
		setBlock(world, new BlockPos(i + 3, j + 0, k + 7), OBSIDIAN);
		setBlock(world, new BlockPos(i + 3, j + 0, k + 8), OBSIDIAN);
		setBlock(world, new BlockPos(i + 3, j + 0, k + 9), OBSIDIAN);
		setBlock(world, new BlockPos(i + 3, j + 0, k + 10), OBSIDIAN);
		setBlock(world, new BlockPos(i + 3, j + 0, k + 11), OBSIDIAN);
		setBlock(world, new BlockPos(i + 3, j + 0, k + 12), OBSIDIAN);
		setBlock(world, new BlockPos(i + 3, j + 0, k + 13), OBSIDIAN);
		setBlock(world, new BlockPos(i + 3, j + 0, k + 14), OBSIDIAN);
		setBlock(world, new BlockPos(i + 3, j + 0, k + 15), OBSIDIAN);
		setBlock(world, new BlockPos(i + 3, j + 0, k + 16), OBSIDIAN);
		setBlock(world, new BlockPos(i + 3, j + 0, k + 17), NETHERIZED_OBSIDIAN);
		setBlock(world, new BlockPos(i + 3, j + 1, k + 1), NETHERIZED_OBSIDIAN);
		setBlock(world, new BlockPos(i + 3, j + 1, k + 16), NETHERIZED_OBSIDIAN);
		setBlock(world, new BlockPos(i + 3, j + 2, k + 2), NETHERIZED_OBSIDIAN);
		setBlock(world, new BlockPos(i + 3, j + 2, k + 15), NETHERIZED_OBSIDIAN);
		setBlock(world, new BlockPos(i + 3, j + 3, k + 3), NETHERIZED_OBSIDIAN);
		setBlock(world, new BlockPos(i + 3, j + 3, k + 4), NETHERIZED_OBSIDIAN);
		setBlock(world, new BlockPos(i + 3, j + 3, k + 5), NETHERIZED_OBSIDIAN);
		setBlock(world, new BlockPos(i + 3, j + 3, k + 6), NETHERIZED_OBSIDIAN);
		setBlock(world, new BlockPos(i + 3, j + 3, k + 7), NETHERIZED_OBSIDIAN);
		setBlock(world, new BlockPos(i + 3, j + 3, k + 8), NETHERIZED_OBSIDIAN);
		setBlock(world, new BlockPos(i + 3, j + 3, k + 9), NETHERIZED_OBSIDIAN);
		setBlock(world, new BlockPos(i + 3, j + 3, k + 10), NETHERIZED_OBSIDIAN);
		setBlock(world, new BlockPos(i + 3, j + 3, k + 11), NETHERIZED_OBSIDIAN);
		setBlock(world, new BlockPos(i + 3, j + 3, k + 12), NETHERIZED_OBSIDIAN);
		setBlock(world, new BlockPos(i + 3, j + 3, k + 13), NETHERIZED_OBSIDIAN);
		setBlock(world, new BlockPos(i + 3, j + 3, k + 14), NETHERIZED_OBSIDIAN);
		setBlock(world, new BlockPos(i + 4, j + 0, k + 0), NETHERIZED_OBSIDIAN);
		setBlock(world, new BlockPos(i + 4, j + 0, k + 1), OBSIDIAN);
		setBlock(world, new BlockPos(i + 4, j + 0, k + 2), OBSIDIAN);
		setBlock(world, new BlockPos(i + 4, j + 0, k + 3), OBSIDIAN);
		setBlock(world, new BlockPos(i + 4, j + 0, k + 4), OBSIDIAN);
		setBlock(world, new BlockPos(i + 4, j + 0, k + 5), OBSIDIAN);
		setBlock(world, new BlockPos(i + 4, j + 0, k + 6), OBSIDIAN);
		setBlock(world, new BlockPos(i + 4, j + 0, k + 7), OBSIDIAN);
		setBlock(world, new BlockPos(i + 4, j + 0, k + 8), OBSIDIAN);
		setBlock(world, new BlockPos(i + 4, j + 0, k + 9), OBSIDIAN);
		setBlock(world, new BlockPos(i + 4, j + 0, k + 10), OBSIDIAN);
		setBlock(world, new BlockPos(i + 4, j + 0, k + 11), OBSIDIAN);
		setBlock(world, new BlockPos(i + 4, j + 0, k + 12), OBSIDIAN);
		setBlock(world, new BlockPos(i + 4, j + 0, k + 13), OBSIDIAN);
		setBlock(world, new BlockPos(i + 4, j + 0, k + 14), OBSIDIAN);
		setBlock(world, new BlockPos(i + 4, j + 0, k + 15), OBSIDIAN);
		setBlock(world, new BlockPos(i + 4, j + 0, k + 16), OBSIDIAN);
		setBlock(world, new BlockPos(i + 4, j + 0, k + 17), NETHERIZED_OBSIDIAN);
		setBlock(world, new BlockPos(i + 4, j + 1, k + 1), NETHERIZED_OBSIDIAN);
		setBlock(world, new BlockPos(i + 4, j + 1, k + 16), NETHERIZED_OBSIDIAN);
		setBlock(world, new BlockPos(i + 4, j + 2, k + 2), NETHERIZED_OBSIDIAN);
		setBlock(world, new BlockPos(i + 4, j + 2, k + 15), NETHERIZED_OBSIDIAN);
		setBlock(world, new BlockPos(i + 4, j + 3, k + 3), NETHERIZED_OBSIDIAN);
		setBlock(world, new BlockPos(i + 4, j + 3, k + 14), NETHERIZED_OBSIDIAN);
		setBlock(world, new BlockPos(i + 4, j + 4, k + 4), NETHERIZED_OBSIDIAN);
		setBlock(world, new BlockPos(i + 4, j + 4, k + 5), NETHERIZED_OBSIDIAN);
		setBlock(world, new BlockPos(i + 4, j + 4, k + 6), NETHERIZED_OBSIDIAN);
		setBlock(world, new BlockPos(i + 4, j + 4, k + 7), NETHERIZED_OBSIDIAN);
		setBlock(world, new BlockPos(i + 4, j + 4, k + 8), NETHERIZED_OBSIDIAN);
		setBlock(world, new BlockPos(i + 4, j + 4, k + 9), NETHERIZED_OBSIDIAN);
		setBlock(world, new BlockPos(i + 4, j + 4, k + 10), NETHERIZED_OBSIDIAN);
		setBlock(world, new BlockPos(i + 4, j + 4, k + 11), NETHERIZED_OBSIDIAN);
		setBlock(world, new BlockPos(i + 4, j + 4, k + 12), NETHERIZED_OBSIDIAN);
		setBlock(world, new BlockPos(i + 4, j + 4, k + 13), NETHERIZED_OBSIDIAN);
		setBlock(world, new BlockPos(i + 4, j + 5, k + 4), NETHERIZED_OBSIDIAN);
		setBlock(world, new BlockPos(i + 4, j + 5, k + 5), NETHERIZED_OBSIDIAN);
		setBlock(world, new BlockPos(i + 4, j + 5, k + 6), NETHERIZED_OBSIDIAN);
		setBlock(world, new BlockPos(i + 4, j + 5, k + 7), NETHERIZED_OBSIDIAN);
		setBlock(world, new BlockPos(i + 4, j + 5, k + 8), NETHERIZED_OBSIDIAN);
		setBlock(world, new BlockPos(i + 4, j + 5, k + 9), NETHERIZED_OBSIDIAN);
		setBlock(world, new BlockPos(i + 4, j + 5, k + 10), NETHERIZED_OBSIDIAN);
		setBlock(world, new BlockPos(i + 4, j + 5, k + 11), NETHERIZED_OBSIDIAN);
		setBlock(world, new BlockPos(i + 4, j + 5, k + 12), NETHERIZED_OBSIDIAN);
		setBlock(world, new BlockPos(i + 4, j + 5, k + 13), NETHERIZED_OBSIDIAN);
		setBlock(world, new BlockPos(i + 4, j + 6, k + 4), NETHERIZED_OBSIDIAN);
		setBlock(world, new BlockPos(i + 4, j + 6, k + 5), NETHERIZED_OBSIDIAN);
		setBlock(world, new BlockPos(i + 4, j + 6, k + 6), NETHERIZED_OBSIDIAN);
		setBlock(world, new BlockPos(i + 4, j + 6, k + 7), NETHERIZED_OBSIDIAN);
		setBlock(world, new BlockPos(i + 4, j + 6, k + 8), NETHERIZED_OBSIDIAN);
		setBlock(world, new BlockPos(i + 4, j + 6, k + 9), NETHERIZED_OBSIDIAN);
		setBlock(world, new BlockPos(i + 4, j + 6, k + 10), NETHERIZED_OBSIDIAN);
		setBlock(world, new BlockPos(i + 4, j + 6, k + 11), NETHERIZED_OBSIDIAN);
		setBlock(world, new BlockPos(i + 4, j + 6, k + 12), NETHERIZED_OBSIDIAN);
		setBlock(world, new BlockPos(i + 4, j + 6, k + 13), NETHERIZED_OBSIDIAN);
		setBlock(world, new BlockPos(i + 4, j + 7, k + 4), NETHERIZED_OBSIDIAN);
		setBlock(world, new BlockPos(i + 4, j + 7, k + 5), NETHERIZED_OBSIDIAN);
		setBlock(world, new BlockPos(i + 4, j + 7, k + 6), NETHERIZED_OBSIDIAN);
		setBlock(world, new BlockPos(i + 4, j + 7, k + 7), NETHERIZED_OBSIDIAN);
		setBlock(world, new BlockPos(i + 4, j + 7, k + 8), NETHERIZED_OBSIDIAN);
		setBlock(world, new BlockPos(i + 4, j + 7, k + 9), NETHERIZED_OBSIDIAN);
		setBlock(world, new BlockPos(i + 4, j + 7, k + 10), NETHERIZED_OBSIDIAN);
		setBlock(world, new BlockPos(i + 4, j + 7, k + 11), NETHERIZED_OBSIDIAN);
		setBlock(world, new BlockPos(i + 4, j + 7, k + 12), NETHERIZED_OBSIDIAN);
		setBlock(world, new BlockPos(i + 4, j + 7, k + 13), NETHERIZED_OBSIDIAN);
		setBlock(world, new BlockPos(i + 4, j + 8, k + 4), NETHERIZED_OBSIDIAN);
		setBlock(world, new BlockPos(i + 4, j + 8, k + 5), NETHERIZED_OBSIDIAN);
		setBlock(world, new BlockPos(i + 4, j + 8, k + 6), NETHERIZED_OBSIDIAN);
		setBlock(world, new BlockPos(i + 4, j + 8, k + 7), NETHERIZED_OBSIDIAN);
		setBlock(world, new BlockPos(i + 4, j + 8, k + 8), NETHERIZED_OBSIDIAN);
		setBlock(world, new BlockPos(i + 4, j + 8, k + 9), NETHERIZED_OBSIDIAN);
		setBlock(world, new BlockPos(i + 4, j + 8, k + 10), NETHERIZED_OBSIDIAN);
		setBlock(world, new BlockPos(i + 4, j + 8, k + 11), NETHERIZED_OBSIDIAN);
		setBlock(world, new BlockPos(i + 4, j + 8, k + 12), NETHERIZED_OBSIDIAN);
		setBlock(world, new BlockPos(i + 4, j + 8, k + 13), NETHERIZED_OBSIDIAN);
		setBlock(world, new BlockPos(i + 4, j + 9, k + 4), NETHERIZED_OBSIDIAN);
		setBlock(world, new BlockPos(i + 4, j + 9, k + 5), NETHERIZED_OBSIDIAN);
		setBlock(world, new BlockPos(i + 4, j + 9, k + 6), NETHERIZED_OBSIDIAN);
		setBlock(world, new BlockPos(i + 4, j + 9, k + 7), NETHERIZED_OBSIDIAN);
		setBlock(world, new BlockPos(i + 4, j + 9, k + 8), NETHERIZED_OBSIDIAN);
		setBlock(world, new BlockPos(i + 4, j + 9, k + 9), NETHERIZED_OBSIDIAN);
		setBlock(world, new BlockPos(i + 4, j + 9, k + 10), NETHERIZED_OBSIDIAN);
		setBlock(world, new BlockPos(i + 4, j + 9, k + 11), NETHERIZED_OBSIDIAN);
		setBlock(world, new BlockPos(i + 4, j + 9, k + 12), NETHERIZED_OBSIDIAN);
		setBlock(world, new BlockPos(i + 4, j + 9, k + 13), NETHERIZED_OBSIDIAN);
		setBlock(world, new BlockPos(i + 5, j + 0, k + 0), NETHERIZED_OBSIDIAN);
		setBlock(world, new BlockPos(i + 5, j + 0, k + 1), OBSIDIAN);
		setBlock(world, new BlockPos(i + 5, j + 0, k + 2), OBSIDIAN);
		setBlock(world, new BlockPos(i + 5, j + 0, k + 3), OBSIDIAN);
		setBlock(world, new BlockPos(i + 5, j + 0, k + 4), OBSIDIAN);
		setBlock(world, new BlockPos(i + 5, j + 0, k + 5), OBSIDIAN);
		setBlock(world, new BlockPos(i + 5, j + 0, k + 6), OBSIDIAN);
		setBlock(world, new BlockPos(i + 5, j + 0, k + 7), OBSIDIAN);
		setBlock(world, new BlockPos(i + 5, j + 0, k + 8), OBSIDIAN);
		setBlock(world, new BlockPos(i + 5, j + 0, k + 9), OBSIDIAN);
		setBlock(world, new BlockPos(i + 5, j + 0, k + 10), OBSIDIAN);
		setBlock(world, new BlockPos(i + 5, j + 0, k + 11), OBSIDIAN);
		setBlock(world, new BlockPos(i + 5, j + 0, k + 12), OBSIDIAN);
		setBlock(world, new BlockPos(i + 5, j + 0, k + 13), OBSIDIAN);
		setBlock(world, new BlockPos(i + 5, j + 0, k + 14), OBSIDIAN);
		setBlock(world, new BlockPos(i + 5, j + 0, k + 15), OBSIDIAN);
		setBlock(world, new BlockPos(i + 5, j + 0, k + 16), OBSIDIAN);
		setBlock(world, new BlockPos(i + 5, j + 0, k + 17), NETHERIZED_OBSIDIAN);
		setBlock(world, new BlockPos(i + 5, j + 1, k + 1), NETHERIZED_OBSIDIAN);
		//
		// if (rand.nextInt(500) <= 125) {
		// BlockPos chestPos = new BlockPos(i + 5, j + 1, k + 13);
		// ZGLootTables.generateChest(world, chestPos, rand, ZGLootTables.CHEST_SHADOW_BOSS);
		// }
		//
		setBlock(world, new BlockPos(i + 5, j + 1, k + 16), NETHERIZED_OBSIDIAN);
		setBlock(world, new BlockPos(i + 5, j + 2, k + 2), NETHERIZED_OBSIDIAN);
		setBlock(world, new BlockPos(i + 5, j + 2, k + 15), NETHERIZED_OBSIDIAN);
		setBlock(world, new BlockPos(i + 5, j + 3, k + 3), NETHERIZED_OBSIDIAN);
		setBlock(world, new BlockPos(i + 5, j + 3, k + 14), NETHERIZED_OBSIDIAN);
		setBlock(world, new BlockPos(i + 5, j + 4, k + 4), NETHERIZED_OBSIDIAN);
		setBlock(world, new BlockPos(i + 5, j + 4, k + 13), NETHERIZED_OBSIDIAN);
		setBlock(world, new BlockPos(i + 5, j + 5, k + 4), NETHERIZED_OBSIDIAN);
		setBlock(world, new BlockPos(i + 5, j + 5, k + 13), NETHERIZED_OBSIDIAN);
		setBlock(world, new BlockPos(i + 5, j + 6, k + 4), NETHERIZED_OBSIDIAN);
		setBlock(world, new BlockPos(i + 5, j + 6, k + 13), NETHERIZED_OBSIDIAN);
		setBlock(world, new BlockPos(i + 5, j + 7, k + 4), NETHERIZED_OBSIDIAN);
		setBlock(world, new BlockPos(i + 5, j + 7, k + 13), NETHERIZED_OBSIDIAN);
		setBlock(world, new BlockPos(i + 5, j + 8, k + 4), NETHERIZED_OBSIDIAN);
		setBlock(world, new BlockPos(i + 5, j + 8, k + 13), NETHERIZED_OBSIDIAN);
		setBlock(world, new BlockPos(i + 5, j + 9, k + 4), NETHERIZED_OBSIDIAN);
		setBlock(world, new BlockPos(i + 5, j + 9, k + 13), NETHERIZED_OBSIDIAN);
		setBlock(world, new BlockPos(i + 5, j + 10, k + 5), NETHERIZED_OBSIDIAN);
		setBlock(world, new BlockPos(i + 5, j + 10, k + 6), NETHERIZED_OBSIDIAN);
		setBlock(world, new BlockPos(i + 5, j + 10, k + 7), NETHERIZED_OBSIDIAN);
		setBlock(world, new BlockPos(i + 5, j + 10, k + 8), NETHERIZED_OBSIDIAN);
		setBlock(world, new BlockPos(i + 5, j + 10, k + 9), NETHERIZED_OBSIDIAN);
		setBlock(world, new BlockPos(i + 5, j + 10, k + 10), NETHERIZED_OBSIDIAN);
		setBlock(world, new BlockPos(i + 5, j + 10, k + 11), NETHERIZED_OBSIDIAN);
		setBlock(world, new BlockPos(i + 5, j + 10, k + 12), NETHERIZED_OBSIDIAN);
		setBlock(world, new BlockPos(i + 6, j + 0, k + 0), NETHERIZED_OBSIDIAN);
		setBlock(world, new BlockPos(i + 6, j + 0, k + 1), OBSIDIAN);
		setBlock(world, new BlockPos(i + 6, j + 0, k + 2), OBSIDIAN);
		setBlock(world, new BlockPos(i + 6, j + 0, k + 3), OBSIDIAN);
		setBlock(world, new BlockPos(i + 6, j + 0, k + 4), OBSIDIAN);
		setBlock(world, new BlockPos(i + 6, j + 0, k + 5), OBSIDIAN);
		setBlock(world, new BlockPos(i + 6, j + 0, k + 6), OBSIDIAN);
		setBlock(world, new BlockPos(i + 6, j + 0, k + 7), OBSIDIAN);
		setBlock(world, new BlockPos(i + 6, j + 0, k + 8), OBSIDIAN);
		setBlock(world, new BlockPos(i + 6, j + 0, k + 9), OBSIDIAN);
		setBlock(world, new BlockPos(i + 6, j + 0, k + 10), OBSIDIAN);
		setBlock(world, new BlockPos(i + 6, j + 0, k + 11), OBSIDIAN);
		setBlock(world, new BlockPos(i + 6, j + 0, k + 12), OBSIDIAN);
		setBlock(world, new BlockPos(i + 6, j + 0, k + 13), OBSIDIAN);
		setBlock(world, new BlockPos(i + 6, j + 0, k + 14), OBSIDIAN);
		setBlock(world, new BlockPos(i + 6, j + 0, k + 15), OBSIDIAN);
		setBlock(world, new BlockPos(i + 6, j + 0, k + 16), OBSIDIAN);
		setBlock(world, new BlockPos(i + 6, j + 0, k + 17), NETHERIZED_OBSIDIAN);
		setBlock(world, new BlockPos(i + 6, j + 1, k + 1), NETHERIZED_OBSIDIAN);
		setBlock(world, new BlockPos(i + 6, j + 1, k + 16), NETHERIZED_OBSIDIAN);
		setBlock(world, new BlockPos(i + 6, j + 2, k + 2), NETHERIZED_OBSIDIAN);
		setBlock(world, new BlockPos(i + 6, j + 2, k + 15), NETHERIZED_OBSIDIAN);
		setBlock(world, new BlockPos(i + 6, j + 3, k + 3), NETHERIZED_OBSIDIAN);
		setBlock(world, new BlockPos(i + 6, j + 3, k + 14), NETHERIZED_OBSIDIAN);
		setBlock(world, new BlockPos(i + 6, j + 4, k + 4), NETHERIZED_OBSIDIAN);
		setBlock(world, new BlockPos(i + 6, j + 4, k + 13), NETHERIZED_OBSIDIAN);
		setBlock(world, new BlockPos(i + 6, j + 5, k + 4), NETHERIZED_OBSIDIAN);
		setBlock(world, new BlockPos(i + 6, j + 5, k + 13), NETHERIZED_OBSIDIAN);
		setBlock(world, new BlockPos(i + 6, j + 6, k + 4), NETHERIZED_OBSIDIAN);
		setBlock(world, new BlockPos(i + 6, j + 6, k + 13), NETHERIZED_OBSIDIAN);
		setBlock(world, new BlockPos(i + 6, j + 7, k + 4), NETHERIZED_OBSIDIAN);
		setBlock(world, new BlockPos(i + 6, j + 7, k + 13), NETHERIZED_OBSIDIAN);
		setBlock(world, new BlockPos(i + 6, j + 8, k + 4), NETHERIZED_OBSIDIAN);
		setBlock(world, new BlockPos(i + 6, j + 8, k + 13), NETHERIZED_OBSIDIAN);
		setBlock(world, new BlockPos(i + 6, j + 9, k + 4), NETHERIZED_OBSIDIAN);
		setBlock(world, new BlockPos(i + 6, j + 9, k + 13), NETHERIZED_OBSIDIAN);
		setBlock(world, new BlockPos(i + 6, j + 10, k + 5), NETHERIZED_OBSIDIAN);
		setBlock(world, new BlockPos(i + 6, j + 10, k + 6), NETHERIZED_OBSIDIAN);
		setBlock(world, new BlockPos(i + 6, j + 10, k + 7), NETHERIZED_OBSIDIAN);
		setBlock(world, new BlockPos(i + 6, j + 10, k + 8), NETHERIZED_OBSIDIAN);
		setBlock(world, new BlockPos(i + 6, j + 10, k + 9), NETHERIZED_OBSIDIAN);
		setBlock(world, new BlockPos(i + 6, j + 10, k + 10), NETHERIZED_OBSIDIAN);
		setBlock(world, new BlockPos(i + 6, j + 10, k + 11), NETHERIZED_OBSIDIAN);
		setBlock(world, new BlockPos(i + 6, j + 10, k + 12), NETHERIZED_OBSIDIAN);
		setBlock(world, new BlockPos(i + 7, j + 0, k + 0), NETHERIZED_OBSIDIAN);
		setBlock(world, new BlockPos(i + 7, j + 0, k + 1), OBSIDIAN);
		setBlock(world, new BlockPos(i + 7, j + 0, k + 2), OBSIDIAN);
		setBlock(world, new BlockPos(i + 7, j + 0, k + 3), OBSIDIAN);
		setBlock(world, new BlockPos(i + 7, j + 0, k + 4), OBSIDIAN);
		setBlock(world, new BlockPos(i + 7, j + 0, k + 5), OBSIDIAN);
		setBlock(world, new BlockPos(i + 7, j + 0, k + 6), OBSIDIAN);
		setBlock(world, new BlockPos(i + 7, j + 0, k + 7), OBSIDIAN);
		setBlock(world, new BlockPos(i + 7, j + 0, k + 8), OBSIDIAN);
		setBlock(world, new BlockPos(i + 7, j + 0, k + 9), OBSIDIAN);
		setBlock(world, new BlockPos(i + 7, j + 0, k + 10), OBSIDIAN);
		setBlock(world, new BlockPos(i + 7, j + 0, k + 11), OBSIDIAN);
		setBlock(world, new BlockPos(i + 7, j + 0, k + 12), OBSIDIAN);
		setBlock(world, new BlockPos(i + 7, j + 0, k + 13), OBSIDIAN);
		setBlock(world, new BlockPos(i + 7, j + 0, k + 14), OBSIDIAN);
		setBlock(world, new BlockPos(i + 7, j + 0, k + 15), OBSIDIAN);
		setBlock(world, new BlockPos(i + 7, j + 0, k + 16), OBSIDIAN);
		setBlock(world, new BlockPos(i + 7, j + 0, k + 17), NETHERIZED_OBSIDIAN);
		setBlock(world, new BlockPos(i + 7, j + 1, k + 1), NETHERIZED_OBSIDIAN);
		setBlock(world, new BlockPos(i + 7, j + 1, k + 16), NETHERIZED_OBSIDIAN);
		setBlock(world, new BlockPos(i + 7, j + 2, k + 2), NETHERIZED_OBSIDIAN);
		setBlock(world, new BlockPos(i + 7, j + 2, k + 15), NETHERIZED_OBSIDIAN);
		setBlock(world, new BlockPos(i + 7, j + 3, k + 3), NETHERIZED_OBSIDIAN);
		setBlock(world, new BlockPos(i + 7, j + 3, k + 14), NETHERIZED_OBSIDIAN);
		setBlock(world, new BlockPos(i + 7, j + 4, k + 4), NETHERIZED_OBSIDIAN);
		setBlock(world, new BlockPos(i + 7, j + 4, k + 13), NETHERIZED_OBSIDIAN);
		setBlock(world, new BlockPos(i + 7, j + 5, k + 4), NETHERIZED_OBSIDIAN);
		setBlock(world, new BlockPos(i + 7, j + 5, k + 13), NETHERIZED_OBSIDIAN);
		setBlock(world, new BlockPos(i + 7, j + 6, k + 4), NETHERIZED_OBSIDIAN);
		setBlock(world, new BlockPos(i + 7, j + 6, k + 13), NETHERIZED_OBSIDIAN);
		setBlock(world, new BlockPos(i + 7, j + 7, k + 4), NETHERIZED_OBSIDIAN);
		setBlock(world, new BlockPos(i + 7, j + 7, k + 13), NETHERIZED_OBSIDIAN);
		setBlock(world, new BlockPos(i + 7, j + 8, k + 4), NETHERIZED_OBSIDIAN);
		setBlock(world, new BlockPos(i + 7, j + 8, k + 13), NETHERIZED_OBSIDIAN);
		setBlock(world, new BlockPos(i + 7, j + 9, k + 4), NETHERIZED_OBSIDIAN);
		setBlock(world, new BlockPos(i + 7, j + 9, k + 13), NETHERIZED_OBSIDIAN);
		setBlock(world, new BlockPos(i + 7, j + 10, k + 5), NETHERIZED_OBSIDIAN);
		setBlock(world, new BlockPos(i + 7, j + 10, k + 6), NETHERIZED_OBSIDIAN);
		setBlock(world, new BlockPos(i + 7, j + 10, k + 7), NETHERIZED_OBSIDIAN);
		setBlock(world, new BlockPos(i + 7, j + 10, k + 8), NETHERIZED_OBSIDIAN);
		setBlock(world, new BlockPos(i + 7, j + 10, k + 9), NETHERIZED_OBSIDIAN);
		setBlock(world, new BlockPos(i + 7, j + 10, k + 10), NETHERIZED_OBSIDIAN);
		setBlock(world, new BlockPos(i + 7, j + 10, k + 11), NETHERIZED_OBSIDIAN);
		setBlock(world, new BlockPos(i + 7, j + 10, k + 12), NETHERIZED_OBSIDIAN);
		setBlock(world, new BlockPos(i + 8, j + 0, k + 0), NETHERIZED_OBSIDIAN);
		setBlock(world, new BlockPos(i + 8, j + 0, k + 1), OBSIDIAN);
		setBlock(world, new BlockPos(i + 8, j + 0, k + 2), OBSIDIAN);
		setBlock(world, new BlockPos(i + 8, j + 0, k + 3), OBSIDIAN);
		setBlock(world, new BlockPos(i + 8, j + 0, k + 4), OBSIDIAN);
		setBlock(world, new BlockPos(i + 8, j + 0, k + 5), OBSIDIAN);
		setBlock(world, new BlockPos(i + 8, j + 0, k + 6), OBSIDIAN);
		setBlock(world, new BlockPos(i + 8, j + 0, k + 7), OBSIDIAN);
		setBlock(world, new BlockPos(i + 8, j + 0, k + 8), OBSIDIAN);
		setBlock(world, new BlockPos(i + 8, j + 0, k + 9), OBSIDIAN);
		setBlock(world, new BlockPos(i + 8, j + 0, k + 10), OBSIDIAN);
		setBlock(world, new BlockPos(i + 8, j + 0, k + 11), OBSIDIAN);
		setBlock(world, new BlockPos(i + 8, j + 0, k + 12), OBSIDIAN);
		setBlock(world, new BlockPos(i + 8, j + 0, k + 13), OBSIDIAN);
		setBlock(world, new BlockPos(i + 8, j + 0, k + 14), OBSIDIAN);
		setBlock(world, new BlockPos(i + 8, j + 0, k + 15), OBSIDIAN);
		setBlock(world, new BlockPos(i + 8, j + 0, k + 16), OBSIDIAN);
		setBlock(world, new BlockPos(i + 8, j + 0, k + 17), NETHERIZED_OBSIDIAN);
		setBlock(world, new BlockPos(i + 8, j + 1, k + 1), NETHERIZED_OBSIDIAN);
		setBlock(world, new BlockPos(i + 8, j + 1, k + 16), NETHERIZED_OBSIDIAN);
		setBlock(world, new BlockPos(i + 8, j + 2, k + 2), NETHERIZED_OBSIDIAN);
		setBlock(world, new BlockPos(i + 8, j + 2, k + 15), NETHERIZED_OBSIDIAN);
		setBlock(world, new BlockPos(i + 8, j + 3, k + 3), NETHERIZED_OBSIDIAN);
		setBlock(world, new BlockPos(i + 8, j + 3, k + 14), NETHERIZED_OBSIDIAN);
		setBlock(world, new BlockPos(i + 8, j + 4, k + 4), NETHERIZED_OBSIDIAN);
		setBlock(world, new BlockPos(i + 8, j + 4, k + 13), NETHERIZED_OBSIDIAN);
		setBlock(world, new BlockPos(i + 8, j + 5, k + 4), NETHERIZED_OBSIDIAN);
		setBlock(world, new BlockPos(i + 8, j + 5, k + 13), NETHERIZED_OBSIDIAN);
		setBlock(world, new BlockPos(i + 8, j + 6, k + 4), NETHERIZED_OBSIDIAN);
		setBlock(world, new BlockPos(i + 8, j + 6, k + 13), NETHERIZED_OBSIDIAN);
		setBlock(world, new BlockPos(i + 8, j + 7, k + 4), NETHERIZED_OBSIDIAN);
		setBlock(world, new BlockPos(i + 8, j + 7, k + 13), NETHERIZED_OBSIDIAN);
		setBlock(world, new BlockPos(i + 8, j + 8, k + 4), NETHERIZED_OBSIDIAN);
		setBlock(world, new BlockPos(i + 8, j + 8, k + 13), NETHERIZED_OBSIDIAN);
		setBlock(world, new BlockPos(i + 8, j + 9, k + 4), NETHERIZED_OBSIDIAN);
		setBlock(world, new BlockPos(i + 8, j + 9, k + 13), NETHERIZED_OBSIDIAN);
		setBlock(world, new BlockPos(i + 8, j + 10, k + 5), NETHERIZED_OBSIDIAN);
		setBlock(world, new BlockPos(i + 8, j + 10, k + 6), NETHERIZED_OBSIDIAN);
		setBlock(world, new BlockPos(i + 8, j + 10, k + 7), NETHERIZED_OBSIDIAN);
		setBlock(world, new BlockPos(i + 8, j + 10, k + 8), NETHERIZED_OBSIDIAN);
		setBlock(world, new BlockPos(i + 8, j + 10, k + 9), NETHERIZED_OBSIDIAN);
		setBlock(world, new BlockPos(i + 8, j + 10, k + 10), NETHERIZED_OBSIDIAN);
		setBlock(world, new BlockPos(i + 8, j + 10, k + 11), NETHERIZED_OBSIDIAN);
		setBlock(world, new BlockPos(i + 8, j + 10, k + 12), NETHERIZED_OBSIDIAN);
		setBlock(world, new BlockPos(i + 9, j + 0, k + 0), NETHERIZED_OBSIDIAN);
		setBlock(world, new BlockPos(i + 9, j + 0, k + 1), OBSIDIAN);
		setBlock(world, new BlockPos(i + 9, j + 0, k + 2), OBSIDIAN);
		setBlock(world, new BlockPos(i + 9, j + 0, k + 3), OBSIDIAN);
		setBlock(world, new BlockPos(i + 9, j + 0, k + 4), OBSIDIAN);
		setBlock(world, new BlockPos(i + 9, j + 0, k + 5), OBSIDIAN);
		setBlock(world, new BlockPos(i + 9, j + 0, k + 6), OBSIDIAN);
		setBlock(world, new BlockPos(i + 9, j + 0, k + 7), OBSIDIAN);
		setBlock(world, new BlockPos(i + 9, j + 0, k + 8), OBSIDIAN);
		setBlock(world, new BlockPos(i + 9, j + 0, k + 9), OBSIDIAN);
		setBlock(world, new BlockPos(i + 9, j + 0, k + 10), OBSIDIAN);
		setBlock(world, new BlockPos(i + 9, j + 0, k + 11), OBSIDIAN);
		setBlock(world, new BlockPos(i + 9, j + 0, k + 12), OBSIDIAN);
		setBlock(world, new BlockPos(i + 9, j + 0, k + 13), OBSIDIAN);
		setBlock(world, new BlockPos(i + 9, j + 0, k + 14), OBSIDIAN);
		setBlock(world, new BlockPos(i + 9, j + 0, k + 15), OBSIDIAN);
		setBlock(world, new BlockPos(i + 9, j + 0, k + 16), OBSIDIAN);
		setBlock(world, new BlockPos(i + 9, j + 0, k + 17), NETHERIZED_OBSIDIAN);
		setBlock(world, new BlockPos(i + 9, j + 1, k + 1), NETHERIZED_OBSIDIAN);
		setBlock(world, new BlockPos(i + 9, j + 1, k + 16), NETHERIZED_OBSIDIAN);
		setBlock(world, new BlockPos(i + 9, j + 2, k + 2), NETHERIZED_OBSIDIAN);
		setBlock(world, new BlockPos(i + 9, j + 2, k + 15), NETHERIZED_OBSIDIAN);
		setBlock(world, new BlockPos(i + 9, j + 3, k + 3), NETHERIZED_OBSIDIAN);
		setBlock(world, new BlockPos(i + 9, j + 3, k + 14), NETHERIZED_OBSIDIAN);
		setBlock(world, new BlockPos(i + 9, j + 4, k + 4), NETHERIZED_OBSIDIAN);
		setBlock(world, new BlockPos(i + 9, j + 4, k + 13), NETHERIZED_OBSIDIAN);
		setBlock(world, new BlockPos(i + 9, j + 5, k + 4), NETHERIZED_OBSIDIAN);
		setBlock(world, new BlockPos(i + 9, j + 5, k + 13), NETHERIZED_OBSIDIAN);
		setBlock(world, new BlockPos(i + 9, j + 6, k + 4), NETHERIZED_OBSIDIAN);
		setBlock(world, new BlockPos(i + 9, j + 6, k + 13), NETHERIZED_OBSIDIAN);
		setBlock(world, new BlockPos(i + 9, j + 7, k + 4), NETHERIZED_OBSIDIAN);
		setBlock(world, new BlockPos(i + 9, j + 7, k + 13), NETHERIZED_OBSIDIAN);
		setBlock(world, new BlockPos(i + 9, j + 8, k + 4), NETHERIZED_OBSIDIAN);
		setBlock(world, new BlockPos(i + 9, j + 8, k + 13), NETHERIZED_OBSIDIAN);
		setBlock(world, new BlockPos(i + 9, j + 9, k + 4), NETHERIZED_OBSIDIAN);
		setBlock(world, new BlockPos(i + 9, j + 9, k + 13), NETHERIZED_OBSIDIAN);
		setBlock(world, new BlockPos(i + 9, j + 10, k + 5), NETHERIZED_OBSIDIAN);
		setBlock(world, new BlockPos(i + 9, j + 10, k + 6), NETHERIZED_OBSIDIAN);
		setBlock(world, new BlockPos(i + 9, j + 10, k + 7), NETHERIZED_OBSIDIAN);
		setBlock(world, new BlockPos(i + 9, j + 10, k + 8), NETHERIZED_OBSIDIAN);
		setBlock(world, new BlockPos(i + 9, j + 10, k + 9), NETHERIZED_OBSIDIAN);
		setBlock(world, new BlockPos(i + 9, j + 10, k + 10), NETHERIZED_OBSIDIAN);
		setBlock(world, new BlockPos(i + 9, j + 10, k + 11), NETHERIZED_OBSIDIAN);
		setBlock(world, new BlockPos(i + 9, j + 10, k + 12), NETHERIZED_OBSIDIAN);
		setBlock(world, new BlockPos(i + 10, j + 0, k + 0), NETHERIZED_OBSIDIAN);
		setBlock(world, new BlockPos(i + 10, j + 0, k + 1), OBSIDIAN);
		setBlock(world, new BlockPos(i + 10, j + 0, k + 2), OBSIDIAN);
		setBlock(world, new BlockPos(i + 10, j + 0, k + 3), OBSIDIAN);
		setBlock(world, new BlockPos(i + 10, j + 0, k + 4), OBSIDIAN);
		setBlock(world, new BlockPos(i + 10, j + 0, k + 5), OBSIDIAN);
		setBlock(world, new BlockPos(i + 10, j + 0, k + 6), OBSIDIAN);
		setBlock(world, new BlockPos(i + 10, j + 0, k + 7), OBSIDIAN);
		setBlock(world, new BlockPos(i + 10, j + 0, k + 8), OBSIDIAN);
		setBlock(world, new BlockPos(i + 10, j + 0, k + 9), OBSIDIAN);
		setBlock(world, new BlockPos(i + 10, j + 0, k + 10), OBSIDIAN);
		setBlock(world, new BlockPos(i + 10, j + 0, k + 11), OBSIDIAN);
		setBlock(world, new BlockPos(i + 10, j + 0, k + 12), OBSIDIAN);
		setBlock(world, new BlockPos(i + 10, j + 0, k + 13), OBSIDIAN);
		setBlock(world, new BlockPos(i + 10, j + 0, k + 14), OBSIDIAN);
		setBlock(world, new BlockPos(i + 10, j + 0, k + 15), OBSIDIAN);
		setBlock(world, new BlockPos(i + 10, j + 0, k + 16), OBSIDIAN);
		setBlock(world, new BlockPos(i + 10, j + 0, k + 17), NETHERIZED_OBSIDIAN);
		setBlock(world, new BlockPos(i + 10, j + 1, k + 1), NETHERIZED_OBSIDIAN);
		setBlock(world, new BlockPos(i + 10, j + 1, k + 16), NETHERIZED_OBSIDIAN);
		setBlock(world, new BlockPos(i + 10, j + 2, k + 2), NETHERIZED_OBSIDIAN);
		setBlock(world, new BlockPos(i + 10, j + 2, k + 15), NETHERIZED_OBSIDIAN);
		setBlock(world, new BlockPos(i + 10, j + 3, k + 3), NETHERIZED_OBSIDIAN);
		setBlock(world, new BlockPos(i + 10, j + 3, k + 14), NETHERIZED_OBSIDIAN);
		setBlock(world, new BlockPos(i + 10, j + 4, k + 4), NETHERIZED_OBSIDIAN);
		setBlock(world, new BlockPos(i + 10, j + 4, k + 13), NETHERIZED_OBSIDIAN);
		setBlock(world, new BlockPos(i + 10, j + 5, k + 4), NETHERIZED_OBSIDIAN);
		setBlock(world, new BlockPos(i + 10, j + 5, k + 13), NETHERIZED_OBSIDIAN);
		setBlock(world, new BlockPos(i + 10, j + 6, k + 4), NETHERIZED_OBSIDIAN);
		setBlock(world, new BlockPos(i + 10, j + 6, k + 13), NETHERIZED_OBSIDIAN);
		setBlock(world, new BlockPos(i + 10, j + 7, k + 4), NETHERIZED_OBSIDIAN);
		setBlock(world, new BlockPos(i + 10, j + 7, k + 13), NETHERIZED_OBSIDIAN);
		setBlock(world, new BlockPos(i + 10, j + 8, k + 4), NETHERIZED_OBSIDIAN);
		setBlock(world, new BlockPos(i + 10, j + 8, k + 13), NETHERIZED_OBSIDIAN);
		setBlock(world, new BlockPos(i + 10, j + 9, k + 4), NETHERIZED_OBSIDIAN);
		setBlock(world, new BlockPos(i + 10, j + 9, k + 13), NETHERIZED_OBSIDIAN);
		setBlock(world, new BlockPos(i + 10, j + 10, k + 5), NETHERIZED_OBSIDIAN);
		setBlock(world, new BlockPos(i + 10, j + 10, k + 6), NETHERIZED_OBSIDIAN);
		setBlock(world, new BlockPos(i + 10, j + 10, k + 7), NETHERIZED_OBSIDIAN);
		setBlock(world, new BlockPos(i + 10, j + 10, k + 8), NETHERIZED_OBSIDIAN);
		setBlock(world, new BlockPos(i + 10, j + 10, k + 9), NETHERIZED_OBSIDIAN);
		setBlock(world, new BlockPos(i + 10, j + 10, k + 10), NETHERIZED_OBSIDIAN);
		setBlock(world, new BlockPos(i + 10, j + 10, k + 11), NETHERIZED_OBSIDIAN);
		setBlock(world, new BlockPos(i + 10, j + 10, k + 12), NETHERIZED_OBSIDIAN);
		setBlock(world, new BlockPos(i + 11, j + 0, k + 0), NETHERIZED_OBSIDIAN);
		setBlock(world, new BlockPos(i + 11, j + 0, k + 1), OBSIDIAN);
		setBlock(world, new BlockPos(i + 11, j + 0, k + 2), OBSIDIAN);
		setBlock(world, new BlockPos(i + 11, j + 0, k + 3), OBSIDIAN);
		setBlock(world, new BlockPos(i + 11, j + 0, k + 4), OBSIDIAN);
		setBlock(world, new BlockPos(i + 11, j + 0, k + 5), OBSIDIAN);
		setBlock(world, new BlockPos(i + 11, j + 0, k + 6), OBSIDIAN);
		setBlock(world, new BlockPos(i + 11, j + 0, k + 7), OBSIDIAN);
		setBlock(world, new BlockPos(i + 11, j + 0, k + 8), OBSIDIAN);
		setBlock(world, new BlockPos(i + 11, j + 0, k + 9), OBSIDIAN);
		setBlock(world, new BlockPos(i + 11, j + 0, k + 10), OBSIDIAN);
		setBlock(world, new BlockPos(i + 11, j + 0, k + 11), OBSIDIAN);
		setBlock(world, new BlockPos(i + 11, j + 0, k + 12), OBSIDIAN);
		setBlock(world, new BlockPos(i + 11, j + 0, k + 13), OBSIDIAN);
		setBlock(world, new BlockPos(i + 11, j + 0, k + 14), OBSIDIAN);
		setBlock(world, new BlockPos(i + 11, j + 0, k + 15), OBSIDIAN);
		setBlock(world, new BlockPos(i + 11, j + 0, k + 16), OBSIDIAN);
		setBlock(world, new BlockPos(i + 11, j + 0, k + 17), NETHERIZED_OBSIDIAN);
		setBlock(world, new BlockPos(i + 11, j + 1, k + 1), NETHERIZED_OBSIDIAN);
		setBlock(world, new BlockPos(i + 11, j + 1, k + 16), NETHERIZED_OBSIDIAN);
		setBlock(world, new BlockPos(i + 11, j + 2, k + 2), NETHERIZED_OBSIDIAN);
		setBlock(world, new BlockPos(i + 11, j + 2, k + 15), NETHERIZED_OBSIDIAN);
		setBlock(world, new BlockPos(i + 11, j + 3, k + 3), NETHERIZED_OBSIDIAN);
		setBlock(world, new BlockPos(i + 11, j + 3, k + 14), NETHERIZED_OBSIDIAN);
		setBlock(world, new BlockPos(i + 11, j + 4, k + 4), NETHERIZED_OBSIDIAN);
		setBlock(world, new BlockPos(i + 11, j + 4, k + 13), NETHERIZED_OBSIDIAN);
		setBlock(world, new BlockPos(i + 11, j + 5, k + 4), NETHERIZED_OBSIDIAN);
		setBlock(world, new BlockPos(i + 11, j + 5, k + 13), NETHERIZED_OBSIDIAN);
		setBlock(world, new BlockPos(i + 11, j + 6, k + 4), NETHERIZED_OBSIDIAN);
		setBlock(world, new BlockPos(i + 11, j + 6, k + 13), NETHERIZED_OBSIDIAN);
		setBlock(world, new BlockPos(i + 11, j + 7, k + 4), NETHERIZED_OBSIDIAN);
		setBlock(world, new BlockPos(i + 11, j + 7, k + 13), NETHERIZED_OBSIDIAN);
		setBlock(world, new BlockPos(i + 11, j + 8, k + 4), NETHERIZED_OBSIDIAN);
		setBlock(world, new BlockPos(i + 11, j + 8, k + 13), NETHERIZED_OBSIDIAN);
		setBlock(world, new BlockPos(i + 11, j + 9, k + 4), NETHERIZED_OBSIDIAN);
		setBlock(world, new BlockPos(i + 11, j + 9, k + 13), NETHERIZED_OBSIDIAN);
		setBlock(world, new BlockPos(i + 11, j + 10, k + 5), NETHERIZED_OBSIDIAN);
		setBlock(world, new BlockPos(i + 11, j + 10, k + 6), NETHERIZED_OBSIDIAN);
		setBlock(world, new BlockPos(i + 11, j + 10, k + 7), NETHERIZED_OBSIDIAN);
		setBlock(world, new BlockPos(i + 11, j + 10, k + 8), NETHERIZED_OBSIDIAN);
		setBlock(world, new BlockPos(i + 11, j + 10, k + 9), NETHERIZED_OBSIDIAN);
		setBlock(world, new BlockPos(i + 11, j + 10, k + 10), NETHERIZED_OBSIDIAN);
		setBlock(world, new BlockPos(i + 11, j + 10, k + 11), NETHERIZED_OBSIDIAN);
		setBlock(world, new BlockPos(i + 11, j + 10, k + 12), NETHERIZED_OBSIDIAN);
		setBlock(world, new BlockPos(i + 12, j + 0, k + 0), NETHERIZED_OBSIDIAN);
		setBlock(world, new BlockPos(i + 12, j + 0, k + 1), OBSIDIAN);
		setBlock(world, new BlockPos(i + 12, j + 0, k + 2), OBSIDIAN);
		setBlock(world, new BlockPos(i + 12, j + 0, k + 3), OBSIDIAN);
		setBlock(world, new BlockPos(i + 12, j + 0, k + 4), OBSIDIAN);
		setBlock(world, new BlockPos(i + 12, j + 0, k + 5), OBSIDIAN);
		setBlock(world, new BlockPos(i + 12, j + 0, k + 6), OBSIDIAN);
		setBlock(world, new BlockPos(i + 12, j + 0, k + 7), OBSIDIAN);
		setBlock(world, new BlockPos(i + 12, j + 0, k + 8), OBSIDIAN);
		setBlock(world, new BlockPos(i + 12, j + 0, k + 9), OBSIDIAN);
		setBlock(world, new BlockPos(i + 12, j + 0, k + 10), OBSIDIAN);
		setBlock(world, new BlockPos(i + 12, j + 0, k + 11), OBSIDIAN);
		setBlock(world, new BlockPos(i + 12, j + 0, k + 12), OBSIDIAN);
		setBlock(world, new BlockPos(i + 12, j + 0, k + 13), OBSIDIAN);
		setBlock(world, new BlockPos(i + 12, j + 0, k + 14), OBSIDIAN);
		setBlock(world, new BlockPos(i + 12, j + 0, k + 15), OBSIDIAN);
		setBlock(world, new BlockPos(i + 12, j + 0, k + 16), OBSIDIAN);
		setBlock(world, new BlockPos(i + 12, j + 0, k + 17), NETHERIZED_OBSIDIAN);
		setBlock(world, new BlockPos(i + 12, j + 1, k + 1), NETHERIZED_OBSIDIAN);
		setBlock(world, new BlockPos(i + 12, j + 1, k + 16), NETHERIZED_OBSIDIAN);
		setBlock(world, new BlockPos(i + 12, j + 2, k + 2), NETHERIZED_OBSIDIAN);
		setBlock(world, new BlockPos(i + 12, j + 2, k + 15), NETHERIZED_OBSIDIAN);
		setBlock(world, new BlockPos(i + 12, j + 3, k + 3), NETHERIZED_OBSIDIAN);
		setBlock(world, new BlockPos(i + 12, j + 3, k + 14), NETHERIZED_OBSIDIAN);
		setBlock(world, new BlockPos(i + 12, j + 4, k + 4), NETHERIZED_OBSIDIAN);
		setBlock(world, new BlockPos(i + 12, j + 4, k + 13), NETHERIZED_OBSIDIAN);
		setBlock(world, new BlockPos(i + 12, j + 5, k + 4), NETHERIZED_OBSIDIAN);
		setBlock(world, new BlockPos(i + 12, j + 5, k + 13), NETHERIZED_OBSIDIAN);
		setBlock(world, new BlockPos(i + 12, j + 6, k + 4), NETHERIZED_OBSIDIAN);
		setBlock(world, new BlockPos(i + 12, j + 6, k + 13), NETHERIZED_OBSIDIAN);
		setBlock(world, new BlockPos(i + 12, j + 7, k + 4), NETHERIZED_OBSIDIAN);
		setBlock(world, new BlockPos(i + 12, j + 7, k + 13), NETHERIZED_OBSIDIAN);
		setBlock(world, new BlockPos(i + 12, j + 8, k + 4), NETHERIZED_OBSIDIAN);
		setBlock(world, new BlockPos(i + 12, j + 8, k + 13), NETHERIZED_OBSIDIAN);
		setBlock(world, new BlockPos(i + 12, j + 9, k + 4), NETHERIZED_OBSIDIAN);
		setBlock(world, new BlockPos(i + 12, j + 9, k + 13), NETHERIZED_OBSIDIAN);
		setBlock(world, new BlockPos(i + 12, j + 10, k + 5), NETHERIZED_OBSIDIAN);
		setBlock(world, new BlockPos(i + 12, j + 10, k + 6), NETHERIZED_OBSIDIAN);
		setBlock(world, new BlockPos(i + 12, j + 10, k + 7), NETHERIZED_OBSIDIAN);
		setBlock(world, new BlockPos(i + 12, j + 10, k + 8), NETHERIZED_OBSIDIAN);
		setBlock(world, new BlockPos(i + 12, j + 10, k + 9), NETHERIZED_OBSIDIAN);
		setBlock(world, new BlockPos(i + 12, j + 10, k + 10), NETHERIZED_OBSIDIAN);
		setBlock(world, new BlockPos(i + 12, j + 10, k + 11), NETHERIZED_OBSIDIAN);
		setBlock(world, new BlockPos(i + 12, j + 10, k + 12), NETHERIZED_OBSIDIAN);
		setBlock(world, new BlockPos(i + 13, j + 0, k + 0), NETHERIZED_OBSIDIAN);
		setBlock(world, new BlockPos(i + 13, j + 0, k + 1), OBSIDIAN);
		setBlock(world, new BlockPos(i + 13, j + 0, k + 2), OBSIDIAN);
		setBlock(world, new BlockPos(i + 13, j + 0, k + 3), OBSIDIAN);
		setBlock(world, new BlockPos(i + 13, j + 0, k + 4), OBSIDIAN);
		setBlock(world, new BlockPos(i + 13, j + 0, k + 5), OBSIDIAN);
		setBlock(world, new BlockPos(i + 13, j + 0, k + 6), OBSIDIAN);
		setBlock(world, new BlockPos(i + 13, j + 0, k + 7), OBSIDIAN);
		setBlock(world, new BlockPos(i + 13, j + 0, k + 8), OBSIDIAN);
		setBlock(world, new BlockPos(i + 13, j + 0, k + 9), OBSIDIAN);
		setBlock(world, new BlockPos(i + 13, j + 0, k + 10), OBSIDIAN);
		setBlock(world, new BlockPos(i + 13, j + 0, k + 11), OBSIDIAN);
		setBlock(world, new BlockPos(i + 13, j + 0, k + 12), OBSIDIAN);
		setBlock(world, new BlockPos(i + 13, j + 0, k + 13), OBSIDIAN);
		setBlock(world, new BlockPos(i + 13, j + 0, k + 14), OBSIDIAN);
		setBlock(world, new BlockPos(i + 13, j + 0, k + 15), OBSIDIAN);
		setBlock(world, new BlockPos(i + 13, j + 0, k + 16), OBSIDIAN);
		setBlock(world, new BlockPos(i + 13, j + 0, k + 17), NETHERIZED_OBSIDIAN);
		setBlock(world, new BlockPos(i + 13, j + 1, k + 1), NETHERIZED_OBSIDIAN);
		setBlock(world, new BlockPos(i + 13, j + 1, k + 16), NETHERIZED_OBSIDIAN);
		setBlock(world, new BlockPos(i + 13, j + 2, k + 2), NETHERIZED_OBSIDIAN);
		setBlock(world, new BlockPos(i + 13, j + 2, k + 15), NETHERIZED_OBSIDIAN);
		setBlock(world, new BlockPos(i + 13, j + 3, k + 3), NETHERIZED_OBSIDIAN);
		setBlock(world, new BlockPos(i + 13, j + 3, k + 14), NETHERIZED_OBSIDIAN);
		setBlock(world, new BlockPos(i + 13, j + 4, k + 4), NETHERIZED_OBSIDIAN);
		setBlock(world, new BlockPos(i + 13, j + 4, k + 13), NETHERIZED_OBSIDIAN);
		setBlock(world, new BlockPos(i + 13, j + 5, k + 4), NETHERIZED_OBSIDIAN);
		setBlock(world, new BlockPos(i + 13, j + 5, k + 13), NETHERIZED_OBSIDIAN);
		setBlock(world, new BlockPos(i + 13, j + 6, k + 4), NETHERIZED_OBSIDIAN);
		setBlock(world, new BlockPos(i + 13, j + 6, k + 13), NETHERIZED_OBSIDIAN);
		setBlock(world, new BlockPos(i + 13, j + 7, k + 4), NETHERIZED_OBSIDIAN);
		setBlock(world, new BlockPos(i + 13, j + 7, k + 13), NETHERIZED_OBSIDIAN);
		setBlock(world, new BlockPos(i + 13, j + 8, k + 4), NETHERIZED_OBSIDIAN);
		setBlock(world, new BlockPos(i + 13, j + 8, k + 13), NETHERIZED_OBSIDIAN);
		setBlock(world, new BlockPos(i + 13, j + 9, k + 4), NETHERIZED_OBSIDIAN);
		setBlock(world, new BlockPos(i + 13, j + 9, k + 13), NETHERIZED_OBSIDIAN);
		setBlock(world, new BlockPos(i + 13, j + 10, k + 5), NETHERIZED_OBSIDIAN);
		setBlock(world, new BlockPos(i + 13, j + 10, k + 6), NETHERIZED_OBSIDIAN);
		setBlock(world, new BlockPos(i + 13, j + 10, k + 7), NETHERIZED_OBSIDIAN);
		setBlock(world, new BlockPos(i + 13, j + 10, k + 8), NETHERIZED_OBSIDIAN);
		setBlock(world, new BlockPos(i + 13, j + 10, k + 9), NETHERIZED_OBSIDIAN);
		setBlock(world, new BlockPos(i + 13, j + 10, k + 10), NETHERIZED_OBSIDIAN);
		setBlock(world, new BlockPos(i + 13, j + 10, k + 11), NETHERIZED_OBSIDIAN);
		setBlock(world, new BlockPos(i + 13, j + 10, k + 12), NETHERIZED_OBSIDIAN);
		setBlock(world, new BlockPos(i + 14, j + 0, k + 0), NETHERIZED_OBSIDIAN);
		setBlock(world, new BlockPos(i + 14, j + 0, k + 1), OBSIDIAN);
		setBlock(world, new BlockPos(i + 14, j + 0, k + 2), OBSIDIAN);
		setBlock(world, new BlockPos(i + 14, j + 0, k + 3), OBSIDIAN);
		setBlock(world, new BlockPos(i + 14, j + 0, k + 4), OBSIDIAN);
		setBlock(world, new BlockPos(i + 14, j + 0, k + 5), OBSIDIAN);
		setBlock(world, new BlockPos(i + 14, j + 0, k + 6), OBSIDIAN);
		setBlock(world, new BlockPos(i + 14, j + 0, k + 7), OBSIDIAN);
		setBlock(world, new BlockPos(i + 14, j + 0, k + 8), OBSIDIAN);
		setBlock(world, new BlockPos(i + 14, j + 0, k + 9), OBSIDIAN);
		setBlock(world, new BlockPos(i + 14, j + 0, k + 10), OBSIDIAN);
		setBlock(world, new BlockPos(i + 14, j + 0, k + 11), OBSIDIAN);
		setBlock(world, new BlockPos(i + 14, j + 0, k + 12), OBSIDIAN);
		setBlock(world, new BlockPos(i + 14, j + 0, k + 13), OBSIDIAN);
		setBlock(world, new BlockPos(i + 14, j + 0, k + 14), OBSIDIAN);
		setBlock(world, new BlockPos(i + 14, j + 0, k + 15), OBSIDIAN);
		setBlock(world, new BlockPos(i + 14, j + 0, k + 16), OBSIDIAN);
		setBlock(world, new BlockPos(i + 14, j + 0, k + 17), NETHERIZED_OBSIDIAN);
		setBlock(world, new BlockPos(i + 14, j + 1, k + 1), NETHERIZED_OBSIDIAN);
		setBlock(world, new BlockPos(i + 14, j + 1, k + 16), NETHERIZED_OBSIDIAN);
		setBlock(world, new BlockPos(i + 14, j + 2, k + 2), NETHERIZED_OBSIDIAN);
		setBlock(world, new BlockPos(i + 14, j + 2, k + 15), NETHERIZED_OBSIDIAN);
		setBlock(world, new BlockPos(i + 14, j + 3, k + 3), NETHERIZED_OBSIDIAN);
		setBlock(world, new BlockPos(i + 14, j + 3, k + 14), NETHERIZED_OBSIDIAN);
		setBlock(world, new BlockPos(i + 14, j + 4, k + 4), NETHERIZED_OBSIDIAN);
		setBlock(world, new BlockPos(i + 14, j + 4, k + 5), NETHERIZED_OBSIDIAN);
		setBlock(world, new BlockPos(i + 14, j + 4, k + 6), NETHERIZED_OBSIDIAN);
		setBlock(world, new BlockPos(i + 14, j + 4, k + 7), NETHERIZED_OBSIDIAN);
		setBlock(world, new BlockPos(i + 14, j + 4, k + 9), NETHERIZED_OBSIDIAN);
		setBlock(world, new BlockPos(i + 14, j + 4, k + 10), NETHERIZED_OBSIDIAN);
		setBlock(world, new BlockPos(i + 14, j + 4, k + 11), NETHERIZED_OBSIDIAN);
		setBlock(world, new BlockPos(i + 14, j + 4, k + 12), NETHERIZED_OBSIDIAN);
		setBlock(world, new BlockPos(i + 14, j + 4, k + 13), NETHERIZED_OBSIDIAN);
		setBlock(world, new BlockPos(i + 14, j + 5, k + 4), NETHERIZED_OBSIDIAN);
		setBlock(world, new BlockPos(i + 14, j + 5, k + 5), NETHERIZED_OBSIDIAN);
		setBlock(world, new BlockPos(i + 14, j + 5, k + 6), NETHERIZED_OBSIDIAN);
		setBlock(world, new BlockPos(i + 14, j + 5, k + 7), NETHERIZED_OBSIDIAN);
		setBlock(world, new BlockPos(i + 14, j + 5, k + 9), NETHERIZED_OBSIDIAN);
		setBlock(world, new BlockPos(i + 14, j + 5, k + 10), NETHERIZED_OBSIDIAN);
		setBlock(world, new BlockPos(i + 14, j + 5, k + 11), NETHERIZED_OBSIDIAN);
		setBlock(world, new BlockPos(i + 14, j + 5, k + 12), NETHERIZED_OBSIDIAN);
		setBlock(world, new BlockPos(i + 14, j + 5, k + 13), NETHERIZED_OBSIDIAN);
		setBlock(world, new BlockPos(i + 14, j + 6, k + 4), NETHERIZED_OBSIDIAN);
		setBlock(world, new BlockPos(i + 14, j + 6, k + 5), NETHERIZED_OBSIDIAN);
		setBlock(world, new BlockPos(i + 14, j + 6, k + 6), NETHERIZED_OBSIDIAN);
		setBlock(world, new BlockPos(i + 14, j + 6, k + 7), NETHERIZED_OBSIDIAN);
		setBlock(world, new BlockPos(i + 14, j + 6, k + 8), NETHERIZED_OBSIDIAN);
		setBlock(world, new BlockPos(i + 14, j + 6, k + 9), NETHERIZED_OBSIDIAN);
		setBlock(world, new BlockPos(i + 14, j + 6, k + 10), NETHERIZED_OBSIDIAN);
		setBlock(world, new BlockPos(i + 14, j + 6, k + 11), NETHERIZED_OBSIDIAN);
		setBlock(world, new BlockPos(i + 14, j + 6, k + 12), NETHERIZED_OBSIDIAN);
		setBlock(world, new BlockPos(i + 14, j + 6, k + 13), NETHERIZED_OBSIDIAN);
		setBlock(world, new BlockPos(i + 14, j + 7, k + 4), NETHERIZED_OBSIDIAN);
		setBlock(world, new BlockPos(i + 14, j + 7, k + 5), NETHERIZED_OBSIDIAN);
		setBlock(world, new BlockPos(i + 14, j + 7, k + 6), NETHERIZED_OBSIDIAN);
		setBlock(world, new BlockPos(i + 14, j + 7, k + 7), NETHERIZED_OBSIDIAN);
		setBlock(world, new BlockPos(i + 14, j + 7, k + 8), NETHERIZED_OBSIDIAN);
		setBlock(world, new BlockPos(i + 14, j + 7, k + 9), NETHERIZED_OBSIDIAN);
		setBlock(world, new BlockPos(i + 14, j + 7, k + 10), NETHERIZED_OBSIDIAN);
		setBlock(world, new BlockPos(i + 14, j + 7, k + 11), NETHERIZED_OBSIDIAN);
		setBlock(world, new BlockPos(i + 14, j + 7, k + 12), NETHERIZED_OBSIDIAN);
		setBlock(world, new BlockPos(i + 14, j + 7, k + 13), NETHERIZED_OBSIDIAN);
		setBlock(world, new BlockPos(i + 14, j + 8, k + 4), NETHERIZED_OBSIDIAN);
		setBlock(world, new BlockPos(i + 14, j + 8, k + 5), NETHERIZED_OBSIDIAN);
		setBlock(world, new BlockPos(i + 14, j + 8, k + 6), NETHERIZED_OBSIDIAN);
		setBlock(world, new BlockPos(i + 14, j + 8, k + 7), NETHERIZED_OBSIDIAN);
		setBlock(world, new BlockPos(i + 14, j + 8, k + 8), NETHERIZED_OBSIDIAN);
		setBlock(world, new BlockPos(i + 14, j + 8, k + 9), NETHERIZED_OBSIDIAN);
		setBlock(world, new BlockPos(i + 14, j + 8, k + 10), NETHERIZED_OBSIDIAN);
		setBlock(world, new BlockPos(i + 14, j + 8, k + 11), NETHERIZED_OBSIDIAN);
		setBlock(world, new BlockPos(i + 14, j + 8, k + 12), NETHERIZED_OBSIDIAN);
		setBlock(world, new BlockPos(i + 14, j + 8, k + 13), NETHERIZED_OBSIDIAN);
		setBlock(world, new BlockPos(i + 14, j + 9, k + 4), NETHERIZED_OBSIDIAN);
		setBlock(world, new BlockPos(i + 14, j + 9, k + 5), NETHERIZED_OBSIDIAN);
		setBlock(world, new BlockPos(i + 14, j + 9, k + 6), NETHERIZED_OBSIDIAN);
		setBlock(world, new BlockPos(i + 14, j + 9, k + 7), NETHERIZED_OBSIDIAN);
		setBlock(world, new BlockPos(i + 14, j + 9, k + 8), NETHERIZED_OBSIDIAN);
		setBlock(world, new BlockPos(i + 14, j + 9, k + 9), NETHERIZED_OBSIDIAN);
		setBlock(world, new BlockPos(i + 14, j + 9, k + 10), NETHERIZED_OBSIDIAN);
		setBlock(world, new BlockPos(i + 14, j + 9, k + 11), NETHERIZED_OBSIDIAN);
		setBlock(world, new BlockPos(i + 14, j + 9, k + 12), NETHERIZED_OBSIDIAN);
		setBlock(world, new BlockPos(i + 14, j + 9, k + 13), NETHERIZED_OBSIDIAN);
		setBlock(world, new BlockPos(i + 15, j + 0, k + 0), NETHERIZED_OBSIDIAN);
		setBlock(world, new BlockPos(i + 15, j + 0, k + 1), OBSIDIAN);
		setBlock(world, new BlockPos(i + 15, j + 0, k + 2), OBSIDIAN);
		setBlock(world, new BlockPos(i + 15, j + 0, k + 3), OBSIDIAN);
		setBlock(world, new BlockPos(i + 15, j + 0, k + 4), OBSIDIAN);
		setBlock(world, new BlockPos(i + 15, j + 0, k + 5), OBSIDIAN);
		setBlock(world, new BlockPos(i + 15, j + 0, k + 6), OBSIDIAN);
		setBlock(world, new BlockPos(i + 15, j + 0, k + 7), OBSIDIAN);
		setBlock(world, new BlockPos(i + 15, j + 0, k + 8), OBSIDIAN);
		setBlock(world, new BlockPos(i + 15, j + 0, k + 9), OBSIDIAN);
		setBlock(world, new BlockPos(i + 15, j + 0, k + 10), OBSIDIAN);
		setBlock(world, new BlockPos(i + 15, j + 0, k + 11), OBSIDIAN);
		setBlock(world, new BlockPos(i + 15, j + 0, k + 12), OBSIDIAN);
		setBlock(world, new BlockPos(i + 15, j + 0, k + 13), OBSIDIAN);
		setBlock(world, new BlockPos(i + 15, j + 0, k + 14), OBSIDIAN);
		setBlock(world, new BlockPos(i + 15, j + 0, k + 15), OBSIDIAN);
		setBlock(world, new BlockPos(i + 15, j + 0, k + 16), OBSIDIAN);
		setBlock(world, new BlockPos(i + 15, j + 0, k + 17), NETHERIZED_OBSIDIAN);
		setBlock(world, new BlockPos(i + 15, j + 1, k + 1), NETHERIZED_OBSIDIAN);
		setBlock(world, new BlockPos(i + 15, j + 1, k + 16), NETHERIZED_OBSIDIAN);
		setBlock(world, new BlockPos(i + 15, j + 2, k + 2), NETHERIZED_OBSIDIAN);
		setBlock(world, new BlockPos(i + 15, j + 2, k + 15), NETHERIZED_OBSIDIAN);
		setBlock(world, new BlockPos(i + 15, j + 3, k + 3), NETHERIZED_OBSIDIAN);
		setBlock(world, new BlockPos(i + 15, j + 3, k + 4), NETHERIZED_OBSIDIAN);
		setBlock(world, new BlockPos(i + 15, j + 3, k + 5), NETHERIZED_OBSIDIAN);
		setBlock(world, new BlockPos(i + 15, j + 3, k + 6), NETHERIZED_OBSIDIAN);
		setBlock(world, new BlockPos(i + 15, j + 3, k + 7), NETHERIZED_OBSIDIAN);
		setBlock(world, new BlockPos(i + 15, j + 3, k + 8), NETHERIZED_OBSIDIAN);
		setBlock(world, new BlockPos(i + 15, j + 3, k + 9), NETHERIZED_OBSIDIAN);
		setBlock(world, new BlockPos(i + 15, j + 3, k + 10), NETHERIZED_OBSIDIAN);
		setBlock(world, new BlockPos(i + 15, j + 3, k + 11), NETHERIZED_OBSIDIAN);
		setBlock(world, new BlockPos(i + 15, j + 3, k + 12), NETHERIZED_OBSIDIAN);
		setBlock(world, new BlockPos(i + 15, j + 3, k + 13), NETHERIZED_OBSIDIAN);
		setBlock(world, new BlockPos(i + 15, j + 3, k + 14), NETHERIZED_OBSIDIAN);
		setBlock(world, new BlockPos(i + 16, j + 0, k + 0), NETHERIZED_OBSIDIAN);
		setBlock(world, new BlockPos(i + 16, j + 0, k + 1), OBSIDIAN);
		setBlock(world, new BlockPos(i + 16, j + 0, k + 2), OBSIDIAN);
		setBlock(world, new BlockPos(i + 16, j + 0, k + 3), OBSIDIAN);
		setBlock(world, new BlockPos(i + 16, j + 0, k + 4), OBSIDIAN);
		setBlock(world, new BlockPos(i + 16, j + 0, k + 5), OBSIDIAN);
		setBlock(world, new BlockPos(i + 16, j + 0, k + 6), OBSIDIAN);
		setBlock(world, new BlockPos(i + 16, j + 0, k + 7), OBSIDIAN);
		setBlock(world, new BlockPos(i + 16, j + 0, k + 8), OBSIDIAN);
		setBlock(world, new BlockPos(i + 16, j + 0, k + 9), OBSIDIAN);
		setBlock(world, new BlockPos(i + 16, j + 0, k + 10), OBSIDIAN);
		setBlock(world, new BlockPos(i + 16, j + 0, k + 11), OBSIDIAN);
		setBlock(world, new BlockPos(i + 16, j + 0, k + 12), OBSIDIAN);
		setBlock(world, new BlockPos(i + 16, j + 0, k + 13), OBSIDIAN);
		setBlock(world, new BlockPos(i + 16, j + 0, k + 14), OBSIDIAN);
		setBlock(world, new BlockPos(i + 16, j + 0, k + 15), OBSIDIAN);
		setBlock(world, new BlockPos(i + 16, j + 0, k + 16), OBSIDIAN);
		setBlock(world, new BlockPos(i + 16, j + 0, k + 17), NETHERIZED_OBSIDIAN);
		setBlock(world, new BlockPos(i + 16, j + 1, k + 1), NETHERIZED_OBSIDIAN);
		setBlock(world, new BlockPos(i + 16, j + 1, k + 16), NETHERIZED_OBSIDIAN);
		setBlock(world, new BlockPos(i + 16, j + 2, k + 2), NETHERIZED_OBSIDIAN);
		setBlock(world, new BlockPos(i + 16, j + 2, k + 3), NETHERIZED_OBSIDIAN);
		setBlock(world, new BlockPos(i + 16, j + 2, k + 4), NETHERIZED_OBSIDIAN);
		setBlock(world, new BlockPos(i + 16, j + 2, k + 5), NETHERIZED_OBSIDIAN);
		setBlock(world, new BlockPos(i + 16, j + 2, k + 6), NETHERIZED_OBSIDIAN);
		setBlock(world, new BlockPos(i + 16, j + 2, k + 7), NETHERIZED_OBSIDIAN);
		setBlock(world, new BlockPos(i + 16, j + 2, k + 8), NETHERIZED_OBSIDIAN);
		setBlock(world, new BlockPos(i + 16, j + 2, k + 9), NETHERIZED_OBSIDIAN);
		setBlock(world, new BlockPos(i + 16, j + 2, k + 10), NETHERIZED_OBSIDIAN);
		setBlock(world, new BlockPos(i + 16, j + 2, k + 11), NETHERIZED_OBSIDIAN);
		setBlock(world, new BlockPos(i + 16, j + 2, k + 12), NETHERIZED_OBSIDIAN);
		setBlock(world, new BlockPos(i + 16, j + 2, k + 13), NETHERIZED_OBSIDIAN);
		setBlock(world, new BlockPos(i + 16, j + 2, k + 14), NETHERIZED_OBSIDIAN);
		setBlock(world, new BlockPos(i + 16, j + 2, k + 15), NETHERIZED_OBSIDIAN);
		setBlock(world, new BlockPos(i + 17, j + 0, k + 0), NETHERIZED_OBSIDIAN);
		setBlock(world, new BlockPos(i + 17, j + 0, k + 1), OBSIDIAN);
		setBlock(world, new BlockPos(i + 17, j + 0, k + 2), OBSIDIAN);
		setBlock(world, new BlockPos(i + 17, j + 0, k + 3), OBSIDIAN);
		setBlock(world, new BlockPos(i + 17, j + 0, k + 4), OBSIDIAN);
		setBlock(world, new BlockPos(i + 17, j + 0, k + 5), OBSIDIAN);
		setBlock(world, new BlockPos(i + 17, j + 0, k + 6), OBSIDIAN);
		setBlock(world, new BlockPos(i + 17, j + 0, k + 7), OBSIDIAN);
		setBlock(world, new BlockPos(i + 17, j + 0, k + 8), OBSIDIAN);
		setBlock(world, new BlockPos(i + 17, j + 0, k + 9), OBSIDIAN);
		setBlock(world, new BlockPos(i + 17, j + 0, k + 10), OBSIDIAN);
		setBlock(world, new BlockPos(i + 17, j + 0, k + 11), OBSIDIAN);
		setBlock(world, new BlockPos(i + 17, j + 0, k + 12), OBSIDIAN);
		setBlock(world, new BlockPos(i + 17, j + 0, k + 13), OBSIDIAN);
		setBlock(world, new BlockPos(i + 17, j + 0, k + 14), OBSIDIAN);
		setBlock(world, new BlockPos(i + 17, j + 0, k + 15), OBSIDIAN);
		setBlock(world, new BlockPos(i + 17, j + 0, k + 16), OBSIDIAN);
		setBlock(world, new BlockPos(i + 17, j + 0, k + 17), NETHERIZED_OBSIDIAN);
		setBlock(world, new BlockPos(i + 17, j + 1, k + 1), NETHERIZED_OBSIDIAN);
		setBlock(world, new BlockPos(i + 17, j + 1, k + 2), NETHERIZED_OBSIDIAN);
		setBlock(world, new BlockPos(i + 17, j + 1, k + 3), NETHERIZED_OBSIDIAN);
		setBlock(world, new BlockPos(i + 17, j + 1, k + 4), NETHERIZED_OBSIDIAN);
		setBlock(world, new BlockPos(i + 17, j + 1, k + 5), NETHERIZED_OBSIDIAN);
		setBlock(world, new BlockPos(i + 17, j + 1, k + 6), NETHERIZED_OBSIDIAN);
		setBlock(world, new BlockPos(i + 17, j + 1, k + 7), NETHERIZED_OBSIDIAN);
		setBlock(world, new BlockPos(i + 17, j + 1, k + 8), NETHERIZED_OBSIDIAN);
		setBlock(world, new BlockPos(i + 17, j + 1, k + 9), NETHERIZED_OBSIDIAN);
		setBlock(world, new BlockPos(i + 17, j + 1, k + 10), NETHERIZED_OBSIDIAN);
		setBlock(world, new BlockPos(i + 17, j + 1, k + 11), NETHERIZED_OBSIDIAN);
		setBlock(world, new BlockPos(i + 17, j + 1, k + 12), NETHERIZED_OBSIDIAN);
		setBlock(world, new BlockPos(i + 17, j + 1, k + 13), NETHERIZED_OBSIDIAN);
		setBlock(world, new BlockPos(i + 17, j + 1, k + 14), NETHERIZED_OBSIDIAN);
		setBlock(world, new BlockPos(i + 17, j + 1, k + 15), NETHERIZED_OBSIDIAN);
		setBlock(world, new BlockPos(i + 17, j + 1, k + 16), NETHERIZED_OBSIDIAN);
		setBlock(world, new BlockPos(i + 18, j + 0, k + 0), NETHERIZED_OBSIDIAN);
		setBlock(world, new BlockPos(i + 18, j + 0, k + 1), NETHERIZED_OBSIDIAN);
		setBlock(world, new BlockPos(i + 18, j + 0, k + 2), NETHERIZED_OBSIDIAN);
		setBlock(world, new BlockPos(i + 18, j + 0, k + 3), NETHERIZED_OBSIDIAN);
		setBlock(world, new BlockPos(i + 18, j + 0, k + 4), NETHERIZED_OBSIDIAN);
		setBlock(world, new BlockPos(i + 18, j + 0, k + 5), NETHERIZED_OBSIDIAN);
		setBlock(world, new BlockPos(i + 18, j + 0, k + 6), NETHERIZED_OBSIDIAN);
		setBlock(world, new BlockPos(i + 18, j + 0, k + 7), NETHERIZED_OBSIDIAN);
		setBlock(world, new BlockPos(i + 18, j + 0, k + 8), NETHERIZED_OBSIDIAN);
		setBlock(world, new BlockPos(i + 18, j + 0, k + 9), NETHERIZED_OBSIDIAN);
		setBlock(world, new BlockPos(i + 18, j + 0, k + 10), NETHERIZED_OBSIDIAN);
		setBlock(world, new BlockPos(i + 18, j + 0, k + 11), NETHERIZED_OBSIDIAN);
		setBlock(world, new BlockPos(i + 18, j + 0, k + 12), NETHERIZED_OBSIDIAN);
		setBlock(world, new BlockPos(i + 18, j + 0, k + 13), NETHERIZED_OBSIDIAN);
		setBlock(world, new BlockPos(i + 18, j + 0, k + 14), NETHERIZED_OBSIDIAN);
		setBlock(world, new BlockPos(i + 18, j + 0, k + 15), NETHERIZED_OBSIDIAN);
		setBlock(world, new BlockPos(i + 18, j + 0, k + 16), NETHERIZED_OBSIDIAN);
		setBlock(world, new BlockPos(i + 18, j + 0, k + 17), NETHERIZED_OBSIDIAN);
		setBlock(world, new BlockPos(i + 6, j + 2, k + 8), ZGBlocks.shadowBossSpawner);
		
		return true;
	}
}