/*******************************************************************************
 * Copyright 2016 Zollern Wolf
 * - Zollern Galaxy
 * Galacticraft Add-On Mod
 * You CAN:
 * - Learn from it
 * - Use it to get ideas and concepts
 * You CAN'T:
 * - Redistribute it
 * - Claim it as your own
 * Steve Kung's "More Planets" mod was a big help.
 *******************************************************************************/

package galaxymod.worldgen.eden;

import galaxymod.blocks.BlockList;
import galaxymod.worldgen.NGWorldGenStructureCore;
import galaxymod.worldgen.eden.treasure.TreasureGenEden;
import java.util.Random;
import net.minecraft.init.Blocks;
import net.minecraft.world.World;

public class WorldGenCrystalTower extends NGWorldGenStructureCore {
	
	public WorldGenCrystalTower() {
	}
	
	@Override
	public boolean generate(World world, Random rand, int i, int j, int k) {
		
		j -= 10;
		if (world.getBlock(i, j + 1, k) == Blocks.air) {
			return false;
		}
		
		world.setBlock(i + 4, j + 2, k + 10, BlockList.edenSacredStone);
		world.setBlock(i + 4, j + 2, k + 11, BlockList.edenSacredStone);
		world.setBlock(i + 4, j + 2, k + 12, BlockList.edenSacredStone);
		world.setBlock(i + 4, j + 2, k + 13, BlockList.edenSacredStone);
		world.setBlock(i + 4, j + 2, k + 14, BlockList.edenSacredStone);
		world.setBlock(i + 4, j + 2, k + 15, BlockList.edenSacredStone);
		world.setBlock(i + 4, j + 2, k + 16, BlockList.edenSacredStone);
		world.setBlock(i + 4, j + 3, k + 10, BlockList.edenSacredStone);
		world.setBlock(i + 4, j + 3, k + 11, BlockList.edenSacredStone);
		world.setBlock(i + 4, j + 3, k + 12, BlockList.edenSacredStone);
		world.setBlock(i + 4, j + 3, k + 13, BlockList.edenSacredStone);
		world.setBlock(i + 4, j + 3, k + 14, BlockList.edenSacredStone);
		world.setBlock(i + 4, j + 3, k + 15, BlockList.edenSacredStone);
		world.setBlock(i + 4, j + 3, k + 16, BlockList.edenSacredStone);
		world.setBlock(i + 4, j + 4, k + 10, BlockList.edenSacredStone);
		world.setBlock(i + 4, j + 4, k + 11, BlockList.edenSacredStone);
		world.setBlock(i + 4, j + 4, k + 12, BlockList.edenSacredStone);
		world.setBlock(i + 4, j + 4, k + 13, BlockList.edenSacredStone);
		world.setBlock(i + 4, j + 4, k + 14, BlockList.edenSacredStone);
		world.setBlock(i + 4, j + 4, k + 15, BlockList.edenSacredStone);
		world.setBlock(i + 4, j + 4, k + 16, BlockList.edenSacredStone);
		world.setBlock(i + 4, j + 5, k + 10, BlockList.edenSacredStone);
		world.setBlock(i + 4, j + 5, k + 11, BlockList.edenSacredStone);
		world.setBlock(i + 4, j + 5, k + 12, BlockList.edenSacredStone);
		world.setBlock(i + 4, j + 5, k + 13, BlockList.edenSacredStone);
		world.setBlock(i + 4, j + 5, k + 14, BlockList.edenSacredStone);
		world.setBlock(i + 4, j + 5, k + 15, BlockList.edenSacredStone);
		world.setBlock(i + 4, j + 5, k + 16, BlockList.edenSacredStone);
		world.setBlock(i + 4, j + 6, k + 10, BlockList.edenSacredStone);
		world.setBlock(i + 4, j + 6, k + 11, BlockList.edenSacredStone);
		world.setBlock(i + 4, j + 6, k + 12, BlockList.edenSacredStone);
		world.setBlock(i + 4, j + 6, k + 13, BlockList.edenSacredStone);
		world.setBlock(i + 4, j + 6, k + 14, BlockList.edenSacredStone);
		world.setBlock(i + 4, j + 6, k + 15, BlockList.edenSacredStone);
		world.setBlock(i + 4, j + 6, k + 16, BlockList.edenSacredStone);
		world.setBlock(i + 4, j + 7, k + 10, BlockList.edenSacredStone);
		world.setBlock(i + 4, j + 7, k + 11, BlockList.edenSacredStone);
		world.setBlock(i + 4, j + 7, k + 12, BlockList.edenSacredStone);
		world.setBlock(i + 4, j + 7, k + 13, BlockList.edenSacredStone);
		world.setBlock(i + 4, j + 7, k + 14, BlockList.edenSacredStone);
		world.setBlock(i + 4, j + 7, k + 15, BlockList.edenSacredStone);
		world.setBlock(i + 4, j + 7, k + 16, BlockList.edenSacredStone);
		world.setBlock(i + 4, j + 8, k + 10, BlockList.edenSacredStone);
		world.setBlock(i + 4, j + 8, k + 11, BlockList.edenSacredStone);
		world.setBlock(i + 4, j + 8, k + 12, BlockList.edenSacredStone);
		world.setBlock(i + 4, j + 8, k + 13, BlockList.edenSacredStone);
		world.setBlock(i + 4, j + 8, k + 14, BlockList.edenSacredStone);
		world.setBlock(i + 4, j + 8, k + 15, BlockList.edenSacredStone);
		world.setBlock(i + 4, j + 8, k + 16, BlockList.edenSacredStone);
		TreasureGenEden.addChest(i + 5, j - 1, k + 13, rand, world);
		world.setBlock(i + 5, j + 2, k + 8, BlockList.edenSacredStone);
		world.setBlock(i + 5, j + 2, k + 9, BlockList.edenSacredStone);
		world.setBlock(i + 5, j + 2, k + 17, BlockList.edenSacredStone);
		world.setBlock(i + 5, j + 2, k + 18, BlockList.edenSacredStone);
		world.setBlock(i + 5, j + 3, k + 8, BlockList.edenSacredStone);
		world.setBlock(i + 5, j + 3, k + 9, BlockList.edenSacredStone);
		world.setBlock(i + 5, j + 3, k + 17, BlockList.edenSacredStone);
		world.setBlock(i + 5, j + 3, k + 18, BlockList.edenSacredStone);
		world.setBlock(i + 5, j + 4, k + 8, BlockList.edenSacredStone);
		world.setBlock(i + 5, j + 4, k + 9, BlockList.edenSacredStone);
		world.setBlock(i + 5, j + 4, k + 17, BlockList.edenSacredStone);
		world.setBlock(i + 5, j + 4, k + 18, BlockList.edenSacredStone);
		world.setBlock(i + 5, j + 5, k + 8, BlockList.edenSacredStone);
		world.setBlock(i + 5, j + 5, k + 9, BlockList.edenSacredStone);
		world.setBlock(i + 5, j + 5, k + 17, BlockList.edenSacredStone);
		world.setBlock(i + 5, j + 5, k + 18, BlockList.edenSacredStone);
		world.setBlock(i + 5, j + 6, k + 8, BlockList.edenSacredStone);
		world.setBlock(i + 5, j + 6, k + 9, BlockList.edenSacredStone);
		world.setBlock(i + 5, j + 6, k + 17, BlockList.edenSacredStone);
		world.setBlock(i + 5, j + 6, k + 18, BlockList.edenSacredStone);
		world.setBlock(i + 5, j + 7, k + 8, BlockList.edenSacredStone);
		world.setBlock(i + 5, j + 7, k + 9, BlockList.edenSacredStone);
		world.setBlock(i + 5, j + 7, k + 17, BlockList.edenSacredStone);
		world.setBlock(i + 5, j + 7, k + 18, BlockList.edenSacredStone);
		world.setBlock(i + 5, j + 8, k + 8, BlockList.edenSacredStone);
		world.setBlock(i + 5, j + 8, k + 9, BlockList.edenSacredStone);
		world.setBlock(i + 5, j + 8, k + 10, BlockList.edenSacredStone);
		world.setBlock(i + 5, j + 8, k + 11, BlockList.edenSacredStone);
		world.setBlock(i + 5, j + 8, k + 12, BlockList.edenSacredStone);
		world.setBlock(i + 5, j + 8, k + 13, BlockList.edenSacredStone);
		world.setBlock(i + 5, j + 8, k + 14, BlockList.edenSacredStone);
		world.setBlock(i + 5, j + 8, k + 15, BlockList.edenSacredStone);
		world.setBlock(i + 5, j + 8, k + 16, BlockList.edenSacredStone);
		world.setBlock(i + 5, j + 8, k + 17, BlockList.edenSacredStone);
		world.setBlock(i + 5, j + 8, k + 18, BlockList.edenSacredStone);
		world.setBlock(i + 5, j + 9, k + 10, BlockList.edenSacredStone);
		world.setBlock(i + 5, j + 9, k + 11, BlockList.edenSacredStone);
		world.setBlock(i + 5, j + 9, k + 12, BlockList.edenSacredStone);
		world.setBlock(i + 5, j + 9, k + 13, BlockList.edenSacredStone);
		world.setBlock(i + 5, j + 9, k + 14, BlockList.edenSacredStone);
		world.setBlock(i + 5, j + 9, k + 15, BlockList.edenSacredStone);
		world.setBlock(i + 5, j + 9, k + 16, BlockList.edenSacredStone);
		world.setBlock(i + 6, j + 2, k + 7, BlockList.edenSacredStone);
		world.setBlock(i + 6, j + 2, k + 19, BlockList.edenSacredStone);
		world.setBlock(i + 6, j + 3, k + 7, BlockList.edenSacredStone);
		world.setBlock(i + 6, j + 3, k + 19, BlockList.edenSacredStone);
		world.setBlock(i + 6, j + 4, k + 7, BlockList.edenSacredStone);
		world.setBlock(i + 6, j + 4, k + 19, BlockList.edenSacredStone);
		world.setBlock(i + 6, j + 5, k + 7, BlockList.edenSacredStone);
		world.setBlock(i + 6, j + 5, k + 19, BlockList.edenSacredStone);
		world.setBlock(i + 6, j + 6, k + 7, BlockList.edenSacredStone);
		world.setBlock(i + 6, j + 6, k + 19, BlockList.edenSacredStone);
		world.setBlock(i + 6, j + 7, k + 7, BlockList.edenSacredStone);
		world.setBlock(i + 6, j + 7, k + 19, BlockList.edenSacredStone);
		world.setBlock(i + 6, j + 8, k + 7, BlockList.edenSacredStone);
		world.setBlock(i + 6, j + 8, k + 8, BlockList.edenSacredStone);
		world.setBlock(i + 6, j + 8, k + 9, BlockList.edenSacredStone);
		world.setBlock(i + 6, j + 8, k + 17, BlockList.edenSacredStone);
		world.setBlock(i + 6, j + 8, k + 18, BlockList.edenSacredStone);
		world.setBlock(i + 6, j + 8, k + 19, BlockList.edenSacredStone);
		world.setBlock(i + 6, j + 9, k + 8, BlockList.edenSacredStone);
		world.setBlock(i + 6, j + 9, k + 9, BlockList.edenSacredStone);
		world.setBlock(i + 6, j + 9, k + 10, BlockList.edenSacredStone);
		world.setBlock(i + 6, j + 9, k + 16, BlockList.edenSacredStone);
		world.setBlock(i + 6, j + 9, k + 17, BlockList.edenSacredStone);
		world.setBlock(i + 6, j + 9, k + 18, BlockList.edenSacredStone);
		world.setBlock(i + 6, j + 10, k + 11, BlockList.edenSacredStone);
		world.setBlock(i + 6, j + 10, k + 12, BlockList.edenSacredStone);
		world.setBlock(i + 6, j + 10, k + 13, BlockList.edenSacredStone);
		world.setBlock(i + 6, j + 10, k + 14, BlockList.edenSacredStone);
		world.setBlock(i + 6, j + 10, k + 15, BlockList.edenSacredStone);
		world.setBlock(i + 6, j + 11, k + 11, BlockList.edenSacredStone);
		world.setBlock(i + 6, j + 11, k + 12, BlockList.edenSacredStone);
		world.setBlock(i + 6, j + 11, k + 13, BlockList.edenSacredStone);
		world.setBlock(i + 6, j + 11, k + 14, BlockList.edenSacredStone);
		world.setBlock(i + 6, j + 11, k + 15, BlockList.edenSacredStone);
		world.setBlock(i + 7, j + 2, k + 6, BlockList.edenSacredStone);
		world.setBlock(i + 7, j + 2, k + 20, BlockList.edenSacredStone);
		world.setBlock(i + 7, j + 3, k + 6, BlockList.edenSacredStone);
		world.setBlock(i + 7, j + 3, k + 20, BlockList.edenSacredStone);
		world.setBlock(i + 7, j + 4, k + 6, BlockList.edenSacredStone);
		world.setBlock(i + 7, j + 4, k + 20, BlockList.edenSacredStone);
		world.setBlock(i + 7, j + 5, k + 6, BlockList.edenSacredStone);
		world.setBlock(i + 7, j + 5, k + 20, BlockList.edenSacredStone);
		world.setBlock(i + 7, j + 6, k + 6, BlockList.edenSacredStone);
		world.setBlock(i + 7, j + 6, k + 20, BlockList.edenSacredStone);
		world.setBlock(i + 7, j + 7, k + 6, BlockList.edenSacredStone);
		world.setBlock(i + 7, j + 7, k + 20, BlockList.edenSacredStone);
		world.setBlock(i + 7, j + 8, k + 6, BlockList.edenSacredStone);
		world.setBlock(i + 7, j + 8, k + 7, BlockList.edenSacredStone);
		world.setBlock(i + 7, j + 8, k + 19, BlockList.edenSacredStone);
		world.setBlock(i + 7, j + 8, k + 20, BlockList.edenSacredStone);
		world.setBlock(i + 7, j + 9, k + 7, BlockList.edenSacredStone);
		world.setBlock(i + 7, j + 9, k + 8, BlockList.edenSacredStone);
		world.setBlock(i + 7, j + 9, k + 18, BlockList.edenSacredStone);
		world.setBlock(i + 7, j + 9, k + 19, BlockList.edenSacredStone);
		world.setBlock(i + 7, j + 10, k + 9, BlockList.edenSacredStone);
		world.setBlock(i + 7, j + 10, k + 10, BlockList.edenSacredStone);
		world.setBlock(i + 7, j + 10, k + 16, BlockList.edenSacredStone);
		world.setBlock(i + 7, j + 10, k + 17, BlockList.edenSacredStone);
		world.setBlock(i + 7, j + 11, k + 9, BlockList.edenSacredStone);
		world.setBlock(i + 7, j + 11, k + 10, BlockList.edenSacredStone);
		world.setBlock(i + 7, j + 11, k + 16, BlockList.edenSacredStone);
		world.setBlock(i + 7, j + 11, k + 17, BlockList.edenSacredStone);
		world.setBlock(i + 7, j + 12, k + 11, BlockList.edenSacredStone);
		world.setBlock(i + 7, j + 12, k + 12, BlockList.edenSacredStone);
		world.setBlock(i + 7, j + 12, k + 13, BlockList.edenSacredStone);
		world.setBlock(i + 7, j + 12, k + 14, BlockList.edenSacredStone);
		world.setBlock(i + 7, j + 12, k + 15, BlockList.edenSacredStone);
		world.setBlock(i + 7, j + 13, k + 11, BlockList.edenSacredStone);
		world.setBlock(i + 7, j + 13, k + 12, BlockList.edenSacredStone);
		world.setBlock(i + 7, j + 13, k + 13, BlockList.edenSacredStone);
		world.setBlock(i + 7, j + 13, k + 14, BlockList.edenSacredStone);
		world.setBlock(i + 7, j + 13, k + 15, BlockList.edenSacredStone);
		world.setBlock(i + 8, j + 2, k + 5, BlockList.edenSacredStone);
		world.setBlock(i + 8, j + 2, k + 21, BlockList.edenSacredStone);
		world.setBlock(i + 8, j + 3, k + 5, BlockList.edenSacredStone);
		world.setBlock(i + 8, j + 3, k + 21, BlockList.edenSacredStone);
		world.setBlock(i + 8, j + 4, k + 5, BlockList.edenSacredStone);
		world.setBlock(i + 8, j + 4, k + 21, BlockList.edenSacredStone);
		world.setBlock(i + 8, j + 5, k + 5, BlockList.edenSacredStone);
		world.setBlock(i + 8, j + 5, k + 21, BlockList.edenSacredStone);
		world.setBlock(i + 8, j + 6, k + 5, BlockList.edenSacredStone);
		world.setBlock(i + 8, j + 6, k + 21, BlockList.edenSacredStone);
		world.setBlock(i + 8, j + 7, k + 5, BlockList.edenSacredStone);
		world.setBlock(i + 8, j + 7, k + 21, BlockList.edenSacredStone);
		world.setBlock(i + 8, j + 8, k + 5, BlockList.edenSacredStone);
		world.setBlock(i + 8, j + 8, k + 6, BlockList.edenSacredStone);
		world.setBlock(i + 8, j + 8, k + 20, BlockList.edenSacredStone);
		world.setBlock(i + 8, j + 8, k + 21, BlockList.edenSacredStone);
		world.setBlock(i + 8, j + 9, k + 6, BlockList.edenSacredStone);
		world.setBlock(i + 8, j + 9, k + 20, BlockList.edenSacredStone);
		world.setBlock(i + 8, j + 10, k + 7, BlockList.edenSacredStone);
		world.setBlock(i + 8, j + 10, k + 8, BlockList.edenSacredStone);
		world.setBlock(i + 8, j + 10, k + 18, BlockList.edenSacredStone);
		world.setBlock(i + 8, j + 10, k + 19, BlockList.edenSacredStone);
		world.setBlock(i + 8, j + 11, k + 7, BlockList.edenSacredStone);
		world.setBlock(i + 8, j + 11, k + 8, BlockList.edenSacredStone);
		world.setBlock(i + 8, j + 11, k + 18, BlockList.edenSacredStone);
		world.setBlock(i + 8, j + 11, k + 19, BlockList.edenSacredStone);
		world.setBlock(i + 8, j + 12, k + 9, BlockList.edenSacredStone);
		world.setBlock(i + 8, j + 12, k + 10, BlockList.edenSacredStone);
		world.setBlock(i + 8, j + 12, k + 16, BlockList.edenSacredStone);
		world.setBlock(i + 8, j + 12, k + 17, BlockList.edenSacredStone);
		world.setBlock(i + 8, j + 13, k + 9, BlockList.edenSacredStone);
		world.setBlock(i + 8, j + 13, k + 10, BlockList.edenSacredStone);
		world.setBlock(i + 8, j + 13, k + 16, BlockList.edenSacredStone);
		world.setBlock(i + 8, j + 13, k + 17, BlockList.edenSacredStone);
		world.setBlock(i + 8, j + 14, k + 11, BlockList.edenSacredStone);
		world.setBlock(i + 8, j + 14, k + 12, BlockList.edenSacredStone);
		world.setBlock(i + 8, j + 14, k + 13, BlockList.edenSacredStone);
		world.setBlock(i + 8, j + 14, k + 14, BlockList.edenSacredStone);
		world.setBlock(i + 8, j + 14, k + 15, BlockList.edenSacredStone);
		world.setBlock(i + 8, j + 15, k + 11, BlockList.edenSacredStone);
		world.setBlock(i + 8, j + 15, k + 12, BlockList.edenSacredStone);
		world.setBlock(i + 8, j + 15, k + 13, BlockList.edenSacredStone);
		world.setBlock(i + 8, j + 15, k + 14, BlockList.edenSacredStone);
		world.setBlock(i + 8, j + 15, k + 15, BlockList.edenSacredStone);
		world.setBlock(i + 9, j + 2, k + 4, BlockList.edenSacredStone);
		world.setBlock(i + 9, j + 2, k + 22, BlockList.edenSacredStone);
		world.setBlock(i + 9, j + 3, k + 4, BlockList.edenSacredStone);
		world.setBlock(i + 9, j + 3, k + 22, BlockList.edenSacredStone);
		world.setBlock(i + 9, j + 4, k + 4, BlockList.edenSacredStone);
		world.setBlock(i + 9, j + 4, k + 22, BlockList.edenSacredStone);
		world.setBlock(i + 9, j + 5, k + 4, BlockList.edenSacredStone);
		world.setBlock(i + 9, j + 5, k + 22, BlockList.edenSacredStone);
		world.setBlock(i + 9, j + 6, k + 4, BlockList.edenSacredStone);
		world.setBlock(i + 9, j + 6, k + 22, BlockList.edenSacredStone);
		world.setBlock(i + 9, j + 7, k + 4, BlockList.edenSacredStone);
		world.setBlock(i + 9, j + 7, k + 22, BlockList.edenSacredStone);
		world.setBlock(i + 9, j + 8, k + 4, BlockList.edenSacredStone);
		world.setBlock(i + 9, j + 8, k + 5, BlockList.edenSacredStone);
		world.setBlock(i + 9, j + 8, k + 21, BlockList.edenSacredStone);
		world.setBlock(i + 9, j + 8, k + 22, BlockList.edenSacredStone);
		world.setBlock(i + 9, j + 9, k + 5, BlockList.edenSacredStone);
		world.setBlock(i + 9, j + 9, k + 6, BlockList.edenSacredStone);
		world.setBlock(i + 9, j + 9, k + 20, BlockList.edenSacredStone);
		world.setBlock(i + 9, j + 9, k + 21, BlockList.edenSacredStone);
		world.setBlock(i + 9, j + 10, k + 7, BlockList.edenSacredStone);
		world.setBlock(i + 9, j + 10, k + 19, BlockList.edenSacredStone);
		world.setBlock(i + 9, j + 11, k + 7, BlockList.edenSacredStone);
		world.setBlock(i + 9, j + 11, k + 19, BlockList.edenSacredStone);
		world.setBlock(i + 9, j + 12, k + 8, BlockList.edenSacredStone);
		world.setBlock(i + 9, j + 12, k + 18, BlockList.edenSacredStone);
		world.setBlock(i + 9, j + 13, k + 8, BlockList.edenSacredStone);
		world.setBlock(i + 9, j + 13, k + 18, BlockList.edenSacredStone);
		world.setBlock(i + 9, j + 14, k + 9, BlockList.edenSacredStone);
		world.setBlock(i + 9, j + 14, k + 10, BlockList.edenSacredStone);
		world.setBlock(i + 9, j + 14, k + 16, BlockList.edenSacredStone);
		world.setBlock(i + 9, j + 14, k + 17, BlockList.edenSacredStone);
		world.setBlock(i + 9, j + 15, k + 9, BlockList.edenSacredStone);
		world.setBlock(i + 9, j + 15, k + 10, BlockList.edenSacredStone);
		world.setBlock(i + 9, j + 15, k + 16, BlockList.edenSacredStone);
		world.setBlock(i + 9, j + 15, k + 17, BlockList.edenSacredStone);
		world.setBlock(i + 9, j + 16, k + 11, BlockList.edenSacredStone);
		world.setBlock(i + 9, j + 16, k + 12, BlockList.edenSacredStone);
		world.setBlock(i + 9, j + 16, k + 13, BlockList.edenSacredStone);
		world.setBlock(i + 9, j + 16, k + 14, BlockList.edenSacredStone);
		world.setBlock(i + 9, j + 16, k + 15, BlockList.edenSacredStone);
		world.setBlock(i + 9, j + 17, k + 11, BlockList.edenSacredStone);
		world.setBlock(i + 9, j + 17, k + 12, BlockList.edenSacredStone);
		world.setBlock(i + 9, j + 17, k + 13, BlockList.edenSacredStone);
		world.setBlock(i + 9, j + 17, k + 14, BlockList.edenSacredStone);
		world.setBlock(i + 9, j + 17, k + 15, BlockList.edenSacredStone);
		world.setBlock(i + 10, j + 2, k + 4, BlockList.edenSacredStone);
		world.setBlock(i + 10, j + 2, k + 22, BlockList.edenSacredStone);
		world.setBlock(i + 10, j + 3, k + 4, BlockList.edenSacredStone);
		world.setBlock(i + 10, j + 3, k + 22, BlockList.edenSacredStone);
		world.setBlock(i + 10, j + 4, k + 4, BlockList.edenSacredStone);
		world.setBlock(i + 10, j + 4, k + 22, BlockList.edenSacredStone);
		world.setBlock(i + 10, j + 5, k + 4, BlockList.edenSacredStone);
		world.setBlock(i + 10, j + 5, k + 22, BlockList.edenSacredStone);
		world.setBlock(i + 10, j + 6, k + 4, BlockList.edenSacredStone);
		world.setBlock(i + 10, j + 6, k + 22, BlockList.edenSacredStone);
		world.setBlock(i + 10, j + 7, k + 4, BlockList.edenSacredStone);
		world.setBlock(i + 10, j + 7, k + 22, BlockList.edenSacredStone);
		world.setBlock(i + 10, j + 8, k + 4, BlockList.edenSacredStone);
		world.setBlock(i + 10, j + 8, k + 5, BlockList.edenSacredStone);
		world.setBlock(i + 10, j + 8, k + 21, BlockList.edenSacredStone);
		world.setBlock(i + 10, j + 8, k + 22, BlockList.edenSacredStone);
		world.setBlock(i + 10, j + 9, k + 5, BlockList.edenSacredStone);
		world.setBlock(i + 10, j + 9, k + 21, BlockList.edenSacredStone);
		world.setBlock(i + 10, j + 10, k + 6, BlockList.edenSacredStone);
		world.setBlock(i + 10, j + 10, k + 20, BlockList.edenSacredStone);
		world.setBlock(i + 10, j + 11, k + 6, BlockList.edenSacredStone);
		world.setBlock(i + 10, j + 11, k + 20, BlockList.edenSacredStone);
		world.setBlock(i + 10, j + 12, k + 7, BlockList.edenSacredStone);
		world.setBlock(i + 10, j + 12, k + 19, BlockList.edenSacredStone);
		world.setBlock(i + 10, j + 13, k + 7, BlockList.edenSacredStone);
		world.setBlock(i + 10, j + 13, k + 19, BlockList.edenSacredStone);
		world.setBlock(i + 10, j + 14, k + 8, BlockList.edenSacredStone);
		world.setBlock(i + 10, j + 14, k + 18, BlockList.edenSacredStone);
		world.setBlock(i + 10, j + 15, k + 8, BlockList.edenSacredStone);
		world.setBlock(i + 10, j + 15, k + 9, BlockList.edenSacredStone);
		world.setBlock(i + 10, j + 15, k + 17, BlockList.edenSacredStone);
		world.setBlock(i + 10, j + 15, k + 18, BlockList.edenSacredStone);
		world.setBlock(i + 10, j + 16, k + 10, BlockList.edenSacredStone);
		world.setBlock(i + 10, j + 16, k + 16, BlockList.edenSacredStone);
		world.setBlock(i + 10, j + 17, k + 10, BlockList.edenSacredStone);
		world.setBlock(i + 10, j + 17, k + 16, BlockList.edenSacredStone);
		world.setBlock(i + 10, j + 18, k + 11, BlockList.edenSacredStone);
		world.setBlock(i + 10, j + 18, k + 12, BlockList.edenSacredStone);
		world.setBlock(i + 10, j + 18, k + 13, BlockList.edenSacredStone);
		world.setBlock(i + 10, j + 18, k + 14, BlockList.edenSacredStone);
		world.setBlock(i + 10, j + 18, k + 15, BlockList.edenSacredStone);
		world.setBlock(i + 10, j + 19, k + 11, BlockList.edenSacredStone);
		world.setBlock(i + 10, j + 19, k + 12, BlockList.edenSacredStone);
		world.setBlock(i + 10, j + 19, k + 13, BlockList.edenSacredStone);
		world.setBlock(i + 10, j + 19, k + 14, BlockList.edenSacredStone);
		world.setBlock(i + 10, j + 19, k + 15, BlockList.edenSacredStone);
		world.setBlock(i + 11, j + 2, k + 3, BlockList.edenSacredStone);
		world.setBlock(i + 11, j + 2, k + 23, BlockList.edenSacredStone);
		world.setBlock(i + 11, j + 3, k + 3, BlockList.edenSacredStone);
		world.setBlock(i + 11, j + 3, k + 23, BlockList.edenSacredStone);
		world.setBlock(i + 11, j + 4, k + 3, BlockList.edenSacredStone);
		world.setBlock(i + 11, j + 4, k + 23, BlockList.edenSacredStone);
		world.setBlock(i + 11, j + 5, k + 3, BlockList.edenSacredStone);
		world.setBlock(i + 11, j + 5, k + 23, BlockList.edenSacredStone);
		world.setBlock(i + 11, j + 6, k + 3, BlockList.edenSacredStone);
		world.setBlock(i + 11, j + 6, k + 23, BlockList.edenSacredStone);
		world.setBlock(i + 11, j + 7, k + 3, BlockList.edenSacredStone);
		world.setBlock(i + 11, j + 7, k + 23, BlockList.edenSacredStone);
		world.setBlock(i + 11, j + 8, k + 3, BlockList.edenSacredStone);
		world.setBlock(i + 11, j + 8, k + 4, BlockList.edenSacredStone);
		world.setBlock(i + 11, j + 8, k + 22, BlockList.edenSacredStone);
		world.setBlock(i + 11, j + 8, k + 23, BlockList.edenSacredStone);
		world.setBlock(i + 11, j + 9, k + 4, BlockList.edenSacredStone);
		world.setBlock(i + 11, j + 9, k + 5, BlockList.edenSacredStone);
		world.setBlock(i + 11, j + 9, k + 21, BlockList.edenSacredStone);
		world.setBlock(i + 11, j + 9, k + 22, BlockList.edenSacredStone);
		world.setBlock(i + 11, j + 10, k + 6, BlockList.edenSacredStone);
		world.setBlock(i + 11, j + 10, k + 20, BlockList.edenSacredStone);
		world.setBlock(i + 11, j + 11, k + 6, BlockList.edenSacredStone);
		world.setBlock(i + 11, j + 11, k + 20, BlockList.edenSacredStone);
		world.setBlock(i + 11, j + 12, k + 7, BlockList.edenSacredStone);
		world.setBlock(i + 11, j + 12, k + 19, BlockList.edenSacredStone);
		world.setBlock(i + 11, j + 13, k + 7, BlockList.edenSacredStone);
		world.setBlock(i + 11, j + 13, k + 19, BlockList.edenSacredStone);
		world.setBlock(i + 11, j + 14, k + 8, BlockList.edenSacredStone);
		world.setBlock(i + 11, j + 14, k + 18, BlockList.edenSacredStone);
		world.setBlock(i + 11, j + 15, k + 8, BlockList.edenSacredStone);
		world.setBlock(i + 11, j + 15, k + 18, BlockList.edenSacredStone);
		world.setBlock(i + 11, j + 16, k + 9, BlockList.edenSacredStone);
		world.setBlock(i + 11, j + 16, k + 17, BlockList.edenSacredStone);
		world.setBlock(i + 11, j + 17, k + 9, BlockList.edenSacredStone);
		world.setBlock(i + 11, j + 17, k + 17, BlockList.edenSacredStone);
		world.setBlock(i + 11, j + 18, k + 10, BlockList.edenSacredStone);
		world.setBlock(i + 11, j + 18, k + 16, BlockList.edenSacredStone);
		world.setBlock(i + 11, j + 19, k + 10, BlockList.edenSacredStone);
		world.setBlock(i + 11, j + 19, k + 11, BlockList.edenSacredStone);
		world.setBlock(i + 11, j + 19, k + 15, BlockList.edenSacredStone);
		world.setBlock(i + 11, j + 19, k + 16, BlockList.edenSacredStone);
		world.setBlock(i + 11, j + 20, k + 12, BlockList.edenSacredStone);
		world.setBlock(i + 11, j + 20, k + 13, BlockList.edenSacredStone);
		world.setBlock(i + 11, j + 20, k + 14, BlockList.edenSacredStone);
		world.setBlock(i + 11, j + 21, k + 12, BlockList.edenSacredStone);
		world.setBlock(i + 11, j + 21, k + 13, BlockList.edenSacredStone);
		world.setBlock(i + 11, j + 21, k + 14, BlockList.edenSacredStone);
		TreasureGenEden.addChest(i + 12, j + 11, k + 13, rand, world);
		world.setBlock(i + 12, j + 2, k + 3, BlockList.edenSacredStone);
		world.setBlock(i + 12, j + 2, k + 23, BlockList.edenSacredStone);
		world.setBlock(i + 12, j + 3, k + 3, BlockList.edenSacredStone);
		world.setBlock(i + 12, j + 3, k + 23, BlockList.edenSacredStone);
		world.setBlock(i + 12, j + 4, k + 3, BlockList.edenSacredStone);
		world.setBlock(i + 12, j + 4, k + 23, BlockList.edenSacredStone);
		world.setBlock(i + 12, j + 5, k + 3, BlockList.edenSacredStone);
		world.setBlock(i + 12, j + 5, k + 23, BlockList.edenSacredStone);
		world.setBlock(i + 12, j + 6, k + 3, BlockList.edenSacredStone);
		world.setBlock(i + 12, j + 6, k + 23, BlockList.edenSacredStone);
		world.setBlock(i + 12, j + 7, k + 3, BlockList.edenSacredStone);
		world.setBlock(i + 12, j + 7, k + 23, BlockList.edenSacredStone);
		world.setBlock(i + 12, j + 8, k + 3, BlockList.edenSacredStone);
		world.setBlock(i + 12, j + 8, k + 4, BlockList.edenSacredStone);
		world.setBlock(i + 12, j + 8, k + 22, BlockList.edenSacredStone);
		world.setBlock(i + 12, j + 8, k + 23, BlockList.edenSacredStone);
		world.setBlock(i + 12, j + 9, k + 4, BlockList.edenSacredStone);
		world.setBlock(i + 12, j + 9, k + 22, BlockList.edenSacredStone);
		world.setBlock(i + 12, j + 10, k + 5, BlockList.edenSacredStone);
		world.setBlock(i + 12, j + 10, k + 21, BlockList.edenSacredStone);
		world.setBlock(i + 12, j + 11, k + 5, BlockList.edenSacredStone);
		world.setBlock(i + 12, j + 11, k + 21, BlockList.edenSacredStone);
		world.setBlock(i + 12, j + 12, k + 6, BlockList.edenSacredStone);
		world.setBlock(i + 12, j + 12, k + 20, BlockList.edenSacredStone);
		world.setBlock(i + 12, j + 13, k + 6, BlockList.edenSacredStone);
		world.setBlock(i + 12, j + 13, k + 20, BlockList.edenSacredStone);
		world.setBlock(i + 12, j + 14, k + 7, BlockList.edenSacredStone);
		world.setBlock(i + 12, j + 14, k + 19, BlockList.edenSacredStone);
		world.setBlock(i + 12, j + 15, k + 7, BlockList.edenSacredStone);
		world.setBlock(i + 12, j + 15, k + 19, BlockList.edenSacredStone);
		world.setBlock(i + 12, j + 16, k + 8, BlockList.edenSacredStone);
		world.setBlock(i + 12, j + 16, k + 18, BlockList.edenSacredStone);
		world.setBlock(i + 12, j + 17, k + 8, BlockList.edenSacredStone);
		world.setBlock(i + 12, j + 17, k + 18, BlockList.edenSacredStone);
		world.setBlock(i + 12, j + 18, k + 9, BlockList.edenSacredStone);
		world.setBlock(i + 12, j + 18, k + 17, BlockList.edenSacredStone);
		world.setBlock(i + 12, j + 19, k + 9, BlockList.edenSacredStone);
		world.setBlock(i + 12, j + 19, k + 10, BlockList.edenSacredStone);
		world.setBlock(i + 12, j + 19, k + 16, BlockList.edenSacredStone);
		world.setBlock(i + 12, j + 19, k + 17, BlockList.edenSacredStone);
		world.setBlock(i + 12, j + 20, k + 11, BlockList.edenSacredStone);
		world.setBlock(i + 12, j + 20, k + 15, BlockList.edenSacredStone);
		world.setBlock(i + 12, j + 21, k + 11, BlockList.edenSacredStone);
		world.setBlock(i + 12, j + 21, k + 15, BlockList.edenSacredStone);
		world.setBlock(i + 12, j + 22, k + 12, BlockList.edenSacredStone);
		world.setBlock(i + 12, j + 22, k + 13, BlockList.edenSacredStone);
		world.setBlock(i + 12, j + 22, k + 14, BlockList.edenSacredStone);
		world.setBlock(i + 12, j + 23, k + 12, BlockList.edenSacredStone);
		world.setBlock(i + 12, j + 23, k + 13, BlockList.edenSacredStone);
		world.setBlock(i + 12, j + 23, k + 14, BlockList.edenSacredStone);
		world.setBlock(i + 13, j + 2, k + 3, BlockList.edenSacredStone);
		world.setBlock(i + 13, j + 2, k + 23, BlockList.edenSacredStone);
		world.setBlock(i + 13, j + 3, k + 3, BlockList.edenSacredStone);
		world.setBlock(i + 13, j + 3, k + 23, BlockList.edenSacredStone);
		world.setBlock(i + 13, j + 4, k + 3, BlockList.edenSacredStone);
		world.setBlock(i + 13, j + 4, k + 23, BlockList.edenSacredStone);
		world.setBlock(i + 13, j + 5, k + 3, BlockList.edenSacredStone);
		world.setBlock(i + 13, j + 5, k + 23, BlockList.edenSacredStone);
		world.setBlock(i + 13, j + 6, k + 3, BlockList.edenSacredStone);
		world.setBlock(i + 13, j + 6, k + 23, BlockList.edenSacredStone);
		world.setBlock(i + 13, j + 7, k + 3, BlockList.edenSacredStone);
		world.setBlock(i + 13, j + 7, k + 23, BlockList.edenSacredStone);
		world.setBlock(i + 13, j + 8, k + 3, BlockList.edenSacredStone);
		world.setBlock(i + 13, j + 8, k + 4, BlockList.edenSacredStone);
		world.setBlock(i + 13, j + 8, k + 22, BlockList.edenSacredStone);
		world.setBlock(i + 13, j + 8, k + 23, BlockList.edenSacredStone);
		world.setBlock(i + 13, j + 9, k + 4, BlockList.edenSacredStone);
		world.setBlock(i + 13, j + 9, k + 22, BlockList.edenSacredStone);
		world.setBlock(i + 13, j + 10, k + 5, BlockList.edenSacredStone);
		world.setBlock(i + 13, j + 10, k + 21, BlockList.edenSacredStone);
		world.setBlock(i + 13, j + 11, k + 5, BlockList.edenSacredStone);
		world.setBlock(i + 13, j + 11, k + 21, BlockList.edenSacredStone);
		world.setBlock(i + 13, j + 12, k + 6, BlockList.edenSacredStone);
		world.setBlock(i + 13, j + 12, k + 20, BlockList.edenSacredStone);
		world.setBlock(i + 13, j + 13, k + 6, BlockList.edenSacredStone);
		world.setBlock(i + 13, j + 13, k + 20, BlockList.edenSacredStone);
		world.setBlock(i + 13, j + 14, k + 7, BlockList.edenSacredStone);
		world.setBlock(i + 13, j + 14, k + 19, BlockList.edenSacredStone);
		world.setBlock(i + 13, j + 15, k + 7, BlockList.edenSacredStone);
		world.setBlock(i + 13, j + 15, k + 19, BlockList.edenSacredStone);
		world.setBlock(i + 13, j + 16, k + 8, BlockList.edenSacredStone);
		world.setBlock(i + 13, j + 16, k + 18, BlockList.edenSacredStone);
		world.setBlock(i + 13, j + 17, k + 8, BlockList.edenSacredStone);
		world.setBlock(i + 13, j + 17, k + 18, BlockList.edenSacredStone);
		world.setBlock(i + 13, j + 18, k + 9, BlockList.edenSacredStone);
		world.setBlock(i + 13, j + 18, k + 17, BlockList.edenSacredStone);
		world.setBlock(i + 13, j + 19, k + 9, BlockList.edenSacredStone);
		world.setBlock(i + 13, j + 19, k + 17, BlockList.edenSacredStone);
		world.setBlock(i + 13, j + 20, k + 10, BlockList.edenSacredStone);
		world.setBlock(i + 13, j + 20, k + 16, BlockList.edenSacredStone);
		world.setBlock(i + 13, j + 21, k + 10, BlockList.edenSacredStone);
		world.setBlock(i + 13, j + 21, k + 16, BlockList.edenSacredStone);
		world.setBlock(i + 13, j + 22, k + 11, BlockList.edenSacredStone);
		world.setBlock(i + 13, j + 22, k + 15, BlockList.edenSacredStone);
		world.setBlock(i + 13, j + 23, k + 11, BlockList.edenSacredStone);
		world.setBlock(i + 13, j + 23, k + 15, BlockList.edenSacredStone);
		world.setBlock(i + 13, j + 24, k + 12, BlockList.edenSacredStone);
		world.setBlock(i + 13, j + 24, k + 13, BlockList.edenSacredStone);
		world.setBlock(i + 13, j + 24, k + 14, BlockList.edenSacredStone);
		world.setBlock(i + 14, j + 2, k + 3, BlockList.edenSacredStone);
		world.setBlock(i + 14, j + 2, k + 23, BlockList.edenSacredStone);
		world.setBlock(i + 14, j + 3, k + 3, BlockList.edenSacredStone);
		world.setBlock(i + 14, j + 3, k + 23, BlockList.edenSacredStone);
		world.setBlock(i + 14, j + 4, k + 3, BlockList.edenSacredStone);
		world.setBlock(i + 14, j + 4, k + 23, BlockList.edenSacredStone);
		world.setBlock(i + 14, j + 5, k + 3, BlockList.edenSacredStone);
		world.setBlock(i + 14, j + 5, k + 23, BlockList.edenSacredStone);
		world.setBlock(i + 14, j + 6, k + 3, BlockList.edenSacredStone);
		world.setBlock(i + 14, j + 6, k + 23, BlockList.edenSacredStone);
		world.setBlock(i + 14, j + 7, k + 3, BlockList.edenSacredStone);
		world.setBlock(i + 14, j + 7, k + 23, BlockList.edenSacredStone);
		world.setBlock(i + 14, j + 8, k + 3, BlockList.edenSacredStone);
		world.setBlock(i + 14, j + 8, k + 4, BlockList.edenSacredStone);
		world.setBlock(i + 14, j + 8, k + 22, BlockList.edenSacredStone);
		world.setBlock(i + 14, j + 8, k + 23, BlockList.edenSacredStone);
		world.setBlock(i + 14, j + 9, k + 4, BlockList.edenSacredStone);
		world.setBlock(i + 14, j + 9, k + 22, BlockList.edenSacredStone);
		world.setBlock(i + 14, j + 10, k + 5, BlockList.edenSacredStone);
		world.setBlock(i + 14, j + 10, k + 21, BlockList.edenSacredStone);
		world.setBlock(i + 14, j + 11, k + 5, BlockList.edenSacredStone);
		world.setBlock(i + 14, j + 11, k + 21, BlockList.edenSacredStone);
		world.setBlock(i + 14, j + 12, k + 6, BlockList.edenSacredStone);
		world.setBlock(i + 14, j + 12, k + 20, BlockList.edenSacredStone);
		world.setBlock(i + 14, j + 13, k + 6, BlockList.edenSacredStone);
		world.setBlock(i + 14, j + 13, k + 20, BlockList.edenSacredStone);
		world.setBlock(i + 14, j + 14, k + 7, BlockList.edenSacredStone);
		world.setBlock(i + 14, j + 14, k + 19, BlockList.edenSacredStone);
		world.setBlock(i + 14, j + 15, k + 7, BlockList.edenSacredStone);
		world.setBlock(i + 14, j + 15, k + 19, BlockList.edenSacredStone);
		world.setBlock(i + 14, j + 16, k + 8, BlockList.edenSacredStone);
		world.setBlock(i + 14, j + 16, k + 18, BlockList.edenSacredStone);
		world.setBlock(i + 14, j + 17, k + 8, BlockList.edenSacredStone);
		world.setBlock(i + 14, j + 17, k + 18, BlockList.edenSacredStone);
		world.setBlock(i + 14, j + 18, k + 9, BlockList.edenSacredStone);
		world.setBlock(i + 14, j + 18, k + 17, BlockList.edenSacredStone);
		world.setBlock(i + 14, j + 19, k + 9, BlockList.edenSacredStone);
		world.setBlock(i + 14, j + 19, k + 17, BlockList.edenSacredStone);
		world.setBlock(i + 14, j + 20, k + 10, BlockList.edenSacredStone);
		world.setBlock(i + 14, j + 20, k + 16, BlockList.edenSacredStone);
		world.setBlock(i + 14, j + 21, k + 10, BlockList.edenSacredStone);
		world.setBlock(i + 14, j + 21, k + 16, BlockList.edenSacredStone);
		world.setBlock(i + 14, j + 22, k + 11, BlockList.edenSacredStone);
		world.setBlock(i + 14, j + 22, k + 15, BlockList.edenSacredStone);
		world.setBlock(i + 14, j + 23, k + 11, BlockList.edenSacredStone);
		world.setBlock(i + 14, j + 23, k + 15, BlockList.edenSacredStone);
		world.setBlock(i + 14, j + 24, k + 12, BlockList.edenSacredStone);
		world.setBlock(i + 14, j + 24, k + 13, Blocks.lapis_block);
		world.setBlock(i + 14, j + 24, k + 14, BlockList.edenSacredStone);
		generate2(world, rand, i, j, k);
		return true;
	}
	
	public boolean generate2(World world, Random rand, int i, int j, int k) {
		world.setBlock(i + 15, j + 2, k + 3, BlockList.edenSacredStone);
		world.setBlock(i + 15, j + 2, k + 23, BlockList.edenSacredStone);
		world.setBlock(i + 15, j + 3, k + 3, BlockList.edenSacredStone);
		world.setBlock(i + 15, j + 3, k + 23, BlockList.edenSacredStone);
		world.setBlock(i + 15, j + 4, k + 3, BlockList.edenSacredStone);
		world.setBlock(i + 15, j + 4, k + 23, BlockList.edenSacredStone);
		world.setBlock(i + 15, j + 5, k + 3, BlockList.edenSacredStone);
		world.setBlock(i + 15, j + 5, k + 23, BlockList.edenSacredStone);
		world.setBlock(i + 15, j + 6, k + 3, BlockList.edenSacredStone);
		world.setBlock(i + 15, j + 6, k + 23, BlockList.edenSacredStone);
		world.setBlock(i + 15, j + 7, k + 3, BlockList.edenSacredStone);
		world.setBlock(i + 15, j + 7, k + 23, BlockList.edenSacredStone);
		world.setBlock(i + 15, j + 8, k + 3, BlockList.edenSacredStone);
		world.setBlock(i + 15, j + 8, k + 4, BlockList.edenSacredStone);
		world.setBlock(i + 15, j + 8, k + 22, BlockList.edenSacredStone);
		world.setBlock(i + 15, j + 8, k + 23, BlockList.edenSacredStone);
		world.setBlock(i + 15, j + 9, k + 4, BlockList.edenSacredStone);
		world.setBlock(i + 15, j + 9, k + 22, BlockList.edenSacredStone);
		world.setBlock(i + 15, j + 10, k + 5, BlockList.edenSacredStone);
		world.setBlock(i + 15, j + 10, k + 21, BlockList.edenSacredStone);
		world.setBlock(i + 15, j + 11, k + 5, BlockList.edenSacredStone);
		world.setBlock(i + 15, j + 11, k + 21, BlockList.edenSacredStone);
		world.setBlock(i + 15, j + 12, k + 6, BlockList.edenSacredStone);
		world.setBlock(i + 15, j + 12, k + 20, BlockList.edenSacredStone);
		world.setBlock(i + 15, j + 13, k + 6, BlockList.edenSacredStone);
		world.setBlock(i + 15, j + 13, k + 20, BlockList.edenSacredStone);
		world.setBlock(i + 15, j + 14, k + 7, BlockList.edenSacredStone);
		world.setBlock(i + 15, j + 14, k + 19, BlockList.edenSacredStone);
		world.setBlock(i + 15, j + 15, k + 7, BlockList.edenSacredStone);
		world.setBlock(i + 15, j + 15, k + 19, BlockList.edenSacredStone);
		world.setBlock(i + 15, j + 16, k + 8, BlockList.edenSacredStone);
		world.setBlock(i + 15, j + 16, k + 18, BlockList.edenSacredStone);
		world.setBlock(i + 15, j + 17, k + 8, BlockList.edenSacredStone);
		world.setBlock(i + 15, j + 17, k + 18, BlockList.edenSacredStone);
		world.setBlock(i + 15, j + 18, k + 9, BlockList.edenSacredStone);
		world.setBlock(i + 15, j + 18, k + 17, BlockList.edenSacredStone);
		world.setBlock(i + 15, j + 19, k + 9, BlockList.edenSacredStone);
		world.setBlock(i + 15, j + 19, k + 17, BlockList.edenSacredStone);
		world.setBlock(i + 15, j + 20, k + 10, BlockList.edenSacredStone);
		world.setBlock(i + 15, j + 20, k + 16, BlockList.edenSacredStone);
		world.setBlock(i + 15, j + 21, k + 10, BlockList.edenSacredStone);
		world.setBlock(i + 15, j + 21, k + 16, BlockList.edenSacredStone);
		world.setBlock(i + 15, j + 22, k + 11, BlockList.edenSacredStone);
		world.setBlock(i + 15, j + 22, k + 15, BlockList.edenSacredStone);
		world.setBlock(i + 15, j + 23, k + 11, BlockList.edenSacredStone);
		world.setBlock(i + 15, j + 23, k + 15, BlockList.edenSacredStone);
		world.setBlock(i + 15, j + 24, k + 12, BlockList.edenSacredStone);
		world.setBlock(i + 15, j + 24, k + 13, BlockList.edenSacredStone);
		world.setBlock(i + 15, j + 24, k + 14, BlockList.edenSacredStone);
		world.setBlock(i + 16, j + 2, k + 3, BlockList.edenSacredStone);
		world.setBlock(i + 16, j + 2, k + 23, BlockList.edenSacredStone);
		world.setBlock(i + 16, j + 3, k + 3, BlockList.edenSacredStone);
		world.setBlock(i + 16, j + 3, k + 23, BlockList.edenSacredStone);
		world.setBlock(i + 16, j + 4, k + 3, BlockList.edenSacredStone);
		world.setBlock(i + 16, j + 4, k + 23, BlockList.edenSacredStone);
		world.setBlock(i + 16, j + 5, k + 3, BlockList.edenSacredStone);
		world.setBlock(i + 16, j + 5, k + 23, BlockList.edenSacredStone);
		world.setBlock(i + 16, j + 6, k + 3, BlockList.edenSacredStone);
		world.setBlock(i + 16, j + 6, k + 23, BlockList.edenSacredStone);
		world.setBlock(i + 16, j + 7, k + 3, BlockList.edenSacredStone);
		world.setBlock(i + 16, j + 7, k + 23, BlockList.edenSacredStone);
		world.setBlock(i + 16, j + 8, k + 3, BlockList.edenSacredStone);
		world.setBlock(i + 16, j + 8, k + 4, BlockList.edenSacredStone);
		world.setBlock(i + 16, j + 8, k + 22, BlockList.edenSacredStone);
		world.setBlock(i + 16, j + 8, k + 23, BlockList.edenSacredStone);
		world.setBlock(i + 16, j + 9, k + 4, BlockList.edenSacredStone);
		world.setBlock(i + 16, j + 9, k + 22, BlockList.edenSacredStone);
		world.setBlock(i + 16, j + 10, k + 5, BlockList.edenSacredStone);
		world.setBlock(i + 16, j + 10, k + 21, BlockList.edenSacredStone);
		world.setBlock(i + 16, j + 11, k + 5, BlockList.edenSacredStone);
		world.setBlock(i + 16, j + 11, k + 21, BlockList.edenSacredStone);
		world.setBlock(i + 16, j + 12, k + 6, BlockList.edenSacredStone);
		world.setBlock(i + 16, j + 12, k + 20, BlockList.edenSacredStone);
		world.setBlock(i + 16, j + 13, k + 6, BlockList.edenSacredStone);
		world.setBlock(i + 16, j + 13, k + 20, BlockList.edenSacredStone);
		world.setBlock(i + 16, j + 14, k + 7, BlockList.edenSacredStone);
		world.setBlock(i + 16, j + 14, k + 19, BlockList.edenSacredStone);
		world.setBlock(i + 16, j + 15, k + 7, BlockList.edenSacredStone);
		world.setBlock(i + 16, j + 15, k + 19, BlockList.edenSacredStone);
		world.setBlock(i + 16, j + 16, k + 8, BlockList.edenSacredStone);
		world.setBlock(i + 16, j + 16, k + 18, BlockList.edenSacredStone);
		world.setBlock(i + 16, j + 17, k + 8, BlockList.edenSacredStone);
		world.setBlock(i + 16, j + 17, k + 18, BlockList.edenSacredStone);
		world.setBlock(i + 16, j + 18, k + 9, BlockList.edenSacredStone);
		world.setBlock(i + 16, j + 18, k + 17, BlockList.edenSacredStone);
		world.setBlock(i + 16, j + 19, k + 9, BlockList.edenSacredStone);
		world.setBlock(i + 16, j + 19, k + 10, BlockList.edenSacredStone);
		world.setBlock(i + 16, j + 19, k + 16, BlockList.edenSacredStone);
		world.setBlock(i + 16, j + 19, k + 17, BlockList.edenSacredStone);
		world.setBlock(i + 16, j + 20, k + 11, BlockList.edenSacredStone);
		world.setBlock(i + 16, j + 20, k + 15, BlockList.edenSacredStone);
		world.setBlock(i + 16, j + 21, k + 11, BlockList.edenSacredStone);
		world.setBlock(i + 16, j + 21, k + 15, BlockList.edenSacredStone);
		world.setBlock(i + 16, j + 22, k + 12, BlockList.edenSacredStone);
		world.setBlock(i + 16, j + 22, k + 13, BlockList.edenSacredStone);
		world.setBlock(i + 16, j + 22, k + 14, BlockList.edenSacredStone);
		world.setBlock(i + 16, j + 23, k + 12, BlockList.edenSacredStone);
		world.setBlock(i + 16, j + 23, k + 13, BlockList.edenSacredStone);
		world.setBlock(i + 16, j + 23, k + 14, BlockList.edenSacredStone);
		world.setBlock(i + 17, j + 2, k + 3, BlockList.edenSacredStone);
		world.setBlock(i + 17, j + 2, k + 23, BlockList.edenSacredStone);
		world.setBlock(i + 17, j + 3, k + 3, BlockList.edenSacredStone);
		world.setBlock(i + 17, j + 3, k + 23, BlockList.edenSacredStone);
		world.setBlock(i + 17, j + 4, k + 3, BlockList.edenSacredStone);
		world.setBlock(i + 17, j + 4, k + 23, BlockList.edenSacredStone);
		world.setBlock(i + 17, j + 5, k + 3, BlockList.edenSacredStone);
		world.setBlock(i + 17, j + 5, k + 23, BlockList.edenSacredStone);
		world.setBlock(i + 17, j + 6, k + 3, BlockList.edenSacredStone);
		world.setBlock(i + 17, j + 6, k + 23, BlockList.edenSacredStone);
		world.setBlock(i + 17, j + 7, k + 3, BlockList.edenSacredStone);
		world.setBlock(i + 17, j + 7, k + 23, BlockList.edenSacredStone);
		world.setBlock(i + 17, j + 8, k + 3, BlockList.edenSacredStone);
		world.setBlock(i + 17, j + 8, k + 4, BlockList.edenSacredStone);
		world.setBlock(i + 17, j + 8, k + 22, BlockList.edenSacredStone);
		world.setBlock(i + 17, j + 8, k + 23, BlockList.edenSacredStone);
		world.setBlock(i + 17, j + 9, k + 4, BlockList.edenSacredStone);
		world.setBlock(i + 17, j + 9, k + 5, BlockList.edenSacredStone);
		world.setBlock(i + 17, j + 9, k + 21, BlockList.edenSacredStone);
		world.setBlock(i + 17, j + 9, k + 22, BlockList.edenSacredStone);
		world.setBlock(i + 17, j + 10, k + 6, BlockList.edenSacredStone);
		world.setBlock(i + 17, j + 10, k + 20, BlockList.edenSacredStone);
		world.setBlock(i + 17, j + 11, k + 6, BlockList.edenSacredStone);
		world.setBlock(i + 17, j + 11, k + 20, BlockList.edenSacredStone);
		world.setBlock(i + 17, j + 12, k + 7, BlockList.edenSacredStone);
		world.setBlock(i + 17, j + 12, k + 19, BlockList.edenSacredStone);
		world.setBlock(i + 17, j + 13, k + 7, BlockList.edenSacredStone);
		world.setBlock(i + 17, j + 13, k + 19, BlockList.edenSacredStone);
		world.setBlock(i + 17, j + 14, k + 8, BlockList.edenSacredStone);
		world.setBlock(i + 17, j + 14, k + 18, BlockList.edenSacredStone);
		world.setBlock(i + 17, j + 15, k + 8, BlockList.edenSacredStone);
		world.setBlock(i + 17, j + 15, k + 18, BlockList.edenSacredStone);
		world.setBlock(i + 17, j + 16, k + 9, BlockList.edenSacredStone);
		world.setBlock(i + 17, j + 16, k + 17, BlockList.edenSacredStone);
		world.setBlock(i + 17, j + 17, k + 9, BlockList.edenSacredStone);
		world.setBlock(i + 17, j + 17, k + 17, BlockList.edenSacredStone);
		world.setBlock(i + 17, j + 18, k + 10, BlockList.edenSacredStone);
		world.setBlock(i + 17, j + 18, k + 16, BlockList.edenSacredStone);
		world.setBlock(i + 17, j + 19, k + 10, BlockList.edenSacredStone);
		world.setBlock(i + 17, j + 19, k + 11, BlockList.edenSacredStone);
		world.setBlock(i + 17, j + 19, k + 15, BlockList.edenSacredStone);
		world.setBlock(i + 17, j + 19, k + 16, BlockList.edenSacredStone);
		world.setBlock(i + 17, j + 20, k + 12, BlockList.edenSacredStone);
		world.setBlock(i + 17, j + 20, k + 13, BlockList.edenSacredStone);
		world.setBlock(i + 17, j + 20, k + 14, BlockList.edenSacredStone);
		world.setBlock(i + 17, j + 21, k + 12, BlockList.edenSacredStone);
		world.setBlock(i + 17, j + 21, k + 13, BlockList.edenSacredStone);
		world.setBlock(i + 17, j + 21, k + 14, BlockList.edenSacredStone);
		world.setBlock(i + 18, j + 2, k + 4, BlockList.edenSacredStone);
		world.setBlock(i + 18, j + 2, k + 22, BlockList.edenSacredStone);
		world.setBlock(i + 18, j + 3, k + 4, BlockList.edenSacredStone);
		world.setBlock(i + 18, j + 3, k + 22, BlockList.edenSacredStone);
		world.setBlock(i + 18, j + 4, k + 4, BlockList.edenSacredStone);
		world.setBlock(i + 18, j + 4, k + 22, BlockList.edenSacredStone);
		world.setBlock(i + 18, j + 5, k + 4, BlockList.edenSacredStone);
		world.setBlock(i + 18, j + 5, k + 22, BlockList.edenSacredStone);
		world.setBlock(i + 18, j + 6, k + 4, BlockList.edenSacredStone);
		world.setBlock(i + 18, j + 6, k + 22, BlockList.edenSacredStone);
		world.setBlock(i + 18, j + 7, k + 4, BlockList.edenSacredStone);
		world.setBlock(i + 18, j + 7, k + 22, BlockList.edenSacredStone);
		world.setBlock(i + 18, j + 8, k + 4, BlockList.edenSacredStone);
		world.setBlock(i + 18, j + 8, k + 5, BlockList.edenSacredStone);
		world.setBlock(i + 18, j + 8, k + 21, BlockList.edenSacredStone);
		world.setBlock(i + 18, j + 8, k + 22, BlockList.edenSacredStone);
		world.setBlock(i + 18, j + 9, k + 5, BlockList.edenSacredStone);
		world.setBlock(i + 18, j + 9, k + 21, BlockList.edenSacredStone);
		world.setBlock(i + 18, j + 10, k + 6, BlockList.edenSacredStone);
		world.setBlock(i + 18, j + 10, k + 20, BlockList.edenSacredStone);
		world.setBlock(i + 18, j + 11, k + 6, BlockList.edenSacredStone);
		world.setBlock(i + 18, j + 11, k + 20, BlockList.edenSacredStone);
		world.setBlock(i + 18, j + 12, k + 7, BlockList.edenSacredStone);
		world.setBlock(i + 18, j + 12, k + 19, BlockList.edenSacredStone);
		world.setBlock(i + 18, j + 13, k + 7, BlockList.edenSacredStone);
		world.setBlock(i + 18, j + 13, k + 19, BlockList.edenSacredStone);
		world.setBlock(i + 18, j + 14, k + 8, BlockList.edenSacredStone);
		world.setBlock(i + 18, j + 14, k + 18, BlockList.edenSacredStone);
		world.setBlock(i + 18, j + 15, k + 8, BlockList.edenSacredStone);
		world.setBlock(i + 18, j + 15, k + 9, BlockList.edenSacredStone);
		world.setBlock(i + 18, j + 15, k + 17, BlockList.edenSacredStone);
		world.setBlock(i + 18, j + 15, k + 18, BlockList.edenSacredStone);
		world.setBlock(i + 18, j + 16, k + 10, BlockList.edenSacredStone);
		world.setBlock(i + 18, j + 16, k + 16, BlockList.edenSacredStone);
		world.setBlock(i + 18, j + 17, k + 10, BlockList.edenSacredStone);
		world.setBlock(i + 18, j + 17, k + 16, BlockList.edenSacredStone);
		world.setBlock(i + 18, j + 18, k + 11, BlockList.edenSacredStone);
		world.setBlock(i + 18, j + 18, k + 12, BlockList.edenSacredStone);
		world.setBlock(i + 18, j + 18, k + 13, BlockList.edenSacredStone);
		world.setBlock(i + 18, j + 18, k + 14, BlockList.edenSacredStone);
		world.setBlock(i + 18, j + 18, k + 15, BlockList.edenSacredStone);
		world.setBlock(i + 18, j + 19, k + 11, BlockList.edenSacredStone);
		world.setBlock(i + 18, j + 19, k + 12, BlockList.edenSacredStone);
		world.setBlock(i + 18, j + 19, k + 13, BlockList.edenSacredStone);
		world.setBlock(i + 18, j + 19, k + 14, BlockList.edenSacredStone);
		world.setBlock(i + 18, j + 19, k + 15, BlockList.edenSacredStone);
		world.setBlock(i + 19, j + 2, k + 4, BlockList.edenSacredStone);
		world.setBlock(i + 19, j + 2, k + 22, BlockList.edenSacredStone);
		world.setBlock(i + 19, j + 3, k + 4, BlockList.edenSacredStone);
		world.setBlock(i + 19, j + 3, k + 22, BlockList.edenSacredStone);
		world.setBlock(i + 19, j + 4, k + 4, BlockList.edenSacredStone);
		world.setBlock(i + 19, j + 4, k + 22, BlockList.edenSacredStone);
		world.setBlock(i + 19, j + 5, k + 4, BlockList.edenSacredStone);
		world.setBlock(i + 19, j + 5, k + 22, BlockList.edenSacredStone);
		world.setBlock(i + 19, j + 6, k + 4, BlockList.edenSacredStone);
		world.setBlock(i + 19, j + 6, k + 22, BlockList.edenSacredStone);
		world.setBlock(i + 19, j + 7, k + 4, BlockList.edenSacredStone);
		world.setBlock(i + 19, j + 7, k + 22, BlockList.edenSacredStone);
		world.setBlock(i + 19, j + 8, k + 4, BlockList.edenSacredStone);
		world.setBlock(i + 19, j + 8, k + 5, BlockList.edenSacredStone);
		world.setBlock(i + 19, j + 8, k + 21, BlockList.edenSacredStone);
		world.setBlock(i + 19, j + 8, k + 22, BlockList.edenSacredStone);
		world.setBlock(i + 19, j + 9, k + 5, BlockList.edenSacredStone);
		world.setBlock(i + 19, j + 9, k + 6, BlockList.edenSacredStone);
		world.setBlock(i + 19, j + 9, k + 20, BlockList.edenSacredStone);
		world.setBlock(i + 19, j + 9, k + 21, BlockList.edenSacredStone);
		world.setBlock(i + 19, j + 10, k + 7, BlockList.edenSacredStone);
		world.setBlock(i + 19, j + 10, k + 19, BlockList.edenSacredStone);
		world.setBlock(i + 19, j + 11, k + 7, BlockList.edenSacredStone);
		world.setBlock(i + 19, j + 11, k + 19, BlockList.edenSacredStone);
		world.setBlock(i + 19, j + 12, k + 8, BlockList.edenSacredStone);
		world.setBlock(i + 19, j + 12, k + 18, BlockList.edenSacredStone);
		world.setBlock(i + 19, j + 13, k + 8, BlockList.edenSacredStone);
		world.setBlock(i + 19, j + 13, k + 18, BlockList.edenSacredStone);
		world.setBlock(i + 19, j + 14, k + 9, BlockList.edenSacredStone);
		world.setBlock(i + 19, j + 14, k + 10, BlockList.edenSacredStone);
		world.setBlock(i + 19, j + 14, k + 16, BlockList.edenSacredStone);
		world.setBlock(i + 19, j + 14, k + 17, BlockList.edenSacredStone);
		world.setBlock(i + 19, j + 15, k + 9, BlockList.edenSacredStone);
		world.setBlock(i + 19, j + 15, k + 10, BlockList.edenSacredStone);
		world.setBlock(i + 19, j + 15, k + 16, BlockList.edenSacredStone);
		world.setBlock(i + 19, j + 15, k + 17, BlockList.edenSacredStone);
		world.setBlock(i + 19, j + 16, k + 11, BlockList.edenSacredStone);
		world.setBlock(i + 19, j + 16, k + 12, BlockList.edenSacredStone);
		world.setBlock(i + 19, j + 16, k + 13, BlockList.edenSacredStone);
		world.setBlock(i + 19, j + 16, k + 14, BlockList.edenSacredStone);
		world.setBlock(i + 19, j + 16, k + 15, BlockList.edenSacredStone);
		world.setBlock(i + 19, j + 17, k + 11, BlockList.edenSacredStone);
		world.setBlock(i + 19, j + 17, k + 12, BlockList.edenSacredStone);
		world.setBlock(i + 19, j + 17, k + 13, BlockList.edenSacredStone);
		world.setBlock(i + 19, j + 17, k + 14, BlockList.edenSacredStone);
		world.setBlock(i + 19, j + 17, k + 15, BlockList.edenSacredStone);
		world.setBlock(i + 20, j + 2, k + 5, BlockList.edenSacredStone);
		world.setBlock(i + 20, j + 2, k + 21, BlockList.edenSacredStone);
		world.setBlock(i + 20, j + 3, k + 5, BlockList.edenSacredStone);
		world.setBlock(i + 20, j + 3, k + 21, BlockList.edenSacredStone);
		world.setBlock(i + 20, j + 4, k + 5, BlockList.edenSacredStone);
		world.setBlock(i + 20, j + 4, k + 21, BlockList.edenSacredStone);
		world.setBlock(i + 20, j + 5, k + 5, BlockList.edenSacredStone);
		world.setBlock(i + 20, j + 5, k + 21, BlockList.edenSacredStone);
		world.setBlock(i + 20, j + 6, k + 5, BlockList.edenSacredStone);
		world.setBlock(i + 20, j + 6, k + 21, BlockList.edenSacredStone);
		world.setBlock(i + 20, j + 7, k + 5, BlockList.edenSacredStone);
		world.setBlock(i + 20, j + 7, k + 21, BlockList.edenSacredStone);
		world.setBlock(i + 20, j + 8, k + 5, BlockList.edenSacredStone);
		world.setBlock(i + 20, j + 8, k + 6, BlockList.edenSacredStone);
		world.setBlock(i + 20, j + 8, k + 20, BlockList.edenSacredStone);
		world.setBlock(i + 20, j + 8, k + 21, BlockList.edenSacredStone);
		world.setBlock(i + 20, j + 9, k + 6, BlockList.edenSacredStone);
		world.setBlock(i + 20, j + 9, k + 20, BlockList.edenSacredStone);
		world.setBlock(i + 20, j + 10, k + 7, BlockList.edenSacredStone);
		world.setBlock(i + 20, j + 10, k + 8, BlockList.edenSacredStone);
		world.setBlock(i + 20, j + 10, k + 18, BlockList.edenSacredStone);
		world.setBlock(i + 20, j + 10, k + 19, BlockList.edenSacredStone);
		world.setBlock(i + 20, j + 11, k + 7, BlockList.edenSacredStone);
		world.setBlock(i + 20, j + 11, k + 8, BlockList.edenSacredStone);
		world.setBlock(i + 20, j + 11, k + 18, BlockList.edenSacredStone);
		world.setBlock(i + 20, j + 11, k + 19, BlockList.edenSacredStone);
		world.setBlock(i + 20, j + 12, k + 9, BlockList.edenSacredStone);
		world.setBlock(i + 20, j + 12, k + 10, BlockList.edenSacredStone);
		world.setBlock(i + 20, j + 12, k + 16, BlockList.edenSacredStone);
		world.setBlock(i + 20, j + 12, k + 17, BlockList.edenSacredStone);
		world.setBlock(i + 20, j + 13, k + 9, BlockList.edenSacredStone);
		world.setBlock(i + 20, j + 13, k + 10, BlockList.edenSacredStone);
		world.setBlock(i + 20, j + 13, k + 16, BlockList.edenSacredStone);
		world.setBlock(i + 20, j + 13, k + 17, BlockList.edenSacredStone);
		world.setBlock(i + 20, j + 14, k + 11, BlockList.edenSacredStone);
		world.setBlock(i + 20, j + 14, k + 12, BlockList.edenSacredStone);
		world.setBlock(i + 20, j + 14, k + 13, BlockList.edenSacredStone);
		world.setBlock(i + 20, j + 14, k + 14, BlockList.edenSacredStone);
		world.setBlock(i + 20, j + 14, k + 15, BlockList.edenSacredStone);
		world.setBlock(i + 20, j + 15, k + 11, BlockList.edenSacredStone);
		world.setBlock(i + 20, j + 15, k + 12, BlockList.edenSacredStone);
		world.setBlock(i + 20, j + 15, k + 13, BlockList.edenSacredStone);
		world.setBlock(i + 20, j + 15, k + 14, BlockList.edenSacredStone);
		world.setBlock(i + 20, j + 15, k + 15, BlockList.edenSacredStone);
		world.setBlock(i + 21, j + 2, k + 6, BlockList.edenSacredStone);
		world.setBlock(i + 21, j + 2, k + 20, BlockList.edenSacredStone);
		world.setBlock(i + 21, j + 3, k + 6, BlockList.edenSacredStone);
		world.setBlock(i + 21, j + 3, k + 20, BlockList.edenSacredStone);
		world.setBlock(i + 21, j + 4, k + 6, BlockList.edenSacredStone);
		world.setBlock(i + 21, j + 4, k + 20, BlockList.edenSacredStone);
		world.setBlock(i + 21, j + 5, k + 6, BlockList.edenSacredStone);
		world.setBlock(i + 21, j + 5, k + 20, BlockList.edenSacredStone);
		world.setBlock(i + 21, j + 6, k + 6, BlockList.edenSacredStone);
		world.setBlock(i + 21, j + 6, k + 20, BlockList.edenSacredStone);
		world.setBlock(i + 21, j + 7, k + 6, BlockList.edenSacredStone);
		world.setBlock(i + 21, j + 7, k + 20, BlockList.edenSacredStone);
		world.setBlock(i + 21, j + 8, k + 6, BlockList.edenSacredStone);
		world.setBlock(i + 21, j + 8, k + 7, BlockList.edenSacredStone);
		world.setBlock(i + 21, j + 8, k + 19, BlockList.edenSacredStone);
		world.setBlock(i + 21, j + 8, k + 20, BlockList.edenSacredStone);
		world.setBlock(i + 21, j + 9, k + 7, BlockList.edenSacredStone);
		world.setBlock(i + 21, j + 9, k + 8, BlockList.edenSacredStone);
		world.setBlock(i + 21, j + 9, k + 18, BlockList.edenSacredStone);
		world.setBlock(i + 21, j + 9, k + 19, BlockList.edenSacredStone);
		world.setBlock(i + 21, j + 10, k + 9, BlockList.edenSacredStone);
		world.setBlock(i + 21, j + 10, k + 10, BlockList.edenSacredStone);
		world.setBlock(i + 21, j + 10, k + 16, BlockList.edenSacredStone);
		world.setBlock(i + 21, j + 10, k + 17, BlockList.edenSacredStone);
		world.setBlock(i + 21, j + 11, k + 9, BlockList.edenSacredStone);
		world.setBlock(i + 21, j + 11, k + 10, BlockList.edenSacredStone);
		world.setBlock(i + 21, j + 11, k + 16, BlockList.edenSacredStone);
		world.setBlock(i + 21, j + 11, k + 17, BlockList.edenSacredStone);
		world.setBlock(i + 21, j + 12, k + 11, BlockList.edenSacredStone);
		world.setBlock(i + 21, j + 12, k + 12, BlockList.edenSacredStone);
		world.setBlock(i + 21, j + 12, k + 13, BlockList.edenSacredStone);
		world.setBlock(i + 21, j + 12, k + 14, BlockList.edenSacredStone);
		world.setBlock(i + 21, j + 12, k + 15, BlockList.edenSacredStone);
		world.setBlock(i + 21, j + 13, k + 11, BlockList.edenSacredStone);
		world.setBlock(i + 21, j + 13, k + 12, BlockList.edenSacredStone);
		world.setBlock(i + 21, j + 13, k + 13, BlockList.edenSacredStone);
		world.setBlock(i + 21, j + 13, k + 14, BlockList.edenSacredStone);
		world.setBlock(i + 21, j + 13, k + 15, BlockList.edenSacredStone);
		world.setBlock(i + 22, j + 2, k + 7, BlockList.edenSacredStone);
		world.setBlock(i + 22, j + 2, k + 19, BlockList.edenSacredStone);
		world.setBlock(i + 22, j + 3, k + 7, BlockList.edenSacredStone);
		world.setBlock(i + 22, j + 3, k + 19, BlockList.edenSacredStone);
		world.setBlock(i + 22, j + 4, k + 7, BlockList.edenSacredStone);
		world.setBlock(i + 22, j + 4, k + 19, BlockList.edenSacredStone);
		world.setBlock(i + 22, j + 5, k + 7, BlockList.edenSacredStone);
		world.setBlock(i + 22, j + 5, k + 19, BlockList.edenSacredStone);
		world.setBlock(i + 22, j + 6, k + 7, BlockList.edenSacredStone);
		world.setBlock(i + 22, j + 6, k + 19, BlockList.edenSacredStone);
		world.setBlock(i + 22, j + 7, k + 7, BlockList.edenSacredStone);
		world.setBlock(i + 22, j + 7, k + 19, BlockList.edenSacredStone);
		world.setBlock(i + 22, j + 8, k + 7, BlockList.edenSacredStone);
		world.setBlock(i + 22, j + 8, k + 8, BlockList.edenSacredStone);
		world.setBlock(i + 22, j + 8, k + 9, BlockList.edenSacredStone);
		world.setBlock(i + 22, j + 8, k + 17, BlockList.edenSacredStone);
		world.setBlock(i + 22, j + 8, k + 18, BlockList.edenSacredStone);
		world.setBlock(i + 22, j + 8, k + 19, BlockList.edenSacredStone);
		world.setBlock(i + 22, j + 9, k + 8, BlockList.edenSacredStone);
		world.setBlock(i + 22, j + 9, k + 9, BlockList.edenSacredStone);
		world.setBlock(i + 22, j + 9, k + 10, BlockList.edenSacredStone);
		world.setBlock(i + 22, j + 9, k + 16, BlockList.edenSacredStone);
		world.setBlock(i + 22, j + 9, k + 17, BlockList.edenSacredStone);
		world.setBlock(i + 22, j + 9, k + 18, BlockList.edenSacredStone);
		world.setBlock(i + 22, j + 10, k + 11, BlockList.edenSacredStone);
		world.setBlock(i + 22, j + 10, k + 12, BlockList.edenSacredStone);
		world.setBlock(i + 22, j + 10, k + 13, BlockList.edenSacredStone);
		world.setBlock(i + 22, j + 10, k + 14, BlockList.edenSacredStone);
		world.setBlock(i + 22, j + 10, k + 15, BlockList.edenSacredStone);
		world.setBlock(i + 22, j + 11, k + 11, BlockList.edenSacredStone);
		world.setBlock(i + 22, j + 11, k + 12, BlockList.edenSacredStone);
		world.setBlock(i + 22, j + 11, k + 13, BlockList.edenSacredStone);
		world.setBlock(i + 22, j + 11, k + 14, BlockList.edenSacredStone);
		world.setBlock(i + 22, j + 11, k + 15, BlockList.edenSacredStone);
		world.setBlock(i + 23, j + 2, k + 8, BlockList.edenSacredStone);
		world.setBlock(i + 23, j + 2, k + 9, BlockList.edenSacredStone);
		world.setBlock(i + 23, j + 2, k + 17, BlockList.edenSacredStone);
		world.setBlock(i + 23, j + 2, k + 18, BlockList.edenSacredStone);
		world.setBlock(i + 23, j + 3, k + 8, BlockList.edenSacredStone);
		world.setBlock(i + 23, j + 3, k + 9, BlockList.edenSacredStone);
		world.setBlock(i + 23, j + 3, k + 17, BlockList.edenSacredStone);
		world.setBlock(i + 23, j + 3, k + 18, BlockList.edenSacredStone);
		world.setBlock(i + 23, j + 4, k + 8, BlockList.edenSacredStone);
		world.setBlock(i + 23, j + 4, k + 9, BlockList.edenSacredStone);
		world.setBlock(i + 23, j + 4, k + 17, BlockList.edenSacredStone);
		world.setBlock(i + 23, j + 4, k + 18, BlockList.edenSacredStone);
		world.setBlock(i + 23, j + 5, k + 8, BlockList.edenSacredStone);
		world.setBlock(i + 23, j + 5, k + 9, BlockList.edenSacredStone);
		world.setBlock(i + 23, j + 5, k + 17, BlockList.edenSacredStone);
		world.setBlock(i + 23, j + 5, k + 18, BlockList.edenSacredStone);
		world.setBlock(i + 23, j + 6, k + 8, BlockList.edenSacredStone);
		world.setBlock(i + 23, j + 6, k + 9, BlockList.edenSacredStone);
		world.setBlock(i + 23, j + 6, k + 17, BlockList.edenSacredStone);
		world.setBlock(i + 23, j + 6, k + 18, BlockList.edenSacredStone);
		world.setBlock(i + 23, j + 7, k + 8, BlockList.edenSacredStone);
		world.setBlock(i + 23, j + 7, k + 9, BlockList.edenSacredStone);
		world.setBlock(i + 23, j + 7, k + 17, BlockList.edenSacredStone);
		world.setBlock(i + 23, j + 7, k + 18, BlockList.edenSacredStone);
		world.setBlock(i + 23, j + 8, k + 8, BlockList.edenSacredStone);
		world.setBlock(i + 23, j + 8, k + 9, BlockList.edenSacredStone);
		world.setBlock(i + 23, j + 8, k + 10, BlockList.edenSacredStone);
		world.setBlock(i + 23, j + 8, k + 11, BlockList.edenSacredStone);
		world.setBlock(i + 23, j + 8, k + 12, BlockList.edenSacredStone);
		world.setBlock(i + 23, j + 8, k + 13, BlockList.edenSacredStone);
		world.setBlock(i + 23, j + 8, k + 14, BlockList.edenSacredStone);
		world.setBlock(i + 23, j + 8, k + 15, BlockList.edenSacredStone);
		world.setBlock(i + 23, j + 8, k + 16, BlockList.edenSacredStone);
		world.setBlock(i + 23, j + 8, k + 17, BlockList.edenSacredStone);
		world.setBlock(i + 23, j + 8, k + 18, BlockList.edenSacredStone);
		world.setBlock(i + 23, j + 9, k + 10, BlockList.edenSacredStone);
		world.setBlock(i + 23, j + 9, k + 11, BlockList.edenSacredStone);
		world.setBlock(i + 23, j + 9, k + 12, BlockList.edenSacredStone);
		world.setBlock(i + 23, j + 9, k + 13, BlockList.edenSacredStone);
		world.setBlock(i + 23, j + 9, k + 14, BlockList.edenSacredStone);
		world.setBlock(i + 23, j + 9, k + 15, BlockList.edenSacredStone);
		world.setBlock(i + 23, j + 9, k + 16, BlockList.edenSacredStone);
		world.setBlock(i + 24, j + 2, k + 10, BlockList.edenSacredStone);
		world.setBlock(i + 24, j + 2, k + 11, BlockList.edenSacredStone);
		world.setBlock(i + 24, j + 2, k + 14, BlockList.edenSacredStone);
		world.setBlock(i + 24, j + 2, k + 15, BlockList.edenSacredStone);
		world.setBlock(i + 24, j + 2, k + 16, BlockList.edenSacredStone);
		world.setBlock(i + 24, j + 3, k + 10, BlockList.edenSacredStone);
		world.setBlock(i + 24, j + 3, k + 11, BlockList.edenSacredStone);
		world.setBlock(i + 24, j + 3, k + 14, BlockList.edenSacredStone);
		world.setBlock(i + 24, j + 3, k + 15, BlockList.edenSacredStone);
		world.setBlock(i + 24, j + 3, k + 16, BlockList.edenSacredStone);
		world.setBlock(i + 24, j + 4, k + 10, BlockList.edenSacredStone);
		world.setBlock(i + 24, j + 4, k + 11, BlockList.edenSacredStone);
		world.setBlock(i + 24, j + 4, k + 12, BlockList.edenSacredStone);
		world.setBlock(i + 24, j + 4, k + 13, BlockList.edenSacredStone);
		world.setBlock(i + 24, j + 4, k + 14, BlockList.edenSacredStone);
		world.setBlock(i + 24, j + 4, k + 15, BlockList.edenSacredStone);
		world.setBlock(i + 24, j + 4, k + 16, BlockList.edenSacredStone);
		world.setBlock(i + 24, j + 5, k + 10, BlockList.edenSacredStone);
		world.setBlock(i + 24, j + 5, k + 11, BlockList.edenSacredStone);
		world.setBlock(i + 24, j + 5, k + 12, BlockList.edenSacredStone);
		world.setBlock(i + 24, j + 5, k + 13, BlockList.edenSacredStone);
		world.setBlock(i + 24, j + 5, k + 14, BlockList.edenSacredStone);
		world.setBlock(i + 24, j + 5, k + 15, BlockList.edenSacredStone);
		world.setBlock(i + 24, j + 5, k + 16, BlockList.edenSacredStone);
		world.setBlock(i + 24, j + 6, k + 10, BlockList.edenSacredStone);
		world.setBlock(i + 24, j + 6, k + 11, BlockList.edenSacredStone);
		world.setBlock(i + 24, j + 6, k + 12, BlockList.edenSacredStone);
		world.setBlock(i + 24, j + 6, k + 13, BlockList.edenSacredStone);
		world.setBlock(i + 24, j + 6, k + 14, BlockList.edenSacredStone);
		world.setBlock(i + 24, j + 6, k + 15, BlockList.edenSacredStone);
		world.setBlock(i + 24, j + 6, k + 16, BlockList.edenSacredStone);
		world.setBlock(i + 24, j + 7, k + 10, BlockList.edenSacredStone);
		world.setBlock(i + 24, j + 7, k + 11, BlockList.edenSacredStone);
		world.setBlock(i + 24, j + 7, k + 12, BlockList.edenSacredStone);
		world.setBlock(i + 24, j + 7, k + 13, BlockList.edenSacredStone);
		world.setBlock(i + 24, j + 7, k + 14, BlockList.edenSacredStone);
		world.setBlock(i + 24, j + 7, k + 15, BlockList.edenSacredStone);
		world.setBlock(i + 24, j + 7, k + 16, BlockList.edenSacredStone);
		world.setBlock(i + 24, j + 8, k + 10, BlockList.edenSacredStone);
		world.setBlock(i + 24, j + 8, k + 11, BlockList.edenSacredStone);
		world.setBlock(i + 24, j + 8, k + 12, BlockList.edenSacredStone);
		world.setBlock(i + 24, j + 8, k + 13, BlockList.edenSacredStone);
		world.setBlock(i + 24, j + 8, k + 14, BlockList.edenSacredStone);
		world.setBlock(i + 24, j + 8, k + 15, BlockList.edenSacredStone);
		world.setBlock(i + 24, j + 8, k + 16, BlockList.edenSacredStone);
		return true;
	}
}