/**
 * Zollern Galaxy by @author Zollern Wolf
 * Copyright 2016 - 2025
 * You may use this code to learn from,
 * but do not claim it as your own, and
 * do not redistribute it.
 */
package zollerngalaxy.worldgen;

import java.util.Random;
import net.minecraft.block.state.IBlockState;
import net.minecraft.init.Blocks;
import net.minecraft.util.math.BlockPos;
import net.minecraft.world.World;
import zollerngalaxy.core.ZGLootTables;
import zollerngalaxy.lib.helpers.ZGHelper;
import zollerngalaxy.mobs.entities.EntityVexBot;

public class WorldGenUFO extends ZGWorldGenMaster {
	
	private final IBlockState glassState = Blocks.GLASS.getDefaultState();
	private final IBlockState barsState = Blocks.IRON_BARS.getDefaultState();
	private final IBlockState slabState = Blocks.STONE_SLAB.getDefaultState();
	
	private final IBlockState casingState;
	private final IBlockState cobbleState;
	private final IBlockState stoneState;
	private final IBlockState glowState;
	
	public WorldGenUFO(IBlockState casingStateIn, IBlockState cobbleStateIn, IBlockState stoneStateIn, IBlockState glowStateIn) {
		this.casingState = casingStateIn;
		this.cobbleState = cobbleStateIn;
		this.stoneState = stoneStateIn;
		this.glowState = glowStateIn;
	}
	
	@Override
	public boolean generate(World world, Random rand, BlockPos position) {
		position = position.add(0, 20, 0);
		this.setBlock(world, position.add(0, 20, 24), this.casingState);
		this.setBlock(world, position.add(0, 20, 25), this.casingState);
		this.setBlock(world, position.add(0, 20, 26), this.casingState);
		this.setBlock(world, position.add(0, 20, 27), this.casingState);
		this.setBlock(world, position.add(0, 20, 28), this.casingState);
		this.setBlock(world, position.add(0, 20, 29), this.casingState);
		this.setBlock(world, position.add(0, 20, 30), this.casingState);
		this.setBlock(world, position.add(0, 21, 22), this.casingState);
		this.setBlock(world, position.add(0, 21, 23), this.casingState);
		this.setBlock(world, position.add(0, 21, 24), this.casingState);
		this.setBlock(world, position.add(0, 21, 25), this.casingState);
		this.setBlock(world, position.add(0, 21, 26), this.casingState);
		this.setBlock(world, position.add(0, 21, 27), this.casingState);
		this.setBlock(world, position.add(0, 21, 28), this.casingState);
		this.setBlock(world, position.add(0, 21, 29), this.casingState);
		this.setBlock(world, position.add(0, 21, 30), this.casingState);
		this.setBlock(world, position.add(0, 21, 31), this.casingState);
		this.setBlock(world, position.add(0, 21, 32), this.casingState);
		this.setBlock(world, position.add(0, 22, 21), this.casingState);
		this.setBlock(world, position.add(0, 22, 22), this.casingState);
		this.setBlock(world, position.add(0, 22, 23), this.casingState);
		this.setBlock(world, position.add(0, 22, 31), this.casingState);
		this.setBlock(world, position.add(0, 22, 32), this.casingState);
		this.setBlock(world, position.add(0, 22, 33), this.casingState);
		this.setBlock(world, position.add(0, 23, 20), this.casingState);
		this.setBlock(world, position.add(0, 23, 21), this.casingState);
		this.setBlock(world, position.add(0, 23, 22), this.casingState);
		this.setBlock(world, position.add(0, 23, 32), this.casingState);
		this.setBlock(world, position.add(0, 23, 33), this.casingState);
		this.setBlock(world, position.add(0, 23, 34), this.casingState);
		this.setBlock(world, position.add(0, 24, 19), this.casingState);
		this.setBlock(world, position.add(0, 24, 20), this.casingState);
		this.setBlock(world, position.add(0, 24, 21), this.casingState);
		this.setBlock(world, position.add(0, 24, 33), this.casingState);
		this.setBlock(world, position.add(0, 24, 34), this.casingState);
		this.setBlock(world, position.add(0, 24, 35), this.casingState);
		this.setBlock(world, position.add(0, 25, 19), this.casingState);
		this.setBlock(world, position.add(0, 25, 20), this.casingState);
		this.setBlock(world, position.add(0, 25, 34), this.casingState);
		this.setBlock(world, position.add(0, 25, 35), this.casingState);
		this.setBlock(world, position.add(0, 26, 18), this.casingState);
		this.setBlock(world, position.add(0, 26, 19), this.casingState);
		this.setBlock(world, position.add(0, 26, 35), this.casingState);
		this.setBlock(world, position.add(0, 26, 36), this.casingState);
		this.setBlock(world, position.add(0, 27, 18), this.casingState);
		this.setBlock(world, position.add(0, 27, 19), this.casingState);
		this.setBlock(world, position.add(0, 27, 35), this.casingState);
		this.setBlock(world, position.add(0, 27, 36), this.casingState);
		this.setBlock(world, position.add(0, 28, 18), this.casingState);
		this.setBlock(world, position.add(0, 28, 19), this.casingState);
		this.setBlock(world, position.add(0, 28, 35), this.casingState);
		this.setBlock(world, position.add(0, 28, 36), this.casingState);
		this.setBlock(world, position.add(0, 29, 18), this.casingState);
		this.setBlock(world, position.add(0, 29, 19), this.casingState);
		this.setBlock(world, position.add(0, 29, 35), this.casingState);
		this.setBlock(world, position.add(0, 29, 36), this.casingState);
		this.setBlock(world, position.add(0, 30, 18), this.casingState);
		this.setBlock(world, position.add(0, 30, 19), this.casingState);
		this.setBlock(world, position.add(0, 30, 35), this.casingState);
		this.setBlock(world, position.add(0, 30, 36), this.casingState);
		this.setBlock(world, position.add(0, 31, 18), this.glassState);
		this.setBlock(world, position.add(0, 31, 19), this.glassState);
		this.setBlock(world, position.add(0, 31, 20), this.glassState);
		this.setBlock(world, position.add(0, 31, 21), this.glassState);
		this.setBlock(world, position.add(0, 31, 22), this.glassState);
		this.setBlock(world, position.add(0, 31, 23), this.glassState);
		this.setBlock(world, position.add(0, 31, 24), this.glassState);
		this.setBlock(world, position.add(0, 31, 25), this.glassState);
		this.setBlock(world, position.add(0, 31, 26), this.glassState);
		this.setBlock(world, position.add(0, 31, 27), this.glassState);
		this.setBlock(world, position.add(0, 31, 28), this.glassState);
		this.setBlock(world, position.add(0, 31, 29), this.glassState);
		this.setBlock(world, position.add(0, 31, 30), this.glassState);
		this.setBlock(world, position.add(0, 31, 31), this.glassState);
		this.setBlock(world, position.add(0, 31, 32), this.glassState);
		this.setBlock(world, position.add(0, 31, 33), this.glassState);
		this.setBlock(world, position.add(0, 31, 34), this.glassState);
		this.setBlock(world, position.add(0, 31, 35), this.glassState);
		this.setBlock(world, position.add(0, 31, 36), this.glassState);
		this.setBlock(world, position.add(0, 32, 18), this.casingState);
		this.setBlock(world, position.add(0, 32, 19), this.casingState);
		this.setBlock(world, position.add(0, 32, 35), this.casingState);
		this.setBlock(world, position.add(0, 32, 36), this.casingState);
		this.setBlock(world, position.add(1, 18, 24), this.casingState);
		this.setBlock(world, position.add(1, 18, 25), this.casingState);
		this.setBlock(world, position.add(1, 18, 26), this.casingState);
		this.setBlock(world, position.add(1, 18, 27), this.casingState);
		this.setBlock(world, position.add(1, 18, 28), this.casingState);
		this.setBlock(world, position.add(1, 18, 29), this.casingState);
		this.setBlock(world, position.add(1, 18, 30), this.casingState);
		this.setBlock(world, position.add(1, 19, 22), this.casingState);
		this.setBlock(world, position.add(1, 19, 23), this.casingState);
		this.setBlock(world, position.add(1, 19, 24), this.casingState);
		this.setBlock(world, position.add(1, 19, 25), this.casingState);
		this.setBlock(world, position.add(1, 19, 26), this.casingState);
		this.setBlock(world, position.add(1, 19, 27), this.casingState);
		this.setBlock(world, position.add(1, 19, 28), this.casingState);
		this.setBlock(world, position.add(1, 19, 29), this.casingState);
		this.setBlock(world, position.add(1, 19, 30), this.casingState);
		this.setBlock(world, position.add(1, 19, 31), this.casingState);
		this.setBlock(world, position.add(1, 19, 32), this.casingState);
		this.setBlock(world, position.add(1, 20, 20), this.casingState);
		this.setBlock(world, position.add(1, 20, 21), this.casingState);
		this.setBlock(world, position.add(1, 20, 22), this.casingState);
		this.setBlock(world, position.add(1, 20, 23), this.casingState);
		this.setBlock(world, position.add(1, 20, 31), this.casingState);
		this.setBlock(world, position.add(1, 20, 32), this.casingState);
		this.setBlock(world, position.add(1, 20, 33), this.casingState);
		this.setBlock(world, position.add(1, 20, 34), this.casingState);
		this.setBlock(world, position.add(1, 21, 19), this.casingState);
		this.setBlock(world, position.add(1, 21, 20), this.casingState);
		this.setBlock(world, position.add(1, 21, 21), this.casingState);
		this.setBlock(world, position.add(1, 21, 33), this.casingState);
		this.setBlock(world, position.add(1, 21, 34), this.casingState);
		this.setBlock(world, position.add(1, 21, 35), this.casingState);
		this.setBlock(world, position.add(1, 22, 18), this.casingState);
		this.setBlock(world, position.add(1, 22, 19), this.casingState);
		this.setBlock(world, position.add(1, 22, 20), this.casingState);
		this.setBlock(world, position.add(1, 22, 34), this.casingState);
		this.setBlock(world, position.add(1, 22, 35), this.casingState);
		this.setBlock(world, position.add(1, 22, 36), this.casingState);
		this.setBlock(world, position.add(1, 23, 18), this.casingState);
		this.setBlock(world, position.add(1, 23, 19), this.casingState);
		this.setBlock(world, position.add(1, 23, 35), this.casingState);
		this.setBlock(world, position.add(1, 23, 36), this.casingState);
		this.setBlock(world, position.add(1, 24, 17), this.casingState);
		this.setBlock(world, position.add(1, 24, 18), this.casingState);
		this.setBlock(world, position.add(1, 24, 36), this.casingState);
		this.setBlock(world, position.add(1, 24, 37), this.casingState);
		this.setBlock(world, position.add(1, 25, 17), this.casingState);
		this.setBlock(world, position.add(1, 25, 18), this.casingState);
		this.setBlock(world, position.add(1, 25, 36), this.casingState);
		this.setBlock(world, position.add(1, 25, 37), this.casingState);
		this.setBlock(world, position.add(1, 26, 16), this.casingState);
		this.setBlock(world, position.add(1, 26, 17), this.casingState);
		this.setBlock(world, position.add(1, 26, 37), this.casingState);
		this.setBlock(world, position.add(1, 26, 38), this.casingState);
		this.setBlock(world, position.add(1, 27, 16), this.casingState);
		this.setBlock(world, position.add(1, 27, 17), this.casingState);
		this.setBlock(world, position.add(1, 27, 37), this.casingState);
		this.setBlock(world, position.add(1, 27, 38), this.casingState);
		this.setBlock(world, position.add(1, 28, 16), this.casingState);
		this.setBlock(world, position.add(1, 28, 17), this.casingState);
		this.setBlock(world, position.add(1, 28, 37), this.casingState);
		this.setBlock(world, position.add(1, 28, 38), this.casingState);
		this.setBlock(world, position.add(1, 29, 16), this.casingState);
		this.setBlock(world, position.add(1, 29, 17), this.casingState);
		this.setBlock(world, position.add(1, 29, 37), this.casingState);
		this.setBlock(world, position.add(1, 29, 38), this.casingState);
		this.setBlock(world, position.add(1, 30, 16), this.casingState);
		this.setBlock(world, position.add(1, 30, 17), this.casingState);
		this.setBlock(world, position.add(1, 30, 37), this.casingState);
		this.setBlock(world, position.add(1, 30, 38), this.casingState);
		this.setBlock(world, position.add(1, 31, 16), this.glassState);
		this.setBlock(world, position.add(1, 31, 17), this.glassState);
		this.setBlock(world, position.add(1, 31, 18), this.glassState);
		this.setBlock(world, position.add(1, 31, 19), this.glassState);
		this.setBlock(world, position.add(1, 31, 20), this.glassState);
		this.setBlock(world, position.add(1, 31, 21), this.glassState);
		this.setBlock(world, position.add(1, 31, 22), this.glassState);
		this.setBlock(world, position.add(1, 31, 23), this.glassState);
		this.setBlock(world, position.add(1, 31, 24), this.glassState);
		this.setBlock(world, position.add(1, 31, 25), this.glassState);
		this.setBlock(world, position.add(1, 31, 26), this.glassState);
		this.setBlock(world, position.add(1, 31, 27), this.glassState);
		this.setBlock(world, position.add(1, 31, 28), this.glassState);
		this.setBlock(world, position.add(1, 31, 29), this.glassState);
		this.setBlock(world, position.add(1, 31, 30), this.glassState);
		this.setBlock(world, position.add(1, 31, 31), this.glassState);
		this.setBlock(world, position.add(1, 31, 32), this.glassState);
		this.setBlock(world, position.add(1, 31, 33), this.glassState);
		this.setBlock(world, position.add(1, 31, 34), this.glassState);
		this.setBlock(world, position.add(1, 31, 35), this.glassState);
		this.setBlock(world, position.add(1, 31, 36), this.glassState);
		this.setBlock(world, position.add(1, 31, 37), this.glassState);
		this.setBlock(world, position.add(1, 31, 38), this.glassState);
		this.setBlock(world, position.add(1, 32, 16), this.casingState);
		this.setBlock(world, position.add(1, 32, 17), this.casingState);
		this.setBlock(world, position.add(1, 32, 37), this.casingState);
		this.setBlock(world, position.add(1, 32, 38), this.casingState);
		this.setBlock(world, position.add(2, 17, 23), this.casingState);
		this.setBlock(world, position.add(2, 17, 24), this.casingState);
		this.setBlock(world, position.add(2, 17, 25), this.casingState);
		this.setBlock(world, position.add(2, 17, 26), this.casingState);
		this.setBlock(world, position.add(2, 17, 27), this.casingState);
		this.setBlock(world, position.add(2, 17, 28), this.casingState);
		this.setBlock(world, position.add(2, 17, 29), this.casingState);
		this.setBlock(world, position.add(2, 17, 30), this.casingState);
		this.setBlock(world, position.add(2, 17, 31), this.casingState);
		this.setBlock(world, position.add(2, 18, 21), this.casingState);
		this.setBlock(world, position.add(2, 18, 22), this.casingState);
		this.setBlock(world, position.add(2, 18, 23), this.casingState);
		this.setBlock(world, position.add(2, 18, 31), this.casingState);
		this.setBlock(world, position.add(2, 18, 32), this.casingState);
		this.setBlock(world, position.add(2, 18, 33), this.casingState);
		this.setBlock(world, position.add(2, 19, 19), this.casingState);
		this.setBlock(world, position.add(2, 19, 20), this.casingState);
		this.setBlock(world, position.add(2, 19, 21), this.casingState);
		this.setBlock(world, position.add(2, 19, 33), this.casingState);
		this.setBlock(world, position.add(2, 19, 34), this.casingState);
		this.setBlock(world, position.add(2, 19, 35), this.casingState);
		this.setBlock(world, position.add(2, 20, 18), this.casingState);
		this.setBlock(world, position.add(2, 20, 19), this.casingState);
		this.setBlock(world, position.add(2, 20, 35), this.casingState);
		this.setBlock(world, position.add(2, 20, 36), this.casingState);
		this.setBlock(world, position.add(2, 21, 17), this.casingState);
		this.setBlock(world, position.add(2, 21, 18), this.casingState);
		this.setBlock(world, position.add(2, 21, 36), this.casingState);
		this.setBlock(world, position.add(2, 21, 37), this.casingState);
		this.setBlock(world, position.add(2, 22, 17), this.casingState);
		this.setBlock(world, position.add(2, 22, 37), this.casingState);
		this.setBlock(world, position.add(2, 23, 16), this.casingState);
		this.setBlock(world, position.add(2, 23, 17), this.casingState);
		this.setBlock(world, position.add(2, 23, 37), this.casingState);
		this.setBlock(world, position.add(2, 23, 38), this.casingState);
		this.setBlock(world, position.add(2, 24, 16), this.casingState);
		this.setBlock(world, position.add(2, 24, 38), this.casingState);
		this.setBlock(world, position.add(2, 25, 15), this.casingState);
		this.setBlock(world, position.add(2, 25, 16), this.casingState);
		this.setBlock(world, position.add(2, 25, 38), this.casingState);
		this.setBlock(world, position.add(2, 25, 39), this.casingState);
		this.setBlock(world, position.add(2, 26, 15), this.casingState);
		this.setBlock(world, position.add(2, 26, 39), this.casingState);
		this.setBlock(world, position.add(2, 27, 15), this.casingState);
		this.setBlock(world, position.add(2, 27, 39), this.casingState);
		this.setBlock(world, position.add(2, 28, 15), this.casingState);
		this.setBlock(world, position.add(2, 28, 39), this.casingState);
		this.setBlock(world, position.add(2, 29, 15), this.casingState);
		this.setBlock(world, position.add(2, 29, 39), this.casingState);
		this.setBlock(world, position.add(2, 30, 15), this.casingState);
		this.setBlock(world, position.add(2, 30, 39), this.casingState);
		this.setBlock(world, position.add(2, 31, 15), this.glassState);
		this.setBlock(world, position.add(2, 31, 16), this.glassState);
		this.setBlock(world, position.add(2, 31, 17), this.glassState);
		this.setBlock(world, position.add(2, 31, 18), this.glassState);
		this.setBlock(world, position.add(2, 31, 19), this.glassState);
		this.setBlock(world, position.add(2, 31, 20), this.glassState);
		this.setBlock(world, position.add(2, 31, 21), this.glassState);
		this.setBlock(world, position.add(2, 31, 22), this.glassState);
		this.setBlock(world, position.add(2, 31, 23), this.glassState);
		this.setBlock(world, position.add(2, 31, 24), this.glassState);
		this.setBlock(world, position.add(2, 31, 25), this.glassState);
		this.setBlock(world, position.add(2, 31, 26), this.glassState);
		this.setBlock(world, position.add(2, 31, 27), this.glassState);
		this.setBlock(world, position.add(2, 31, 28), this.glassState);
		this.setBlock(world, position.add(2, 31, 29), this.glassState);
		this.setBlock(world, position.add(2, 31, 30), this.glassState);
		this.setBlock(world, position.add(2, 31, 31), this.glassState);
		this.setBlock(world, position.add(2, 31, 32), this.glassState);
		this.setBlock(world, position.add(2, 31, 33), this.glassState);
		this.setBlock(world, position.add(2, 31, 34), this.glassState);
		this.setBlock(world, position.add(2, 31, 35), this.glassState);
		this.setBlock(world, position.add(2, 31, 36), this.glassState);
		this.setBlock(world, position.add(2, 31, 37), this.glassState);
		this.setBlock(world, position.add(2, 31, 38), this.glassState);
		this.setBlock(world, position.add(2, 31, 39), this.glassState);
		this.setBlock(world, position.add(2, 32, 15), this.casingState);
		this.setBlock(world, position.add(2, 32, 39), this.casingState);
		this.setBlock(world, position.add(3, 16, 22), this.casingState);
		this.setBlock(world, position.add(3, 16, 23), this.casingState);
		this.setBlock(world, position.add(3, 16, 24), this.casingState);
		this.setBlock(world, position.add(3, 16, 25), this.casingState);
		this.setBlock(world, position.add(3, 16, 26), this.casingState);
		this.setBlock(world, position.add(3, 16, 27), this.casingState);
		this.setBlock(world, position.add(3, 16, 28), this.casingState);
		this.setBlock(world, position.add(3, 16, 29), this.casingState);
		this.setBlock(world, position.add(3, 16, 30), this.casingState);
		this.setBlock(world, position.add(3, 16, 31), this.casingState);
		this.setBlock(world, position.add(3, 16, 32), this.casingState);
		this.setBlock(world, position.add(3, 17, 20), this.casingState);
		this.setBlock(world, position.add(3, 17, 21), this.casingState);
		this.setBlock(world, position.add(3, 17, 22), this.casingState);
		this.setBlock(world, position.add(3, 17, 32), this.casingState);
		this.setBlock(world, position.add(3, 17, 33), this.casingState);
		this.setBlock(world, position.add(3, 17, 34), this.casingState);
		this.setBlock(world, position.add(3, 18, 19), this.casingState);
		this.setBlock(world, position.add(3, 18, 20), this.casingState);
		this.setBlock(world, position.add(3, 18, 34), this.casingState);
		this.setBlock(world, position.add(3, 18, 35), this.casingState);
		this.setBlock(world, position.add(3, 19, 18), this.casingState);
		this.setBlock(world, position.add(3, 19, 36), this.casingState);
		this.setBlock(world, position.add(3, 20, 17), this.casingState);
		this.setBlock(world, position.add(3, 20, 37), this.casingState);
		this.setBlock(world, position.add(3, 21, 16), this.casingState);
		this.setBlock(world, position.add(3, 21, 38), this.casingState);
		this.setBlock(world, position.add(3, 22, 15), this.casingState);
		this.setBlock(world, position.add(3, 22, 16), this.casingState);
		this.setBlock(world, position.add(3, 22, 38), this.casingState);
		this.setBlock(world, position.add(3, 22, 39), this.casingState);
		this.setBlock(world, position.add(3, 23, 15), this.casingState);
		this.setBlock(world, position.add(3, 23, 39), this.casingState);
		this.setBlock(world, position.add(3, 24, 14), this.casingState);
		this.setBlock(world, position.add(3, 24, 15), this.casingState);
		this.setBlock(world, position.add(3, 24, 39), this.casingState);
		this.setBlock(world, position.add(3, 24, 40), this.casingState);
		this.setBlock(world, position.add(3, 25, 14), this.casingState);
		this.setBlock(world, position.add(3, 25, 40), this.casingState);
		this.setBlock(world, position.add(3, 26, 14), this.casingState);
		this.setBlock(world, position.add(3, 26, 40), this.casingState);
		this.setBlock(world, position.add(3, 27, 14), this.casingState);
		this.setBlock(world, position.add(3, 27, 40), this.casingState);
		this.setBlock(world, position.add(3, 28, 14), this.casingState);
		this.setBlock(world, position.add(3, 28, 40), this.casingState);
		this.setBlock(world, position.add(3, 29, 14), this.casingState);
		this.setBlock(world, position.add(3, 29, 40), this.casingState);
		this.setBlock(world, position.add(3, 30, 14), this.casingState);
		this.setBlock(world, position.add(3, 30, 40), this.casingState);
		this.setBlock(world, position.add(3, 31, 14), this.glassState);
		this.setBlock(world, position.add(3, 31, 15), this.glassState);
		this.setBlock(world, position.add(3, 31, 16), this.glassState);
		this.setBlock(world, position.add(3, 31, 17), this.glassState);
		this.setBlock(world, position.add(3, 31, 18), this.glassState);
		this.setBlock(world, position.add(3, 31, 19), this.glassState);
		this.setBlock(world, position.add(3, 31, 20), this.glassState);
		this.setBlock(world, position.add(3, 31, 21), this.glassState);
		this.setBlock(world, position.add(3, 31, 22), this.glassState);
		this.setBlock(world, position.add(3, 31, 23), this.glassState);
		this.setBlock(world, position.add(3, 31, 24), this.glassState);
		this.setBlock(world, position.add(3, 31, 25), this.glassState);
		this.setBlock(world, position.add(3, 31, 26), this.glassState);
		this.setBlock(world, position.add(3, 31, 27), this.glassState);
		this.setBlock(world, position.add(3, 31, 28), this.glassState);
		this.setBlock(world, position.add(3, 31, 29), this.glassState);
		this.setBlock(world, position.add(3, 31, 30), this.glassState);
		this.setBlock(world, position.add(3, 31, 31), this.glassState);
		this.setBlock(world, position.add(3, 31, 32), this.glassState);
		this.setBlock(world, position.add(3, 31, 33), this.glassState);
		this.setBlock(world, position.add(3, 31, 34), this.glassState);
		this.setBlock(world, position.add(3, 31, 35), this.glassState);
		this.setBlock(world, position.add(3, 31, 36), this.glassState);
		this.setBlock(world, position.add(3, 31, 37), this.glassState);
		this.setBlock(world, position.add(3, 31, 38), this.glassState);
		this.setBlock(world, position.add(3, 31, 39), this.glassState);
		this.setBlock(world, position.add(3, 31, 40), this.glassState);
		this.setBlock(world, position.add(3, 32, 14), this.casingState);
		this.setBlock(world, position.add(3, 32, 40), this.casingState);
		this.setBlock(world, position.add(4, 15, 22), this.casingState);
		this.setBlock(world, position.add(4, 15, 23), this.casingState);
		this.setBlock(world, position.add(4, 15, 24), this.casingState);
		this.setBlock(world, position.add(4, 15, 25), this.casingState);
		this.setBlock(world, position.add(4, 15, 26), this.casingState);
		this.setBlock(world, position.add(4, 15, 27), this.casingState);
		this.setBlock(world, position.add(4, 15, 28), this.casingState);
		this.setBlock(world, position.add(4, 15, 29), this.casingState);
		this.setBlock(world, position.add(4, 15, 30), this.casingState);
		this.setBlock(world, position.add(4, 15, 31), this.casingState);
		this.setBlock(world, position.add(4, 15, 32), this.casingState);
		this.setBlock(world, position.add(4, 16, 20), this.casingState);
		this.setBlock(world, position.add(4, 16, 21), this.casingState);
		this.setBlock(world, position.add(4, 16, 33), this.casingState);
		this.setBlock(world, position.add(4, 16, 34), this.casingState);
		this.setBlock(world, position.add(4, 17, 19), this.casingState);
		this.setBlock(world, position.add(4, 17, 35), this.casingState);
		this.setBlock(world, position.add(4, 18, 17), this.casingState);
		this.setBlock(world, position.add(4, 18, 18), this.casingState);
		this.setBlock(world, position.add(4, 18, 36), this.casingState);
		this.setBlock(world, position.add(4, 18, 37), this.casingState);
		this.setBlock(world, position.add(4, 19, 16), this.casingState);
		this.setBlock(world, position.add(4, 19, 17), this.casingState);
		this.setBlock(world, position.add(4, 19, 37), this.casingState);
		this.setBlock(world, position.add(4, 19, 38), this.casingState);
		this.setBlock(world, position.add(4, 20, 16), this.casingState);
		this.setBlock(world, position.add(4, 20, 38), this.casingState);
		this.setBlock(world, position.add(4, 21, 15), this.casingState);
		this.setBlock(world, position.add(4, 21, 39), this.casingState);
		this.setBlock(world, position.add(4, 22, 14), this.casingState);
		this.setBlock(world, position.add(4, 22, 40), this.casingState);
		this.setBlock(world, position.add(4, 23, 14), this.casingState);
		this.setBlock(world, position.add(4, 23, 40), this.casingState);
		this.setBlock(world, position.add(4, 24, 13), this.casingState);
		this.setBlock(world, position.add(4, 24, 41), this.casingState);
		this.setBlock(world, position.add(4, 25, 13), this.casingState);
		this.setBlock(world, position.add(4, 25, 41), this.casingState);
		this.setBlock(world, position.add(4, 26, 13), this.casingState);
		this.setBlock(world, position.add(4, 26, 41), this.casingState);
		this.setBlock(world, position.add(4, 27, 13), this.casingState);
		this.setBlock(world, position.add(4, 27, 41), this.casingState);
		this.setBlock(world, position.add(4, 28, 13), this.casingState);
		this.setBlock(world, position.add(4, 28, 41), this.casingState);
		this.setBlock(world, position.add(4, 29, 13), this.casingState);
		this.setBlock(world, position.add(4, 29, 41), this.casingState);
		this.setBlock(world, position.add(4, 30, 13), this.casingState);
		this.setBlock(world, position.add(4, 30, 41), this.casingState);
		this.setBlock(world, position.add(4, 31, 13), this.glassState);
		this.setBlock(world, position.add(4, 31, 14), this.glassState);
		this.setBlock(world, position.add(4, 31, 15), this.glassState);
		this.setBlock(world, position.add(4, 31, 16), this.glassState);
		this.setBlock(world, position.add(4, 31, 17), this.glassState);
		this.setBlock(world, position.add(4, 31, 18), this.glassState);
		this.setBlock(world, position.add(4, 31, 19), this.glassState);
		this.setBlock(world, position.add(4, 31, 20), this.glassState);
		this.setBlock(world, position.add(4, 31, 21), this.glassState);
		this.setBlock(world, position.add(4, 31, 22), this.glassState);
		this.setBlock(world, position.add(4, 31, 23), this.glassState);
		this.setBlock(world, position.add(4, 31, 24), this.glassState);
		this.setBlock(world, position.add(4, 31, 25), this.glassState);
		this.setBlock(world, position.add(4, 31, 26), this.glassState);
		this.setBlock(world, position.add(4, 31, 27), this.glassState);
		this.setBlock(world, position.add(4, 31, 28), this.glassState);
		this.setBlock(world, position.add(4, 31, 29), this.glassState);
		this.setBlock(world, position.add(4, 31, 30), this.glassState);
		this.setBlock(world, position.add(4, 31, 31), this.glassState);
		this.setBlock(world, position.add(4, 31, 32), this.glassState);
		this.setBlock(world, position.add(4, 31, 33), this.glassState);
		this.setBlock(world, position.add(4, 31, 34), this.glassState);
		this.setBlock(world, position.add(4, 31, 35), this.glassState);
		this.setBlock(world, position.add(4, 31, 36), this.glassState);
		this.setBlock(world, position.add(4, 31, 37), this.glassState);
		this.setBlock(world, position.add(4, 31, 38), this.glassState);
		this.setBlock(world, position.add(4, 31, 39), this.glassState);
		this.setBlock(world, position.add(4, 31, 40), this.glassState);
		this.setBlock(world, position.add(4, 31, 41), this.glassState);
		this.setBlock(world, position.add(4, 32, 13), this.casingState);
		this.setBlock(world, position.add(4, 32, 41), this.casingState);
		this.setBlock(world, position.add(5, 14, 22), this.casingState);
		this.setBlock(world, position.add(5, 14, 23), this.casingState);
		this.setBlock(world, position.add(5, 14, 24), this.casingState);
		this.setBlock(world, position.add(5, 14, 25), this.casingState);
		this.setBlock(world, position.add(5, 14, 26), this.casingState);
		this.setBlock(world, position.add(5, 14, 27), this.casingState);
		this.setBlock(world, position.add(5, 14, 28), this.casingState);
		this.setBlock(world, position.add(5, 14, 29), this.casingState);
		this.setBlock(world, position.add(5, 14, 30), this.casingState);
		this.setBlock(world, position.add(5, 14, 31), this.casingState);
		this.setBlock(world, position.add(5, 14, 32), this.casingState);
		this.setBlock(world, position.add(5, 15, 20), this.casingState);
		this.setBlock(world, position.add(5, 15, 21), this.casingState);
		this.setBlock(world, position.add(5, 15, 33), this.casingState);
		this.setBlock(world, position.add(5, 15, 34), this.casingState);
		this.setBlock(world, position.add(5, 16, 18), this.casingState);
		this.setBlock(world, position.add(5, 16, 19), this.casingState);
		this.setBlock(world, position.add(5, 16, 35), this.casingState);
		this.setBlock(world, position.add(5, 16, 36), this.casingState);
		this.setBlock(world, position.add(5, 17, 17), this.casingState);
		this.setBlock(world, position.add(5, 17, 18), this.casingState);
		this.setBlock(world, position.add(5, 17, 36), this.casingState);
		this.setBlock(world, position.add(5, 17, 37), this.casingState);
		this.setBlock(world, position.add(5, 18, 16), this.casingState);
		this.setBlock(world, position.add(5, 18, 38), this.casingState);
		this.setBlock(world, position.add(5, 19, 15), this.casingState);
		this.setBlock(world, position.add(5, 19, 39), this.casingState);
		this.setBlock(world, position.add(5, 20, 14), this.casingState);
		this.setBlock(world, position.add(5, 20, 15), this.casingState);
		this.setBlock(world, position.add(5, 20, 39), this.casingState);
		this.setBlock(world, position.add(5, 20, 40), this.casingState);
		this.setBlock(world, position.add(5, 21, 14), this.casingState);
		this.setBlock(world, position.add(5, 21, 40), this.casingState);
		this.setBlock(world, position.add(5, 22, 13), this.casingState);
		this.setBlock(world, position.add(5, 22, 41), this.casingState);
		this.setBlock(world, position.add(5, 23, 13), this.casingState);
		this.setBlock(world, position.add(5, 23, 41), this.casingState);
		this.setBlock(world, position.add(5, 24, 12), this.casingState);
		this.setBlock(world, position.add(5, 24, 42), this.casingState);
		this.setBlock(world, position.add(5, 25, 12), this.casingState);
		this.setBlock(world, position.add(5, 25, 42), this.casingState);
		this.setBlock(world, position.add(5, 26, 12), this.casingState);
		this.setBlock(world, position.add(5, 26, 42), this.casingState);
		this.setBlock(world, position.add(5, 27, 12), this.casingState);
		this.setBlock(world, position.add(5, 27, 42), this.casingState);
		this.setBlock(world, position.add(5, 28, 12), this.casingState);
		this.setBlock(world, position.add(5, 28, 42), this.casingState);
		this.setBlock(world, position.add(5, 29, 12), this.casingState);
		this.setBlock(world, position.add(5, 29, 42), this.casingState);
		this.setBlock(world, position.add(5, 30, 12), this.casingState);
		this.setBlock(world, position.add(5, 30, 42), this.casingState);
		this.setBlock(world, position.add(5, 31, 12), this.glassState);
		this.setBlock(world, position.add(5, 31, 13), this.glassState);
		this.setBlock(world, position.add(5, 31, 14), this.glassState);
		this.setBlock(world, position.add(5, 31, 15), this.glassState);
		this.setBlock(world, position.add(5, 31, 16), this.glassState);
		this.setBlock(world, position.add(5, 31, 17), this.glassState);
		this.setBlock(world, position.add(5, 31, 18), this.glassState);
		this.setBlock(world, position.add(5, 31, 19), this.glassState);
		this.setBlock(world, position.add(5, 31, 20), this.glassState);
		this.setBlock(world, position.add(5, 31, 21), this.glassState);
		this.setBlock(world, position.add(5, 31, 22), this.glassState);
		this.setBlock(world, position.add(5, 31, 23), this.glassState);
		this.setBlock(world, position.add(5, 31, 24), this.glassState);
		this.setBlock(world, position.add(5, 31, 25), this.glassState);
		this.setBlock(world, position.add(5, 31, 26), this.glassState);
		this.setBlock(world, position.add(5, 31, 27), this.glassState);
		this.setBlock(world, position.add(5, 31, 28), this.glassState);
		this.setBlock(world, position.add(5, 31, 29), this.glassState);
		this.setBlock(world, position.add(5, 31, 30), this.glassState);
		this.setBlock(world, position.add(5, 31, 31), this.glassState);
		this.setBlock(world, position.add(5, 31, 32), this.glassState);
		this.setBlock(world, position.add(5, 31, 33), this.glassState);
		this.setBlock(world, position.add(5, 31, 34), this.glassState);
		this.setBlock(world, position.add(5, 31, 35), this.glassState);
		this.setBlock(world, position.add(5, 31, 36), this.glassState);
		this.setBlock(world, position.add(5, 31, 37), this.glassState);
		this.setBlock(world, position.add(5, 31, 38), this.glassState);
		this.setBlock(world, position.add(5, 31, 39), this.glassState);
		this.setBlock(world, position.add(5, 31, 40), this.glassState);
		this.setBlock(world, position.add(5, 31, 41), this.glassState);
		this.setBlock(world, position.add(5, 31, 42), this.glassState);
		this.setBlock(world, position.add(5, 32, 12), this.casingState);
		this.setBlock(world, position.add(5, 32, 42), this.casingState);
		this.setBlock(world, position.add(6, 13, 23), this.casingState);
		this.setBlock(world, position.add(6, 13, 24), this.casingState);
		this.setBlock(world, position.add(6, 13, 25), this.casingState);
		this.setBlock(world, position.add(6, 13, 26), this.casingState);
		this.setBlock(world, position.add(6, 13, 27), this.casingState);
		this.setBlock(world, position.add(6, 13, 28), this.casingState);
		this.setBlock(world, position.add(6, 13, 29), this.casingState);
		this.setBlock(world, position.add(6, 13, 30), this.casingState);
		this.setBlock(world, position.add(6, 13, 31), this.casingState);
		this.setBlock(world, position.add(6, 14, 20), this.casingState);
		this.setBlock(world, position.add(6, 14, 21), this.casingState);
		this.setBlock(world, position.add(6, 14, 22), this.casingState);
		this.setBlock(world, position.add(6, 14, 32), this.casingState);
		this.setBlock(world, position.add(6, 14, 33), this.casingState);
		this.setBlock(world, position.add(6, 14, 34), this.casingState);
		this.setBlock(world, position.add(6, 15, 19), this.casingState);
		this.setBlock(world, position.add(6, 15, 35), this.casingState);
		this.setBlock(world, position.add(6, 16, 17), this.casingState);
		this.setBlock(world, position.add(6, 16, 18), this.casingState);
		this.setBlock(world, position.add(6, 16, 36), this.casingState);
		this.setBlock(world, position.add(6, 16, 37), this.casingState);
		this.setBlock(world, position.add(6, 17, 16), this.casingState);
		this.setBlock(world, position.add(6, 17, 38), this.casingState);
		this.setBlock(world, position.add(6, 18, 15), this.casingState);
		this.setBlock(world, position.add(6, 18, 39), this.casingState);
		this.setBlock(world, position.add(6, 19, 14), this.casingState);
		this.setBlock(world, position.add(6, 19, 40), this.casingState);
		this.setBlock(world, position.add(6, 20, 14), this.casingState);
		this.setBlock(world, position.add(6, 20, 40), this.casingState);
		this.setBlock(world, position.add(6, 21, 13), this.casingState);
		this.setBlock(world, position.add(6, 21, 41), this.casingState);
		this.setBlock(world, position.add(6, 22, 12), this.casingState);
		this.setBlock(world, position.add(6, 22, 42), this.casingState);
		this.setBlock(world, position.add(6, 23, 12), this.casingState);
		this.setBlock(world, position.add(6, 23, 42), this.casingState);
		this.setBlock(world, position.add(6, 24, 12), this.casingState);
		this.setBlock(world, position.add(6, 24, 42), this.casingState);
		this.setBlock(world, position.add(6, 25, 11), this.casingState);
		this.setBlock(world, position.add(6, 25, 43), this.casingState);
		this.setBlock(world, position.add(6, 26, 11), this.casingState);
		this.setBlock(world, position.add(6, 26, 43), this.casingState);
		this.setBlock(world, position.add(6, 27, 11), this.casingState);
		this.setBlock(world, position.add(6, 27, 43), this.casingState);
		this.setBlock(world, position.add(6, 28, 11), this.casingState);
		this.setBlock(world, position.add(6, 28, 43), this.casingState);
		this.setBlock(world, position.add(6, 29, 11), this.casingState);
		this.setBlock(world, position.add(6, 29, 43), this.casingState);
		this.setBlock(world, position.add(6, 30, 11), this.casingState);
		this.setBlock(world, position.add(6, 30, 43), this.casingState);
		this.setBlock(world, position.add(6, 31, 11), this.glassState);
		this.setBlock(world, position.add(6, 31, 12), this.glassState);
		this.setBlock(world, position.add(6, 31, 13), this.glassState);
		this.setBlock(world, position.add(6, 31, 14), this.glassState);
		this.setBlock(world, position.add(6, 31, 15), this.glassState);
		this.setBlock(world, position.add(6, 31, 16), this.glassState);
		this.setBlock(world, position.add(6, 31, 17), this.glassState);
		this.setBlock(world, position.add(6, 31, 18), this.glassState);
		this.setBlock(world, position.add(6, 31, 19), this.glassState);
		this.setBlock(world, position.add(6, 31, 20), this.glassState);
		this.setBlock(world, position.add(6, 31, 21), this.glassState);
		this.setBlock(world, position.add(6, 31, 22), this.glassState);
		this.setBlock(world, position.add(6, 31, 23), this.glassState);
		this.setBlock(world, position.add(6, 31, 24), this.glassState);
		this.setBlock(world, position.add(6, 31, 25), this.glassState);
		this.setBlock(world, position.add(6, 31, 26), this.glassState);
		this.setBlock(world, position.add(6, 31, 27), this.glassState);
		this.setBlock(world, position.add(6, 31, 28), this.glassState);
		this.setBlock(world, position.add(6, 31, 29), this.glassState);
		this.setBlock(world, position.add(6, 31, 30), this.glassState);
		this.setBlock(world, position.add(6, 31, 31), this.glassState);
		this.setBlock(world, position.add(6, 31, 32), this.glassState);
		this.setBlock(world, position.add(6, 31, 33), this.glassState);
		this.setBlock(world, position.add(6, 31, 34), this.glassState);
		this.setBlock(world, position.add(6, 31, 35), this.glassState);
		this.setBlock(world, position.add(6, 31, 36), this.glassState);
		this.setBlock(world, position.add(6, 31, 37), this.glassState);
		this.setBlock(world, position.add(6, 31, 38), this.glassState);
		this.setBlock(world, position.add(6, 31, 39), this.glassState);
		this.setBlock(world, position.add(6, 31, 40), this.glassState);
		this.setBlock(world, position.add(6, 31, 41), this.glassState);
		this.setBlock(world, position.add(6, 31, 42), this.glassState);
		this.setBlock(world, position.add(6, 31, 43), this.glassState);
		this.setBlock(world, position.add(6, 32, 11), this.casingState);
		this.setBlock(world, position.add(6, 32, 43), this.casingState);
		this.setBlock(world, position.add(7, 12, 24), this.casingState);
		this.setBlock(world, position.add(7, 12, 25), this.casingState);
		this.setBlock(world, position.add(7, 12, 26), this.casingState);
		this.setBlock(world, position.add(7, 12, 27), this.casingState);
		this.setBlock(world, position.add(7, 12, 28), this.casingState);
		this.setBlock(world, position.add(7, 12, 29), this.casingState);
		this.setBlock(world, position.add(7, 12, 30), this.casingState);
		this.setBlock(world, position.add(7, 13, 21), this.casingState);
		this.setBlock(world, position.add(7, 13, 22), this.casingState);
		this.setBlock(world, position.add(7, 13, 23), this.casingState);
		this.setBlock(world, position.add(7, 13, 31), this.casingState);
		this.setBlock(world, position.add(7, 13, 32), this.casingState);
		this.setBlock(world, position.add(7, 13, 33), this.casingState);
		this.setBlock(world, position.add(7, 14, 19), this.casingState);
		this.setBlock(world, position.add(7, 14, 20), this.casingState);
		this.setBlock(world, position.add(7, 14, 34), this.casingState);
		this.setBlock(world, position.add(7, 14, 35), this.casingState);
		this.setBlock(world, position.add(7, 15, 17), this.casingState);
		this.setBlock(world, position.add(7, 15, 18), this.casingState);
		this.setBlock(world, position.add(7, 15, 36), this.casingState);
		this.setBlock(world, position.add(7, 15, 37), this.casingState);
		this.setBlock(world, position.add(7, 16, 16), this.casingState);
		this.setBlock(world, position.add(7, 16, 38), this.casingState);
		this.setBlock(world, position.add(7, 17, 15), this.casingState);
		this.setBlock(world, position.add(7, 17, 39), this.casingState);
		this.setBlock(world, position.add(7, 18, 14), this.casingState);
		this.setBlock(world, position.add(7, 18, 40), this.casingState);
		this.setBlock(world, position.add(7, 19, 13), this.casingState);
		this.setBlock(world, position.add(7, 19, 41), this.casingState);
		this.setBlock(world, position.add(7, 20, 13), this.casingState);
		this.setBlock(world, position.add(7, 20, 41), this.casingState);
		this.setBlock(world, position.add(7, 21, 12), this.casingState);
		this.setBlock(world, position.add(7, 21, 42), this.casingState);
		this.setBlock(world, position.add(7, 22, 12), this.casingState);
		this.setBlock(world, position.add(7, 22, 42), this.casingState);
		this.setBlock(world, position.add(7, 23, 11), this.casingState);
		this.setBlock(world, position.add(7, 23, 43), this.casingState);
		this.setBlock(world, position.add(7, 24, 11), this.casingState);
		this.setBlock(world, position.add(7, 24, 43), this.casingState);
		this.setBlock(world, position.add(7, 25, 11), this.casingState);
		this.setBlock(world, position.add(7, 25, 43), this.casingState);
		this.setBlock(world, position.add(7, 26, 10), this.casingState);
		this.setBlock(world, position.add(7, 26, 44), this.casingState);
		this.setBlock(world, position.add(7, 27, 10), this.casingState);
		this.setBlock(world, position.add(7, 27, 44), this.casingState);
		this.setBlock(world, position.add(7, 28, 10), this.casingState);
		this.setBlock(world, position.add(7, 28, 44), this.casingState);
		this.setBlock(world, position.add(7, 29, 10), this.casingState);
		this.setBlock(world, position.add(7, 29, 44), this.casingState);
		this.setBlock(world, position.add(7, 30, 10), this.casingState);
		this.setBlock(world, position.add(7, 30, 44), this.casingState);
		this.setBlock(world, position.add(7, 31, 10), this.glassState);
		this.setBlock(world, position.add(7, 31, 11), this.glassState);
		this.setBlock(world, position.add(7, 31, 12), this.glassState);
		this.setBlock(world, position.add(7, 31, 13), this.glassState);
		this.setBlock(world, position.add(7, 31, 14), this.glassState);
		this.setBlock(world, position.add(7, 31, 15), this.glassState);
		this.setBlock(world, position.add(7, 31, 16), this.glassState);
		this.setBlock(world, position.add(7, 31, 17), this.glassState);
		this.setBlock(world, position.add(7, 31, 18), this.glassState);
		this.setBlock(world, position.add(7, 31, 19), this.glassState);
		this.setBlock(world, position.add(7, 31, 20), this.glassState);
		this.setBlock(world, position.add(7, 31, 21), this.glassState);
		this.setBlock(world, position.add(7, 31, 22), this.glassState);
		this.setBlock(world, position.add(7, 31, 23), this.glassState);
		this.setBlock(world, position.add(7, 31, 24), this.glassState);
		this.setBlock(world, position.add(7, 31, 25), this.glassState);
		this.setBlock(world, position.add(7, 31, 26), this.glassState);
		this.setBlock(world, position.add(7, 31, 27), this.glassState);
		this.setBlock(world, position.add(7, 31, 28), this.glassState);
		this.setBlock(world, position.add(7, 31, 29), this.glassState);
		this.setBlock(world, position.add(7, 31, 30), this.glassState);
		this.setBlock(world, position.add(7, 31, 31), this.glassState);
		this.setBlock(world, position.add(7, 31, 32), this.glassState);
		this.setBlock(world, position.add(7, 31, 33), this.glassState);
		this.setBlock(world, position.add(7, 31, 34), this.glassState);
		this.setBlock(world, position.add(7, 31, 35), this.glassState);
		this.setBlock(world, position.add(7, 31, 36), this.glassState);
		this.setBlock(world, position.add(7, 31, 37), this.glassState);
		this.setBlock(world, position.add(7, 31, 38), this.glassState);
		this.setBlock(world, position.add(7, 31, 39), this.glassState);
		this.setBlock(world, position.add(7, 31, 40), this.glassState);
		this.setBlock(world, position.add(7, 31, 41), this.glassState);
		this.setBlock(world, position.add(7, 31, 42), this.glassState);
		this.setBlock(world, position.add(7, 31, 43), this.glassState);
		this.setBlock(world, position.add(7, 31, 44), this.glassState);
		this.setBlock(world, position.add(7, 32, 10), this.casingState);
		this.setBlock(world, position.add(7, 32, 44), this.casingState);
		this.setBlock(world, position.add(8, 12, 22), this.casingState);
		this.setBlock(world, position.add(8, 12, 23), this.casingState);
		this.setBlock(world, position.add(8, 12, 24), this.casingState);
		this.setBlock(world, position.add(8, 12, 25), this.casingState);
		this.setBlock(world, position.add(8, 12, 26), this.casingState);
		this.setBlock(world, position.add(8, 12, 27), this.casingState);
		this.setBlock(world, position.add(8, 12, 28), this.casingState);
		this.setBlock(world, position.add(8, 12, 29), this.casingState);
		this.setBlock(world, position.add(8, 12, 30), this.casingState);
		this.setBlock(world, position.add(8, 12, 31), this.casingState);
		this.setBlock(world, position.add(8, 12, 32), this.casingState);
		this.setBlock(world, position.add(8, 13, 19), this.casingState);
		this.setBlock(world, position.add(8, 13, 20), this.casingState);
		this.setBlock(world, position.add(8, 13, 21), this.casingState);
		this.setBlock(world, position.add(8, 13, 33), this.casingState);
		this.setBlock(world, position.add(8, 13, 34), this.casingState);
		this.setBlock(world, position.add(8, 13, 35), this.casingState);
		this.setBlock(world, position.add(8, 14, 18), this.casingState);
		this.setBlock(world, position.add(8, 14, 36), this.casingState);
		this.setBlock(world, position.add(8, 15, 16), this.casingState);
		this.setBlock(world, position.add(8, 15, 17), this.casingState);
		this.setBlock(world, position.add(8, 15, 37), this.casingState);
		this.setBlock(world, position.add(8, 15, 38), this.casingState);
		this.setBlock(world, position.add(8, 16, 15), this.casingState);
		this.setBlock(world, position.add(8, 16, 39), this.casingState);
		this.setBlock(world, position.add(8, 17, 14), this.casingState);
		this.setBlock(world, position.add(8, 17, 40), this.casingState);
		this.setBlock(world, position.add(8, 18, 13), this.casingState);
		this.setBlock(world, position.add(8, 18, 41), this.casingState);
		this.setBlock(world, position.add(8, 19, 13), this.casingState);
		this.setBlock(world, position.add(8, 19, 41), this.casingState);
		this.setBlock(world, position.add(8, 20, 12), this.casingState);
		this.setBlock(world, position.add(8, 20, 42), this.casingState);
		this.setBlock(world, position.add(8, 21, 11), this.casingState);
		this.setBlock(world, position.add(8, 21, 43), this.casingState);
		this.setBlock(world, position.add(8, 22, 11), this.casingState);
		this.setBlock(world, position.add(8, 22, 43), this.casingState);
		this.setBlock(world, position.add(8, 23, 11), this.casingState);
		this.setBlock(world, position.add(8, 23, 43), this.casingState);
		this.setBlock(world, position.add(8, 24, 10), this.casingState);
		this.setBlock(world, position.add(8, 24, 44), this.casingState);
		this.setBlock(world, position.add(8, 25, 10), this.casingState);
		this.setBlock(world, position.add(8, 25, 44), this.casingState);
		this.setBlock(world, position.add(8, 26, 10), this.casingState);
		this.setBlock(world, position.add(8, 26, 44), this.casingState);
		this.setBlock(world, position.add(8, 27, 10), this.casingState);
		this.setBlock(world, position.add(8, 27, 44), this.casingState);
		this.setBlock(world, position.add(8, 28, 10), this.casingState);
		this.setBlock(world, position.add(8, 28, 44), this.casingState);
		this.setBlock(world, position.add(8, 29, 10), this.casingState);
		this.setBlock(world, position.add(8, 29, 44), this.casingState);
		this.setBlock(world, position.add(8, 30, 10), this.casingState);
		this.setBlock(world, position.add(8, 30, 44), this.casingState);
		this.setBlock(world, position.add(8, 31, 10), this.glassState);
		this.setBlock(world, position.add(8, 31, 11), this.glassState);
		this.setBlock(world, position.add(8, 31, 12), this.glassState);
		this.setBlock(world, position.add(8, 31, 13), this.glassState);
		this.setBlock(world, position.add(8, 31, 14), this.glassState);
		this.setBlock(world, position.add(8, 31, 15), this.glassState);
		this.setBlock(world, position.add(8, 31, 16), this.glassState);
		this.setBlock(world, position.add(8, 31, 17), this.glassState);
		this.setBlock(world, position.add(8, 31, 18), this.glassState);
		this.setBlock(world, position.add(8, 31, 19), this.glassState);
		this.setBlock(world, position.add(8, 31, 20), this.glassState);
		this.setBlock(world, position.add(8, 31, 21), this.glassState);
		this.setBlock(world, position.add(8, 31, 22), this.glassState);
		this.setBlock(world, position.add(8, 31, 23), this.glassState);
		this.setBlock(world, position.add(8, 31, 24), this.glassState);
		this.setBlock(world, position.add(8, 31, 25), this.glassState);
		this.setBlock(world, position.add(8, 31, 26), this.glassState);
		this.setBlock(world, position.add(8, 31, 27), this.glassState);
		this.setBlock(world, position.add(8, 31, 28), this.glassState);
		this.setBlock(world, position.add(8, 31, 29), this.glassState);
		this.setBlock(world, position.add(8, 31, 30), this.glassState);
		this.setBlock(world, position.add(8, 31, 31), this.glassState);
		this.setBlock(world, position.add(8, 31, 32), this.glassState);
		this.setBlock(world, position.add(8, 31, 33), this.glassState);
		this.setBlock(world, position.add(8, 31, 34), this.glassState);
		this.setBlock(world, position.add(8, 31, 35), this.glassState);
		this.setBlock(world, position.add(8, 31, 36), this.glassState);
		this.setBlock(world, position.add(8, 31, 37), this.glassState);
		this.setBlock(world, position.add(8, 31, 38), this.glassState);
		this.setBlock(world, position.add(8, 31, 39), this.glassState);
		this.setBlock(world, position.add(8, 31, 40), this.glassState);
		this.setBlock(world, position.add(8, 31, 41), this.glassState);
		this.setBlock(world, position.add(8, 31, 42), this.glassState);
		this.setBlock(world, position.add(8, 31, 43), this.glassState);
		this.setBlock(world, position.add(8, 31, 44), this.glassState);
		this.setBlock(world, position.add(8, 32, 10), this.casingState);
		this.setBlock(world, position.add(8, 32, 44), this.casingState);
		this.setBlock(world, position.add(9, 11, 24), this.casingState);
		this.setBlock(world, position.add(9, 11, 25), this.casingState);
		this.setBlock(world, position.add(9, 11, 26), this.casingState);
		this.setBlock(world, position.add(9, 11, 27), this.casingState);
		this.setBlock(world, position.add(9, 11, 28), this.casingState);
		this.setBlock(world, position.add(9, 11, 29), this.casingState);
		this.setBlock(world, position.add(9, 11, 30), this.casingState);
		this.setBlock(world, position.add(9, 12, 20), this.casingState);
		this.setBlock(world, position.add(9, 12, 21), this.casingState);
		this.setBlock(world, position.add(9, 12, 22), this.casingState);
		this.setBlock(world, position.add(9, 12, 23), this.casingState);
		this.setBlock(world, position.add(9, 12, 31), this.casingState);
		this.setBlock(world, position.add(9, 12, 32), this.casingState);
		this.setBlock(world, position.add(9, 12, 33), this.casingState);
		this.setBlock(world, position.add(9, 12, 34), this.casingState);
		this.setBlock(world, position.add(9, 13, 18), this.casingState);
		this.setBlock(world, position.add(9, 13, 19), this.casingState);
		this.setBlock(world, position.add(9, 13, 35), this.casingState);
		this.setBlock(world, position.add(9, 13, 36), this.casingState);
		this.setBlock(world, position.add(9, 14, 17), this.casingState);
		this.setBlock(world, position.add(9, 14, 37), this.casingState);
		this.setBlock(world, position.add(9, 15, 16), this.casingState);
		this.setBlock(world, position.add(9, 15, 38), this.casingState);
		this.setBlock(world, position.add(9, 16, 14), this.casingState);
		this.setBlock(world, position.add(9, 16, 15), this.casingState);
		this.setBlock(world, position.add(9, 16, 39), this.casingState);
		this.setBlock(world, position.add(9, 16, 40), this.casingState);
		this.setBlock(world, position.add(9, 17, 14), this.casingState);
		this.setBlock(world, position.add(9, 17, 40), this.casingState);
		this.setBlock(world, position.add(9, 18, 13), this.casingState);
		this.setBlock(world, position.add(9, 18, 41), this.casingState);
		this.setBlock(world, position.add(9, 19, 12), this.casingState);
		this.setBlock(world, position.add(9, 19, 42), this.casingState);
		this.setBlock(world, position.add(9, 20, 11), this.casingState);
		this.setBlock(world, position.add(9, 20, 43), this.casingState);
		this.setBlock(world, position.add(9, 21, 11), this.casingState);
		this.setBlock(world, position.add(9, 21, 43), this.casingState);
		this.setBlock(world, position.add(9, 22, 10), this.casingState);
		this.setBlock(world, position.add(9, 22, 44), this.casingState);
		this.setBlock(world, position.add(9, 23, 10), this.casingState);
		this.setBlock(world, position.add(9, 23, 44), this.casingState);
		this.setBlock(world, position.add(9, 24, 10), this.casingState);
		this.setBlock(world, position.add(9, 24, 44), this.casingState);
		this.setBlock(world, position.add(9, 25, 10), this.casingState);
		this.setBlock(world, position.add(9, 25, 44), this.casingState);
		this.setBlock(world, position.add(9, 26, 9), this.casingState);
		this.setBlock(world, position.add(9, 26, 45), this.casingState);
		this.setBlock(world, position.add(9, 27, 9), this.casingState);
		this.setBlock(world, position.add(9, 27, 45), this.casingState);
		this.setBlock(world, position.add(9, 28, 9), this.casingState);
		this.setBlock(world, position.add(9, 28, 45), this.casingState);
		this.setBlock(world, position.add(9, 29, 9), this.casingState);
		this.setBlock(world, position.add(9, 29, 45), this.casingState);
		this.setBlock(world, position.add(9, 30, 9), this.casingState);
		this.setBlock(world, position.add(9, 30, 45), this.casingState);
		this.setBlock(world, position.add(9, 31, 9), this.glassState);
		this.setBlock(world, position.add(9, 31, 10), this.glassState);
		this.setBlock(world, position.add(9, 31, 11), this.glassState);
		this.setBlock(world, position.add(9, 31, 12), this.glassState);
		this.setBlock(world, position.add(9, 31, 13), this.glassState);
		this.setBlock(world, position.add(9, 31, 14), this.glassState);
		this.setBlock(world, position.add(9, 31, 15), this.glassState);
		this.setBlock(world, position.add(9, 31, 16), this.glassState);
		this.setBlock(world, position.add(9, 31, 17), this.glassState);
		this.setBlock(world, position.add(9, 31, 18), this.glassState);
		this.setBlock(world, position.add(9, 31, 19), this.glassState);
		this.setBlock(world, position.add(9, 31, 20), this.glassState);
		this.setBlock(world, position.add(9, 31, 21), this.glassState);
		this.setBlock(world, position.add(9, 31, 22), this.glassState);
		this.setBlock(world, position.add(9, 31, 23), this.glassState);
		this.setBlock(world, position.add(9, 31, 24), this.glassState);
		this.setBlock(world, position.add(9, 31, 25), this.glassState);
		this.setBlock(world, position.add(9, 31, 26), this.glassState);
		this.setBlock(world, position.add(9, 31, 27), this.glassState);
		this.setBlock(world, position.add(9, 31, 28), this.glassState);
		this.setBlock(world, position.add(9, 31, 29), this.glassState);
		this.setBlock(world, position.add(9, 31, 30), this.glassState);
		this.setBlock(world, position.add(9, 31, 31), this.glassState);
		this.setBlock(world, position.add(9, 31, 32), this.glassState);
		this.setBlock(world, position.add(9, 31, 33), this.glassState);
		this.setBlock(world, position.add(9, 31, 34), this.glassState);
		this.setBlock(world, position.add(9, 31, 35), this.glassState);
		this.setBlock(world, position.add(9, 31, 36), this.glassState);
		this.setBlock(world, position.add(9, 31, 37), this.glassState);
		this.setBlock(world, position.add(9, 31, 38), this.glassState);
		this.setBlock(world, position.add(9, 31, 39), this.glassState);
		this.setBlock(world, position.add(9, 31, 40), this.glassState);
		this.setBlock(world, position.add(9, 31, 41), this.glassState);
		this.setBlock(world, position.add(9, 31, 42), this.glassState);
		this.setBlock(world, position.add(9, 31, 43), this.glassState);
		this.setBlock(world, position.add(9, 31, 44), this.glassState);
		this.setBlock(world, position.add(9, 31, 45), this.glassState);
		this.setBlock(world, position.add(9, 32, 9), this.casingState);
		this.setBlock(world, position.add(9, 32, 45), this.casingState);
		this.setBlock(world, position.add(10, 11, 22), this.casingState);
		this.setBlock(world, position.add(10, 11, 23), this.casingState);
		this.setBlock(world, position.add(10, 11, 24), this.casingState);
		this.setBlock(world, position.add(10, 11, 25), this.casingState);
		this.setBlock(world, position.add(10, 11, 26), this.casingState);
		this.setBlock(world, position.add(10, 11, 27), this.casingState);
		this.setBlock(world, position.add(10, 11, 28), this.casingState);
		this.setBlock(world, position.add(10, 11, 29), this.casingState);
		this.setBlock(world, position.add(10, 11, 30), this.casingState);
		this.setBlock(world, position.add(10, 11, 31), this.casingState);
		this.setBlock(world, position.add(10, 11, 32), this.casingState);
		this.setBlock(world, position.add(10, 12, 19), this.casingState);
		this.setBlock(world, position.add(10, 12, 20), this.casingState);
		this.setBlock(world, position.add(10, 12, 21), this.casingState);
		this.setBlock(world, position.add(10, 12, 27), this.cobbleState);//
		// CHEST
		ZGLootTables.generateChest(world, position.add(10, 13, 27), rand, ZGLootTables.CHEST_UFO);
		//
		this.setBlock(world, position.add(10, 12, 33), this.casingState);//
		this.setBlock(world, position.add(10, 12, 34), this.casingState);
		this.setBlock(world, position.add(10, 12, 35), this.casingState);
		this.setBlock(world, position.add(10, 13, 17), this.casingState);
		this.setBlock(world, position.add(10, 13, 18), this.casingState);
		this.setBlock(world, position.add(10, 13, 36), this.casingState);
		this.setBlock(world, position.add(10, 13, 37), this.casingState);
		this.setBlock(world, position.add(10, 14, 16), this.casingState);
		this.setBlock(world, position.add(10, 14, 38), this.casingState);
		this.setBlock(world, position.add(10, 15, 15), this.casingState);
		this.setBlock(world, position.add(10, 15, 39), this.casingState);
		this.setBlock(world, position.add(10, 16, 14), this.casingState);
		this.setBlock(world, position.add(10, 16, 40), this.casingState);
		this.setBlock(world, position.add(10, 17, 13), this.casingState);
		this.setBlock(world, position.add(10, 17, 41), this.casingState);
		this.setBlock(world, position.add(10, 18, 12), this.casingState);
		this.setBlock(world, position.add(10, 18, 42), this.casingState);
		this.setBlock(world, position.add(10, 19, 11), this.casingState);
		this.setBlock(world, position.add(10, 19, 43), this.casingState);
		this.setBlock(world, position.add(10, 20, 11), this.casingState);
		this.setBlock(world, position.add(10, 20, 43), this.casingState);
		this.setBlock(world, position.add(10, 21, 10), this.casingState);
		this.setBlock(world, position.add(10, 21, 44), this.casingState);
		this.setBlock(world, position.add(10, 22, 10), this.casingState);
		this.setBlock(world, position.add(10, 22, 44), this.casingState);
		this.setBlock(world, position.add(10, 23, 10), this.casingState);
		this.setBlock(world, position.add(10, 23, 44), this.casingState);
		this.setBlock(world, position.add(10, 24, 9), this.casingState);
		this.setBlock(world, position.add(10, 24, 45), this.casingState);
		this.setBlock(world, position.add(10, 25, 9), this.casingState);
		this.setBlock(world, position.add(10, 25, 45), this.casingState);
		this.setBlock(world, position.add(10, 26, 9), this.casingState);
		this.setBlock(world, position.add(10, 26, 45), this.casingState);
		this.setBlock(world, position.add(10, 27, 9), this.casingState);
		this.setBlock(world, position.add(10, 27, 45), this.casingState);
		this.setBlock(world, position.add(10, 28, 9), this.casingState);
		this.setBlock(world, position.add(10, 28, 45), this.casingState);
		this.setBlock(world, position.add(10, 29, 9), this.casingState);
		this.setBlock(world, position.add(10, 29, 45), this.casingState);
		this.setBlock(world, position.add(10, 30, 9), this.casingState);
		this.setBlock(world, position.add(10, 30, 45), this.casingState);
		this.setBlock(world, position.add(10, 31, 9), this.glassState);
		this.setBlock(world, position.add(10, 31, 10), this.glassState);
		this.setBlock(world, position.add(10, 31, 11), this.glassState);
		this.setBlock(world, position.add(10, 31, 12), this.glassState);
		this.setBlock(world, position.add(10, 31, 13), this.glassState);
		this.setBlock(world, position.add(10, 31, 14), this.glassState);
		this.setBlock(world, position.add(10, 31, 15), this.glassState);
		this.setBlock(world, position.add(10, 31, 16), this.glassState);
		this.setBlock(world, position.add(10, 31, 17), this.glassState);
		this.setBlock(world, position.add(10, 31, 18), this.glassState);
		this.setBlock(world, position.add(10, 31, 19), this.glassState);
		this.setBlock(world, position.add(10, 31, 20), this.glassState);
		this.setBlock(world, position.add(10, 31, 21), this.glassState);
		this.setBlock(world, position.add(10, 31, 22), this.glassState);
		this.setBlock(world, position.add(10, 31, 23), this.glassState);
		this.setBlock(world, position.add(10, 31, 24), this.glassState);
		this.setBlock(world, position.add(10, 31, 25), this.glassState);
		this.setBlock(world, position.add(10, 31, 26), this.glassState);
		this.setBlock(world, position.add(10, 31, 27), this.glassState);
		this.setBlock(world, position.add(10, 31, 28), this.glassState);
		this.setBlock(world, position.add(10, 31, 29), this.glassState);
		this.setBlock(world, position.add(10, 31, 30), this.glassState);
		this.setBlock(world, position.add(10, 31, 31), this.glassState);
		this.setBlock(world, position.add(10, 31, 32), this.glassState);
		this.setBlock(world, position.add(10, 31, 33), this.glassState);
		this.setBlock(world, position.add(10, 31, 34), this.glassState);
		this.setBlock(world, position.add(10, 31, 35), this.glassState);
		this.setBlock(world, position.add(10, 31, 36), this.glassState);
		this.setBlock(world, position.add(10, 31, 37), this.glassState);
		this.setBlock(world, position.add(10, 31, 38), this.glassState);
		this.setBlock(world, position.add(10, 31, 39), this.glassState);
		this.setBlock(world, position.add(10, 31, 40), this.glassState);
		this.setBlock(world, position.add(10, 31, 41), this.glassState);
		this.setBlock(world, position.add(10, 31, 42), this.glassState);
		this.setBlock(world, position.add(10, 31, 43), this.glassState);
		this.setBlock(world, position.add(10, 31, 44), this.glassState);
		this.setBlock(world, position.add(10, 31, 45), this.glassState);
		this.setBlock(world, position.add(10, 32, 9), this.casingState);
		this.setBlock(world, position.add(10, 32, 45), this.casingState);
		this.setBlock(world, position.add(11, 10, 24), this.casingState);
		this.setBlock(world, position.add(11, 10, 25), this.casingState);
		this.setBlock(world, position.add(11, 10, 26), this.casingState);
		this.setBlock(world, position.add(11, 10, 27), this.casingState);
		this.setBlock(world, position.add(11, 10, 28), this.casingState);
		this.setBlock(world, position.add(11, 10, 29), this.casingState);
		this.setBlock(world, position.add(11, 10, 30), this.casingState);
		this.setBlock(world, position.add(11, 11, 21), this.casingState);
		this.setBlock(world, position.add(11, 11, 22), this.casingState);
		this.setBlock(world, position.add(11, 11, 23), this.casingState);
		this.setBlock(world, position.add(11, 11, 31), this.casingState);
		this.setBlock(world, position.add(11, 11, 32), this.casingState);
		this.setBlock(world, position.add(11, 11, 33), this.casingState);
		this.setBlock(world, position.add(11, 12, 18), this.casingState);
		this.setBlock(world, position.add(11, 12, 19), this.casingState);
		this.setBlock(world, position.add(11, 12, 20), this.casingState);
		this.setBlock(world, position.add(11, 12, 34), this.casingState);
		this.setBlock(world, position.add(11, 12, 35), this.casingState);
		this.setBlock(world, position.add(11, 12, 36), this.casingState);
		this.setBlock(world, position.add(11, 13, 17), this.casingState);
		this.setBlock(world, position.add(11, 13, 37), this.casingState);
		this.setBlock(world, position.add(11, 14, 15), this.casingState);
		this.setBlock(world, position.add(11, 14, 16), this.casingState);
		this.setBlock(world, position.add(11, 14, 38), this.casingState);
		this.setBlock(world, position.add(11, 14, 39), this.casingState);
		this.setBlock(world, position.add(11, 15, 14), this.casingState);
		this.setBlock(world, position.add(11, 15, 40), this.casingState);
		this.setBlock(world, position.add(11, 16, 13), this.casingState);
		this.setBlock(world, position.add(11, 16, 41), this.casingState);
		this.setBlock(world, position.add(11, 17, 12), this.casingState);
		this.setBlock(world, position.add(11, 17, 42), this.casingState);
		this.setBlock(world, position.add(11, 18, 12), this.casingState);
		this.setBlock(world, position.add(11, 18, 42), this.casingState);
		this.setBlock(world, position.add(11, 19, 11), this.casingState);
		this.setBlock(world, position.add(11, 19, 43), this.casingState);
		this.setBlock(world, position.add(11, 20, 10), this.casingState);
		this.setBlock(world, position.add(11, 20, 44), this.casingState);
		this.setBlock(world, position.add(11, 21, 10), this.casingState);
		this.setBlock(world, position.add(11, 21, 44), this.casingState);
		this.setBlock(world, position.add(11, 22, 10), this.casingState);
		this.setBlock(world, position.add(11, 22, 44), this.casingState);
		this.setBlock(world, position.add(11, 23, 9), this.casingState);
		this.setBlock(world, position.add(11, 23, 45), this.casingState);
		this.setBlock(world, position.add(11, 24, 9), this.casingState);
		this.setBlock(world, position.add(11, 24, 45), this.casingState);
		this.setBlock(world, position.add(11, 25, 9), this.casingState);
		this.setBlock(world, position.add(11, 25, 45), this.casingState);
		this.setBlock(world, position.add(11, 26, 8), this.casingState);
		this.setBlock(world, position.add(11, 26, 46), this.casingState);
		this.setBlock(world, position.add(11, 27, 8), this.casingState);
		this.setBlock(world, position.add(11, 27, 46), this.casingState);
		this.setBlock(world, position.add(11, 28, 8), this.casingState);
		this.setBlock(world, position.add(11, 28, 46), this.casingState);
		this.setBlock(world, position.add(11, 29, 8), this.casingState);
		this.setBlock(world, position.add(11, 29, 46), this.casingState);
		this.setBlock(world, position.add(11, 30, 8), this.casingState);
		this.setBlock(world, position.add(11, 30, 46), this.casingState);
		this.setBlock(world, position.add(11, 31, 8), this.glassState);
		this.setBlock(world, position.add(11, 31, 9), this.glassState);
		this.setBlock(world, position.add(11, 31, 10), this.glassState);
		this.setBlock(world, position.add(11, 31, 11), this.glassState);
		this.setBlock(world, position.add(11, 31, 12), this.glassState);
		this.setBlock(world, position.add(11, 31, 13), this.glassState);
		this.setBlock(world, position.add(11, 31, 14), this.glassState);
		this.setBlock(world, position.add(11, 31, 15), this.glassState);
		this.setBlock(world, position.add(11, 31, 16), this.glassState);
		this.setBlock(world, position.add(11, 31, 17), this.glassState);
		this.setBlock(world, position.add(11, 31, 18), this.glassState);
		this.setBlock(world, position.add(11, 31, 19), this.glassState);
		this.setBlock(world, position.add(11, 31, 20), this.glassState);
		this.setBlock(world, position.add(11, 31, 21), this.glassState);
		this.setBlock(world, position.add(11, 31, 22), this.glassState);
		this.setBlock(world, position.add(11, 31, 23), this.glassState);
		this.setBlock(world, position.add(11, 31, 24), this.glassState);
		this.setBlock(world, position.add(11, 31, 25), this.glassState);
		this.setBlock(world, position.add(11, 31, 26), this.glassState);
		this.setBlock(world, position.add(11, 31, 27), this.glassState);
		this.setBlock(world, position.add(11, 31, 28), this.glassState);
		this.setBlock(world, position.add(11, 31, 29), this.glassState);
		this.setBlock(world, position.add(11, 31, 30), this.glassState);
		this.setBlock(world, position.add(11, 31, 31), this.glassState);
		this.setBlock(world, position.add(11, 31, 32), this.glassState);
		this.setBlock(world, position.add(11, 31, 33), this.glassState);
		this.setBlock(world, position.add(11, 31, 34), this.glassState);
		this.setBlock(world, position.add(11, 31, 35), this.glassState);
		this.setBlock(world, position.add(11, 31, 36), this.glassState);
		this.setBlock(world, position.add(11, 31, 37), this.glassState);
		this.setBlock(world, position.add(11, 31, 38), this.glassState);
		this.setBlock(world, position.add(11, 31, 39), this.glassState);
		this.setBlock(world, position.add(11, 31, 40), this.glassState);
		this.setBlock(world, position.add(11, 31, 41), this.glassState);
		this.setBlock(world, position.add(11, 31, 42), this.glassState);
		this.setBlock(world, position.add(11, 31, 43), this.glassState);
		this.setBlock(world, position.add(11, 31, 44), this.glassState);
		this.setBlock(world, position.add(11, 31, 45), this.glassState);
		this.setBlock(world, position.add(11, 31, 46), this.glassState);
		this.setBlock(world, position.add(11, 32, 8), this.casingState);
		this.setBlock(world, position.add(11, 32, 46), this.casingState);
		this.setBlock(world, position.add(12, 10, 23), this.casingState);
		this.setBlock(world, position.add(12, 10, 24), this.casingState);
		this.setBlock(world, position.add(12, 10, 25), this.casingState);
		this.setBlock(world, position.add(12, 10, 26), this.casingState);
		this.setBlock(world, position.add(12, 10, 27), this.casingState);
		this.setBlock(world, position.add(12, 10, 28), this.casingState);
		this.setBlock(world, position.add(12, 10, 29), this.casingState);
		this.setBlock(world, position.add(12, 10, 30), this.casingState);
		this.setBlock(world, position.add(12, 10, 31), this.casingState);
		this.setBlock(world, position.add(12, 11, 20), this.casingState);
		this.setBlock(world, position.add(12, 11, 21), this.casingState);
		this.setBlock(world, position.add(12, 11, 22), this.casingState);
		this.setBlock(world, position.add(12, 11, 32), this.casingState);
		this.setBlock(world, position.add(12, 11, 33), this.casingState);
		this.setBlock(world, position.add(12, 11, 34), this.casingState);
		this.setBlock(world, position.add(12, 12, 18), this.casingState);
		this.setBlock(world, position.add(12, 12, 19), this.casingState);
		this.setBlock(world, position.add(12, 12, 35), this.casingState);
		this.setBlock(world, position.add(12, 12, 36), this.casingState);
		this.setBlock(world, position.add(12, 13, 16), this.casingState);
		this.setBlock(world, position.add(12, 13, 17), this.casingState);
		this.setBlock(world, position.add(12, 13, 37), this.casingState);
		this.setBlock(world, position.add(12, 13, 38), this.casingState);
		this.setBlock(world, position.add(12, 14, 15), this.casingState);
		this.setBlock(world, position.add(12, 14, 39), this.casingState);
		this.setBlock(world, position.add(12, 15, 14), this.casingState);
		this.setBlock(world, position.add(12, 15, 40), this.casingState);
		this.setBlock(world, position.add(12, 16, 13), this.casingState);
		this.setBlock(world, position.add(12, 16, 41), this.casingState);
		this.setBlock(world, position.add(12, 17, 12), this.casingState);
		this.setBlock(world, position.add(12, 17, 42), this.casingState);
		this.setBlock(world, position.add(12, 18, 11), this.casingState);
		this.setBlock(world, position.add(12, 18, 43), this.casingState);
		this.setBlock(world, position.add(12, 19, 11), this.casingState);
		this.setBlock(world, position.add(12, 19, 43), this.casingState);
		this.setBlock(world, position.add(12, 20, 10), this.casingState);
		this.setBlock(world, position.add(12, 20, 44), this.casingState);
		this.setBlock(world, position.add(12, 21, 10), this.casingState);
		this.setBlock(world, position.add(12, 21, 44), this.casingState);
		this.setBlock(world, position.add(12, 22, 9), this.casingState);
		this.setBlock(world, position.add(12, 22, 45), this.casingState);
		this.setBlock(world, position.add(12, 23, 9), this.casingState);
		this.setBlock(world, position.add(12, 23, 45), this.casingState);
		this.setBlock(world, position.add(12, 24, 9), this.casingState);
		this.setBlock(world, position.add(12, 24, 45), this.casingState);
		this.setBlock(world, position.add(12, 25, 8), this.casingState);
		this.setBlock(world, position.add(12, 25, 46), this.casingState);
		this.setBlock(world, position.add(12, 26, 8), this.casingState);
		this.setBlock(world, position.add(12, 26, 46), this.casingState);
		this.setBlock(world, position.add(12, 27, 8), this.casingState);
		this.setBlock(world, position.add(12, 27, 46), this.casingState);
		this.setBlock(world, position.add(12, 28, 8), this.casingState);
		this.setBlock(world, position.add(12, 28, 46), this.casingState);
		this.setBlock(world, position.add(12, 29, 8), this.casingState);
		this.setBlock(world, position.add(12, 29, 46), this.casingState);
		this.setBlock(world, position.add(12, 30, 8), this.casingState);
		this.setBlock(world, position.add(12, 30, 46), this.casingState);
		this.setBlock(world, position.add(12, 31, 8), this.glassState);
		this.setBlock(world, position.add(12, 31, 9), this.glassState);
		this.setBlock(world, position.add(12, 31, 10), this.glassState);
		this.setBlock(world, position.add(12, 31, 11), this.glassState);
		this.setBlock(world, position.add(12, 31, 12), this.glassState);
		this.setBlock(world, position.add(12, 31, 13), this.glassState);
		this.setBlock(world, position.add(12, 31, 14), this.glassState);
		this.setBlock(world, position.add(12, 31, 15), this.glassState);
		this.setBlock(world, position.add(12, 31, 16), this.glassState);
		this.setBlock(world, position.add(12, 31, 17), this.glassState);
		this.setBlock(world, position.add(12, 31, 18), this.glassState);
		this.setBlock(world, position.add(12, 31, 19), this.glassState);
		this.setBlock(world, position.add(12, 31, 20), this.glassState);
		this.setBlock(world, position.add(12, 31, 21), this.glassState);
		this.setBlock(world, position.add(12, 31, 22), this.glassState);
		this.setBlock(world, position.add(12, 31, 23), this.glassState);
		this.setBlock(world, position.add(12, 31, 24), this.glassState);
		this.setBlock(world, position.add(12, 31, 25), this.glassState);
		this.setBlock(world, position.add(12, 31, 26), this.glassState);
		this.setBlock(world, position.add(12, 31, 27), this.glassState);
		this.setBlock(world, position.add(12, 31, 28), this.glassState);
		this.setBlock(world, position.add(12, 31, 29), this.glassState);
		this.setBlock(world, position.add(12, 31, 30), this.glassState);
		this.setBlock(world, position.add(12, 31, 31), this.glassState);
		this.setBlock(world, position.add(12, 31, 32), this.glassState);
		this.setBlock(world, position.add(12, 31, 33), this.glassState);
		this.setBlock(world, position.add(12, 31, 34), this.glassState);
		this.setBlock(world, position.add(12, 31, 35), this.glassState);
		this.setBlock(world, position.add(12, 31, 36), this.glassState);
		this.setBlock(world, position.add(12, 31, 37), this.glassState);
		this.setBlock(world, position.add(12, 31, 38), this.glassState);
		this.setBlock(world, position.add(12, 31, 39), this.glassState);
		this.setBlock(world, position.add(12, 31, 40), this.glassState);
		this.setBlock(world, position.add(12, 31, 41), this.glassState);
		this.setBlock(world, position.add(12, 31, 42), this.glassState);
		this.setBlock(world, position.add(12, 31, 43), this.glassState);
		this.setBlock(world, position.add(12, 31, 44), this.glassState);
		this.setBlock(world, position.add(12, 31, 45), this.glassState);
		this.setBlock(world, position.add(12, 31, 46), this.glassState);
		this.setBlock(world, position.add(12, 32, 8), this.casingState);
		this.setBlock(world, position.add(12, 32, 46), this.casingState);
		this.setBlock(world, position.add(13, 10, 22), this.casingState);
		this.setBlock(world, position.add(13, 10, 23), this.casingState);
		this.setBlock(world, position.add(13, 10, 24), this.casingState);
		this.setBlock(world, position.add(13, 10, 25), this.casingState);
		this.setBlock(world, position.add(13, 10, 26), this.casingState);
		this.setBlock(world, position.add(13, 10, 27), this.casingState);
		this.setBlock(world, position.add(13, 10, 28), this.casingState);
		this.setBlock(world, position.add(13, 10, 29), this.casingState);
		this.setBlock(world, position.add(13, 10, 30), this.casingState);
		this.setBlock(world, position.add(13, 10, 31), this.casingState);
		this.setBlock(world, position.add(13, 10, 32), this.casingState);
		this.setBlock(world, position.add(13, 11, 19), this.casingState);
		this.setBlock(world, position.add(13, 11, 20), this.casingState);
		this.setBlock(world, position.add(13, 11, 21), this.casingState);
		this.setBlock(world, position.add(13, 11, 33), this.casingState);
		this.setBlock(world, position.add(13, 11, 34), this.casingState);
		this.setBlock(world, position.add(13, 11, 35), this.casingState);
		this.setBlock(world, position.add(13, 12, 17), this.casingState);
		this.setBlock(world, position.add(13, 12, 18), this.casingState);
		this.setBlock(world, position.add(13, 12, 36), this.casingState);
		this.setBlock(world, position.add(13, 12, 37), this.casingState);
		this.setBlock(world, position.add(13, 13, 16), this.casingState);
		this.setBlock(world, position.add(13, 13, 38), this.casingState);
		this.setBlock(world, position.add(13, 14, 14), this.casingState);
		this.setBlock(world, position.add(13, 14, 15), this.casingState);
		this.setBlock(world, position.add(13, 14, 39), this.casingState);
		this.setBlock(world, position.add(13, 14, 40), this.casingState);
		this.setBlock(world, position.add(13, 15, 13), this.casingState);
		this.setBlock(world, position.add(13, 15, 41), this.casingState);
		this.setBlock(world, position.add(13, 16, 12), this.casingState);
		this.setBlock(world, position.add(13, 16, 42), this.casingState);
		this.setBlock(world, position.add(13, 17, 12), this.casingState);
		this.setBlock(world, position.add(13, 17, 42), this.casingState);
		this.setBlock(world, position.add(13, 18, 11), this.casingState);
		this.setBlock(world, position.add(13, 18, 43), this.casingState);
		this.setBlock(world, position.add(13, 19, 10), this.casingState);
		this.setBlock(world, position.add(13, 19, 44), this.casingState);
		this.setBlock(world, position.add(13, 20, 10), this.casingState);
		this.setBlock(world, position.add(13, 20, 44), this.casingState);
		this.setBlock(world, position.add(13, 21, 9), this.casingState);
		this.setBlock(world, position.add(13, 21, 45), this.casingState);
		this.setBlock(world, position.add(13, 22, 9), this.casingState);
		this.setBlock(world, position.add(13, 22, 45), this.casingState);
		this.setBlock(world, position.add(13, 23, 9), this.casingState);
		this.setBlock(world, position.add(13, 23, 45), this.casingState);
		this.setBlock(world, position.add(13, 24, 8), this.casingState);
		this.setBlock(world, position.add(13, 24, 46), this.casingState);
		this.setBlock(world, position.add(13, 25, 8), this.casingState);
		this.setBlock(world, position.add(13, 25, 46), this.casingState);
		this.setBlock(world, position.add(13, 26, 8), this.casingState);
		this.setBlock(world, position.add(13, 26, 46), this.casingState);
		this.setBlock(world, position.add(13, 27, 8), this.casingState);
		this.setBlock(world, position.add(13, 27, 46), this.casingState);
		this.setBlock(world, position.add(13, 28, 8), this.casingState);
		this.setBlock(world, position.add(13, 28, 46), this.casingState);
		this.setBlock(world, position.add(13, 29, 8), this.casingState);
		this.setBlock(world, position.add(13, 29, 46), this.casingState);
		this.setBlock(world, position.add(13, 30, 8), this.casingState);
		this.setBlock(world, position.add(13, 30, 46), this.casingState);
		this.setBlock(world, position.add(13, 31, 8), this.glassState);
		this.setBlock(world, position.add(13, 31, 9), this.glassState);
		this.setBlock(world, position.add(13, 31, 10), this.glassState);
		this.setBlock(world, position.add(13, 31, 11), this.glassState);
		this.setBlock(world, position.add(13, 31, 12), this.glassState);
		this.setBlock(world, position.add(13, 31, 13), this.glassState);
		this.setBlock(world, position.add(13, 31, 14), this.glassState);
		this.setBlock(world, position.add(13, 31, 15), this.glassState);
		this.setBlock(world, position.add(13, 31, 16), this.glassState);
		this.setBlock(world, position.add(13, 31, 17), this.glassState);
		this.setBlock(world, position.add(13, 31, 18), this.glassState);
		this.setBlock(world, position.add(13, 31, 19), this.glassState);
		this.setBlock(world, position.add(13, 31, 20), this.glassState);
		this.setBlock(world, position.add(13, 31, 21), this.glassState);
		this.setBlock(world, position.add(13, 31, 22), this.glassState);
		this.setBlock(world, position.add(13, 31, 23), this.glassState);
		this.setBlock(world, position.add(13, 31, 24), this.glassState);
		this.setBlock(world, position.add(13, 31, 25), this.glassState);
		this.setBlock(world, position.add(13, 31, 26), this.glassState);
		this.setBlock(world, position.add(13, 31, 27), this.glassState);
		this.setBlock(world, position.add(13, 31, 28), this.glassState);
		this.setBlock(world, position.add(13, 31, 29), this.glassState);
		this.setBlock(world, position.add(13, 31, 30), this.glassState);
		this.setBlock(world, position.add(13, 31, 31), this.glassState);
		this.setBlock(world, position.add(13, 31, 32), this.glassState);
		this.setBlock(world, position.add(13, 31, 33), this.glassState);
		this.setBlock(world, position.add(13, 31, 34), this.glassState);
		this.setBlock(world, position.add(13, 31, 35), this.glassState);
		this.setBlock(world, position.add(13, 31, 36), this.glassState);
		this.setBlock(world, position.add(13, 31, 37), this.glassState);
		this.setBlock(world, position.add(13, 31, 38), this.glassState);
		this.setBlock(world, position.add(13, 31, 39), this.glassState);
		this.setBlock(world, position.add(13, 31, 40), this.glassState);
		this.setBlock(world, position.add(13, 31, 41), this.glassState);
		this.setBlock(world, position.add(13, 31, 42), this.glassState);
		this.setBlock(world, position.add(13, 31, 43), this.glassState);
		this.setBlock(world, position.add(13, 31, 44), this.glassState);
		this.setBlock(world, position.add(13, 31, 45), this.glassState);
		this.setBlock(world, position.add(13, 31, 46), this.glassState);
		this.setBlock(world, position.add(13, 32, 8), this.casingState);
		this.setBlock(world, position.add(13, 32, 46), this.casingState);
		this.setBlock(world, position.add(14, 9, 25), this.casingState);
		this.setBlock(world, position.add(14, 9, 26), this.casingState);
		this.setBlock(world, position.add(14, 9, 27), this.casingState);
		this.setBlock(world, position.add(14, 9, 28), this.casingState);
		this.setBlock(world, position.add(14, 9, 29), this.casingState);
		this.setBlock(world, position.add(14, 10, 21), this.casingState);
		this.setBlock(world, position.add(14, 10, 22), this.casingState);
		this.setBlock(world, position.add(14, 10, 23), this.casingState);
		this.setBlock(world, position.add(14, 10, 24), this.casingState);
		this.setBlock(world, position.add(14, 10, 27), this.cobbleState);//
		// CHEST
		ZGLootTables.generateChest(world, position.add(14, 11, 27), rand, ZGLootTables.CHEST_UFO);
		//
		this.setBlock(world, position.add(14, 10, 30), this.casingState);//
		this.setBlock(world, position.add(14, 10, 31), this.casingState);
		this.setBlock(world, position.add(14, 10, 32), this.casingState);
		this.setBlock(world, position.add(14, 10, 33), this.casingState);
		this.setBlock(world, position.add(14, 11, 19), this.casingState);
		this.setBlock(world, position.add(14, 11, 20), this.casingState);
		this.setBlock(world, position.add(14, 11, 34), this.casingState);
		this.setBlock(world, position.add(14, 11, 35), this.casingState);
		this.setBlock(world, position.add(14, 12, 17), this.casingState);
		this.setBlock(world, position.add(14, 12, 18), this.casingState);
		this.setBlock(world, position.add(14, 12, 36), this.casingState);
		this.setBlock(world, position.add(14, 12, 37), this.casingState);
		this.setBlock(world, position.add(14, 13, 15), this.casingState);
		this.setBlock(world, position.add(14, 13, 16), this.casingState);
		this.setBlock(world, position.add(14, 13, 38), this.casingState);
		this.setBlock(world, position.add(14, 13, 39), this.casingState);
		this.setBlock(world, position.add(14, 14, 14), this.casingState);
		this.setBlock(world, position.add(14, 14, 40), this.casingState);
		this.setBlock(world, position.add(14, 15, 13), this.casingState);
		this.setBlock(world, position.add(14, 15, 41), this.casingState);
		this.setBlock(world, position.add(14, 16, 12), this.casingState);
		this.setBlock(world, position.add(14, 16, 42), this.casingState);
		this.setBlock(world, position.add(14, 17, 11), this.casingState);
		this.setBlock(world, position.add(14, 17, 43), this.casingState);
		this.setBlock(world, position.add(14, 18, 11), this.casingState);
		this.setBlock(world, position.add(14, 18, 43), this.casingState);
		this.setBlock(world, position.add(14, 19, 10), this.casingState);
		this.setBlock(world, position.add(14, 19, 44), this.casingState);
		this.setBlock(world, position.add(14, 20, 10), this.casingState);
		this.setBlock(world, position.add(14, 20, 44), this.casingState);
		this.setBlock(world, position.add(14, 21, 9), this.casingState);
		this.setBlock(world, position.add(14, 21, 45), this.casingState);
		this.setBlock(world, position.add(14, 22, 9), this.casingState);
		this.setBlock(world, position.add(14, 22, 45), this.casingState);
		this.setBlock(world, position.add(14, 23, 8), this.casingState);
		this.setBlock(world, position.add(14, 23, 46), this.casingState);
		this.setBlock(world, position.add(14, 24, 8), this.casingState);
		this.setBlock(world, position.add(14, 24, 46), this.casingState);
		this.setBlock(world, position.add(14, 25, 8), this.casingState);
		this.setBlock(world, position.add(14, 25, 46), this.casingState);
		this.setBlock(world, position.add(14, 26, 8), this.casingState);
		this.setBlock(world, position.add(14, 26, 46), this.casingState);
		this.setBlock(world, position.add(14, 27, 7), this.casingState);
		this.setBlock(world, position.add(14, 27, 47), this.casingState);
		this.setBlock(world, position.add(14, 28, 7), this.casingState);
		this.setBlock(world, position.add(14, 28, 47), this.casingState);
		this.setBlock(world, position.add(14, 29, 7), this.casingState);
		this.setBlock(world, position.add(14, 29, 47), this.casingState);
		this.setBlock(world, position.add(14, 30, 7), this.casingState);
		this.setBlock(world, position.add(14, 30, 47), this.casingState);
		this.setBlock(world, position.add(14, 31, 7), this.glassState);
		this.setBlock(world, position.add(14, 31, 8), this.glassState);
		this.setBlock(world, position.add(14, 31, 9), this.glassState);
		this.setBlock(world, position.add(14, 31, 10), this.glassState);
		this.setBlock(world, position.add(14, 31, 11), this.glassState);
		this.setBlock(world, position.add(14, 31, 12), this.glassState);
		this.setBlock(world, position.add(14, 31, 13), this.glassState);
		this.setBlock(world, position.add(14, 31, 14), this.glassState);
		this.setBlock(world, position.add(14, 31, 15), this.glassState);
		this.setBlock(world, position.add(14, 31, 16), this.glassState);
		this.setBlock(world, position.add(14, 31, 17), this.glassState);
		this.setBlock(world, position.add(14, 31, 18), this.glassState);
		this.setBlock(world, position.add(14, 31, 19), this.glassState);
		this.setBlock(world, position.add(14, 31, 20), this.glassState);
		this.setBlock(world, position.add(14, 31, 21), this.glassState);
		this.setBlock(world, position.add(14, 31, 22), this.glassState);
		this.setBlock(world, position.add(14, 31, 23), this.glassState);
		this.setBlock(world, position.add(14, 31, 24), this.glassState);
		this.setBlock(world, position.add(14, 31, 25), this.glassState);
		this.setBlock(world, position.add(14, 31, 26), this.glassState);
		this.setBlock(world, position.add(14, 31, 27), this.glassState);
		this.setBlock(world, position.add(14, 31, 28), this.glassState);
		this.setBlock(world, position.add(14, 31, 29), this.glassState);
		this.setBlock(world, position.add(14, 31, 30), this.glassState);
		this.setBlock(world, position.add(14, 31, 31), this.glassState);
		this.setBlock(world, position.add(14, 31, 32), this.glassState);
		this.setBlock(world, position.add(14, 31, 33), this.glassState);
		this.setBlock(world, position.add(14, 31, 34), this.glassState);
		this.setBlock(world, position.add(14, 31, 35), this.glassState);
		this.setBlock(world, position.add(14, 31, 36), this.glassState);
		this.setBlock(world, position.add(14, 31, 37), this.glassState);
		this.setBlock(world, position.add(14, 31, 38), this.glassState);
		this.setBlock(world, position.add(14, 31, 39), this.glassState);
		this.setBlock(world, position.add(14, 31, 40), this.glassState);
		this.setBlock(world, position.add(14, 31, 41), this.glassState);
		this.setBlock(world, position.add(14, 31, 42), this.glassState);
		this.setBlock(world, position.add(14, 31, 43), this.glassState);
		this.setBlock(world, position.add(14, 31, 44), this.glassState);
		this.setBlock(world, position.add(14, 31, 45), this.glassState);
		this.setBlock(world, position.add(14, 31, 46), this.glassState);
		this.setBlock(world, position.add(14, 31, 47), this.glassState);
		this.setBlock(world, position.add(14, 32, 8), this.casingState);
		this.setBlock(world, position.add(14, 32, 46), this.casingState);
		this.setBlock(world, position.add(15, 9, 24), this.casingState);
		this.setBlock(world, position.add(15, 9, 25), this.casingState);
		this.setBlock(world, position.add(15, 9, 26), this.casingState);
		this.setBlock(world, position.add(15, 9, 27), this.casingState);
		this.setBlock(world, position.add(15, 9, 28), this.casingState);
		this.setBlock(world, position.add(15, 9, 29), this.casingState);
		this.setBlock(world, position.add(15, 9, 30), this.casingState);
		this.setBlock(world, position.add(15, 10, 20), this.casingState);
		this.setBlock(world, position.add(15, 10, 21), this.casingState);
		this.setBlock(world, position.add(15, 10, 22), this.casingState);
		this.setBlock(world, position.add(15, 10, 23), this.casingState);
		this.setBlock(world, position.add(15, 10, 31), this.casingState);
		this.setBlock(world, position.add(15, 10, 32), this.casingState);
		this.setBlock(world, position.add(15, 10, 33), this.casingState);
		this.setBlock(world, position.add(15, 10, 34), this.casingState);
		this.setBlock(world, position.add(15, 11, 18), this.casingState);
		this.setBlock(world, position.add(15, 11, 19), this.casingState);
		this.setBlock(world, position.add(15, 11, 35), this.casingState);
		this.setBlock(world, position.add(15, 11, 36), this.casingState);
		this.setBlock(world, position.add(15, 12, 16), this.casingState);
		this.setBlock(world, position.add(15, 12, 17), this.casingState);
		this.setBlock(world, position.add(15, 12, 37), this.casingState);
		this.setBlock(world, position.add(15, 12, 38), this.casingState);
		this.setBlock(world, position.add(15, 13, 15), this.casingState);
		this.setBlock(world, position.add(15, 13, 39), this.casingState);
		this.setBlock(world, position.add(15, 14, 14), this.casingState);
		this.setBlock(world, position.add(15, 14, 40), this.casingState);
		this.setBlock(world, position.add(15, 15, 13), this.casingState);
		this.setBlock(world, position.add(15, 15, 41), this.casingState);
		this.setBlock(world, position.add(15, 16, 12), this.casingState);
		this.setBlock(world, position.add(15, 16, 42), this.casingState);
		this.setBlock(world, position.add(15, 17, 11), this.casingState);
		this.setBlock(world, position.add(15, 17, 43), this.casingState);
		this.setBlock(world, position.add(15, 18, 10), this.casingState);
		this.setBlock(world, position.add(15, 18, 44), this.casingState);
		this.setBlock(world, position.add(15, 19, 10), this.casingState);
		this.setBlock(world, position.add(15, 19, 44), this.casingState);
		this.setBlock(world, position.add(15, 20, 9), this.casingState);
		this.setBlock(world, position.add(15, 20, 45), this.casingState);
		this.setBlock(world, position.add(15, 21, 9), this.casingState);
		this.setBlock(world, position.add(15, 21, 45), this.casingState);
		this.setBlock(world, position.add(15, 22, 8), this.casingState);
		this.setBlock(world, position.add(15, 22, 46), this.casingState);
		this.setBlock(world, position.add(15, 23, 8), this.casingState);
		this.setBlock(world, position.add(15, 23, 46), this.casingState);
		this.setBlock(world, position.add(15, 24, 8), this.casingState);
		this.setBlock(world, position.add(15, 24, 46), this.casingState);
		this.setBlock(world, position.add(15, 25, 8), this.casingState);
		this.setBlock(world, position.add(15, 25, 46), this.casingState);
		this.setBlock(world, position.add(15, 26, 7), this.casingState);
		this.setBlock(world, position.add(15, 26, 47), this.casingState);
		this.setBlock(world, position.add(15, 27, 7), this.casingState);
		this.setBlock(world, position.add(15, 27, 47), this.casingState);
		this.setBlock(world, position.add(15, 28, 7), this.casingState);
		this.setBlock(world, position.add(15, 28, 47), this.casingState);
		this.setBlock(world, position.add(15, 29, 7), this.casingState);
		this.setBlock(world, position.add(15, 29, 47), this.casingState);
		this.setBlock(world, position.add(15, 30, 7), this.casingState);
		this.setBlock(world, position.add(15, 30, 47), this.casingState);
		this.setBlock(world, position.add(15, 31, 7), this.glassState);
		this.setBlock(world, position.add(15, 31, 8), this.glassState);
		this.setBlock(world, position.add(15, 31, 9), this.glassState);
		this.setBlock(world, position.add(15, 31, 10), this.glassState);
		this.setBlock(world, position.add(15, 31, 11), this.glassState);
		this.setBlock(world, position.add(15, 31, 12), this.glassState);
		this.setBlock(world, position.add(15, 31, 13), this.glassState);
		this.setBlock(world, position.add(15, 31, 14), this.glassState);
		this.setBlock(world, position.add(15, 31, 15), this.glassState);
		this.setBlock(world, position.add(15, 31, 16), this.glassState);
		this.setBlock(world, position.add(15, 31, 17), this.glassState);
		this.setBlock(world, position.add(15, 31, 18), this.glassState);
		this.setBlock(world, position.add(15, 31, 19), this.glassState);
		this.setBlock(world, position.add(15, 31, 20), this.glassState);
		this.setBlock(world, position.add(15, 31, 21), this.glassState);
		this.setBlock(world, position.add(15, 31, 22), this.glassState);
		this.setBlock(world, position.add(15, 31, 23), this.glassState);
		this.setBlock(world, position.add(15, 31, 24), this.glassState);
		this.setBlock(world, position.add(15, 31, 25), this.glassState);
		this.setBlock(world, position.add(15, 31, 26), this.glassState);
		this.setBlock(world, position.add(15, 31, 27), this.glassState);
		this.setBlock(world, position.add(15, 31, 28), this.glassState);
		this.setBlock(world, position.add(15, 31, 29), this.glassState);
		this.setBlock(world, position.add(15, 31, 30), this.glassState);
		this.setBlock(world, position.add(15, 31, 31), this.glassState);
		this.setBlock(world, position.add(15, 31, 32), this.glassState);
		this.setBlock(world, position.add(15, 31, 33), this.glassState);
		this.setBlock(world, position.add(15, 31, 34), this.glassState);
		this.setBlock(world, position.add(15, 31, 35), this.glassState);
		this.setBlock(world, position.add(15, 31, 36), this.glassState);
		this.setBlock(world, position.add(15, 31, 37), this.glassState);
		this.setBlock(world, position.add(15, 31, 38), this.glassState);
		this.setBlock(world, position.add(15, 31, 39), this.glassState);
		this.setBlock(world, position.add(15, 31, 40), this.glassState);
		this.setBlock(world, position.add(15, 31, 41), this.glassState);
		this.setBlock(world, position.add(15, 31, 42), this.glassState);
		this.setBlock(world, position.add(15, 31, 43), this.glassState);
		this.setBlock(world, position.add(15, 31, 44), this.glassState);
		this.setBlock(world, position.add(15, 31, 45), this.glassState);
		this.setBlock(world, position.add(15, 31, 46), this.glassState);
		this.setBlock(world, position.add(15, 31, 47), this.glassState);
		this.setBlock(world, position.add(15, 32, 7), this.casingState);
		this.setBlock(world, position.add(15, 32, 47), this.casingState);
		this.setBlock(world, position.add(16, 9, 23), this.casingState);
		this.setBlock(world, position.add(16, 9, 24), this.casingState);
		this.setBlock(world, position.add(16, 9, 25), this.casingState);
		this.setBlock(world, position.add(16, 9, 26), this.casingState);
		this.setBlock(world, position.add(16, 9, 27), this.casingState);
		this.setBlock(world, position.add(16, 9, 28), this.casingState);
		this.setBlock(world, position.add(16, 9, 29), this.casingState);
		this.setBlock(world, position.add(16, 9, 30), this.casingState);
		this.setBlock(world, position.add(16, 9, 31), this.casingState);
		this.setBlock(world, position.add(16, 10, 20), this.casingState);
		this.setBlock(world, position.add(16, 10, 21), this.casingState);
		this.setBlock(world, position.add(16, 10, 22), this.casingState);
		this.setBlock(world, position.add(16, 10, 32), this.casingState);
		this.setBlock(world, position.add(16, 10, 33), this.casingState);
		this.setBlock(world, position.add(16, 10, 34), this.casingState);
		this.setBlock(world, position.add(16, 11, 18), this.casingState);
		this.setBlock(world, position.add(16, 11, 19), this.casingState);
		this.setBlock(world, position.add(16, 11, 33), this.barsState);//
		// SPAWN VEXBOTS
		BlockPos spawnPos = position.add(16, 11, 33);
