/**
 * Zollern Galaxy by @author Zollern Wolf
 * Copyright 2016 - 2025
 * You may use this code to learn from,
 * but do not claim it as your own, and
 * do not redistribute it.
 */
package zollerngalaxy.worldgen;

import java.util.Random;
import net.minecraft.block.state.IBlockState;
import net.minecraft.util.math.BlockPos;
import net.minecraft.world.World;
import zollerngalaxy.core.ZGLootTables;
import zollerngalaxy.lib.helpers.ZGHelper;

public class WorldGenCrystalTower extends ZGWorldGenMaster {
	
	protected IBlockState blockState;
	
	public WorldGenCrystalTower(IBlockState blockStateIn) {
		this.blockState = blockStateIn;
	}
	
	@Override
	public boolean generate(World world, Random rand, BlockPos position) {
		this.setBlock(world, position.add(4, 2, 10), blockState);
		this.setBlock(world, position.add(4, 2, 11), blockState);
		this.setBlock(world, position.add(4, 2, 12), blockState);
		this.setBlock(world, position.add(4, 2, 13), blockState);
		this.setBlock(world, position.add(4, 2, 14), blockState);
		this.setBlock(world, position.add(4, 2, 15), blockState);
		this.setBlock(world, position.add(4, 2, 16), blockState);
		this.setBlock(world, position.add(4, 3, 10), blockState);
		this.setBlock(world, position.add(4, 3, 11), blockState);
		this.setBlock(world, position.add(4, 3, 12), blockState);
		this.setBlock(world, position.add(4, 3, 13), blockState);
		this.setBlock(world, position.add(4, 3, 14), blockState);
		this.setBlock(world, position.add(4, 3, 15), blockState);
		this.setBlock(world, position.add(4, 3, 16), blockState);
		this.setBlock(world, position.add(4, 4, 10), blockState);
		this.setBlock(world, position.add(4, 4, 11), blockState);
		this.setBlock(world, position.add(4, 4, 12), blockState);
		this.setBlock(world, position.add(4, 4, 13), blockState);
		this.setBlock(world, position.add(4, 4, 14), blockState);
		this.setBlock(world, position.add(4, 4, 15), blockState);
		this.setBlock(world, position.add(4, 4, 16), blockState);
		this.setBlock(world, position.add(4, 5, 10), blockState);
		this.setBlock(world, position.add(4, 5, 11), blockState);
		this.setBlock(world, position.add(4, 5, 12), blockState);
		this.setBlock(world, position.add(4, 5, 13), blockState);
		this.setBlock(world, position.add(4, 5, 14), blockState);
		this.setBlock(world, position.add(4, 5, 15), blockState);
		this.setBlock(world, position.add(4, 5, 16), blockState);
		this.setBlock(world, position.add(4, 6, 10), blockState);
		this.setBlock(world, position.add(4, 6, 11), blockState);
		this.setBlock(world, position.add(4, 6, 12), blockState);
		this.setBlock(world, position.add(4, 6, 13), blockState);
		this.setBlock(world, position.add(4, 6, 14), blockState);
		this.setBlock(world, position.add(4, 6, 15), blockState);
		this.setBlock(world, position.add(4, 6, 16), blockState);
		this.setBlock(world, position.add(4, 7, 10), blockState);
		this.setBlock(world, position.add(4, 7, 11), blockState);
		this.setBlock(world, position.add(4, 7, 12), blockState);
		this.setBlock(world, position.add(4, 7, 13), blockState);
		this.setBlock(world, position.add(4, 7, 14), blockState);
		this.setBlock(world, position.add(4, 7, 15), blockState);
		this.setBlock(world, position.add(4, 7, 16), blockState);
		this.setBlock(world, position.add(4, 8, 10), blockState);
		this.setBlock(world, position.add(4, 8, 11), blockState);
		this.setBlock(world, position.add(4, 8, 12), blockState);
		this.setBlock(world, position.add(4, 8, 13), blockState);
		this.setBlock(world, position.add(4, 8, 14), blockState);
		this.setBlock(world, position.add(4, 8, 15), blockState);
		this.setBlock(world, position.add(4, 8, 16), blockState);
		ZGLootTables.generateChest(world, position.add(5, 0, 13), rand, ZGLootTables.CHEST_EDEN_TOWER);
		this.setBlock(world, position.add(5, 2, 8), blockState);
		this.setBlock(world, position.add(5, 2, 9), blockState);
		this.setBlock(world, position.add(5, 2, 17), blockState);
		this.setBlock(world, position.add(5, 2, 18), blockState);
		this.setBlock(world, position.add(5, 3, 8), blockState);
		this.setBlock(world, position.add(5, 3, 9), blockState);
		this.setBlock(world, position.add(5, 3, 17), blockState);
		this.setBlock(world, position.add(5, 3, 18), blockState);
		this.setBlock(world, position.add(5, 4, 8), blockState);
		this.setBlock(world, position.add(5, 4, 9), blockState);
		this.setBlock(world, position.add(5, 4, 17), blockState);
		this.setBlock(world, position.add(5, 4, 18), blockState);
		this.setBlock(world, position.add(5, 5, 8), blockState);
		this.setBlock(world, position.add(5, 5, 9), blockState);
		this.setBlock(world, position.add(5, 5, 17), blockState);
		this.setBlock(world, position.add(5, 5, 18), blockState);
		this.setBlock(world, position.add(5, 6, 8), blockState);
		this.setBlock(world, position.add(5, 6, 9), blockState);
		this.setBlock(world, position.add(5, 6, 17), blockState);
		this.setBlock(world, position.add(5, 6, 18), blockState);
		this.setBlock(world, position.add(5, 7, 8), blockState);
		this.setBlock(world, position.add(5, 7, 9), blockState);
		this.setBlock(world, position.add(5, 7, 17), blockState);
		this.setBlock(world, position.add(5, 7, 18), blockState);
		this.setBlock(world, position.add(5, 8, 8), blockState);
		this.setBlock(world, position.add(5, 8, 9), blockState);
		this.setBlock(world, position.add(5, 8, 10), blockState);
		this.setBlock(world, position.add(5, 8, 11), blockState);
		this.setBlock(world, position.add(5, 8, 12), blockState);
		this.setBlock(world, position.add(5, 8, 13), blockState);
		this.setBlock(world, position.add(5, 8, 14), blockState);
		this.setBlock(world, position.add(5, 8, 15), blockState);
		this.setBlock(world, position.add(5, 8, 16), blockState);
		this.setBlock(world, position.add(5, 8, 17), blockState);
		this.setBlock(world, position.add(5, 8, 18), blockState);
		this.setBlock(world, position.add(5, 9, 10), blockState);
		this.setBlock(world, position.add(5, 9, 11), blockState);
		this.setBlock(world, position.add(5, 9, 12), blockState);
		this.setBlock(world, position.add(5, 9, 13), blockState);
		this.setBlock(world, position.add(5, 9, 14), blockState);
		this.setBlock(world, position.add(5, 9, 15), blockState);
		this.setBlock(world, position.add(5, 9, 16), blockState);
		this.setBlock(world, position.add(6, 2, 7), blockState);
		this.setBlock(world, position.add(6, 2, 19), blockState);
		this.setBlock(world, position.add(6, 3, 7), blockState);
		this.setBlock(world, position.add(6, 3, 19), blockState);
		this.setBlock(world, position.add(6, 4, 7), blockState);
		this.setBlock(world, position.add(6, 4, 19), blockState);
		this.setBlock(world, position.add(6, 5, 7), blockState);
		this.setBlock(world, position.add(6, 5, 19), blockState);
		this.setBlock(world, position.add(6, 6, 7), blockState);
		this.setBlock(world, position.add(6, 6, 19), blockState);
		this.setBlock(world, position.add(6, 7, 7), blockState);
		this.setBlock(world, position.add(6, 7, 19), blockState);
		this.setBlock(world, position.add(6, 8, 7), blockState);
		this.setBlock(world, position.add(6, 8, 8), blockState);
		this.setBlock(world, position.add(6, 8, 9), blockState);
		this.setBlock(world, position.add(6, 8, 17), blockState);
		this.setBlock(world, position.add(6, 8, 18), blockState);
		this.setBlock(world, position.add(6, 8, 19), blockState);
		this.setBlock(world, position.add(6, 9, 8), blockState);
		this.setBlock(world, position.add(6, 9, 9), blockState);
		this.setBlock(world, position.add(6, 9, 10), blockState);
		this.setBlock(world, position.add(6, 9, 16), blockState);
		this.setBlock(world, position.add(6, 9, 17), blockState);
		this.setBlock(world, position.add(6, 9, 18), blockState);
		this.setBlock(world, position.add(6, 10, 11), blockState);
		this.setBlock(world, position.add(6, 10, 12), blockState);
		this.setBlock(world, position.add(6, 10, 13), blockState);
		this.setBlock(world, position.add(6, 10, 14), blockState);
		this.setBlock(world, position.add(6, 10, 15), blockState);
		this.setBlock(world, position.add(6, 11, 11), blockState);
		this.setBlock(world, position.add(6, 11, 12), blockState);
		this.setBlock(world, position.add(6, 11, 13), blockState);
		this.setBlock(world, position.add(6, 11, 14), blockState);
		this.setBlock(world, position.add(6, 11, 15), blockState);
		this.setBlock(world, position.add(7, 2, 6), blockState);
		this.setBlock(world, position.add(7, 2, 20), blockState);
		this.setBlock(world, position.add(7, 3, 6), blockState);
		this.setBlock(world, position.add(7, 3, 20), blockState);
		this.setBlock(world, position.add(7, 4, 6), blockState);
		this.setBlock(world, position.add(7, 4, 20), blockState);
		this.setBlock(world, position.add(7, 5, 6), blockState);
		this.setBlock(world, position.add(7, 5, 20), blockState);
		this.setBlock(world, position.add(7, 6, 6), blockState);
		this.setBlock(world, position.add(7, 6, 20), blockState);
		this.setBlock(world, position.add(7, 7, 6), blockState);
		this.setBlock(world, position.add(7, 7, 20), blockState);
		this.setBlock(world, position.add(7, 8, 6), blockState);
		this.setBlock(world, position.add(7, 8, 7), blockState);
		this.setBlock(world, position.add(7, 8, 19), blockState);
		this.setBlock(world, position.add(7, 8, 20), blockState);
		this.setBlock(world, position.add(7, 9, 7), blockState);
		this.setBlock(world, position.add(7, 9, 8), blockState);
		this.setBlock(world, position.add(7, 9, 18), blockState);
		this.setBlock(world, position.add(7, 9, 19), blockState);
		this.setBlock(world, position.add(7, 10, 9), blockState);
		this.setBlock(world, position.add(7, 10, 10), blockState);
		this.setBlock(world, position.add(7, 10, 16), blockState);
		this.setBlock(world, position.add(7, 10, 17), blockState);
		this.setBlock(world, position.add(7, 11, 9), blockState);
		this.setBlock(world, position.add(7, 11, 10), blockState);
		this.setBlock(world, position.add(7, 11, 16), blockState);
		this.setBlock(world, position.add(7, 11, 17), blockState);
		this.setBlock(world, position.add(7, 12, 11), blockState);
		this.setBlock(world, position.add(7, 12, 12), blockState);
		this.setBlock(world, position.add(7, 12, 13), blockState);
		this.setBlock(world, position.add(7, 12, 14), blockState);
		this.setBlock(world, position.add(7, 12, 15), blockState);
		this.setBlock(world, position.add(7, 13, 11), blockState);
		this.setBlock(world, position.add(7, 13, 12), blockState);
		this.setBlock(world, position.add(7, 13, 13), blockState);
		this.setBlock(world, position.add(7, 13, 14), blockState);
		this.setBlock(world, position.add(7, 13, 15), blockState);
		this.setBlock(world, position.add(8, 2, 5), blockState);
		this.setBlock(world, position.add(8, 2, 21), blockState);
		this.setBlock(world, position.add(8, 3, 5), blockState);
		this.setBlock(world, position.add(8, 3, 21), blockState);
		this.setBlock(world, position.add(8, 4, 5), blockState);
		this.setBlock(world, position.add(8, 4, 21), blockState);
		this.setBlock(world, position.add(8, 5, 5), blockState);
		this.setBlock(world, position.add(8, 5, 21), blockState);
		this.setBlock(world, position.add(8, 6, 5), blockState);
		this.setBlock(world, position.add(8, 6, 21), blockState);
		this.setBlock(world, position.add(8, 7, 5), blockState);
		this.setBlock(world, position.add(8, 7, 21), blockState);
		this.setBlock(world, position.add(8, 8, 5), blockState);
		this.setBlock(world, position.add(8, 8, 6), blockState);
		this.setBlock(world, position.add(8, 8, 20), blockState);
		this.setBlock(world, position.add(8, 8, 21), blockState);
		this.setBlock(world, position.add(8, 9, 6), blockState);
		this.setBlock(world, position.add(8, 9, 20), blockState);
		this.setBlock(world, position.add(8, 10, 7), blockState);
		this.setBlock(world, position.add(8, 10, 8), blockState);
		this.setBlock(world, position.add(8, 10, 18), blockState);
		this.setBlock(world, position.add(8, 10, 19), blockState);
		this.setBlock(world, position.add(8, 11, 7), blockState);
		this.setBlock(world, position.add(8, 11, 8), blockState);
		this.setBlock(world, position.add(8, 11, 18), blockState);
		this.setBlock(world, position.add(8, 11, 19), blockState);
		this.setBlock(world, position.add(8, 12, 9), blockState);
		this.setBlock(world, position.add(8, 12, 10), blockState);
		this.setBlock(world, position.add(8, 12, 16), blockState);
		this.setBlock(world, position.add(8, 12, 17), blockState);
		this.setBlock(world, position.add(8, 13, 9), blockState);
		this.setBlock(world, position.add(8, 13, 10), blockState);
		this.setBlock(world, position.add(8, 13, 16), blockState);
		this.setBlock(world, position.add(8, 13, 17), blockState);
		this.setBlock(world, position.add(8, 14, 11), blockState);
		this.setBlock(world, position.add(8, 14, 12), blockState);
		this.setBlock(world, position.add(8, 14, 13), blockState);
		this.setBlock(world, position.add(8, 14, 14), blockState);
		this.setBlock(world, position.add(8, 14, 15), blockState);
		this.setBlock(world, position.add(8, 15, 11), blockState);
		this.setBlock(world, position.add(8, 15, 12), blockState);
		this.setBlock(world, position.add(8, 15, 13), blockState);
		this.setBlock(world, position.add(8, 15, 14), blockState);
		this.setBlock(world, position.add(8, 15, 15), blockState);
		this.setBlock(world, position.add(9, 2, 4), blockState);
		this.setBlock(world, position.add(9, 2, 22), blockState);
		this.setBlock(world, position.add(9, 3, 4), blockState);
		this.setBlock(world, position.add(9, 3, 22), blockState);
		this.setBlock(world, position.add(9, 4, 4), blockState);
		this.setBlock(world, position.add(9, 4, 22), blockState);
		this.setBlock(world, position.add(9, 5, 4), blockState);
		this.setBlock(world, position.add(9, 5, 22), blockState);
		this.setBlock(world, position.add(9, 6, 4), blockState);
		this.setBlock(world, position.add(9, 6, 22), blockState);
		this.setBlock(world, position.add(9, 7, 4), blockState);
		this.setBlock(world, position.add(9, 7, 22), blockState);
		this.setBlock(world, position.add(9, 8, 4), blockState);
		this.setBlock(world, position.add(9, 8, 5), blockState);
		this.setBlock(world, position.add(9, 8, 21), blockState);
		this.setBlock(world, position.add(9, 8, 22), blockState);
		this.setBlock(world, position.add(9, 9, 5), blockState);
		this.setBlock(world, position.add(9, 9, 6), blockState);
		this.setBlock(world, position.add(9, 9, 20), blockState);
		this.setBlock(world, position.add(9, 9, 21), blockState);
		this.setBlock(world, position.add(9, 10, 7), blockState);
		this.setBlock(world, position.add(9, 10, 19), blockState);
		this.setBlock(world, position.add(9, 11, 7), blockState);
		this.setBlock(world, position.add(9, 11, 19), blockState);
		this.setBlock(world, position.add(9, 12, 8), blockState);
		this.setBlock(world, position.add(9, 12, 18), blockState);
		this.setBlock(world, position.add(9, 13, 8), blockState);
		this.setBlock(world, position.add(9, 13, 18), blockState);
		this.setBlock(world, position.add(9, 14, 9), blockState);
		this.setBlock(world, position.add(9, 14, 10), blockState);
		this.setBlock(world, position.add(9, 14, 16), blockState);
		this.setBlock(world, position.add(9, 14, 17), blockState);
		this.setBlock(world, position.add(9, 15, 9), blockState);
		this.setBlock(world, position.add(9, 15, 10), blockState);
		this.setBlock(world, position.add(9, 15, 16), blockState);
		this.setBlock(world, position.add(9, 15, 17), blockState);
		this.setBlock(world, position.add(9, 16, 11), blockState);
		this.setBlock(world, position.add(9, 16, 12), blockState);
		this.setBlock(world, position.add(9, 16, 13), blockState);
		this.setBlock(world, position.add(9, 16, 14), blockState);
		this.setBlock(world, position.add(9, 16, 15), blockState);
		this.setBlock(world, position.add(9, 17, 11), blockState);
		this.setBlock(world, position.add(9, 17, 12), blockState);
		this.setBlock(world, position.add(9, 17, 13), blockState);
		this.setBlock(world, position.add(9, 17, 14), blockState);
		this.setBlock(world, position.add(9, 17, 15), blockState);
		this.setBlock(world, position.add(10, 2, 4), blockState);
		this.setBlock(world, position.add(10, 2, 22), blockState);
		this.setBlock(world, position.add(10, 3, 4), blockState);
		this.setBlock(world, position.add(10, 3, 22), blockState);
		this.setBlock(world, position.add(10, 4, 4), blockState);
		this.setBlock(world, position.add(10, 4, 22), blockState);
		this.setBlock(world, position.add(10, 5, 4), blockState);
		this.setBlock(world, position.add(10, 5, 22), blockState);
		this.setBlock(world, position.add(10, 6, 4), blockState);
		this.setBlock(world, position.add(10, 6, 22), blockState);
		this.setBlock(world, position.add(10, 7, 4), blockState);
		this.setBlock(world, position.add(10, 7, 22), blockState);
		this.setBlock(world, position.add(10, 8, 4), blockState);
		this.setBlock(world, position.add(10, 8, 5), blockState);
		this.setBlock(world, position.add(10, 8, 21), blockState);
		this.setBlock(world, position.add(10, 8, 22), blockState);
		this.setBlock(world, position.add(10, 9, 5), blockState);
		this.setBlock(world, position.add(10, 9, 21), blockState);
		this.setBlock(world, position.add(10, 10, 6), blockState);
		this.setBlock(world, position.add(10, 10, 20), blockState);
		this.setBlock(world, position.add(10, 11, 6), blockState);
		this.setBlock(world, position.add(10, 11, 20), blockState);
		this.setBlock(world, position.add(10, 12, 7), blockState);
		this.setBlock(world, position.add(10, 12, 19), blockState);
		this.setBlock(world, position.add(10, 13, 7), blockState);
		this.setBlock(world, position.add(10, 13, 19), blockState);
		this.setBlock(world, position.add(10, 14, 8), blockState);
		this.setBlock(world, position.add(10, 14, 18), blockState);
		this.setBlock(world, position.add(10, 15, 8), blockState);
		this.setBlock(world, position.add(10, 15, 9), blockState);
		this.setBlock(world, position.add(10, 15, 17), blockState);
		this.setBlock(world, position.add(10, 15, 18), blockState);
		this.setBlock(world, position.add(10, 16, 10), blockState);
		this.setBlock(world, position.add(10, 16, 16), blockState);
		this.setBlock(world, position.add(10, 17, 10), blockState);
		this.setBlock(world, position.add(10, 17, 16), blockState);
		this.setBlock(world, position.add(10, 18, 11), blockState);
		this.setBlock(world, position.add(10, 18, 12), blockState);
		this.setBlock(world, position.add(10, 18, 13), blockState);
		this.setBlock(world, position.add(10, 18, 14), blockState);
		this.setBlock(world, position.add(10, 18, 15), blockState);
		this.setBlock(world, position.add(10, 19, 11), blockState);
		this.setBlock(world, position.add(10, 19, 12), blockState);
		this.setBlock(world, position.add(10, 19, 13), blockState);
		this.setBlock(world, position.add(10, 19, 14), blockState);
		this.setBlock(world, position.add(10, 19, 15), blockState);
		this.setBlock(world, position.add(11, 2, 3), blockState);
		this.setBlock(world, position.add(11, 2, 23), blockState);
		this.setBlock(world, position.add(11, 3, 3), blockState);
		this.setBlock(world, position.add(11, 3, 23), blockState);
		this.setBlock(world, position.add(11, 4, 3), blockState);
		this.setBlock(world, position.add(11, 4, 23), blockState);
		this.setBlock(world, position.add(11, 5, 3), blockState);
		this.setBlock(world, position.add(11, 5, 23), blockState);
		this.setBlock(world, position.add(11, 6, 3), blockState);
		this.setBlock(world, position.add(11, 6, 23), blockState);
		this.setBlock(world, position.add(11, 7, 3), blockState);
		this.setBlock(world, position.add(11, 7, 23), blockState);
		this.setBlock(world, position.add(11, 8, 3), blockState);
		this.setBlock(world, position.add(11, 8, 4), blockState);
		this.setBlock(world, position.add(11, 8, 22), blockState);
		this.setBlock(world, position.add(11, 8, 23), blockState);
		this.setBlock(world, position.add(11, 9, 4), blockState);
		this.setBlock(world, position.add(11, 9, 5), blockState);
		this.setBlock(world, position.add(11, 9, 21), blockState);
		this.setBlock(world, position.add(11, 9, 22), blockState);
		this.setBlock(world, position.add(11, 10, 6), blockState);
		this.setBlock(world, position.add(11, 10, 20), blockState);
		this.setBlock(world, position.add(11, 11, 6), blockState);
		this.setBlock(world, position.add(11, 11, 20), blockState);
		this.setBlock(world, position.add(11, 12, 7), blockState);
		this.setBlock(world, position.add(11, 12, 19), blockState);
		this.setBlock(world, position.add(11, 13, 7), blockState);
		this.setBlock(world, position.add(11, 13, 19), blockState);
		this.setBlock(world, position.add(11, 14, 8), blockState);
		this.setBlock(world, position.add(11, 14, 18), blockState);
		this.setBlock(world, position.add(11, 15, 8), blockState);
		this.setBlock(world, position.add(11, 15, 18), blockState);
		this.setBlock(world, position.add(11, 16, 9), blockState);
		this.setBlock(world, position.add(11, 16, 17), blockState);
		this.setBlock(world, position.add(11, 17, 9), blockState);
		this.setBlock(world, position.add(11, 17, 17), blockState);
		this.setBlock(world, position.add(11, 18, 10), blockState);
		this.setBlock(world, position.add(11, 18, 16), blockState);
		this.setBlock(world, position.add(11, 19, 10), blockState);
		this.setBlock(world, position.add(11, 19, 11), blockState);
		this.setBlock(world, position.add(11, 19, 15), blockState);
		this.setBlock(world, position.add(11, 19, 16), blockState);
		this.setBlock(world, position.add(11, 20, 12), blockState);
		this.setBlock(world, position.add(11, 20, 13), blockState);
		this.setBlock(world, position.add(11, 20, 14), blockState);
		this.setBlock(world, position.add(11, 21, 12), blockState);
		this.setBlock(world, position.add(11, 21, 13), blockState);
		ZGLootTables.generateChest(world, position.add(12, 1, 13), rand, ZGLootTables.CHEST_EDEN_TOWER);
		this.setBlock(world, position.add(12, 2, 3), blockState);
		ZGHelper.setupMobSpawner(world, rand, position.add(12, 2, 13), ZGHelper.getRandomMob(rand));
		this.setBlock(world, position.add(12, 2, 23), blockState);
		this.setBlock(world, position.add(12, 3, 3), blockState);
		this.setBlock(world, position.add(12, 3, 23), blockState);
		this.setBlock(world, position.add(12, 4, 3), blockState);
		this.setBlock(world, position.add(12, 4, 23), blockState);
		this.setBlock(world, position.add(12, 5, 3), blockState);
		this.setBlock(world, position.add(12, 5, 23), blockState);
		this.setBlock(world, position.add(12, 6, 3), blockState);
		this.setBlock(world, position.add(12, 6, 23), blockState);
		this.setBlock(world, position.add(12, 7, 3), blockState);
		this.setBlock(world, position.add(12, 7, 23), blockState);
		this.setBlock(world, position.add(12, 8, 3), blockState);
		this.setBlock(world, position.add(12, 8, 4), blockState);
		this.setBlock(world, position.add(12, 8, 22), blockState);
		this.setBlock(world, position.add(12, 8, 23), blockState);
		this.setBlock(world, position.add(12, 9, 4), blockState);
		this.setBlock(world, position.add(12, 9, 22), blockState);
		this.setBlock(world, position.add(12, 10, 5), blockState);
		this.setBlock(world, position.add(12, 10, 21), blockState);
		this.setBlock(world, position.add(12, 11, 5), blockState);
		this.setBlock(world, position.add(12, 11, 21), blockState);
		this.setBlock(world, position.add(12, 12, 6), blockState);
		this.setBlock(world, position.add(12, 12, 20), blockState);
		this.setBlock(world, position.add(12, 13, 6), blockState);
		this.setBlock(world, position.add(12, 13, 20), blockState);
		this.setBlock(world, position.add(12, 14, 7), blockState);
		this.setBlock(world, position.add(12, 14, 19), blockState);
		this.setBlock(world, position.add(12, 15, 7), blockState);
		this.setBlock(world, position.add(12, 15, 19), blockState);
		this.setBlock(world, position.add(12, 16, 8), blockState);
		this.setBlock(world, position.add(12, 16, 18), blockState);
		this.setBlock(world, position.add(12, 17, 8), blockState);
		this.setBlock(world, position.add(12, 17, 18), blockState);
		this.setBlock(world, position.add(12, 18, 9), blockState);
		this.setBlock(world, position.add(12, 18, 17), blockState);
		this.setBlock(world, position.add(12, 19, 9), blockState);
		this.setBlock(world, position.add(12, 19, 10), blockState);
		this.setBlock(world, position.add(12, 19, 16), blockState);
		this.setBlock(world, position.add(12, 19, 17), blockState);
		this.setBlock(world, position.add(12, 20, 11), blockState);
		this.setBlock(world, position.add(12, 20, 15), blockState);
		this.setBlock(world, position.add(12, 21, 11), blockState);
		this.setBlock(world, position.add(12, 21, 15), blockState);
		this.setBlock(world, position.add(12, 22, 12), blockState);
		this.setBlock(world, position.add(12, 22, 13), blockState);
		this.setBlock(world, position.add(12, 22, 14), blockState);
		this.setBlock(world, position.add(12, 23, 12), blockState);
		this.setBlock(world, position.add(12, 23, 13), blockState);
		this.setBlock(world, position.add(12, 23, 14), blockState);
		this.setBlock(world, position.add(13, 2, 3), blockState);
		this.setBlock(world, position.add(13, 2, 23), blockState);
		this.setBlock(world, position.add(13, 3, 3), blockState);
		this.setBlock(world, position.add(13, 3, 23), blockState);
		this.setBlock(world, position.add(13, 4, 3), blockState);
		this.setBlock(world, position.add(13, 4, 23), blockState);
		this.setBlock(world, position.add(13, 5, 3), blockState);
		this.setBlock(world, position.add(13, 5, 23), blockState);
		this.setBlock(world, position.add(13, 6, 3), blockState);
		this.setBlock(world, position.add(13, 6, 23), blockState);
		this.setBlock(world, position.add(13, 7, 3), blockState);
		this.setBlock(world, position.add(13, 7, 23), blockState);
		this.setBlock(world, position.add(13, 8, 3), blockState);
		this.setBlock(world, position.add(13, 8, 4), blockState);
		this.setBlock(world, position.add(13, 8, 22), blockState);
		this.setBlock(world, position.add(13, 8, 23), blockState);
		this.setBlock(world, position.add(13, 9, 4), blockState);
		this.setBlock(world, position.add(13, 9, 22), blockState);
		this.setBlock(world, position.add(13, 10, 5), blockState);
		this.setBlock(world, position.add(13, 10, 21), blockState);
		this.setBlock(world, position.add(13, 11, 5), blockState);
		this.setBlock(world, position.add(13, 11, 21), blockState);
		this.setBlock(world, position.add(13, 12, 6), blockState);
		this.setBlock(world, position.add(13, 12, 20), blockState);
		this.setBlock(world, position.add(13, 13, 6), blockState);
		this.setBlock(world, position.add(13, 13, 20), blockState);
		this.setBlock(world, position.add(13, 14, 7), blockState);
		this.setBlock(world, position.add(13, 14, 19), blockState);
		this.setBlock(world, position.add(13, 15, 7), blockState);
		this.setBlock(world, position.add(13, 15, 19), blockState);
		this.setBlock(world, position.add(13, 16, 8), blockState);
		this.setBlock(world, position.add(13, 16, 18), blockState);
		this.setBlock(world, position.add(13, 17, 8), blockState);
		this.setBlock(world, position.add(13, 17, 18), blockState);
		this.setBlock(world, position.add(13, 18, 9), blockState);
		this.setBlock(world, position.add(13, 18, 17), blockState);
		this.setBlock(world, position.add(13, 19, 9), blockState);
		this.setBlock(world, position.add(13, 19, 17), blockState);
		this.setBlock(world, position.add(13, 20, 10), blockState);
		this.setBlock(world, position.add(13, 20, 16), blockState);
		this.setBlock(world, position.add(13, 21, 10), blockState);
		this.setBlock(world, position.add(13, 21, 16), blockState);
		this.setBlock(world, position.add(13, 22, 11), blockState);
		this.setBlock(world, position.add(13, 22, 15), blockState);
		this.setBlock(world, position.add(13, 23, 11), blockState);
		this.setBlock(world, position.add(13, 23, 15), blockState);
		this.setBlock(world, position.add(14, 2, 3), blockState);
		this.setBlock(world, position.add(14, 2, 23), blockState);
		this.setBlock(world, position.add(14, 3, 3), blockState);
		this.setBlock(world, position.add(14, 3, 23), blockState);
		this.setBlock(world, position.add(14, 4, 3), blockState);
		this.setBlock(world, position.add(14, 4, 23), blockState);
		this.setBlock(world, position.add(14, 5, 3), blockState);
		this.setBlock(world, position.add(14, 5, 23), blockState);
		this.setBlock(world, position.add(14, 6, 3), blockState);
		this.setBlock(world, position.add(14, 6, 23), blockState);
		this.setBlock(world, position.add(14, 7, 3), blockState);
		this.setBlock(world, position.add(14, 7, 23), blockState);
		this.setBlock(world, position.add(14, 8, 3), blockState);
		this.setBlock(world, position.add(14, 8, 4), blockState);
		this.setBlock(world, position.add(14, 8, 22), blockState);
		this.setBlock(world, position.add(14, 8, 23), blockState);
		this.setBlock(world, position.add(14, 9, 4), blockState);
		this.setBlock(world, position.add(14, 9, 22), blockState);
		this.setBlock(world, position.add(14, 10, 5), blockState);
		this.setBlock(world, position.add(14, 10, 21), blockState);
		this.setBlock(world, position.add(14, 11, 5), blockState);
		this.setBlock(world, position.add(14, 11, 21), blockState);
		this.setBlock(world, position.add(14, 12, 6), blockState);
		this.setBlock(world, position.add(14, 12, 20), blockState);
		this.setBlock(world, position.add(14, 13, 6), blockState);
		this.setBlock(world, position.add(14, 13, 20), blockState);
		this.setBlock(world, position.add(14, 14, 7), blockState);
		this.setBlock(world, position.add(14, 14, 19), blockState);
		this.setBlock(world, position.add(14, 15, 7), blockState);
		this.setBlock(world, position.add(14, 15, 19), blockState);
		this.setBlock(world, position.add(14, 16, 8), blockState);
		this.setBlock(world, position.add(14, 16, 18), blockState);
		this.setBlock(world, position.add(14, 17, 8), blockState);
		this.setBlock(world, position.add(14, 17, 18), blockState);
		this.setBlock(world, position.add(14, 18, 9), blockState);
		this.setBlock(world, position.add(14, 18, 17), blockState);
		this.setBlock(world, position.add(14, 19, 9), blockState);
		this.setBlock(world, position.add(14, 19, 17), blockState);
		this.setBlock(world, position.add(14, 20, 10), blockState);
		this.setBlock(world, position.add(14, 20, 16), blockState);
		this.setBlock(world, position.add(14, 21, 10), blockState);
		this.setBlock(world, position.add(14, 21, 16), blockState);
		this.setBlock(world, position.add(14, 22, 11), blockState);
		this.setBlock(world, position.add(14, 22, 15), blockState);
		this.setBlock(world, position.add(14, 23, 11), blockState);
		this.setBlock(world, position.add(14, 23, 15), blockState);
		this.setBlock(world, position.add(15, 2, 3), blockState);
		this.setBlock(world, position.add(15, 2, 23), blockState);
		this.setBlock(world, position.add(15, 3, 3), blockState);
		this.setBlock(world, position.add(15, 3, 23), blockState);
		this.setBlock(world, position.add(15, 4, 3), blockState);
		this.setBlock(world, position.add(15, 4, 23), blockState);
		this.setBlock(world, position.add(15, 5, 3), blockState);
		this.setBlock(world, position.add(15, 5, 23), blockState);
		this.setBlock(world, position.add(15, 6, 3), blockState);
		this.setBlock(world, position.add(15, 6, 23), blockState);
		this.setBlock(world, position.add(15, 7, 3), blockState);
		this.setBlock(world, position.add(15, 7, 23), blockState);
		this.setBlock(world, position.add(15, 8, 3), blockState);
		this.setBlock(world, position.add(15, 8, 4), blockState);
		this.setBlock(world, position.add(15, 8, 22), blockState);
		this.setBlock(world, position.add(15, 8, 23), blockState);
		this.setBlock(world, position.add(15, 9, 4), blockState);
		this.setBlock(world, position.add(15, 9, 22), blockState);
		this.setBlock(world, position.add(15, 10, 5), blockState);
		this.setBlock(world, position.add(15, 10, 21), blockState);
		this.setBlock(world, position.add(15, 11, 5), blockState);
		this.setBlock(world, position.add(15, 11, 21), blockState);
		this.setBlock(world, position.add(15, 12, 6), blockState);
		this.setBlock(world, position.add(15, 12, 20), blockState);
		this.setBlock(world, position.add(15, 13, 6), blockState);
		this.setBlock(world, position.add(15, 13, 20), blockState);
		this.setBlock(world, position.add(15, 14, 7), blockState);
		this.setBlock(world, position.add(15, 14, 19), blockState);
		this.setBlock(world, position.add(15, 15, 7), blockState);
		this.setBlock(world, position.add(15, 15, 19), blockState);
		this.setBlock(world, position.add(15, 16, 8), blockState);
		this.setBlock(world, position.add(15, 16, 18), blockState);
		this.setBlock(world, position.add(15, 17, 8), blockState);
		this.setBlock(world, position.add(15, 17, 18), blockState);
		this.setBlock(world, position.add(15, 18, 9), blockState);
		this.setBlock(world, position.add(15, 18, 17), blockState);
		this.setBlock(world, position.add(15, 19, 9), blockState);
		this.setBlock(world, position.add(15, 19, 17), blockState);
		this.setBlock(world, position.add(15, 20, 10), blockState);
		this.setBlock(world, position.add(15, 20, 16), blockState);
		this.setBlock(world, position.add(15, 21, 10), blockState);
		this.setBlock(world, position.add(15, 21, 16), blockState);
		this.setBlock(world, position.add(15, 22, 11), blockState);
		this.setBlock(world, position.add(15, 22, 15), blockState);
		this.setBlock(world, position.add(15, 23, 11), blockState);
		this.setBlock(world, position.add(15, 23, 15), blockState);
		this.setBlock(world, position.add(16, 2, 3), blockState);
		this.setBlock(world, position.add(16, 2, 23), blockState);
		this.setBlock(world, position.add(16, 3, 3), blockState);
		this.setBlock(world, position.add(16, 3, 23), blockState);
		this.setBlock(world, position.add(16, 4, 3), blockState);
		this.setBlock(world, position.add(16, 4, 23), blockState);
		this.setBlock(world, position.add(16, 5, 3), blockState);
		this.setBlock(world, position.add(16, 5, 23), blockState);
		this.setBlock(world, position.add(16, 6, 3), blockState);
		this.setBlock(world, position.add(16, 6, 23), blockState);
		this.setBlock(world, position.add(16, 7, 3), blockState);
		this.setBlock(world, position.add(16, 7, 23), blockState);
		this.setBlock(world, position.add(16, 8, 3), blockState);
		this.setBlock(world, position.add(16, 8, 4), blockState);
		this.setBlock(world, position.add(16, 8, 22), blockState);
		this.setBlock(world, position.add(16, 8, 23), blockState);
		this.setBlock(world, position.add(16, 9, 4), blockState);
		this.setBlock(world, position.add(16, 9, 22), blockState);
		this.setBlock(world, position.add(16, 10, 5), blockState);
		this.setBlock(world, position.add(16, 10, 21), blockState);
		this.setBlock(world, position.add(16, 11, 5), blockState);
		this.setBlock(world, position.add(16, 11, 21), blockState);
		this.setBlock(world, position.add(16, 12, 6), blockState);
		this.setBlock(world, position.add(16, 12, 20), blockState);
		this.setBlock(world, position.add(16, 13, 6), blockState);
		this.setBlock(world, position.add(16, 13, 20), blockState);
		this.setBlock(world, position.add(16, 14, 7), blockState);
		this.setBlock(world, position.add(16, 14, 19), blockState);
		this.setBlock(world, position.add(16, 15, 7), blockState);
		this.setBlock(world, position.add(16, 15, 19), blockState);
		this.setBlock(world, position.add(16, 16, 8), blockState);
		this.setBlock(world, position.add(16, 16, 18), blockState);
		this.setBlock(world, position.add(16, 17, 8), blockState);
		this.setBlock(world, position.add(16, 17, 18), blockState);
		this.setBlock(world, position.add(16, 18, 9), blockState);
		this.setBlock(world, position.add(16, 18, 17), blockState);
		this.setBlock(world, position.add(16, 19, 9), blockState);
		this.setBlock(world, position.add(16, 19, 10), blockState);
		this.setBlock(world, position.add(16, 19, 16), blockState);
		this.setBlock(world, position.add(16, 19, 17), blockState);
		this.setBlock(world, position.add(16, 20, 11), blockState);
		this.setBlock(world, position.add(16, 20, 15), blockState);
		this.setBlock(world, position.add(16, 21, 11), blockState);
		this.setBlock(world, position.add(16, 21, 15), blockState);
		this.setBlock(world, position.add(16, 22, 12), blockState);
		this.setBlock(world, position.add(16, 22, 13), blockState);
		this.setBlock(world, position.add(16, 22, 14), blockState);
		this.setBlock(world, position.add(16, 23, 12), blockState);
		this.setBlock(world, position.add(16, 23, 13), blockState);
		this.setBlock(world, position.add(16, 23, 14), blockState);
		this.setBlock(world, position.add(17, 2, 3), blockState);
		this.setBlock(world, position.add(17, 2, 23), blockState);
		this.setBlock(world, position.add(17, 3, 3), blockState);
		this.setBlock(world, position.add(17, 3, 23), blockState);
		this.setBlock(world, position.add(17, 4, 3), blockState);
		this.setBlock(world, position.add(17, 4, 23), blockState);
		this.setBlock(world, position.add(17, 5, 3), blockState);
		this.setBlock(world, position.add(17, 5, 23), blockState);
		this.setBlock(world, position.add(17, 6, 3), blockState);
		this.setBlock(world, position.add(17, 6, 23), blockState);
		this.setBlock(world, position.add(17, 7, 3), blockState);
		this.setBlock(world, position.add(17, 7, 23), blockState);
		this.setBlock(world, position.add(17, 8, 3), blockState);
		this.setBlock(world, position.add(17, 8, 4), blockState);
		this.setBlock(world, position.add(17, 8, 22), blockState);
		this.setBlock(world, position.add(17, 8, 23), blockState);
		this.setBlock(world, position.add(17, 9, 4), blockState);
		this.setBlock(world, position.add(17, 9, 5), blockState);
		this.setBlock(world, position.add(17, 9, 21), blockState);
		this.setBlock(world, position.add(17, 9, 22), blockState);
		this.setBlock(world, position.add(17, 10, 6), blockState);
		this.setBlock(world, position.add(17, 10, 20), blockState);
		this.setBlock(world, position.add(17, 11, 6), blockState);
		this.setBlock(world, position.add(17, 11, 20), blockState);
		this.setBlock(world, position.add(17, 12, 7), blockState);
		this.setBlock(world, position.add(17, 12, 19), blockState);
		this.setBlock(world, position.add(17, 13, 7), blockState);
		this.setBlock(world, position.add(17, 13, 19), blockState);
		this.setBlock(world, position.add(17, 14, 8), blockState);
		this.setBlock(world, position.add(17, 14, 18), blockState);
		this.setBlock(world, position.add(17, 15, 8), blockState);
		this.setBlock(world, position.add(17, 15, 18), blockState);
		this.setBlock(world, position.add(17, 16, 9), blockState);
		this.setBlock(world, position.add(17, 16, 17), blockState);
		this.setBlock(world, position.add(17, 17, 9), blockState);
		this.setBlock(world, position.add(17, 17, 17), blockState);
		this.setBlock(world, position.add(17, 18, 10), blockState);
		this.setBlock(world, position.add(17, 18, 16), blockState);
		this.setBlock(world, position.add(17, 19, 10), blockState);
		this.setBlock(world, position.add(17, 19, 11), blockState);
		this.setBlock(world, position.add(17, 19, 15), blockState);
		this.setBlock(world, position.add(17, 19, 16), blockState);
		this.setBlock(world, position.add(17, 20, 12), blockState);
		this.setBlock(world, position.add(17, 20, 13), blockState);
		this.setBlock(world, position.add(17, 20, 14), blockState);
		this.setBlock(world, position.add(17, 21, 12), blockState);
		this.setBlock(world, position.add(17, 21, 13), blockState);
		this.setBlock(world, position.add(17, 21, 14), blockState);
		this.setBlock(world, position.add(18, 2, 4), blockState);
		this.setBlock(world, position.add(18, 2, 22), blockState);
		this.setBlock(world, position.add(18, 3, 4), blockState);
		this.setBlock(world, position.add(18, 3, 22), blockState);
		this.setBlock(world, position.add(18, 4, 4), blockState);
		this.setBlock(world, position.add(18, 4, 22), blockState);
		this.setBlock(world, position.add(18, 5, 4), blockState);
		this.setBlock(world, position.add(18, 5, 22), blockState);
		this.setBlock(world, position.add(18, 6, 4), blockState);
		this.setBlock(world, position.add(18, 6, 22), blockState);
		this.setBlock(world, position.add(18, 7, 4), blockState);
		this.setBlock(world, position.add(18, 7, 22), blockState);
		this.setBlock(world, position.add(18, 8, 4), blockState);
		this.setBlock(world, position.add(18, 8, 5), blockState);
		this.setBlock(world, position.add(18, 8, 21), blockState);
		this.setBlock(world, position.add(18, 8, 22), blockState);
		this.setBlock(world, position.add(18, 9, 5), blockState);
		this.setBlock(world, position.add(18, 9, 21), blockState);
		this.setBlock(world, position.add(18, 10, 6), blockState);
		this.setBlock(world, position.add(18, 10, 20), blockState);
		this.setBlock(world, position.add(18, 11, 6), blockState);
		this.setBlock(world, position.add(18, 11, 20), blockState);
		this.setBlock(world, position.add(18, 12, 7), blockState);
		this.setBlock(world, position.add(18, 12, 19), blockState);
		this.setBlock(world, position.add(18, 13, 7), blockState);
		this.setBlock(world, position.add(18, 13, 19), blockState);
		this.setBlock(world, position.add(18, 14, 8), blockState);
		this.setBlock(world, position.add(18, 14, 18), blockState);
		this.setBlock(world, position.add(18, 15, 8), blockState);
		this.setBlock(world, position.add(18, 15, 9), blockState);
		this.setBlock(world, position.add(18, 15, 17), blockState);
		this.setBlock(world, position.add(18, 15, 18), blockState);
		this.setBlock(world, position.add(18, 16, 10), blockState);
		this.setBlock(world, position.add(18, 16, 16), blockState);
		this.setBlock(world, position.add(18, 17, 10), blockState);
		this.setBlock(world, position.add(18, 17, 16), blockState);
		this.setBlock(world, position.add(18, 18, 11), blockState);
		this.setBlock(world, position.add(18, 18, 12), blockState);
		this.setBlock(world, position.add(18, 18, 13), blockState);
		this.setBlock(world, position.add(18, 18, 14), blockState);
		this.setBlock(world, position.add(18, 18, 15), blockState);
		this.setBlock(world, position.add(18, 19, 11), blockState);
		this.setBlock(world, position.add(18, 19, 12), blockState);
		this.setBlock(world, position.add(18, 19, 13), blockState);
		this.setBlock(world, position.add(18, 19, 14), blockState);
		this.setBlock(world, position.add(18, 19, 15), blockState);
		this.setBlock(world, position.add(19, 2, 4), blockState);
		this.setBlock(world, position.add(19, 2, 22), blockState);
		this.setBlock(world, position.add(19, 3, 4), blockState);
		this.setBlock(world, position.add(19, 3, 22), blockState);
		this.setBlock(world, position.add(19, 4, 4), blockState);
		this.setBlock(world, position.add(19, 4, 22), blockState);
		this.setBlock(world, position.add(19, 5, 4), blockState);
		this.setBlock(world, position.add(19, 5, 22), blockState);
		this.setBlock(world, position.add(19, 6, 4), blockState);
		this.setBlock(world, position.add(19, 6, 22), blockState);
		this.setBlock(world, position.add(19, 7, 4), blockState);
		this.setBlock(world, position.add(19, 7, 22), blockState);
		this.setBlock(world, position.add(19, 8, 4), blockState);
		this.setBlock(world, position.add(19, 8, 5), blockState);
		this.setBlock(world, position.add(19, 8, 21), blockState);
		this.setBlock(world, position.add(19, 8, 22), blockState);
		this.setBlock(world, position.add(19, 9, 5), blockState);
		this.setBlock(world, position.add(19, 9, 6), blockState);
		this.setBlock(world, position.add(19, 9, 20), blockState);
		this.setBlock(world, position.add(19, 9, 21), blockState);
		this.setBlock(world, position.add(19, 10, 7), blockState);
		this.setBlock(world, position.add(19, 10, 19), blockState);
		this.setBlock(world, position.add(19, 11, 7), blockState);
		this.setBlock(world, position.add(19, 11, 19), blockState);
		this.setBlock(world, position.add(19, 12, 8), blockState);
		this.setBlock(world, position.add(19, 12, 18), blockState);
		this.setBlock(world, position.add(19, 13, 8), blockState);
		this.setBlock(world, position.add(19, 13, 18), blockState);
		this.setBlock(world, position.add(19, 14, 9), blockState);
		this.setBlock(world, position.add(19, 14, 10), blockState);
		this.setBlock(world, position.add(19, 14, 16), blockState);
		this.setBlock(world, position.add(19, 14, 17), blockState);
		this.setBlock(world, position.add(19, 15, 9), blockState);
		this.setBlock(world, position.add(19, 15, 10), blockState);
		this.setBlock(world, position.add(19, 15, 16), blockState);
		this.setBlock(world, position.add(19, 15, 17), blockState);
		this.setBlock(world, position.add(19, 16, 11), blockState);
		this.setBlock(world, position.add(19, 16, 12), blockState);
		this.setBlock(world, position.add(19, 16, 13), blockState);
		this.setBlock(world, position.add(19, 16, 14), blockState);
		this.setBlock(world, position.add(19, 16, 15), blockState);
		this.setBlock(world, position.add(19, 17, 11), blockState);
		this.setBlock(world, position.add(19, 17, 12), blockState);
		this.setBlock(world, position.add(19, 17, 13), blockState);
		this.setBlock(world, position.add(19, 17, 14), blockState);
		this.setBlock(world, position.add(19, 17, 15), blockState);
		this.setBlock(world, position.add(20, 2, 5), blockState);
		this.setBlock(world, position.add(20, 2, 21), blockState);
		this.setBlock(world, position.add(20, 3, 5), blockState);
		this.setBlock(world, position.add(20, 3, 21), blockState);
		this.setBlock(world, position.add(20, 4, 5), blockState);
		this.setBlock(world, position.add(20, 4, 21), blockState);
		this.setBlock(world, position.add(20, 5, 5), blockState);
		this.setBlock(world, position.add(20, 5, 21), blockState);
		this.setBlock(world, position.add(20, 6, 5), blockState);
		this.setBlock(world, position.add(20, 6, 21), blockState);
		this.setBlock(world, position.add(20, 7, 5), blockState);
		this.setBlock(world, position.add(20, 7, 21), blockState);
		this.setBlock(world, position.add(20, 8, 5), blockState);
		this.setBlock(world, position.add(20, 8, 6), blockState);
		this.setBlock(world, position.add(20, 8, 20), blockState);
		this.setBlock(world, position.add(20, 8, 21), blockState);
		this.setBlock(world, position.add(20, 9, 6), blockState);
		this.setBlock(world, position.add(20, 9, 20), blockState);
		this.setBlock(world, position.add(20, 10, 7), blockState);
		this.setBlock(world, position.add(20, 10, 8), blockState);
		this.setBlock(world, position.add(20, 10, 18), blockState);
		this.setBlock(world, position.add(20, 10, 19), blockState);
		this.setBlock(world, position.add(20, 11, 7), blockState);
		this.setBlock(world, position.add(20, 11, 8), blockState);
		this.setBlock(world, position.add(20, 11, 18), blockState);
		this.setBlock(world, position.add(20, 11, 19), blockState);
		this.setBlock(world, position.add(20, 12, 9), blockState);
		this.setBlock(world, position.add(20, 12, 10), blockState);
		this.setBlock(world, position.add(20, 12, 16), blockState);
		this.setBlock(world, position.add(20, 12, 17), blockState);
		this.setBlock(world, position.add(20, 13, 9), blockState);
		this.setBlock(world, position.add(20, 13, 10), blockState);
		this.setBlock(world, position.add(20, 13, 16), blockState);
		this.setBlock(world, position.add(20, 13, 17), blockState);
		this.setBlock(world, position.add(20, 14, 11), blockState);
		this.setBlock(world, position.add(20, 14, 12), blockState);
		this.setBlock(world, position.add(20, 14, 13), blockState);
		this.setBlock(world, position.add(20, 14, 14), blockState);
		this.setBlock(world, position.add(20, 14, 15), blockState);
		this.setBlock(world, position.add(20, 15, 11), blockState);
		this.setBlock(world, position.add(20, 15, 12), blockState);
		this.setBlock(world, position.add(20, 15, 13), blockState);
		this.setBlock(world, position.add(20, 15, 14), blockState);
		this.setBlock(world, position.add(20, 15, 15), blockState);
		this.setBlock(world, position.add(21, 2, 6), blockState);
		this.setBlock(world, position.add(21, 2, 20), blockState);
		this.setBlock(world, position.add(21, 3, 6), blockState);
		this.setBlock(world, position.add(21, 3, 20), blockState);
		this.setBlock(world, position.add(21, 4, 6), blockState);
		this.setBlock(world, position.add(21, 4, 20), blockState);
		this.setBlock(world, position.add(21, 5, 6), blockState);
		this.setBlock(world, position.add(21, 5, 20), blockState);
		this.setBlock(world, position.add(21, 6, 6), blockState);
		this.setBlock(world, position.add(21, 6, 20), blockState);
		this.setBlock(world, position.add(21, 7, 6), blockState);
		this.setBlock(world, position.add(21, 7, 20), blockState);
		this.setBlock(world, position.add(21, 8, 6), blockState);
		this.setBlock(world, position.add(21, 8, 7), blockState);
		this.setBlock(world, position.add(21, 8, 19), blockState);
		this.setBlock(world, position.add(21, 8, 20), blockState);
		this.setBlock(world, position.add(21, 9, 7), blockState);
		this.setBlock(world, position.add(21, 9, 8), blockState);
		this.setBlock(world, position.add(21, 9, 18), blockState);
		this.setBlock(world, position.add(21, 9, 19), blockState);
		this.setBlock(world, position.add(21, 10, 9), blockState);
		this.setBlock(world, position.add(21, 10, 10), blockState);
		this.setBlock(world, position.add(21, 10, 16), blockState);
		this.setBlock(world, position.add(21, 10, 17), blockState);
		this.setBlock(world, position.add(21, 11, 9), blockState);
		this.setBlock(world, position.add(21, 11, 10), blockState);
		this.setBlock(world, position.add(21, 11, 16), blockState);
		this.setBlock(world, position.add(21, 11, 17), blockState);
		this.setBlock(world, position.add(21, 12, 11), blockState);
		this.setBlock(world, position.add(21, 12, 12), blockState);
		this.setBlock(world, position.add(21, 12, 13), blockState);
		this.setBlock(world, position.add(21, 12, 14), blockState);
		this.setBlock(world, position.add(21, 12, 15), blockState);
		this.setBlock(world, position.add(21, 13, 11), blockState);
		this.setBlock(world, position.add(21, 13, 12), blockState);
		this.setBlock(world, position.add(21, 13, 13), blockState);
		this.setBlock(world, position.add(21, 13, 14), blockState);
		this.setBlock(world, position.add(21, 13, 15), blockState);
		this.setBlock(world, position.add(22, 2, 7), blockState);
		this.setBlock(world, position.add(22, 2, 19), blockState);
		this.setBlock(world, position.add(22, 3, 7), blockState);
		this.setBlock(world, position.add(22, 3, 19), blockState);
		this.setBlock(world, position.add(22, 4, 7), blockState);
		this.setBlock(world, position.add(22, 4, 19), blockState);
		this.setBlock(world, position.add(22, 5, 7), blockState);
		this.setBlock(world, position.add(22, 5, 19), blockState);
		this.setBlock(world, position.add(22, 6, 7), blockState);
		this.setBlock(world, position.add(22, 6, 19), blockState);
		this.setBlock(world, position.add(22, 7, 7), blockState);
		this.setBlock(world, position.add(22, 7, 19), blockState);
		this.setBlock(world, position.add(22, 8, 7), blockState);
		this.setBlock(world, position.add(22, 8, 8), blockState);
		this.setBlock(world, position.add(22, 8, 9), blockState);
		this.setBlock(world, position.add(22, 8, 17), blockState);
		this.setBlock(world, position.add(22, 8, 18), blockState);
		this.setBlock(world, position.add(22, 8, 19), blockState);
		this.setBlock(world, position.add(22, 9, 8), blockState);
		this.setBlock(world, position.add(22, 9, 9), blockState);
		this.setBlock(world, position.add(22, 9, 10), blockState);
		this.setBlock(world, position.add(22, 9, 16), blockState);
		this.setBlock(world, position.add(22, 9, 17), blockState);
		this.setBlock(world, position.add(22, 9, 18), blockState);
		this.setBlock(world, position.add(22, 10, 11), blockState);
		this.setBlock(world, position.add(22, 10, 12), blockState);
		this.setBlock(world, position.add(22, 10, 13), blockState);
		this.setBlock(world, position.add(22, 10, 14), blockState);
		this.setBlock(world, position.add(22, 10, 15), blockState);
		this.setBlock(world, position.add(22, 11, 11), blockState);
		this.setBlock(world, position.add(22, 11, 12), blockState);
		this.setBlock(world, position.add(22, 11, 13), blockState);
		this.setBlock(world, position.add(22, 11, 14), blockState);
		this.setBlock(world, position.add(22, 11, 15), blockState);
		this.setBlock(world, position.add(23, 2, 8), blockState);
		this.setBlock(world, position.add(23, 2, 9), blockState);
		this.setBlock(world, position.add(23, 2, 17), blockState);
		this.setBlock(world, position.add(23, 2, 18), blockState);
		this.setBlock(world, position.add(23, 3, 8), blockState);
		this.setBlock(world, position.add(23, 3, 9), blockState);
		this.setBlock(world, position.add(23, 3, 17), blockState);
		this.setBlock(world, position.add(23, 3, 18), blockState);
		this.setBlock(world, position.add(23, 4, 8), blockState);
		this.setBlock(world, position.add(23, 4, 9), blockState);
		this.setBlock(world, position.add(23, 4, 17), blockState);
		this.setBlock(world, position.add(23, 4, 18), blockState);
		this.setBlock(world, position.add(23, 5, 8), blockState);
		this.setBlock(world, position.add(23, 5, 9), blockState);
		this.setBlock(world, position.add(23, 5, 17), blockState);
		this.setBlock(world, position.add(23, 5, 18), blockState);
		this.setBlock(world, position.add(23, 6, 8), blockState);
		this.setBlock(world, position.add(23, 6, 9), blockState);
		this.setBlock(world, position.add(23, 6, 17), blockState);
		this.setBlock(world, position.add(23, 6, 18), blockState);
		this.setBlock(world, position.add(23, 7, 8), blockState);
		this.setBlock(world, position.add(23, 7, 9), blockState);
		this.setBlock(world, position.add(23, 7, 17), blockState);
		this.setBlock(world, position.add(23, 7, 18), blockState);
		this.setBlock(world, position.add(23, 8, 8), blockState);
		this.setBlock(world, position.add(23, 8, 9), blockState);
		this.setBlock(world, position.add(23, 8, 10), blockState);
		this.setBlock(world, position.add(23, 8, 11), blockState);
		this.setBlock(world, position.add(23, 8, 12), blockState);
		this.setBlock(world, position.add(23, 8, 13), blockState);
		this.setBlock(world, position.add(23, 8, 14), blockState);
		this.setBlock(world, position.add(23, 8, 15), blockState);
		this.setBlock(world, position.add(23, 8, 16), blockState);
		this.setBlock(world, position.add(23, 8, 17), blockState);
		this.setBlock(world, position.add(23, 8, 18), blockState);
		this.setBlock(world, position.add(23, 9, 10), blockState);
		this.setBlock(world, position.add(23, 9, 11), blockState);
		this.setBlock(world, position.add(23, 9, 12), blockState);
		this.setBlock(world, position.add(23, 9, 13), blockState);
		this.setBlock(world, position.add(23, 9, 14), blockState);
		this.setBlock(world, position.add(23, 9, 15), blockState);
		this.setBlock(world, position.add(23, 9, 16), blockState);
		this.setBlock(world, position.add(24, 2, 10), blockState);
		this.setBlock(world, position.add(24, 2, 11), blockState);
		// this.setBlock(world, position.add(24, 2, 12), -101);
		// this.setBlock(world, position.add(24, 2, 13), -101);
		this.setBlock(world, position.add(24, 2, 14), blockState);
		this.setBlock(world, position.add(24, 2, 15), blockState);
		this.setBlock(world, position.add(24, 2, 16), blockState);
		this.setBlock(world, position.add(24, 3, 10), blockState);
		this.setBlock(world, position.add(24, 3, 11), blockState);
		// this.setBlock(world, position.add(24, 3, 12), -101);
		// this.setBlock(world, position.add(24, 3, 13), -101);
		this.setBlock(world, position.add(24, 3, 14), blockState);
		this.setBlock(world, position.add(24, 3, 15), blockState);
		this.setBlock(world, position.add(24, 3, 16), blockState);
		this.setBlock(world, position.add(24, 4, 10), blockState);
		this.setBlock(world, position.add(24, 4, 11), blockState);
		this.setBlock(world, position.add(24, 4, 12), blockState);
		this.setBlock(world, position.add(24, 4, 13), blockState);
		this.setBlock(world, position.add(24, 4, 14), blockState);
		this.setBlock(world, position.add(24, 4, 15), blockState);
		this.setBlock(world, position.add(24, 4, 16), blockState);
		this.setBlock(world, position.add(24, 5, 10), blockState);
		this.setBlock(world, position.add(24, 5, 11), blockState);
		this.setBlock(world, position.add(24, 5, 12), blockState);
		this.setBlock(world, position.add(24, 5, 13), blockState);
		this.setBlock(world, position.add(24, 5, 14), blockState);
		this.setBlock(world, position.add(24, 5, 15), blockState);
		this.setBlock(world, position.add(24, 5, 16), blockState);
		this.setBlock(world, position.add(24, 6, 10), blockState);
		this.setBlock(world, position.add(24, 6, 11), blockState);
		this.setBlock(world, position.add(24, 6, 12), blockState);
		this.setBlock(world, position.add(24, 6, 13), blockState);
		this.setBlock(world, position.add(24, 6, 14), blockState);
		this.setBlock(world, position.add(24, 6, 15), blockState);
		this.setBlock(world, position.add(24, 6, 16), blockState);
		this.setBlock(world, position.add(24, 7, 10), blockState);
		this.setBlock(world, position.add(24, 7, 11), blockState);
		this.setBlock(world, position.add(24, 7, 12), blockState);
		this.setBlock(world, position.add(24, 7, 13), blockState);
		this.setBlock(world, position.add(24, 7, 14), blockState);
		this.setBlock(world, position.add(24, 7, 15), blockState);
		this.setBlock(world, position.add(24, 7, 16), blockState);
		this.setBlock(world, position.add(24, 8, 10), blockState);
		this.setBlock(world, position.add(24, 8, 11), blockState);
		this.setBlock(world, position.add(24, 8, 12), blockState);
		this.setBlock(world, position.add(24, 8, 13), blockState);
		this.setBlock(world, position.add(24, 8, 14), blockState);
		this.setBlock(world, position.add(24, 8, 15), blockState);
		this.setBlock(world, position.add(24, 8, 16), blockState);
		
		return true;
	}
}