/**
 * Zollern Galaxy by @author Zollern Wolf
 * Copyright 2016 - 2025
 * You may use this code to learn from,
 * but do not claim it as your own, and
 * do not redistribute it.
 */
package zollerngalaxy.worldgen;

import java.util.Random;
import net.minecraft.block.Block;
import net.minecraft.block.state.IBlockState;
import net.minecraft.util.math.BlockPos;
import net.minecraft.world.World;
import zollerngalaxy.blocks.ZGBlocks;

public class WorldGenOutpost extends ZGWorldGenMaster {
	
	IBlockState wallBlockState = null;
	IBlockState floorBlockState = null;
	
	public WorldGenOutpost(IBlockState wallBlockStateIn, IBlockState floorBlockStateIn) {
		this.wallBlockState = wallBlockStateIn;
		this.floorBlockState = floorBlockStateIn;
	}
	
	@Override
	public boolean generate(World worldIn, Random rand, BlockPos position) {
		if (!this.isValidSpawn(worldIn, position)) {
			return false;
		}
		
		Block wallBlock = this.wallBlockState.getBlock();
		Block floorBlock = this.floorBlockState.getBlock();
		
		this.setBlock(worldIn, position.add(4, 1, 10), wallBlock);
		this.setBlock(worldIn, position.add(4, 1, 11), wallBlock);
		this.setBlock(worldIn, position.add(4, 1, 12), wallBlock);
		this.setBlock(worldIn, position.add(4, 1, 13), wallBlock);
		this.setBlock(worldIn, position.add(4, 1, 14), wallBlock);
		this.setBlock(worldIn, position.add(4, 1, 15), wallBlock);
		this.setBlock(worldIn, position.add(4, 1, 16), wallBlock);
		this.setBlock(worldIn, position.add(4, 1, 17), wallBlock);
		this.setBlock(worldIn, position.add(4, 1, 18), wallBlock);
		this.setBlock(worldIn, position.add(4, 1, 19), wallBlock);
		this.setBlock(worldIn, position.add(4, 1, 20), wallBlock);
		this.setBlock(worldIn, position.add(4, 1, 21), wallBlock);
		this.setBlock(worldIn, position.add(4, 2, 10), wallBlock);
		this.setBlock(worldIn, position.add(4, 2, 11), wallBlock);
		this.setBlock(worldIn, position.add(4, 2, 12), wallBlock);
		this.setBlock(worldIn, position.add(4, 2, 13), wallBlock);
		this.setBlock(worldIn, position.add(4, 2, 14), wallBlock);
		this.setBlock(worldIn, position.add(4, 2, 15), wallBlock);
		this.setBlock(worldIn, position.add(4, 2, 16), wallBlock);
		this.setBlock(worldIn, position.add(4, 2, 17), wallBlock);
		this.setBlock(worldIn, position.add(4, 2, 18), wallBlock);
		this.setBlock(worldIn, position.add(4, 2, 19), wallBlock);
		this.setBlock(worldIn, position.add(4, 2, 20), wallBlock);
		this.setBlock(worldIn, position.add(4, 2, 21), wallBlock);
		this.setBlock(worldIn, position.add(5, 0, 10), floorBlock);
		this.setBlock(worldIn, position.add(5, 0, 11), floorBlock);
		this.setBlock(worldIn, position.add(5, 0, 12), floorBlock);
		this.setBlock(worldIn, position.add(5, 0, 13), floorBlock);
		this.setBlock(worldIn, position.add(5, 0, 14), floorBlock);
		this.setBlock(worldIn, position.add(5, 0, 15), floorBlock);
		this.setBlock(worldIn, position.add(5, 0, 16), floorBlock);
		this.setBlock(worldIn, position.add(5, 0, 17), floorBlock);
		this.setBlock(worldIn, position.add(5, 0, 18), floorBlock);
		this.setBlock(worldIn, position.add(5, 0, 19), floorBlock);
		this.setBlock(worldIn, position.add(5, 0, 20), floorBlock);
		this.setBlock(worldIn, position.add(5, 0, 21), floorBlock);
		this.setBlock(worldIn, position.add(5, 1, 10), wallBlock);
		this.setBlock(worldIn, position.add(5, 1, 11), wallBlock);
		this.setBlock(worldIn, position.add(5, 1, 12), wallBlock);
		this.setBlock(worldIn, position.add(5, 1, 13), wallBlock);
		this.setBlock(worldIn, position.add(5, 1, 14), wallBlock);
		this.setBlock(worldIn, position.add(5, 1, 15), wallBlock);
		this.setBlock(worldIn, position.add(5, 1, 16), wallBlock);
		this.setBlock(worldIn, position.add(5, 1, 17), wallBlock);
		this.setBlock(worldIn, position.add(5, 1, 18), wallBlock);
		this.setBlock(worldIn, position.add(5, 1, 19), wallBlock);
		this.setBlock(worldIn, position.add(5, 1, 20), wallBlock);
		this.setBlock(worldIn, position.add(5, 1, 21), wallBlock);
		this.setBlock(worldIn, position.add(5, 2, 10), wallBlock);
		this.setBlock(worldIn, position.add(5, 2, 11), wallBlock);
		this.setBlock(worldIn, position.add(5, 2, 12), wallBlock);
		this.setBlock(worldIn, position.add(5, 2, 13), wallBlock);
		this.setBlock(worldIn, position.add(5, 2, 14), ZGBlocks.blockBlueprintStation);
		this.setBlock(worldIn, position.add(5, 2, 15), wallBlock);
		this.setBlock(worldIn, position.add(5, 2, 16), ZGBlocks.blockHealingStation);
		this.setBlock(worldIn, position.add(5, 2, 17), wallBlock);
		this.setBlock(worldIn, position.add(5, 2, 18), wallBlock);
		this.setBlock(worldIn, position.add(5, 2, 19), wallBlock);
		this.setBlock(worldIn, position.add(5, 2, 20), wallBlock);
		this.setBlock(worldIn, position.add(5, 2, 21), wallBlock);
		this.setBlock(worldIn, position.add(5, 3, 10), wallBlock);
		this.setBlock(worldIn, position.add(5, 3, 11), wallBlock);
		this.setBlock(worldIn, position.add(5, 3, 12), wallBlock);
		this.setBlock(worldIn, position.add(5, 3, 13), wallBlock);
		this.setBlock(worldIn, position.add(5, 3, 14), wallBlock);
		this.setBlock(worldIn, position.add(5, 3, 15), wallBlock);
		this.setBlock(worldIn, position.add(5, 3, 16), wallBlock);
		this.setBlock(worldIn, position.add(5, 3, 17), wallBlock);
		this.setBlock(worldIn, position.add(5, 3, 18), wallBlock);
		this.setBlock(worldIn, position.add(5, 3, 19), wallBlock);
		this.setBlock(worldIn, position.add(5, 3, 20), wallBlock);
		this.setBlock(worldIn, position.add(5, 3, 21), wallBlock);
		this.setBlock(worldIn, position.add(6, 0, 9), floorBlock);
		this.setBlock(worldIn, position.add(6, 0, 10), floorBlock);
		this.setBlock(worldIn, position.add(6, 0, 11), floorBlock);
		this.setBlock(worldIn, position.add(6, 0, 12), floorBlock);
		this.setBlock(worldIn, position.add(6, 0, 13), floorBlock);
		this.setBlock(worldIn, position.add(6, 0, 14), floorBlock);
		this.setBlock(worldIn, position.add(6, 0, 15), floorBlock);
		this.setBlock(worldIn, position.add(6, 0, 16), floorBlock);
		this.setBlock(worldIn, position.add(6, 0, 17), floorBlock);
		this.setBlock(worldIn, position.add(6, 0, 18), floorBlock);
		this.setBlock(worldIn, position.add(6, 0, 19), floorBlock);
		this.setBlock(worldIn, position.add(6, 0, 20), floorBlock);
		this.setBlock(worldIn, position.add(6, 0, 21), floorBlock);
		this.setBlock(worldIn, position.add(6, 1, 9), wallBlock);
		this.setBlock(worldIn, position.add(6, 1, 22), wallBlock);
		this.setBlock(worldIn, position.add(6, 2, 9), wallBlock);
		this.setBlock(worldIn, position.add(6, 2, 22), wallBlock);
		this.setBlock(worldIn, position.add(6, 3, 9), wallBlock);
		this.setBlock(worldIn, position.add(6, 3, 22), wallBlock);
		this.setBlock(worldIn, position.add(6, 4, 10), wallBlock);
		this.setBlock(worldIn, position.add(6, 4, 11), wallBlock);
		this.setBlock(worldIn, position.add(6, 4, 12), wallBlock);
		this.setBlock(worldIn, position.add(6, 4, 13), wallBlock);
		this.setBlock(worldIn, position.add(6, 4, 14), wallBlock);
		this.setBlock(worldIn, position.add(6, 4, 15), wallBlock);
		this.setBlock(worldIn, position.add(6, 4, 16), wallBlock);
		this.setBlock(worldIn, position.add(6, 4, 17), wallBlock);
		this.setBlock(worldIn, position.add(6, 4, 18), wallBlock);
		this.setBlock(worldIn, position.add(6, 4, 19), wallBlock);
		this.setBlock(worldIn, position.add(6, 4, 20), wallBlock);
		this.setBlock(worldIn, position.add(6, 4, 21), wallBlock);
		this.setBlock(worldIn, position.add(7, 0, 9), floorBlock);
		this.setBlock(worldIn, position.add(7, 0, 10), floorBlock);
		this.setBlock(worldIn, position.add(7, 0, 11), floorBlock);
		this.setBlock(worldIn, position.add(7, 0, 12), floorBlock);
		this.setBlock(worldIn, position.add(7, 0, 13), floorBlock);
		this.setBlock(worldIn, position.add(7, 0, 14), floorBlock);
		this.setBlock(worldIn, position.add(7, 0, 15), floorBlock);
		this.setBlock(worldIn, position.add(7, 0, 16), floorBlock);
		this.setBlock(worldIn, position.add(7, 0, 17), floorBlock);
		this.setBlock(worldIn, position.add(7, 0, 18), floorBlock);
		this.setBlock(worldIn, position.add(7, 0, 19), floorBlock);
		this.setBlock(worldIn, position.add(7, 0, 20), floorBlock);
		this.setBlock(worldIn, position.add(7, 0, 21), floorBlock);
		this.setBlock(worldIn, position.add(7, 1, 9), wallBlock);
		this.setBlock(worldIn, position.add(7, 1, 22), wallBlock);
		this.setBlock(worldIn, position.add(7, 2, 9), wallBlock);
		this.setBlock(worldIn, position.add(7, 2, 22), wallBlock);
		this.setBlock(worldIn, position.add(7, 3, 9), wallBlock);
		this.setBlock(worldIn, position.add(7, 3, 22), wallBlock);
		this.setBlock(worldIn, position.add(7, 4, 10), wallBlock);
		this.setBlock(worldIn, position.add(7, 4, 21), wallBlock);
		this.setBlock(worldIn, position.add(7, 5, 11), wallBlock);
		this.setBlock(worldIn, position.add(7, 5, 12), wallBlock);
		this.setBlock(worldIn, position.add(7, 5, 13), wallBlock);
		this.setBlock(worldIn, position.add(7, 5, 14), wallBlock);
		this.setBlock(worldIn, position.add(7, 5, 15), wallBlock);
		this.setBlock(worldIn, position.add(7, 5, 16), wallBlock);
		this.setBlock(worldIn, position.add(7, 5, 17), wallBlock);
		this.setBlock(worldIn, position.add(7, 5, 18), wallBlock);
		this.setBlock(worldIn, position.add(7, 5, 19), wallBlock);
		this.setBlock(worldIn, position.add(7, 5, 20), wallBlock);
		this.setBlock(worldIn, position.add(8, 0, 9), floorBlock);
		this.setBlock(worldIn, position.add(8, 0, 10), floorBlock);
		this.setBlock(worldIn, position.add(8, 0, 11), floorBlock);
		this.setBlock(worldIn, position.add(8, 0, 12), floorBlock);
		this.setBlock(worldIn, position.add(8, 0, 13), floorBlock);
		this.setBlock(worldIn, position.add(8, 0, 14), floorBlock);
		this.setBlock(worldIn, position.add(8, 0, 15), floorBlock);
		this.setBlock(worldIn, position.add(8, 0, 16), floorBlock);
		this.setBlock(worldIn, position.add(8, 0, 17), floorBlock);
		this.setBlock(worldIn, position.add(8, 0, 18), floorBlock);
		this.setBlock(worldIn, position.add(8, 0, 19), floorBlock);
		this.setBlock(worldIn, position.add(8, 0, 20), floorBlock);
		this.setBlock(worldIn, position.add(8, 0, 21), floorBlock);
		this.setBlock(worldIn, position.add(8, 1, 9), wallBlock);
		this.setBlock(worldIn, position.add(8, 1, 22), wallBlock);
		this.setBlock(worldIn, position.add(8, 2, 9), wallBlock);
		this.setBlock(worldIn, position.add(8, 2, 22), wallBlock);
		this.setBlock(worldIn, position.add(8, 3, 9), wallBlock);
		this.setBlock(worldIn, position.add(8, 3, 22), wallBlock);
		this.setBlock(worldIn, position.add(8, 4, 10), wallBlock);
		this.setBlock(worldIn, position.add(8, 4, 21), wallBlock);
		this.setBlock(worldIn, position.add(8, 5, 11), wallBlock);
		this.setBlock(worldIn, position.add(8, 5, 20), wallBlock);
		this.setBlock(worldIn, position.add(8, 6, 12), wallBlock);
		this.setBlock(worldIn, position.add(8, 6, 13), wallBlock);
		this.setBlock(worldIn, position.add(8, 6, 14), wallBlock);
		this.setBlock(worldIn, position.add(8, 6, 15), wallBlock);
		this.setBlock(worldIn, position.add(8, 6, 16), wallBlock);
		this.setBlock(worldIn, position.add(8, 6, 17), wallBlock);
		this.setBlock(worldIn, position.add(8, 6, 18), wallBlock);
		this.setBlock(worldIn, position.add(8, 6, 19), wallBlock);
		this.setBlock(worldIn, position.add(9, 0, 9), floorBlock);
		this.setBlock(worldIn, position.add(9, 0, 10), floorBlock);
		this.setBlock(worldIn, position.add(9, 0, 11), floorBlock);
		this.setBlock(worldIn, position.add(9, 0, 12), floorBlock);
		this.setBlock(worldIn, position.add(9, 0, 13), floorBlock);
		this.setBlock(worldIn, position.add(9, 0, 14), floorBlock);
		this.setBlock(worldIn, position.add(9, 0, 15), floorBlock);
		this.setBlock(worldIn, position.add(9, 0, 16), floorBlock);
		this.setBlock(worldIn, position.add(9, 0, 17), floorBlock);
		this.setBlock(worldIn, position.add(9, 0, 18), floorBlock);
		this.setBlock(worldIn, position.add(9, 0, 19), floorBlock);
		this.setBlock(worldIn, position.add(9, 0, 20), floorBlock);
		this.setBlock(worldIn, position.add(9, 0, 21), floorBlock);
		this.setBlock(worldIn, position.add(9, 1, 9), wallBlock);
		this.setBlock(worldIn, position.add(9, 1, 22), wallBlock);
		this.setBlock(worldIn, position.add(9, 2, 9), wallBlock);
		this.setBlock(worldIn, position.add(9, 2, 22), wallBlock);
		this.setBlock(worldIn, position.add(9, 3, 9), wallBlock);
		this.setBlock(worldIn, position.add(9, 3, 22), wallBlock);
		this.setBlock(worldIn, position.add(9, 4, 10), wallBlock);
		this.setBlock(worldIn, position.add(9, 4, 21), wallBlock);
		this.setBlock(worldIn, position.add(9, 5, 11), wallBlock);
		this.setBlock(worldIn, position.add(9, 5, 20), wallBlock);
		this.setBlock(worldIn, position.add(9, 6, 12), wallBlock);
		this.setBlock(worldIn, position.add(9, 6, 19), wallBlock);
		this.setBlock(worldIn, position.add(9, 7, 13), wallBlock);
		this.setBlock(worldIn, position.add(9, 7, 14), wallBlock);
		this.setBlock(worldIn, position.add(9, 7, 15), wallBlock);
		this.setBlock(worldIn, position.add(9, 7, 16), wallBlock);
		this.setBlock(worldIn, position.add(9, 7, 17), wallBlock);
		this.setBlock(worldIn, position.add(9, 7, 18), wallBlock);
		this.setBlock(worldIn, position.add(10, 0, 9), floorBlock);
		this.setBlock(worldIn, position.add(10, 0, 10), floorBlock);
		this.setBlock(worldIn, position.add(10, 0, 11), floorBlock);
		this.setBlock(worldIn, position.add(10, 0, 12), floorBlock);
		this.setBlock(worldIn, position.add(10, 0, 13), floorBlock);
		this.setBlock(worldIn, position.add(10, 0, 14), floorBlock);
		this.setBlock(worldIn, position.add(10, 0, 15), floorBlock);
		this.setBlock(worldIn, position.add(10, 0, 16), floorBlock);
		this.setBlock(worldIn, position.add(10, 0, 17), floorBlock);
		this.setBlock(worldIn, position.add(10, 0, 18), floorBlock);
		this.setBlock(worldIn, position.add(10, 0, 19), floorBlock);
		this.setBlock(worldIn, position.add(10, 0, 20), floorBlock);
		this.setBlock(worldIn, position.add(10, 0, 21), floorBlock);
		this.setBlock(worldIn, position.add(10, 1, 22), wallBlock);
		this.setBlock(worldIn, position.add(10, 2, 22), wallBlock);
		this.setBlock(worldIn, position.add(10, 3, 9), wallBlock);
		this.setBlock(worldIn, position.add(10, 3, 22), wallBlock);
		this.setBlock(worldIn, position.add(10, 4, 10), wallBlock);
		this.setBlock(worldIn, position.add(10, 4, 21), wallBlock);
		this.setBlock(worldIn, position.add(10, 5, 11), wallBlock);
		this.setBlock(worldIn, position.add(10, 5, 20), wallBlock);
		this.setBlock(worldIn, position.add(10, 6, 12), wallBlock);
		this.setBlock(worldIn, position.add(10, 6, 19), wallBlock);
		this.setBlock(worldIn, position.add(10, 7, 13), wallBlock);
		this.setBlock(worldIn, position.add(10, 7, 14), wallBlock);
		this.setBlock(worldIn, position.add(10, 7, 15), wallBlock);
		this.setBlock(worldIn, position.add(10, 7, 16), wallBlock);
		this.setBlock(worldIn, position.add(10, 7, 17), wallBlock);
		this.setBlock(worldIn, position.add(10, 7, 18), wallBlock);
		this.setBlock(worldIn, position.add(11, 0, 9), floorBlock);
		this.setBlock(worldIn, position.add(11, 0, 10), floorBlock);
		this.setBlock(worldIn, position.add(11, 0, 11), floorBlock);
		this.setBlock(worldIn, position.add(11, 0, 12), floorBlock);
		this.setBlock(worldIn, position.add(11, 0, 13), floorBlock);
		this.setBlock(worldIn, position.add(11, 0, 14), floorBlock);
		this.setBlock(worldIn, position.add(11, 0, 15), floorBlock);
		this.setBlock(worldIn, position.add(11, 0, 16), floorBlock);
		this.setBlock(worldIn, position.add(11, 0, 17), floorBlock);
		this.setBlock(worldIn, position.add(11, 0, 18), floorBlock);
		this.setBlock(worldIn, position.add(11, 0, 19), floorBlock);
		this.setBlock(worldIn, position.add(11, 0, 20), floorBlock);
		this.setBlock(worldIn, position.add(11, 0, 21), floorBlock);
		this.setBlock(worldIn, position.add(11, 1, 22), wallBlock);
		this.setBlock(worldIn, position.add(11, 2, 22), wallBlock);
		this.setBlock(worldIn, position.add(11, 3, 9), wallBlock);
		this.setBlock(worldIn, position.add(11, 3, 22), wallBlock);
		this.setBlock(worldIn, position.add(11, 4, 10), wallBlock);
		this.setBlock(worldIn, position.add(11, 4, 21), wallBlock);
		this.setBlock(worldIn, position.add(11, 5, 11), wallBlock);
		this.setBlock(worldIn, position.add(11, 5, 20), wallBlock);
		this.setBlock(worldIn, position.add(11, 6, 12), wallBlock);
		this.setBlock(worldIn, position.add(11, 6, 19), wallBlock);
		this.setBlock(worldIn, position.add(11, 7, 13), wallBlock);
		this.setBlock(worldIn, position.add(11, 7, 14), wallBlock);
		this.setBlock(worldIn, position.add(11, 7, 15), wallBlock);
		this.setBlock(worldIn, position.add(11, 7, 16), wallBlock);
		this.setBlock(worldIn, position.add(11, 7, 17), wallBlock);
		this.setBlock(worldIn, position.add(11, 7, 18), wallBlock);
		this.setBlock(worldIn, position.add(12, 0, 9), floorBlock);
		this.setBlock(worldIn, position.add(12, 0, 10), floorBlock);
		this.setBlock(worldIn, position.add(12, 0, 11), floorBlock);
		this.setBlock(worldIn, position.add(12, 0, 12), floorBlock);
		this.setBlock(worldIn, position.add(12, 0, 13), floorBlock);
		this.setBlock(worldIn, position.add(12, 0, 14), floorBlock);
		this.setBlock(worldIn, position.add(12, 0, 15), floorBlock);
		this.setBlock(worldIn, position.add(12, 0, 16), floorBlock);
		this.setBlock(worldIn, position.add(12, 0, 17), floorBlock);
		this.setBlock(worldIn, position.add(12, 0, 18), floorBlock);
		this.setBlock(worldIn, position.add(12, 0, 19), floorBlock);
		this.setBlock(worldIn, position.add(12, 0, 20), floorBlock);
		this.setBlock(worldIn, position.add(12, 0, 21), floorBlock);
		this.setBlock(worldIn, position.add(12, 1, 9), wallBlock);
		this.setBlock(worldIn, position.add(12, 1, 22), wallBlock);
		this.setBlock(worldIn, position.add(12, 2, 9), wallBlock);
		this.setBlock(worldIn, position.add(12, 2, 22), wallBlock);
		this.setBlock(worldIn, position.add(12, 3, 9), wallBlock);
		this.setBlock(worldIn, position.add(12, 3, 22), wallBlock);
		this.setBlock(worldIn, position.add(12, 4, 10), wallBlock);
		this.setBlock(worldIn, position.add(12, 4, 21), wallBlock);
		this.setBlock(worldIn, position.add(12, 5, 11), wallBlock);
		this.setBlock(worldIn, position.add(12, 5, 20), wallBlock);
		this.setBlock(worldIn, position.add(12, 6, 12), wallBlock);
		this.setBlock(worldIn, position.add(12, 6, 19), wallBlock);
		this.setBlock(worldIn, position.add(12, 7, 13), wallBlock);
		this.setBlock(worldIn, position.add(12, 7, 14), wallBlock);
		this.setBlock(worldIn, position.add(12, 7, 15), wallBlock);
		this.setBlock(worldIn, position.add(12, 7, 16), wallBlock);
		this.setBlock(worldIn, position.add(12, 7, 17), wallBlock);
		this.setBlock(worldIn, position.add(12, 7, 18), wallBlock);
		this.setBlock(worldIn, position.add(13, 0, 9), floorBlock);
		this.setBlock(worldIn, position.add(13, 0, 10), floorBlock);
		this.setBlock(worldIn, position.add(13, 0, 11), floorBlock);
		this.setBlock(worldIn, position.add(13, 0, 12), floorBlock);
		this.setBlock(worldIn, position.add(13, 0, 13), floorBlock);
		this.setBlock(worldIn, position.add(13, 0, 14), floorBlock);
		this.setBlock(worldIn, position.add(13, 0, 15), floorBlock);
		this.setBlock(worldIn, position.add(13, 0, 16), floorBlock);
		this.setBlock(worldIn, position.add(13, 0, 17), floorBlock);
		this.setBlock(worldIn, position.add(13, 0, 18), floorBlock);
		this.setBlock(worldIn, position.add(13, 0, 19), floorBlock);
		this.setBlock(worldIn, position.add(13, 0, 20), floorBlock);
		this.setBlock(worldIn, position.add(13, 0, 21), floorBlock);
		this.setBlock(worldIn, position.add(13, 1, 9), wallBlock);
		this.setBlock(worldIn, position.add(13, 1, 22), wallBlock);
		this.setBlock(worldIn, position.add(13, 2, 9), wallBlock);
		this.setBlock(worldIn, position.add(13, 2, 22), wallBlock);
		this.setBlock(worldIn, position.add(13, 3, 9), wallBlock);
		this.setBlock(worldIn, position.add(13, 3, 22), wallBlock);
		this.setBlock(worldIn, position.add(13, 4, 10), wallBlock);
		this.setBlock(worldIn, position.add(13, 4, 21), wallBlock);
		this.setBlock(worldIn, position.add(13, 5, 11), wallBlock);
		this.setBlock(worldIn, position.add(13, 5, 20), wallBlock);
		this.setBlock(worldIn, position.add(13, 6, 12), wallBlock);
		this.setBlock(worldIn, position.add(13, 6, 13), wallBlock);
		this.setBlock(worldIn, position.add(13, 6, 14), wallBlock);
		this.setBlock(worldIn, position.add(13, 6, 15), wallBlock);
		this.setBlock(worldIn, position.add(13, 6, 16), wallBlock);
		this.setBlock(worldIn, position.add(13, 6, 17), wallBlock);
		this.setBlock(worldIn, position.add(13, 6, 18), wallBlock);
		this.setBlock(worldIn, position.add(13, 6, 19), wallBlock);
		this.setBlock(worldIn, position.add(14, 0, 9), floorBlock);
		this.setBlock(worldIn, position.add(14, 0, 10), floorBlock);
		this.setBlock(worldIn, position.add(14, 0, 11), floorBlock);
		this.setBlock(worldIn, position.add(14, 0, 12), floorBlock);
		this.setBlock(worldIn, position.add(14, 0, 13), floorBlock);
		this.setBlock(worldIn, position.add(14, 0, 14), floorBlock);
		this.setBlock(worldIn, position.add(14, 0, 15), floorBlock);
		this.setBlock(worldIn, position.add(14, 0, 16), floorBlock);
		this.setBlock(worldIn, position.add(14, 0, 17), floorBlock);
		this.setBlock(worldIn, position.add(14, 0, 18), floorBlock);
		this.setBlock(worldIn, position.add(14, 0, 19), floorBlock);
		this.setBlock(worldIn, position.add(14, 0, 20), floorBlock);
		this.setBlock(worldIn, position.add(14, 0, 21), floorBlock);
		this.setBlock(worldIn, position.add(14, 1, 9), wallBlock);
		this.setBlock(worldIn, position.add(14, 1, 22), wallBlock);
		this.setBlock(worldIn, position.add(14, 2, 9), wallBlock);
		this.setBlock(worldIn, position.add(14, 2, 22), wallBlock);
		this.setBlock(worldIn, position.add(14, 3, 9), wallBlock);
		this.setBlock(worldIn, position.add(14, 3, 22), wallBlock);
		this.setBlock(worldIn, position.add(14, 4, 10), wallBlock);
		this.setBlock(worldIn, position.add(14, 4, 21), wallBlock);
		this.setBlock(worldIn, position.add(14, 5, 11), wallBlock);
		this.setBlock(worldIn, position.add(14, 5, 12), wallBlock);
		this.setBlock(worldIn, position.add(14, 5, 13), wallBlock);
		this.setBlock(worldIn, position.add(14, 5, 14), wallBlock);
		this.setBlock(worldIn, position.add(14, 5, 15), wallBlock);
		this.setBlock(worldIn, position.add(14, 5, 16), wallBlock);
		this.setBlock(worldIn, position.add(14, 5, 17), wallBlock);
		this.setBlock(worldIn, position.add(14, 5, 18), wallBlock);
		this.setBlock(worldIn, position.add(14, 5, 19), wallBlock);
		this.setBlock(worldIn, position.add(14, 5, 20), wallBlock);
		this.setBlock(worldIn, position.add(15, 0, 9), floorBlock);
		this.setBlock(worldIn, position.add(15, 0, 10), floorBlock);
		this.setBlock(worldIn, position.add(15, 0, 11), floorBlock);
		this.setBlock(worldIn, position.add(15, 0, 12), floorBlock);
		this.setBlock(worldIn, position.add(15, 0, 13), floorBlock);
		this.setBlock(worldIn, position.add(15, 0, 14), floorBlock);
		this.setBlock(worldIn, position.add(15, 0, 15), floorBlock);
		this.setBlock(worldIn, position.add(15, 0, 16), floorBlock);
		this.setBlock(worldIn, position.add(15, 0, 17), floorBlock);
		this.setBlock(worldIn, position.add(15, 0, 18), floorBlock);
		this.setBlock(worldIn, position.add(15, 0, 19), floorBlock);
		this.setBlock(worldIn, position.add(15, 0, 20), floorBlock);
		this.setBlock(worldIn, position.add(15, 0, 21), floorBlock);
		this.setBlock(worldIn, position.add(15, 1, 9), wallBlock);
		this.setBlock(worldIn, position.add(15, 1, 22), wallBlock);
		this.setBlock(worldIn, position.add(15, 2, 9), wallBlock);
		this.setBlock(worldIn, position.add(15, 2, 22), wallBlock);
		this.setBlock(worldIn, position.add(15, 3, 9), wallBlock);
		this.setBlock(worldIn, position.add(15, 3, 22), wallBlock);
		this.setBlock(worldIn, position.add(15, 4, 10), wallBlock);
		this.setBlock(worldIn, position.add(15, 4, 11), wallBlock);
		this.setBlock(worldIn, position.add(15, 4, 12), wallBlock);
		this.setBlock(worldIn, position.add(15, 4, 13), wallBlock);
		this.setBlock(worldIn, position.add(15, 4, 14), wallBlock);
		this.setBlock(worldIn, position.add(15, 4, 15), wallBlock);
		this.setBlock(worldIn, position.add(15, 4, 16), wallBlock);
		this.setBlock(worldIn, position.add(15, 4, 17), wallBlock);
		this.setBlock(worldIn, position.add(15, 4, 18), wallBlock);
		this.setBlock(worldIn, position.add(15, 4, 19), wallBlock);
		this.setBlock(worldIn, position.add(15, 4, 20), wallBlock);
		this.setBlock(worldIn, position.add(15, 4, 21), wallBlock);
		this.setBlock(worldIn, position.add(16, 1, 10), wallBlock);
		this.setBlock(worldIn, position.add(16, 1, 11), wallBlock);
		this.setBlock(worldIn, position.add(16, 1, 12), wallBlock);
		this.setBlock(worldIn, position.add(16, 1, 13), wallBlock);
		this.setBlock(worldIn, position.add(16, 1, 14), wallBlock);
		this.setBlock(worldIn, position.add(16, 1, 15), wallBlock);
		this.setBlock(worldIn, position.add(16, 1, 16), wallBlock);
		this.setBlock(worldIn, position.add(16, 1, 17), wallBlock);
		this.setBlock(worldIn, position.add(16, 1, 18), wallBlock);
		this.setBlock(worldIn, position.add(16, 1, 19), wallBlock);
		this.setBlock(worldIn, position.add(16, 1, 20), wallBlock);
		this.setBlock(worldIn, position.add(16, 1, 21), wallBlock);
		this.setBlock(worldIn, position.add(16, 2, 10), wallBlock);
		this.setBlock(worldIn, position.add(16, 2, 11), wallBlock);
		this.setBlock(worldIn, position.add(16, 2, 12), wallBlock);
		this.setBlock(worldIn, position.add(16, 2, 13), wallBlock);
		this.setBlock(worldIn, position.add(16, 2, 14), wallBlock);
		this.setBlock(worldIn, position.add(16, 2, 15), wallBlock);
		this.setBlock(worldIn, position.add(16, 2, 16), wallBlock);
		this.setBlock(worldIn, position.add(16, 2, 17), wallBlock);
		this.setBlock(worldIn, position.add(16, 2, 18), wallBlock);
		this.setBlock(worldIn, position.add(16, 2, 19), wallBlock);
		this.setBlock(worldIn, position.add(16, 2, 20), wallBlock);
		this.setBlock(worldIn, position.add(16, 2, 21), wallBlock);
		this.setBlock(worldIn, position.add(16, 3, 10), wallBlock);
		this.setBlock(worldIn, position.add(16, 3, 11), wallBlock);
		this.setBlock(worldIn, position.add(16, 3, 12), wallBlock);
		this.setBlock(worldIn, position.add(16, 3, 13), wallBlock);
		this.setBlock(worldIn, position.add(16, 3, 14), wallBlock);
		this.setBlock(worldIn, position.add(16, 3, 15), wallBlock);
		this.setBlock(worldIn, position.add(16, 3, 16), wallBlock);
		this.setBlock(worldIn, position.add(16, 3, 17), wallBlock);
		this.setBlock(worldIn, position.add(16, 3, 18), wallBlock);
		this.setBlock(worldIn, position.add(16, 3, 19), wallBlock);
		this.setBlock(worldIn, position.add(16, 3, 20), wallBlock);
		this.setBlock(worldIn, position.add(16, 3, 21), wallBlock);
		this.setBlock(worldIn, position.add(17, 1, 10), wallBlock);
		this.setBlock(worldIn, position.add(17, 1, 11), wallBlock);
		this.setBlock(worldIn, position.add(17, 1, 12), wallBlock);
		this.setBlock(worldIn, position.add(17, 1, 13), wallBlock);
		this.setBlock(worldIn, position.add(17, 1, 14), wallBlock);
		this.setBlock(worldIn, position.add(17, 1, 15), wallBlock);
		this.setBlock(worldIn, position.add(17, 1, 16), wallBlock);
		this.setBlock(worldIn, position.add(17, 1, 17), wallBlock);
		this.setBlock(worldIn, position.add(17, 1, 18), wallBlock);
		this.setBlock(worldIn, position.add(17, 1, 19), wallBlock);
		this.setBlock(worldIn, position.add(17, 1, 20), wallBlock);
		this.setBlock(worldIn, position.add(17, 1, 21), wallBlock);
		this.setBlock(worldIn, position.add(17, 2, 10), wallBlock);
		this.setBlock(worldIn, position.add(17, 2, 11), wallBlock);
		this.setBlock(worldIn, position.add(17, 2, 12), wallBlock);
		this.setBlock(worldIn, position.add(17, 2, 13), wallBlock);
		this.setBlock(worldIn, position.add(17, 2, 14), wallBlock);
		this.setBlock(worldIn, position.add(17, 2, 15), wallBlock);
		this.setBlock(worldIn, position.add(17, 2, 16), wallBlock);
		this.setBlock(worldIn, position.add(17, 2, 17), wallBlock);
		this.setBlock(worldIn, position.add(17, 2, 18), wallBlock);
		this.setBlock(worldIn, position.add(17, 2, 19), wallBlock);
		this.setBlock(worldIn, position.add(17, 2, 20), wallBlock);
		this.setBlock(worldIn, position.add(17, 2, 21), wallBlock);
		
		return true;
	}
}